<robot name = "robot">
    <link name="0">
        <inertial>
            <origin xyz="0 0 0.35" rpy="0 0 0"/>
            <mass value="1" />
            <inertia ixx="100" ixy="0" ixz="0" iyy="100" iyz="0" izz="100" />
        </inertial>
        <visual>
            <origin xyz="0 0 0.35" rpy="0 0 0"/>
            <geometry>
                <box size="0.7 0.7 0.7" />
            </geometry>
            <material name="Green">
                <color rgba="0 128 0 1"/>
            </material>
        </visual>
        <collision>
            <origin xyz="0 0 0.35" rpy="0 0 0"/>
            <geometry>
                <box size="0.7 0.7 0.7" />
            </geometry>
        </collision>
    </link>
    <link name="1">
        <inertial>
            <origin xyz="0.3967285239242313 0 0.059596989517842425" rpy="0 0 0"/>
            <mass value="1" />
            <inertia ixx="100" ixy="0" ixz="0" iyy="100" iyz="0" izz="100" />
        </inertial>
        <visual>
            <origin xyz="0.3967285239242313 0 0.059596989517842425" rpy="0 0 0"/>
            <geometry>
                <box size="0.7934570478484626 0.6647668867194073 0.11919397903568485" />
            </geometry>
            <material name="Blue">
                <color rgba="0 0 255 1"/>
            </material>
        </visual>
        <collision>
            <origin xyz="0.3967285239242313 0 0.059596989517842425" rpy="0 0 0"/>
            <geometry>
                <box size="0.7934570478484626 0.6647668867194073 0.11919397903568485" />
            </geometry>
        </collision>
    </link>
    <joint name="0_1" type="revolute">
       <parent link="0"/>
       <child  link="1"/>
       <origin rpy="0 0 0" xyz="0.35 0 0.7" />
     <axis xyz="0 1 0"/>
       <limit effort="0.0" lower="-3.14159" upper="3.14159" velocity="0.0"/>
    </joint>
    <link name="2">
        <inertial>
            <origin xyz="0 0.14204555056614881 0.4015419113809993" rpy="0 0 0"/>
            <mass value="1" />
            <inertia ixx="100" ixy="0" ixz="0" iyy="100" iyz="0" izz="100" />
        </inertial>
        <visual>
            <origin xyz="0 0.14204555056614881 0.4015419113809993" rpy="0 0 0"/>
            <geometry>
                <box size="0.7502734891676963 0.28409110113229763 0.8030838227619986" />
            </geometry>
            <material name="Green">
                <color rgba="0 128 0 1"/>
            </material>
        </visual>
        <collision>
            <origin xyz="0 0.14204555056614881 0.4015419113809993" rpy="0 0 0"/>
            <geometry>
                <box size="0.7502734891676963 0.28409110113229763 0.8030838227619986" />
            </geometry>
        </collision>
    </link>
    <joint name="0_2" type="revolute">
       <parent link="0"/>
       <child  link="2"/>
       <origin rpy="0 0 0" xyz="0 0.35 0.7" />
     <axis xyz="0 1 0"/>
       <limit effort="0.0" lower="-3.14159" upper="3.14159" velocity="0.0"/>
    </joint>
    <link name="3">
        <inertial>
            <origin xyz="0 0.0083453150577798 0.007279987462406157" rpy="0 0 0"/>
            <mass value="1" />
            <inertia ixx="100" ixy="0" ixz="0" iyy="100" iyz="0" izz="100" />
        </inertial>
        <visual>
            <origin xyz="0 0.0083453150577798 0.007279987462406157" rpy="0 0 0"/>
            <geometry>
                <box size="0.08323413780389788 0.0166906301155596 0.014559974924812313" />
            </geometry>
            <material name="Blue">
                <color rgba="0 0 255 1"/>
            </material>
        </visual>
        <collision>
            <origin xyz="0 0.0083453150577798 0.007279987462406157" rpy="0 0 0"/>
            <geometry>
                <box size="0.08323413780389788 0.0166906301155596 0.014559974924812313" />
            </geometry>
        </collision>
    </link>
    <joint name="2_3" type="revolute">
       <parent link="2"/>
       <child  link="3"/>
       <origin rpy="0 0 0" xyz="0 0.28409110113229763 0.8030838227619986" />
     <axis xyz="0 1 1"/>
       <limit effort="0.0" lower="-3.14159" upper="3.14159" velocity="0.0"/>
    </joint>
</robot>