<robot name = "robot">
    <link name="0">
        <inertial>
            <origin xyz="0 0 2" rpy="0 0 0"/>
            <mass value="1" />
            <inertia ixx="100" ixy="0" ixz="0" iyy="100" iyz="0" izz="100" />
        </inertial>
        <visual>
            <origin xyz="0 0 2" rpy="0 0 0"/>
            <geometry>
                <box size="1.5 1.5 0.8" />
            </geometry>
            <material name="Green">
                <color rgba="0 128 0 1"/>
            </material>
        </visual>
        <collision>
            <origin xyz="0 0 2" rpy="0 0 0"/>
            <geometry>
                <box size="1.5 1.5 0.8" />
            </geometry>
        </collision>
    </link>
    <link name="1">
        <inertial>
            <origin xyz="-0.4859565274571809 0 0" rpy="0 0 0"/>
            <mass value="1" />
            <inertia ixx="100" ixy="0" ixz="0" iyy="100" iyz="0" izz="100" />
        </inertial>
        <visual>
            <origin xyz="-0.4859565274571809 0 0" rpy="0 0 0"/>
            <geometry>
                <box size="0.9719130549143618 0.3378771661298672 0.089093441988642" />
            </geometry>
            <material name="Green">
                <color rgba="0 128 0 1"/>
            </material>
        </visual>
        <collision>
            <origin xyz="-0.4859565274571809 0 0" rpy="0 0 0"/>
            <geometry>
                <box size="0.9719130549143618 0.3378771661298672 0.089093441988642" />
            </geometry>
        </collision>
    </link>
    <joint name="0_1" type="revolute">
       <parent link="0"/>
       <child  link="1"/>
       <origin rpy="0 0 0" xyz="-0.75 0 2" />
     <axis xyz="1 0 0"/>
       <limit effort="0.0" lower="-3.14159" upper="3.14159" velocity="0.0"/>
    </joint>
    <link name="2">
        <inertial>
            <origin xyz="-0.1322585482728899 0 0" rpy="0 0 0"/>
            <mass value="1" />
            <inertia ixx="100" ixy="0" ixz="0" iyy="100" iyz="0" izz="100" />
        </inertial>
        <visual>
            <origin xyz="-0.1322585482728899 0 0" rpy="0 0 0"/>
            <geometry>
                <box size="0.2645170965457798 0.666205181564181 0.9823003950118661" />
            </geometry>
            <material name="Blue">
                <color rgba="0 0 255 1"/>
            </material>
        </visual>
        <collision>
            <origin xyz="-0.1322585482728899 0 0" rpy="0 0 0"/>
            <geometry>
                <box size="0.2645170965457798 0.666205181564181 0.9823003950118661" />
            </geometry>
        </collision>
    </link>
    <joint name="1_2" type="revolute">
       <parent link="1"/>
       <child  link="2"/>
       <origin rpy="0 0 0" xyz="-0.9719130549143618 0 0" />
     <axis xyz="0 1 0"/>
       <limit effort="0.0" lower="-3.14159" upper="3.14159" velocity="0.0"/>
    </joint>
    <link name="3">
        <inertial>
            <origin xyz="-0.2743648719152567 0 0" rpy="0 0 0"/>
            <mass value="1" />
            <inertia ixx="100" ixy="0" ixz="0" iyy="100" iyz="0" izz="100" />
        </inertial>
        <visual>
            <origin xyz="-0.2743648719152567 0 0" rpy="0 0 0"/>
            <geometry>
                <box size="0.5487297438305134 0.6150187281511935 0.8043673821373724" />
            </geometry>
            <material name="Green">
                <color rgba="0 128 0 1"/>
            </material>
        </visual>
        <collision>
            <origin xyz="-0.2743648719152567 0 0" rpy="0 0 0"/>
            <geometry>
                <box size="0.5487297438305134 0.6150187281511935 0.8043673821373724" />
            </geometry>
        </collision>
    </link>
    <joint name="2_3" type="revolute">
       <parent link="2"/>
       <child  link="3"/>
       <origin rpy="0 0 0" xyz="-0.2645170965457798 0 0" />
     <axis xyz="0 0 1"/>
       <limit effort="0.0" lower="-3.14159" upper="3.14159" velocity="0.0"/>
    </joint>
    <link name="4">
        <inertial>
            <origin xyz="0 0 -0.2409060902235882" rpy="0 0 0"/>
            <mass value="1" />
            <inertia ixx="100" ixy="0" ixz="0" iyy="100" iyz="0" izz="100" />
        </inertial>
        <visual>
            <origin xyz="0 0 -0.2409060902235882" rpy="0 0 0"/>
            <geometry>
                <box size="0.8977171071737486 0.16708090899063333 0.4818121804471764" />
            </geometry>
            <material name="Green">
                <color rgba="0 128 0 1"/>
            </material>
        </visual>
        <collision>
            <origin xyz="0 0 -0.2409060902235882" rpy="0 0 0"/>
            <geometry>
                <box size="0.8977171071737486 0.16708090899063333 0.4818121804471764" />
            </geometry>
        </collision>
    </link>
    <joint name="3_4" type="revolute">
       <parent link="3"/>
       <child  link="4"/>
       <origin rpy="0 0 0" xyz="-0.2743648719152567 0 -0.4021836910686862" />
     <axis xyz="1 1 1"/>
       <limit effort="0.0" lower="-3.14159" upper="3.14159" velocity="0.0"/>
    </joint>
    <link name="5">
        <inertial>
            <origin xyz="0 0 -0.20679303038211402" rpy="0 0 0"/>
            <mass value="1" />
            <inertia ixx="100" ixy="0" ixz="0" iyy="100" iyz="0" izz="100" />
        </inertial>
        <visual>
            <origin xyz="0 0 -0.20679303038211402" rpy="0 0 0"/>
            <geometry>
                <box size="0.8508345154692164 0.25481978043873754 0.41358606076422805" />
            </geometry>
            <material name="Green">
                <color rgba="0 128 0 1"/>
            </material>
        </visual>
        <collision>
            <origin xyz="0 0 -0.20679303038211402" rpy="0 0 0"/>
            <geometry>
                <box size="0.8508345154692164 0.25481978043873754 0.41358606076422805" />
            </geometry>
        </collision>
    </link>
    <joint name="4_5" type="revolute">
       <parent link="4"/>
       <child  link="5"/>
       <origin rpy="0 0 0" xyz="0 0 -0.4818121804471764" />
     <axis xyz="0 0 1"/>
       <limit effort="0.0" lower="-3.14159" upper="3.14159" velocity="0.0"/>
    </joint>
    <link name="6">
        <inertial>
            <origin xyz="0 0 -0.3523008793942978" rpy="0 0 0"/>
            <mass value="1" />
            <inertia ixx="100" ixy="0" ixz="0" iyy="100" iyz="0" izz="100" />
        </inertial>
        <visual>
            <origin xyz="0 0 -0.3523008793942978" rpy="0 0 0"/>
            <geometry>
                <box size="0.536270750981813 0.03665480751137373 0.7046017587885955" />
            </geometry>
            <material name="Green">
                <color rgba="0 128 0 1"/>
            </material>
        </visual>
        <collision>
            <origin xyz="0 0 -0.3523008793942978" rpy="0 0 0"/>
            <geometry>
                <box size="0.536270750981813 0.03665480751137373 0.7046017587885955" />
            </geometry>
        </collision>
    </link>
    <joint name="5_6" type="revolute">
       <parent link="5"/>
       <child  link="6"/>
       <origin rpy="0 0 0" xyz="0 0 -0.41358606076422805" />
     <axis xyz="0 0 1"/>
       <limit effort="0.0" lower="-3.14159" upper="3.14159" velocity="0.0"/>
    </joint>
    <link name="7">
        <inertial>
            <origin xyz="0.16729582665206338 0 0" rpy="0 0 0"/>
            <mass value="1" />
            <inertia ixx="100" ixy="0" ixz="0" iyy="100" iyz="0" izz="100" />
        </inertial>
        <visual>
            <origin xyz="0.16729582665206338 0 0" rpy="0 0 0"/>
            <geometry>
                <box size="0.33459165330412677 0.47488274489834537 0.7654484826789296" />
            </geometry>
            <material name="Green">
                <color rgba="0 128 0 1"/>
            </material>
        </visual>
        <collision>
            <origin xyz="0.16729582665206338 0 0" rpy="0 0 0"/>
            <geometry>
                <box size="0.33459165330412677 0.47488274489834537 0.7654484826789296" />
            </geometry>
        </collision>
    </link>
    <joint name="0_7" type="revolute">
       <parent link="0"/>
       <child  link="7"/>
       <origin rpy="0 0 0" xyz="0.75 0 2" />
     <axis xyz="1 0 1"/>
       <limit effort="0.0" lower="-3.14159" upper="3.14159" velocity="0.0"/>
    </joint>
    <link name="8">
        <inertial>
            <origin xyz="0.15780715996031147 0 0" rpy="0 0 0"/>
            <mass value="1" />
            <inertia ixx="100" ixy="0" ixz="0" iyy="100" iyz="0" izz="100" />
        </inertial>
        <visual>
            <origin xyz="0.15780715996031147 0 0" rpy="0 0 0"/>
            <geometry>
                <box size="0.31561431992062294 0.5002331574180487 0.7014110894273413" />
            </geometry>
            <material name="Green">
                <color rgba="0 128 0 1"/>
            </material>
        </visual>
        <collision>
            <origin xyz="0.15780715996031147 0 0" rpy="0 0 0"/>
            <geometry>
                <box size="0.31561431992062294 0.5002331574180487 0.7014110894273413" />
            </geometry>
        </collision>
    </link>
    <joint name="7_8" type="revolute">
       <parent link="7"/>
       <child  link="8"/>
       <origin rpy="0 0 0" xyz="0.33459165330412677 0 0" />
     <axis xyz="1 0 0"/>
       <limit effort="0.0" lower="-3.14159" upper="3.14159" velocity="0.0"/>
    </joint>
    <link name="9">
        <inertial>
            <origin xyz="0.1950210422311358 0 0" rpy="0 0 0"/>
            <mass value="1" />
            <inertia ixx="100" ixy="0" ixz="0" iyy="100" iyz="0" izz="100" />
        </inertial>
        <visual>
            <origin xyz="0.1950210422311358 0 0" rpy="0 0 0"/>
            <geometry>
                <box size="0.3900420844622716 0.19069075046976736 0.7274582604701869" />
            </geometry>
            <material name="Blue">
                <color rgba="0 0 255 1"/>
            </material>
        </visual>
        <collision>
            <origin xyz="0.1950210422311358 0 0" rpy="0 0 0"/>
            <geometry>
                <box size="0.3900420844622716 0.19069075046976736 0.7274582604701869" />
            </geometry>
        </collision>
    </link>
    <joint name="8_9" type="revolute">
       <parent link="8"/>
       <child  link="9"/>
       <origin rpy="0 0 0" xyz="0.31561431992062294 0 0" />
     <axis xyz="1 0 0"/>
       <limit effort="0.0" lower="-3.14159" upper="3.14159" velocity="0.0"/>
    </joint>
    <link name="10">
        <inertial>
            <origin xyz="0 0 -0.4130727508722216" rpy="0 0 0"/>
            <mass value="1" />
            <inertia ixx="100" ixy="0" ixz="0" iyy="100" iyz="0" izz="100" />
        </inertial>
        <visual>
            <origin xyz="0 0 -0.4130727508722216" rpy="0 0 0"/>
            <geometry>
                <box size="0.4536367734558794 0.4701174929455887 0.8261455017444432" />
            </geometry>
            <material name="Blue">
                <color rgba="0 0 255 1"/>
            </material>
        </visual>
        <collision>
            <origin xyz="0 0 -0.4130727508722216" rpy="0 0 0"/>
            <geometry>
                <box size="0.4536367734558794 0.4701174929455887 0.8261455017444432" />
            </geometry>
        </collision>
    </link>
    <joint name="9_10" type="revolute">
       <parent link="9"/>
       <child  link="10"/>
       <origin rpy="0 0 0" xyz="0.1950210422311358 0 -0.36372913023509346" />
     <axis xyz="0 1 1"/>
       <limit effort="0.0" lower="-3.14159" upper="3.14159" velocity="0.0"/>
    </joint>
    <link name="11">
        <inertial>
            <origin xyz="0 0 -0.1121655602280525" rpy="0 0 0"/>
            <mass value="1" />
            <inertia ixx="100" ixy="0" ixz="0" iyy="100" iyz="0" izz="100" />
        </inertial>
        <visual>
            <origin xyz="0 0 -0.1121655602280525" rpy="0 0 0"/>
            <geometry>
                <box size="0.9023339951984924 0.09860008584420454 0.224331120456105" />
            </geometry>
            <material name="Green">
                <color rgba="0 128 0 1"/>
            </material>
        </visual>
        <collision>
            <origin xyz="0 0 -0.1121655602280525" rpy="0 0 0"/>
            <geometry>
                <box size="0.9023339951984924 0.09860008584420454 0.224331120456105" />
            </geometry>
        </collision>
    </link>
    <joint name="10_11" type="revolute">
       <parent link="10"/>
       <child  link="11"/>
       <origin rpy="0 0 0" xyz="0 0 -0.8261455017444432" />
     <axis xyz="1 1 1"/>
       <limit effort="0.0" lower="-3.14159" upper="3.14159" velocity="0.0"/>
    </joint>
    <link name="12">
        <inertial>
            <origin xyz="0 0 -0.2747616888997259" rpy="0 0 0"/>
            <mass value="1" />
            <inertia ixx="100" ixy="0" ixz="0" iyy="100" iyz="0" izz="100" />
        </inertial>
        <visual>
            <origin xyz="0 0 -0.2747616888997259" rpy="0 0 0"/>
            <geometry>
                <box size="0.7388433838740944 0.19192883116412496 0.5495233777994518" />
            </geometry>
            <material name="Blue">
                <color rgba="0 0 255 1"/>
            </material>
        </visual>
        <collision>
            <origin xyz="0 0 -0.2747616888997259" rpy="0 0 0"/>
            <geometry>
                <box size="0.7388433838740944 0.19192883116412496 0.5495233777994518" />
            </geometry>
        </collision>
    </link>
    <joint name="11_12" type="revolute">
       <parent link="11"/>
       <child  link="12"/>
       <origin rpy="0 0 0" xyz="0 0 -0.224331120456105" />
     <axis xyz="1 0 1"/>
       <limit effort="0.0" lower="-3.14159" upper="3.14159" velocity="0.0"/>
    </joint>
    <link name="13">
        <inertial>
            <origin xyz="0 -0.3511051569690844 0" rpy="0 0 0"/>
            <mass value="1" />
            <inertia ixx="100" ixy="0" ixz="0" iyy="100" iyz="0" izz="100" />
        </inertial>
        <visual>
            <origin xyz="0 -0.3511051569690844 0" rpy="0 0 0"/>
            <geometry>
                <box size="0.1694464176038234 0.7022103139381688 0.454710648875029" />
            </geometry>
            <material name="Blue">
                <color rgba="0 0 255 1"/>
            </material>
        </visual>
        <collision>
            <origin xyz="0 -0.3511051569690844 0" rpy="0 0 0"/>
            <geometry>
                <box size="0.1694464176038234 0.7022103139381688 0.454710648875029" />
            </geometry>
        </collision>
    </link>
    <joint name="0_13" type="revolute">
       <parent link="0"/>
       <child  link="13"/>
       <origin rpy="0 0 0" xyz="0 -0.75 2" />
     <axis xyz="1 1 1"/>
       <limit effort="0.0" lower="-3.14159" upper="3.14159" velocity="0.0"/>
    </joint>
    <link name="14">
        <inertial>
            <origin xyz="0 -0.32689223343108825 0" rpy="0 0 0"/>
            <mass value="1" />
            <inertia ixx="100" ixy="0" ixz="0" iyy="100" iyz="0" izz="100" />
        </inertial>
        <visual>
            <origin xyz="0 -0.32689223343108825 0" rpy="0 0 0"/>
            <geometry>
                <box size="0.25485356223250155 0.6537844668621765 0.3282333311226202" />
            </geometry>
            <material name="Green">
                <color rgba="0 128 0 1"/>
            </material>
        </visual>
        <collision>
            <origin xyz="0 -0.32689223343108825 0" rpy="0 0 0"/>
            <geometry>
                <box size="0.25485356223250155 0.6537844668621765 0.3282333311226202" />
            </geometry>
        </collision>
    </link>
    <joint name="13_14" type="revolute">
       <parent link="13"/>
       <child  link="14"/>
       <origin rpy="0 0 0" xyz="0 -0.7022103139381688 0" />
     <axis xyz="1 0 0"/>
       <limit effort="0.0" lower="-3.14159" upper="3.14159" velocity="0.0"/>
    </joint>
    <link name="15">
        <inertial>
            <origin xyz="0 -0.39260133123815977 0" rpy="0 0 0"/>
            <mass value="1" />
            <inertia ixx="100" ixy="0" ixz="0" iyy="100" iyz="0" izz="100" />
        </inertial>
        <visual>
            <origin xyz="0 -0.39260133123815977 0" rpy="0 0 0"/>
            <geometry>
                <box size="0.17420773837268633 0.7852026624763195 0.21702914560637632" />
            </geometry>
            <material name="Blue">
                <color rgba="0 0 255 1"/>
            </material>
        </visual>
        <collision>
            <origin xyz="0 -0.39260133123815977 0" rpy="0 0 0"/>
            <geometry>
                <box size="0.17420773837268633 0.7852026624763195 0.21702914560637632" />
            </geometry>
        </collision>
    </link>
    <joint name="14_15" type="revolute">
       <parent link="14"/>
       <child  link="15"/>
       <origin rpy="0 0 0" xyz="0 -0.6537844668621765 0" />
     <axis xyz="0 1 1"/>
       <limit effort="0.0" lower="-3.14159" upper="3.14159" velocity="0.0"/>
    </joint>
    <link name="16">
        <inertial>
            <origin xyz="0 0 -0.7015545280732914" rpy="0 0 0"/>
            <mass value="1" />
            <inertia ixx="100" ixy="0" ixz="0" iyy="100" iyz="0" izz="100" />
        </inertial>
        <visual>
            <origin xyz="0 0 -0.7015545280732914" rpy="0 0 0"/>
            <geometry>
                <box size="0.10288401361043509 0.826799258315479 1.4031090561465829" />
            </geometry>
            <material name="Green">
                <color rgba="0 128 0 1"/>
            </material>
        </visual>
        <collision>
            <origin xyz="0 0 -0.7015545280732914" rpy="0 0 0"/>
            <geometry>
                <box size="0.10288401361043509 0.826799258315479 1.4031090561465829" />
            </geometry>
        </collision>
    </link>
    <joint name="15_16" type="revolute">
       <parent link="15"/>
       <child  link="16"/>
       <origin rpy="0 0 0" xyz="0 -0.39260133123815977 -0.10851457280318816" />
     <axis xyz="0 1 1"/>
       <limit effort="0.0" lower="-3.14159" upper="3.14159" velocity="0.0"/>
    </joint>
    <link name="17">
        <inertial>
            <origin xyz="0 0 -0.06805029544913606" rpy="0 0 0"/>
            <mass value="1" />
            <inertia ixx="100" ixy="0" ixz="0" iyy="100" iyz="0" izz="100" />
        </inertial>
        <visual>
            <origin xyz="0 0 -0.06805029544913606" rpy="0 0 0"/>
            <geometry>
                <box size="0.8147538161033806 0.8967481184522048 0.13610059089827212" />
            </geometry>
            <material name="Green">
                <color rgba="0 128 0 1"/>
            </material>
        </visual>
        <collision>
            <origin xyz="0 0 -0.06805029544913606" rpy="0 0 0"/>
            <geometry>
                <box size="0.8147538161033806 0.8967481184522048 0.13610059089827212" />
            </geometry>
        </collision>
    </link>
    <joint name="16_17" type="revolute">
       <parent link="16"/>
       <child  link="17"/>
       <origin rpy="0 0 0" xyz="0 0 -1.4031090561465829" />
     <axis xyz="1 1 0"/>
       <limit effort="0.0" lower="-3.14159" upper="3.14159" velocity="0.0"/>
    </joint>
    <link name="18">
        <inertial>
            <origin xyz="0 0 -0.030395176477572547" rpy="0 0 0"/>
            <mass value="1" />
            <inertia ixx="100" ixy="0" ixz="0" iyy="100" iyz="0" izz="100" />
        </inertial>
        <visual>
            <origin xyz="0 0 -0.030395176477572547" rpy="0 0 0"/>
            <geometry>
                <box size="0.3769175682579905 0.9530101071475092 0.060790352955145094" />
            </geometry>
            <material name="Blue">
                <color rgba="0 0 255 1"/>
            </material>
        </visual>
        <collision>
            <origin xyz="0 0 -0.030395176477572547" rpy="0 0 0"/>
            <geometry>
                <box size="0.3769175682579905 0.9530101071475092 0.060790352955145094" />
            </geometry>
        </collision>
    </link>
    <joint name="17_18" type="revolute">
       <parent link="17"/>
       <child  link="18"/>
       <origin rpy="0 0 0" xyz="0 0 -0.13610059089827212" />
     <axis xyz="1 1 0"/>
       <limit effort="0.0" lower="-3.14159" upper="3.14159" velocity="0.0"/>
    </joint>
    <link name="19">
        <inertial>
            <origin xyz="0 0.2667504182196525 0" rpy="0 0 0"/>
            <mass value="1" />
            <inertia ixx="100" ixy="0" ixz="0" iyy="100" iyz="0" izz="100" />
        </inertial>
        <visual>
            <origin xyz="0 0.2667504182196525 0" rpy="0 0 0"/>
            <geometry>
                <box size="0.6369646093873974 0.533500836439305 0.1968858155725075" />
            </geometry>
            <material name="Green">
                <color rgba="0 128 0 1"/>
            </material>
        </visual>
        <collision>
            <origin xyz="0 0.2667504182196525 0" rpy="0 0 0"/>
            <geometry>
                <box size="0.6369646093873974 0.533500836439305 0.1968858155725075" />
            </geometry>
        </collision>
    </link>
    <joint name="0_19" type="revolute">
       <parent link="0"/>
       <child  link="19"/>
       <origin rpy="0 0 0" xyz="0 0.75 2" />
     <axis xyz="0 1 0"/>
       <limit effort="0.0" lower="-3.14159" upper="3.14159" velocity="0.0"/>
    </joint>
    <link name="20">
        <inertial>
            <origin xyz="0 0.18668186439131595 0" rpy="0 0 0"/>
            <mass value="1" />
            <inertia ixx="100" ixy="0" ixz="0" iyy="100" iyz="0" izz="100" />
        </inertial>
        <visual>
            <origin xyz="0 0.18668186439131595 0" rpy="0 0 0"/>
            <geometry>
                <box size="0.6119991110356782 0.3733637287826319 0.01563697110642448" />
            </geometry>
            <material name="Green">
                <color rgba="0 128 0 1"/>
            </material>
        </visual>
        <collision>
            <origin xyz="0 0.18668186439131595 0" rpy="0 0 0"/>
            <geometry>
                <box size="0.6119991110356782 0.3733637287826319 0.01563697110642448" />
            </geometry>
        </collision>
    </link>
    <joint name="19_20" type="revolute">
       <parent link="19"/>
       <child  link="20"/>
       <origin rpy="0 0 0" xyz="0 0.533500836439305 0" />
     <axis xyz="1 0 0"/>
       <limit effort="0.0" lower="-3.14159" upper="3.14159" velocity="0.0"/>
    </joint>
    <link name="21">
        <inertial>
            <origin xyz="0 0.3272920517961384 0" rpy="0 0 0"/>
            <mass value="1" />
            <inertia ixx="100" ixy="0" ixz="0" iyy="100" iyz="0" izz="100" />
        </inertial>
        <visual>
            <origin xyz="0 0.3272920517961384 0" rpy="0 0 0"/>
            <geometry>
                <box size="0.5120970987241481 0.6545841035922768 0.4978430531216975" />
            </geometry>
            <material name="Green">
                <color rgba="0 128 0 1"/>
            </material>
        </visual>
        <collision>
            <origin xyz="0 0.3272920517961384 0" rpy="0 0 0"/>
            <geometry>
                <box size="0.5120970987241481 0.6545841035922768 0.4978430531216975" />
            </geometry>
        </collision>
    </link>
    <joint name="20_21" type="revolute">
       <parent link="20"/>
       <child  link="21"/>
       <origin rpy="0 0 0" xyz="0 0.3733637287826319 0" />
     <axis xyz="1 1 0"/>
       <limit effort="0.0" lower="-3.14159" upper="3.14159" velocity="0.0"/>
    </joint>
    <link name="22">
        <inertial>
            <origin xyz="0 0 -0.06479056707098599" rpy="0 0 0"/>
            <mass value="1" />
            <inertia ixx="100" ixy="0" ixz="0" iyy="100" iyz="0" izz="100" />
        </inertial>
        <visual>
            <origin xyz="0 0 -0.06479056707098599" rpy="0 0 0"/>
            <geometry>
                <box size="0.3255351673691007 0.3853337340686689 0.12958113414197198" />
            </geometry>
            <material name="Green">
                <color rgba="0 128 0 1"/>
            </material>
        </visual>
        <collision>
            <origin xyz="0 0 -0.06479056707098599" rpy="0 0 0"/>
            <geometry>
                <box size="0.3255351673691007 0.3853337340686689 0.12958113414197198" />
            </geometry>
        </collision>
    </link>
    <joint name="21_22" type="revolute">
       <parent link="21"/>
       <child  link="22"/>
       <origin rpy="0 0 0" xyz="0 0.3272920517961384 -0.24892152656084876" />
     <axis xyz="0 1 1"/>
       <limit effort="0.0" lower="-3.14159" upper="3.14159" velocity="0.0"/>
    </joint>
    <link name="23">
        <inertial>
            <origin xyz="0 0 -0.3113043098634964" rpy="0 0 0"/>
            <mass value="1" />
            <inertia ixx="100" ixy="0" ixz="0" iyy="100" iyz="0" izz="100" />
        </inertial>
        <visual>
            <origin xyz="0 0 -0.3113043098634964" rpy="0 0 0"/>
            <geometry>
                <box size="0.8786421321584086 0.09867123964417124 0.6226086197269928" />
            </geometry>
            <material name="Green">
                <color rgba="0 128 0 1"/>
            </material>
        </visual>
        <collision>
            <origin xyz="0 0 -0.3113043098634964" rpy="0 0 0"/>
            <geometry>
                <box size="0.8786421321584086 0.09867123964417124 0.6226086197269928" />
            </geometry>
        </collision>
    </link>
    <joint name="22_23" type="revolute">
       <parent link="22"/>
       <child  link="23"/>
       <origin rpy="0 0 0" xyz="0 0 -0.12958113414197198" />
     <axis xyz="1 0 0"/>
       <limit effort="0.0" lower="-3.14159" upper="3.14159" velocity="0.0"/>
    </joint>
    <link name="24">
        <inertial>
            <origin xyz="0 0 -0.4239051230655177" rpy="0 0 0"/>
            <mass value="1" />
            <inertia ixx="100" ixy="0" ixz="0" iyy="100" iyz="0" izz="100" />
        </inertial>
        <visual>
            <origin xyz="0 0 -0.4239051230655177" rpy="0 0 0"/>
            <geometry>
                <box size="0.2023821789893382 0.004778963617182552 0.8478102461310354" />
            </geometry>
            <material name="Blue">
                <color rgba="0 0 255 1"/>
            </material>
        </visual>
        <collision>
            <origin xyz="0 0 -0.4239051230655177" rpy="0 0 0"/>
            <geometry>
                <box size="0.2023821789893382 0.004778963617182552 0.8478102461310354" />
            </geometry>
        </collision>
    </link>
    <joint name="23_24" type="revolute">
       <parent link="23"/>
       <child  link="24"/>
       <origin rpy="0 0 0" xyz="0 0 -0.6226086197269928" />
     <axis xyz="0 0 1"/>
       <limit effort="0.0" lower="-3.14159" upper="3.14159" velocity="0.0"/>
    </joint>
</robot>