<robot name = "robot">
    <link name="0">
        <inertial>
            <origin xyz="0 0 0.35" rpy="0 0 0"/>
            <mass value="1" />
            <inertia ixx="100" ixy="0" ixz="0" iyy="100" iyz="0" izz="100" />
        </inertial>
        <visual>
            <origin xyz="0 0 0.35" rpy="0 0 0"/>
            <geometry>
                <box size="0.7 0.7 0.7" />
            </geometry>
            <material name="Green">
                <color rgba="0 128 0 1"/>
            </material>
        </visual>
        <collision>
            <origin xyz="0 0 0.35" rpy="0 0 0"/>
            <geometry>
                <box size="0.7 0.7 0.7" />
            </geometry>
        </collision>
    </link>
    <link name="1">
        <inertial>
            <origin xyz="-0.41342606233601903 0 0.11161948230350727" rpy="0 0 0"/>
            <mass value="1" />
            <inertia ixx="100" ixy="0" ixz="0" iyy="100" iyz="0" izz="100" />
        </inertial>
        <visual>
            <origin xyz="-0.41342606233601903 0 0.11161948230350727" rpy="0 0 0"/>
            <geometry>
                <box size="0.8268521246720381 0.12380196114964559 0.22323896460701453" />
            </geometry>
            <material name="Blue">
                <color rgba="0 0 255 1"/>
            </material>
        </visual>
        <collision>
            <origin xyz="-0.41342606233601903 0 0.11161948230350727" rpy="0 0 0"/>
            <geometry>
                <box size="0.8268521246720381 0.12380196114964559 0.22323896460701453" />
            </geometry>
        </collision>
    </link>
    <joint name="0_1" type="revolute">
       <parent link="0"/>
       <child  link="1"/>
       <origin rpy="0 0 0" xyz="-0.35 0 0.7" />
     <axis xyz="0 0 1"/>
       <limit effort="0.0" lower="-3.14159" upper="3.14159" velocity="0.0"/>
    </joint>
    <link name="2">
        <inertial>
            <origin xyz="-0.2927707113201934 0 0.11054091172882419" rpy="0 0 0"/>
            <mass value="1" />
            <inertia ixx="100" ixy="0" ixz="0" iyy="100" iyz="0" izz="100" />
        </inertial>
        <visual>
            <origin xyz="-0.2927707113201934 0 0.11054091172882419" rpy="0 0 0"/>
            <geometry>
                <box size="0.5855414226403868 0.04958931338977146 0.22108182345764837" />
            </geometry>
            <material name="Green">
                <color rgba="0 128 0 1"/>
            </material>
        </visual>
        <collision>
            <origin xyz="-0.2927707113201934 0 0.11054091172882419" rpy="0 0 0"/>
            <geometry>
                <box size="0.5855414226403868 0.04958931338977146 0.22108182345764837" />
            </geometry>
        </collision>
    </link>
    <joint name="1_2" type="revolute">
       <parent link="1"/>
       <child  link="2"/>
       <origin rpy="0 0 0" xyz="-0.8268521246720381 0 0.22323896460701453" />
     <axis xyz="1 1 1"/>
       <limit effort="0.0" lower="-3.14159" upper="3.14159" velocity="0.0"/>
    </joint>
    <link name="3">
        <inertial>
            <origin xyz="-0.07212754167871877 0 0.15424091205096718" rpy="0 0 0"/>
            <mass value="1" />
            <inertia ixx="100" ixy="0" ixz="0" iyy="100" iyz="0" izz="100" />
        </inertial>
        <visual>
            <origin xyz="-0.07212754167871877 0 0.15424091205096718" rpy="0 0 0"/>
            <geometry>
                <box size="0.14425508335743753 0.11779223807836836 0.30848182410193437" />
            </geometry>
            <material name="Green">
                <color rgba="0 128 0 1"/>
            </material>
        </visual>
        <collision>
            <origin xyz="-0.07212754167871877 0 0.15424091205096718" rpy="0 0 0"/>
            <geometry>
                <box size="0.14425508335743753 0.11779223807836836 0.30848182410193437" />
            </geometry>
        </collision>
    </link>
    <joint name="2_3" type="revolute">
       <parent link="2"/>
       <child  link="3"/>
       <origin rpy="0 0 0" xyz="-0.5855414226403868 0 0.22108182345764837" />
     <axis xyz="0 1 0"/>
       <limit effort="0.0" lower="-3.14159" upper="3.14159" velocity="0.0"/>
    </joint>
    <link name="4">
        <inertial>
            <origin xyz="-0.10297935640966327 0 0.21379615283470144" rpy="0 0 0"/>
            <mass value="1" />
            <inertia ixx="100" ixy="0" ixz="0" iyy="100" iyz="0" izz="100" />
        </inertial>
        <visual>
            <origin xyz="-0.10297935640966327 0 0.21379615283470144" rpy="0 0 0"/>
            <geometry>
                <box size="0.20595871281932654 0.6803999731817859 0.4275923056694029" />
            </geometry>
            <material name="Blue">
                <color rgba="0 0 255 1"/>
            </material>
        </visual>
        <collision>
            <origin xyz="-0.10297935640966327 0 0.21379615283470144" rpy="0 0 0"/>
            <geometry>
                <box size="0.20595871281932654 0.6803999731817859 0.4275923056694029" />
            </geometry>
        </collision>
    </link>
    <joint name="3_4" type="revolute">
       <parent link="3"/>
       <child  link="4"/>
       <origin rpy="0 0 0" xyz="-0.14425508335743753 0 0.30848182410193437" />
     <axis xyz="0 1 1"/>
       <limit effort="0.0" lower="-3.14159" upper="3.14159" velocity="0.0"/>
    </joint>
    <link name="5">
        <inertial>
            <origin xyz="-0.18079117797228317 0 0.0898833747915716" rpy="0 0 0"/>
            <mass value="1" />
            <inertia ixx="100" ixy="0" ixz="0" iyy="100" iyz="0" izz="100" />
        </inertial>
        <visual>
            <origin xyz="-0.18079117797228317 0 0.0898833747915716" rpy="0 0 0"/>
            <geometry>
                <box size="0.36158235594456634 0.24842658485754932 0.1797667495831432" />
            </geometry>
            <material name="Green">
                <color rgba="0 128 0 1"/>
            </material>
        </visual>
        <collision>
            <origin xyz="-0.18079117797228317 0 0.0898833747915716" rpy="0 0 0"/>
            <geometry>
                <box size="0.36158235594456634 0.24842658485754932 0.1797667495831432" />
            </geometry>
        </collision>
    </link>
    <joint name="4_5" type="revolute">
       <parent link="4"/>
       <child  link="5"/>
       <origin rpy="0 0 0" xyz="-0.20595871281932654 0 0.4275923056694029" />
     <axis xyz="1 0 0"/>
       <limit effort="0.0" lower="-3.14159" upper="3.14159" velocity="0.0"/>
    </joint>
    <link name="6">
        <inertial>
            <origin xyz="0.2625982519057257 0 0.3647226447196088" rpy="0 0 0"/>
            <mass value="1" />
            <inertia ixx="100" ixy="0" ixz="0" iyy="100" iyz="0" izz="100" />
        </inertial>
        <visual>
            <origin xyz="0.2625982519057257 0 0.3647226447196088" rpy="0 0 0"/>
            <geometry>
                <box size="0.5251965038114514 0.8751374955734289 0.7294452894392176" />
            </geometry>
            <material name="Green">
                <color rgba="0 128 0 1"/>
            </material>
        </visual>
        <collision>
            <origin xyz="0.2625982519057257 0 0.3647226447196088" rpy="0 0 0"/>
            <geometry>
                <box size="0.5251965038114514 0.8751374955734289 0.7294452894392176" />
            </geometry>
        </collision>
    </link>
    <joint name="0_6" type="revolute">
       <parent link="0"/>
       <child  link="6"/>
       <origin rpy="0 0 0" xyz="0.35 0 0.7" />
     <axis xyz="0 1 0"/>
       <limit effort="0.0" lower="-3.14159" upper="3.14159" velocity="0.0"/>
    </joint>
    <link name="7">
        <inertial>
            <origin xyz="0.25596641532377457 0 0.17102790307992893" rpy="0 0 0"/>
            <mass value="1" />
            <inertia ixx="100" ixy="0" ixz="0" iyy="100" iyz="0" izz="100" />
        </inertial>
        <visual>
            <origin xyz="0.25596641532377457 0 0.17102790307992893" rpy="0 0 0"/>
            <geometry>
                <box size="0.5119328306475491 0.16496210364357322 0.34205580615985787" />
            </geometry>
            <material name="Blue">
                <color rgba="0 0 255 1"/>
            </material>
        </visual>
        <collision>
            <origin xyz="0.25596641532377457 0 0.17102790307992893" rpy="0 0 0"/>
            <geometry>
                <box size="0.5119328306475491 0.16496210364357322 0.34205580615985787" />
            </geometry>
        </collision>
    </link>
    <joint name="6_7" type="revolute">
       <parent link="6"/>
       <child  link="7"/>
       <origin rpy="0 0 0" xyz="0.5251965038114514 0 0.7294452894392176" />
     <axis xyz="1 1 0"/>
       <limit effort="0.0" lower="-3.14159" upper="3.14159" velocity="0.0"/>
    </joint>
    <link name="8">
        <inertial>
            <origin xyz="0.38228543310640656 0 0.4377389059154441" rpy="0 0 0"/>
            <mass value="1" />
            <inertia ixx="100" ixy="0" ixz="0" iyy="100" iyz="0" izz="100" />
        </inertial>
        <visual>
            <origin xyz="0.38228543310640656 0 0.4377389059154441" rpy="0 0 0"/>
            <geometry>
                <box size="0.7645708662128131 0.573025940277384 0.8754778118308882" />
            </geometry>
            <material name="Blue">
                <color rgba="0 0 255 1"/>
            </material>
        </visual>
        <collision>
            <origin xyz="0.38228543310640656 0 0.4377389059154441" rpy="0 0 0"/>
            <geometry>
                <box size="0.7645708662128131 0.573025940277384 0.8754778118308882" />
            </geometry>
        </collision>
    </link>
    <joint name="7_8" type="revolute">
       <parent link="7"/>
       <child  link="8"/>
       <origin rpy="0 0 0" xyz="0.5119328306475491 0 0.34205580615985787" />
     <axis xyz="0 1 1"/>
       <limit effort="0.0" lower="-3.14159" upper="3.14159" velocity="0.0"/>
    </joint>
    <link name="9">
        <inertial>
            <origin xyz="0 0.39844598791079716 0.03438147470343028" rpy="0 0 0"/>
            <mass value="1" />
            <inertia ixx="100" ixy="0" ixz="0" iyy="100" iyz="0" izz="100" />
        </inertial>
        <visual>
            <origin xyz="0 0.39844598791079716 0.03438147470343028" rpy="0 0 0"/>
            <geometry>
                <box size="0.4966747952989876 0.7968919758215943 0.06876294940686056" />
            </geometry>
            <material name="Green">
                <color rgba="0 128 0 1"/>
            </material>
        </visual>
        <collision>
            <origin xyz="0 0.39844598791079716 0.03438147470343028" rpy="0 0 0"/>
            <geometry>
                <box size="0.4966747952989876 0.7968919758215943 0.06876294940686056" />
            </geometry>
        </collision>
    </link>
    <joint name="0_9" type="revolute">
       <parent link="0"/>
       <child  link="9"/>
       <origin rpy="0 0 0" xyz="0 0.35 0.7" />
     <axis xyz="1 0 0"/>
       <limit effort="0.0" lower="-3.14159" upper="3.14159" velocity="0.0"/>
    </joint>
</robot>