<robot name = "robot">
    <link name="0">
        <inertial>
            <origin xyz="0 0 0.35" rpy="0 0 0"/>
            <mass value="1" />
            <inertia ixx="100" ixy="0" ixz="0" iyy="100" iyz="0" izz="100" />
        </inertial>
        <visual>
            <origin xyz="0 0 0.35" rpy="0 0 0"/>
            <geometry>
                <box size="0.7 0.7 0.7" />
            </geometry>
            <material name="Green">
                <color rgba="0 128 0 1"/>
            </material>
        </visual>
        <collision>
            <origin xyz="0 0 0.35" rpy="0 0 0"/>
            <geometry>
                <box size="0.7 0.7 0.7" />
            </geometry>
        </collision>
    </link>
    <link name="1">
        <inertial>
            <origin xyz="0.09396104603869226 0 0.293396437246403" rpy="0 0 0"/>
            <mass value="1" />
            <inertia ixx="100" ixy="0" ixz="0" iyy="100" iyz="0" izz="100" />
        </inertial>
        <visual>
            <origin xyz="0.09396104603869226 0 0.293396437246403" rpy="0 0 0"/>
            <geometry>
                <box size="0.18792209207738453 0.7855121343445666 0.586792874492806" />
            </geometry>
            <material name="Blue">
                <color rgba="0 0 255 1"/>
            </material>
        </visual>
        <collision>
            <origin xyz="0.09396104603869226 0 0.293396437246403" rpy="0 0 0"/>
            <geometry>
                <box size="0.18792209207738453 0.7855121343445666 0.586792874492806" />
            </geometry>
        </collision>
    </link>
    <joint name="0_1" type="revolute">
       <parent link="0"/>
       <child  link="1"/>
       <origin rpy="0 0 0" xyz="0.35 0 0.7" />
     <axis xyz="1 0 1"/>
       <limit effort="0.0" lower="-3.14159" upper="3.14159" velocity="0.0"/>
    </joint>
    <link name="2">
        <inertial>
            <origin xyz="0.07947238066794876 0 0.2175514173163638" rpy="0 0 0"/>
            <mass value="1" />
            <inertia ixx="100" ixy="0" ixz="0" iyy="100" iyz="0" izz="100" />
        </inertial>
        <visual>
            <origin xyz="0.07947238066794876 0 0.2175514173163638" rpy="0 0 0"/>
            <geometry>
                <box size="0.15894476133589752 0.8450189016970555 0.4351028346327276" />
            </geometry>
            <material name="Blue">
                <color rgba="0 0 255 1"/>
            </material>
        </visual>
        <collision>
            <origin xyz="0.07947238066794876 0 0.2175514173163638" rpy="0 0 0"/>
            <geometry>
                <box size="0.15894476133589752 0.8450189016970555 0.4351028346327276" />
            </geometry>
        </collision>
    </link>
    <joint name="1_2" type="revolute">
       <parent link="1"/>
       <child  link="2"/>
       <origin rpy="0 0 0" xyz="0.18792209207738453 0 0.586792874492806" />
     <axis xyz="1 0 0"/>
       <limit effort="0.0" lower="-3.14159" upper="3.14159" velocity="0.0"/>
    </joint>
    <link name="3">
        <inertial>
            <origin xyz="0.27821637712626907 0 0.12670506802056336" rpy="0 0 0"/>
            <mass value="1" />
            <inertia ixx="100" ixy="0" ixz="0" iyy="100" iyz="0" izz="100" />
        </inertial>
        <visual>
            <origin xyz="0.27821637712626907 0 0.12670506802056336" rpy="0 0 0"/>
            <geometry>
                <box size="0.5564327542525381 0.29402358494854774 0.2534101360411267" />
            </geometry>
            <material name="Green">
                <color rgba="0 128 0 1"/>
            </material>
        </visual>
        <collision>
            <origin xyz="0.27821637712626907 0 0.12670506802056336" rpy="0 0 0"/>
            <geometry>
                <box size="0.5564327542525381 0.29402358494854774 0.2534101360411267" />
            </geometry>
        </collision>
    </link>
    <joint name="2_3" type="revolute">
       <parent link="2"/>
       <child  link="3"/>
       <origin rpy="0 0 0" xyz="0.15894476133589752 0 0.4351028346327276" />
     <axis xyz="0 0 1"/>
       <limit effort="0.0" lower="-3.14159" upper="3.14159" velocity="0.0"/>
    </joint>
    <link name="4">
        <inertial>
            <origin xyz="0 -0.1992775800189554 0.032095990752398995" rpy="0 0 0"/>
            <mass value="1" />
            <inertia ixx="100" ixy="0" ixz="0" iyy="100" iyz="0" izz="100" />
        </inertial>
        <visual>
            <origin xyz="0 -0.1992775800189554 0.032095990752398995" rpy="0 0 0"/>
            <geometry>
                <box size="0.3912690528726641 0.3985551600379108 0.06419198150479799" />
            </geometry>
            <material name="Green">
                <color rgba="0 128 0 1"/>
            </material>
        </visual>
        <collision>
            <origin xyz="0 -0.1992775800189554 0.032095990752398995" rpy="0 0 0"/>
            <geometry>
                <box size="0.3912690528726641 0.3985551600379108 0.06419198150479799" />
            </geometry>
        </collision>
    </link>
    <joint name="0_4" type="revolute">
       <parent link="0"/>
       <child  link="4"/>
       <origin rpy="0 0 0" xyz="0 -0.35 0.7" />
     <axis xyz="0 0 1"/>
       <limit effort="0.0" lower="-3.14159" upper="3.14159" velocity="0.0"/>
    </joint>
    <link name="5">
        <inertial>
            <origin xyz="0 -0.10759663501804922 0.30890344000577785" rpy="0 0 0"/>
            <mass value="1" />
            <inertia ixx="100" ixy="0" ixz="0" iyy="100" iyz="0" izz="100" />
        </inertial>
        <visual>
            <origin xyz="0 -0.10759663501804922 0.30890344000577785" rpy="0 0 0"/>
            <geometry>
                <box size="0.1113623101268919 0.21519327003609845 0.6178068800115557" />
            </geometry>
            <material name="Blue">
                <color rgba="0 0 255 1"/>
            </material>
        </visual>
        <collision>
            <origin xyz="0 -0.10759663501804922 0.30890344000577785" rpy="0 0 0"/>
            <geometry>
                <box size="0.1113623101268919 0.21519327003609845 0.6178068800115557" />
            </geometry>
        </collision>
    </link>
    <joint name="4_5" type="revolute">
       <parent link="4"/>
       <child  link="5"/>
       <origin rpy="0 0 0" xyz="0 -0.3985551600379108 0.06419198150479799" />
     <axis xyz="1 0 0"/>
       <limit effort="0.0" lower="-3.14159" upper="3.14159" velocity="0.0"/>
    </joint>
    <link name="6">
        <inertial>
            <origin xyz="0 -0.38849884612102287 0.27080113145648277" rpy="0 0 0"/>
            <mass value="1" />
            <inertia ixx="100" ixy="0" ixz="0" iyy="100" iyz="0" izz="100" />
        </inertial>
        <visual>
            <origin xyz="0 -0.38849884612102287 0.27080113145648277" rpy="0 0 0"/>
            <geometry>
                <box size="0.6618344288753493 0.7769976922420457 0.5416022629129655" />
            </geometry>
            <material name="Green">
                <color rgba="0 128 0 1"/>
            </material>
        </visual>
        <collision>
            <origin xyz="0 -0.38849884612102287 0.27080113145648277" rpy="0 0 0"/>
            <geometry>
                <box size="0.6618344288753493 0.7769976922420457 0.5416022629129655" />
            </geometry>
        </collision>
    </link>
    <joint name="5_6" type="revolute">
       <parent link="5"/>
       <child  link="6"/>
       <origin rpy="0 0 0" xyz="0 -0.21519327003609845 0.6178068800115557" />
     <axis xyz="1 0 0"/>
       <limit effort="0.0" lower="-3.14159" upper="3.14159" velocity="0.0"/>
    </joint>
    <link name="7">
        <inertial>
            <origin xyz="0 -0.044707406250300674 0.37664334270321664" rpy="0 0 0"/>
            <mass value="1" />
            <inertia ixx="100" ixy="0" ixz="0" iyy="100" iyz="0" izz="100" />
        </inertial>
        <visual>
            <origin xyz="0 -0.044707406250300674 0.37664334270321664" rpy="0 0 0"/>
            <geometry>
                <box size="0.8199770471512282 0.08941481250060135 0.7532866854064333" />
            </geometry>
            <material name="Green">
                <color rgba="0 128 0 1"/>
            </material>
        </visual>
        <collision>
            <origin xyz="0 -0.044707406250300674 0.37664334270321664" rpy="0 0 0"/>
            <geometry>
                <box size="0.8199770471512282 0.08941481250060135 0.7532866854064333" />
            </geometry>
        </collision>
    </link>
    <joint name="6_7" type="revolute">
       <parent link="6"/>
       <child  link="7"/>
       <origin rpy="0 0 0" xyz="0 -0.7769976922420457 0.5416022629129655" />
     <axis xyz="1 0 0"/>
       <limit effort="0.0" lower="-3.14159" upper="3.14159" velocity="0.0"/>
    </joint>
    <link name="8">
        <inertial>
            <origin xyz="0 -0.19523927556946158 0.1533921474257568" rpy="0 0 0"/>
            <mass value="1" />
            <inertia ixx="100" ixy="0" ixz="0" iyy="100" iyz="0" izz="100" />
        </inertial>
        <visual>
            <origin xyz="0 -0.19523927556946158 0.1533921474257568" rpy="0 0 0"/>
            <geometry>
                <box size="0.940734522249 0.39047855113892316 0.3067842948515136" />
            </geometry>
            <material name="Green">
                <color rgba="0 128 0 1"/>
            </material>
        </visual>
        <collision>
            <origin xyz="0 -0.19523927556946158 0.1533921474257568" rpy="0 0 0"/>
            <geometry>
                <box size="0.940734522249 0.39047855113892316 0.3067842948515136" />
            </geometry>
        </collision>
    </link>
    <joint name="7_8" type="revolute">
       <parent link="7"/>
       <child  link="8"/>
       <origin rpy="0 0 0" xyz="0 -0.08941481250060135 0.7532866854064333" />
     <axis xyz="1 1 1"/>
       <limit effort="0.0" lower="-3.14159" upper="3.14159" velocity="0.0"/>
    </joint>
</robot>