<robot name = "robot">
    <link name="0">
        <inertial>
            <origin xyz="0 0 0.35" rpy="0 0 0"/>
            <mass value="1" />
            <inertia ixx="100" ixy="0" ixz="0" iyy="100" iyz="0" izz="100" />
        </inertial>
        <visual>
            <origin xyz="0 0 0.35" rpy="0 0 0"/>
            <geometry>
                <box size="0.7 0.7 0.7" />
            </geometry>
            <material name="Blue">
                <color rgba="0 0 255 1"/>
            </material>
        </visual>
        <collision>
            <origin xyz="0 0 0.35" rpy="0 0 0"/>
            <geometry>
                <box size="0.7 0.7 0.7" />
            </geometry>
        </collision>
    </link>
    <link name="1">
        <inertial>
            <origin xyz="-0.0461064834731062 0 0.2438266119987077" rpy="0 0 0"/>
            <mass value="1" />
            <inertia ixx="100" ixy="0" ixz="0" iyy="100" iyz="0" izz="100" />
        </inertial>
        <visual>
            <origin xyz="-0.0461064834731062 0 0.2438266119987077" rpy="0 0 0"/>
            <geometry>
                <box size="0.0922129669462124 0.42843649586869426 0.4876532239974154" />
            </geometry>
            <material name="Blue">
                <color rgba="0 0 255 1"/>
            </material>
        </visual>
        <collision>
            <origin xyz="-0.0461064834731062 0 0.2438266119987077" rpy="0 0 0"/>
            <geometry>
                <box size="0.0922129669462124 0.42843649586869426 0.4876532239974154" />
            </geometry>
        </collision>
    </link>
    <joint name="0_1" type="revolute">
       <parent link="0"/>
       <child  link="1"/>
       <origin rpy="0 0 0" xyz="-0.35 0 0.7" />
     <axis xyz="1 1 0"/>
       <limit effort="0.0" lower="-3.14159" upper="3.14159" velocity="0.0"/>
    </joint>
    <link name="2">
        <inertial>
            <origin xyz="-0.47181551322139603 0 0.443734416059149" rpy="0 0 0"/>
            <mass value="1" />
            <inertia ixx="100" ixy="0" ixz="0" iyy="100" iyz="0" izz="100" />
        </inertial>
        <visual>
            <origin xyz="-0.47181551322139603 0 0.443734416059149" rpy="0 0 0"/>
            <geometry>
                <box size="0.9436310264427921 0.22192679638852653 0.887468832118298" />
            </geometry>
            <material name="Blue">
                <color rgba="0 0 255 1"/>
            </material>
        </visual>
        <collision>
            <origin xyz="-0.47181551322139603 0 0.443734416059149" rpy="0 0 0"/>
            <geometry>
                <box size="0.9436310264427921 0.22192679638852653 0.887468832118298" />
            </geometry>
        </collision>
    </link>
    <joint name="1_2" type="revolute">
       <parent link="1"/>
       <child  link="2"/>
       <origin rpy="0 0 0" xyz="-0.0922129669462124 0 0.4876532239974154" />
     <axis xyz="0 0 1"/>
       <limit effort="0.0" lower="-3.14159" upper="3.14159" velocity="0.0"/>
    </joint>
    <link name="3">
        <inertial>
            <origin xyz="-0.45255192646509895 0 0.06185967359993161" rpy="0 0 0"/>
            <mass value="1" />
            <inertia ixx="100" ixy="0" ixz="0" iyy="100" iyz="0" izz="100" />
        </inertial>
        <visual>
            <origin xyz="-0.45255192646509895 0 0.06185967359993161" rpy="0 0 0"/>
            <geometry>
                <box size="0.9051038529301979 0.888489058426965 0.12371934719986322" />
            </geometry>
            <material name="Green">
                <color rgba="0 128 0 1"/>
            </material>
        </visual>
        <collision>
            <origin xyz="-0.45255192646509895 0 0.06185967359993161" rpy="0 0 0"/>
            <geometry>
                <box size="0.9051038529301979 0.888489058426965 0.12371934719986322" />
            </geometry>
        </collision>
    </link>
    <joint name="2_3" type="revolute">
       <parent link="2"/>
       <child  link="3"/>
       <origin rpy="0 0 0" xyz="-0.9436310264427921 0 0.887468832118298" />
     <axis xyz="0 1 1"/>
       <limit effort="0.0" lower="-3.14159" upper="3.14159" velocity="0.0"/>
    </joint>
    <link name="4">
        <inertial>
            <origin xyz="-0.20421012818734952 0 0.07920205039836525" rpy="0 0 0"/>
            <mass value="1" />
            <inertia ixx="100" ixy="0" ixz="0" iyy="100" iyz="0" izz="100" />
        </inertial>
        <visual>
            <origin xyz="-0.20421012818734952 0 0.07920205039836525" rpy="0 0 0"/>
            <geometry>
                <box size="0.40842025637469903 0.7577774489802028 0.1584041007967305" />
            </geometry>
            <material name="Green">
                <color rgba="0 128 0 1"/>
            </material>
        </visual>
        <collision>
            <origin xyz="-0.20421012818734952 0 0.07920205039836525" rpy="0 0 0"/>
            <geometry>
                <box size="0.40842025637469903 0.7577774489802028 0.1584041007967305" />
            </geometry>
        </collision>
    </link>
    <joint name="3_4" type="revolute">
       <parent link="3"/>
       <child  link="4"/>
       <origin rpy="0 0 0" xyz="-0.9051038529301979 0 0.12371934719986322" />
     <axis xyz="0 1 0"/>
       <limit effort="0.0" lower="-3.14159" upper="3.14159" velocity="0.0"/>
    </joint>
    <link name="5">
        <inertial>
            <origin xyz="-0.03694678752372177 0 0.25088281286026565" rpy="0 0 0"/>
            <mass value="1" />
            <inertia ixx="100" ixy="0" ixz="0" iyy="100" iyz="0" izz="100" />
        </inertial>
        <visual>
            <origin xyz="-0.03694678752372177 0 0.25088281286026565" rpy="0 0 0"/>
            <geometry>
                <box size="0.07389357504744354 0.6363358196947871 0.5017656257205313" />
            </geometry>
            <material name="Blue">
                <color rgba="0 0 255 1"/>
            </material>
        </visual>
        <collision>
            <origin xyz="-0.03694678752372177 0 0.25088281286026565" rpy="0 0 0"/>
            <geometry>
                <box size="0.07389357504744354 0.6363358196947871 0.5017656257205313" />
            </geometry>
        </collision>
    </link>
    <joint name="4_5" type="revolute">
       <parent link="4"/>
       <child  link="5"/>
       <origin rpy="0 0 0" xyz="-0.40842025637469903 0 0.1584041007967305" />
     <axis xyz="1 0 0"/>
       <limit effort="0.0" lower="-3.14159" upper="3.14159" velocity="0.0"/>
    </joint>
    <link name="6">
        <inertial>
            <origin xyz="0.20632790503824072 0 0.40035478898612753" rpy="0 0 0"/>
            <mass value="1" />
            <inertia ixx="100" ixy="0" ixz="0" iyy="100" iyz="0" izz="100" />
        </inertial>
        <visual>
            <origin xyz="0.20632790503824072 0 0.40035478898612753" rpy="0 0 0"/>
            <geometry>
                <box size="0.41265581007648144 0.4592893103708955 0.8007095779722551" />
            </geometry>
            <material name="Green">
                <color rgba="0 128 0 1"/>
            </material>
        </visual>
        <collision>
            <origin xyz="0.20632790503824072 0 0.40035478898612753" rpy="0 0 0"/>
            <geometry>
                <box size="0.41265581007648144 0.4592893103708955 0.8007095779722551" />
            </geometry>
        </collision>
    </link>
    <joint name="0_6" type="revolute">
       <parent link="0"/>
       <child  link="6"/>
       <origin rpy="0 0 0" xyz="0.35 0 0.7" />
     <axis xyz="0 1 0"/>
       <limit effort="0.0" lower="-3.14159" upper="3.14159" velocity="0.0"/>
    </joint>
    <link name="7">
        <inertial>
            <origin xyz="0.4402529044832874 0 0.37474618516364283" rpy="0 0 0"/>
            <mass value="1" />
            <inertia ixx="100" ixy="0" ixz="0" iyy="100" iyz="0" izz="100" />
        </inertial>
        <visual>
            <origin xyz="0.4402529044832874 0 0.37474618516364283" rpy="0 0 0"/>
            <geometry>
                <box size="0.8805058089665748 0.06084924577904882 0.7494923703272857" />
            </geometry>
            <material name="Green">
                <color rgba="0 128 0 1"/>
            </material>
        </visual>
        <collision>
            <origin xyz="0.4402529044832874 0 0.37474618516364283" rpy="0 0 0"/>
            <geometry>
                <box size="0.8805058089665748 0.06084924577904882 0.7494923703272857" />
            </geometry>
        </collision>
    </link>
    <joint name="6_7" type="revolute">
       <parent link="6"/>
       <child  link="7"/>
       <origin rpy="0 0 0" xyz="0.41265581007648144 0 0.8007095779722551" />
     <axis xyz="1 0 1"/>
       <limit effort="0.0" lower="-3.14159" upper="3.14159" velocity="0.0"/>
    </joint>
    <link name="8">
        <inertial>
            <origin xyz="0 0.2969290331301494 0.3942601336544656" rpy="0 0 0"/>
            <mass value="1" />
            <inertia ixx="100" ixy="0" ixz="0" iyy="100" iyz="0" izz="100" />
        </inertial>
        <visual>
            <origin xyz="0 0.2969290331301494 0.3942601336544656" rpy="0 0 0"/>
            <geometry>
                <box size="0.6716268091842862 0.5938580662602988 0.7885202673089312" />
            </geometry>
            <material name="Blue">
                <color rgba="0 0 255 1"/>
            </material>
        </visual>
        <collision>
            <origin xyz="0 0.2969290331301494 0.3942601336544656" rpy="0 0 0"/>
            <geometry>
                <box size="0.6716268091842862 0.5938580662602988 0.7885202673089312" />
            </geometry>
        </collision>
    </link>
    <joint name="0_8" type="revolute">
       <parent link="0"/>
       <child  link="8"/>
       <origin rpy="0 0 0" xyz="0 0.35 0.7" />
     <axis xyz="0 1 0"/>
       <limit effort="0.0" lower="-3.14159" upper="3.14159" velocity="0.0"/>
    </joint>
    <link name="9">
        <inertial>
            <origin xyz="0 0.2722430072998009 0.46714875791494187" rpy="0 0 0"/>
            <mass value="1" />
            <inertia ixx="100" ixy="0" ixz="0" iyy="100" iyz="0" izz="100" />
        </inertial>
        <visual>
            <origin xyz="0 0.2722430072998009 0.46714875791494187" rpy="0 0 0"/>
            <geometry>
                <box size="0.8643829436513524 0.5444860145996018 0.9342975158298837" />
            </geometry>
            <material name="Green">
                <color rgba="0 128 0 1"/>
            </material>
        </visual>
        <collision>
            <origin xyz="0 0.2722430072998009 0.46714875791494187" rpy="0 0 0"/>
            <geometry>
                <box size="0.8643829436513524 0.5444860145996018 0.9342975158298837" />
            </geometry>
        </collision>
    </link>
    <joint name="8_9" type="revolute">
       <parent link="8"/>
       <child  link="9"/>
       <origin rpy="0 0 0" xyz="0 0.5938580662602988 0.7885202673089312" />
     <axis xyz="1 1 0"/>
       <limit effort="0.0" lower="-3.14159" upper="3.14159" velocity="0.0"/>
    </joint>
</robot>