<robot name = "robot">
    <link name="0">
        <inertial>
            <origin xyz="0 0 0.35" rpy="0 0 0"/>
            <mass value="1" />
            <inertia ixx="100" ixy="0" ixz="0" iyy="100" iyz="0" izz="100" />
        </inertial>
        <visual>
            <origin xyz="0 0 0.35" rpy="0 0 0"/>
            <geometry>
                <box size="0.7 0.7 0.7" />
            </geometry>
            <material name="Green">
                <color rgba="0 128 0 1"/>
            </material>
        </visual>
        <collision>
            <origin xyz="0 0 0.35" rpy="0 0 0"/>
            <geometry>
                <box size="0.7 0.7 0.7" />
            </geometry>
        </collision>
    </link>
    <link name="1">
        <inertial>
            <origin xyz="-0.04264810507631772 0 0.16340055089236621" rpy="0 0 0"/>
            <mass value="1" />
            <inertia ixx="100" ixy="0" ixz="0" iyy="100" iyz="0" izz="100" />
        </inertial>
        <visual>
            <origin xyz="-0.04264810507631772 0 0.16340055089236621" rpy="0 0 0"/>
            <geometry>
                <box size="0.08529621015263544 0.331852378012386 0.32680110178473243" />
            </geometry>
            <material name="Blue">
                <color rgba="0 0 255 1"/>
            </material>
        </visual>
        <collision>
            <origin xyz="-0.04264810507631772 0 0.16340055089236621" rpy="0 0 0"/>
            <geometry>
                <box size="0.08529621015263544 0.331852378012386 0.32680110178473243" />
            </geometry>
        </collision>
    </link>
    <joint name="0_1" type="revolute">
       <parent link="0"/>
       <child  link="1"/>
       <origin rpy="0 0 0" xyz="-0.35 0 0.7" />
     <axis xyz="1 1 0"/>
       <limit effort="0.0" lower="-3.14159" upper="3.14159" velocity="0.0"/>
    </joint>
    <link name="2">
        <inertial>
            <origin xyz="-0.38913316095364076 0 0.16169624314017794" rpy="0 0 0"/>
            <mass value="1" />
            <inertia ixx="100" ixy="0" ixz="0" iyy="100" iyz="0" izz="100" />
        </inertial>
        <visual>
            <origin xyz="-0.38913316095364076 0 0.16169624314017794" rpy="0 0 0"/>
            <geometry>
                <box size="0.7782663219072815 0.5053903748429275 0.3233924862803559" />
            </geometry>
            <material name="Green">
                <color rgba="0 128 0 1"/>
            </material>
        </visual>
        <collision>
            <origin xyz="-0.38913316095364076 0 0.16169624314017794" rpy="0 0 0"/>
            <geometry>
                <box size="0.7782663219072815 0.5053903748429275 0.3233924862803559" />
            </geometry>
        </collision>
    </link>
    <joint name="1_2" type="revolute">
       <parent link="1"/>
       <child  link="2"/>
       <origin rpy="0 0 0" xyz="-0.08529621015263544 0 0.32680110178473243" />
     <axis xyz="1 1 0"/>
       <limit effort="0.0" lower="-3.14159" upper="3.14159" velocity="0.0"/>
    </joint>
    <link name="3">
        <inertial>
            <origin xyz="0 -0.37726330820110243 0.10100713163637182" rpy="0 0 0"/>
            <mass value="1" />
            <inertia ixx="100" ixy="0" ixz="0" iyy="100" iyz="0" izz="100" />
        </inertial>
        <visual>
            <origin xyz="0 -0.37726330820110243 0.10100713163637182" rpy="0 0 0"/>
            <geometry>
                <box size="0.7249160559644788 0.7545266164022049 0.20201426327274363" />
            </geometry>
            <material name="Green">
                <color rgba="0 128 0 1"/>
            </material>
        </visual>
        <collision>
            <origin xyz="0 -0.37726330820110243 0.10100713163637182" rpy="0 0 0"/>
            <geometry>
                <box size="0.7249160559644788 0.7545266164022049 0.20201426327274363" />
            </geometry>
        </collision>
    </link>
    <joint name="0_3" type="revolute">
       <parent link="0"/>
       <child  link="3"/>
       <origin rpy="0 0 0" xyz="0 -0.35 0.7" />
     <axis xyz="1 0 0"/>
       <limit effort="0.0" lower="-3.14159" upper="3.14159" velocity="0.0"/>
    </joint>
    <link name="4">
        <inertial>
            <origin xyz="0 -0.3260024029186083 0.405441369934955" rpy="0 0 0"/>
            <mass value="1" />
            <inertia ixx="100" ixy="0" ixz="0" iyy="100" iyz="0" izz="100" />
        </inertial>
        <visual>
            <origin xyz="0 -0.3260024029186083 0.405441369934955" rpy="0 0 0"/>
            <geometry>
                <box size="0.45730274798755666 0.6520048058372166 0.81088273986991" />
            </geometry>
            <material name="Blue">
                <color rgba="0 0 255 1"/>
            </material>
        </visual>
        <collision>
            <origin xyz="0 -0.3260024029186083 0.405441369934955" rpy="0 0 0"/>
            <geometry>
                <box size="0.45730274798755666 0.6520048058372166 0.81088273986991" />
            </geometry>
        </collision>
    </link>
    <joint name="3_4" type="revolute">
       <parent link="3"/>
       <child  link="4"/>
       <origin rpy="0 0 0" xyz="0 -0.7545266164022049 0.20201426327274363" />
     <axis xyz="0 0 1"/>
       <limit effort="0.0" lower="-3.14159" upper="3.14159" velocity="0.0"/>
    </joint>
    <link name="5">
        <inertial>
            <origin xyz="0 -0.1751780117797438 0.12178968123139072" rpy="0 0 0"/>
            <mass value="1" />
            <inertia ixx="100" ixy="0" ixz="0" iyy="100" iyz="0" izz="100" />
        </inertial>
        <visual>
            <origin xyz="0 -0.1751780117797438 0.12178968123139072" rpy="0 0 0"/>
            <geometry>
                <box size="0.004216761668945912 0.3503560235594876 0.24357936246278145" />
            </geometry>
            <material name="Blue">
                <color rgba="0 0 255 1"/>
            </material>
        </visual>
        <collision>
            <origin xyz="0 -0.1751780117797438 0.12178968123139072" rpy="0 0 0"/>
            <geometry>
                <box size="0.004216761668945912 0.3503560235594876 0.24357936246278145" />
            </geometry>
        </collision>
    </link>
    <joint name="4_5" type="revolute">
       <parent link="4"/>
       <child  link="5"/>
       <origin rpy="0 0 0" xyz="0 -0.6520048058372166 0.81088273986991" />
     <axis xyz="1 0 0"/>
       <limit effort="0.0" lower="-3.14159" upper="3.14159" velocity="0.0"/>
    </joint>
    <link name="6">
        <inertial>
            <origin xyz="0 -0.33941369127014887 0.3658805461681568" rpy="0 0 0"/>
            <mass value="1" />
            <inertia ixx="100" ixy="0" ixz="0" iyy="100" iyz="0" izz="100" />
        </inertial>
        <visual>
            <origin xyz="0 -0.33941369127014887 0.3658805461681568" rpy="0 0 0"/>
            <geometry>
                <box size="0.6629538305206248 0.6788273825402977 0.7317610923363136" />
            </geometry>
            <material name="Green">
                <color rgba="0 128 0 1"/>
            </material>
        </visual>
        <collision>
            <origin xyz="0 -0.33941369127014887 0.3658805461681568" rpy="0 0 0"/>
            <geometry>
                <box size="0.6629538305206248 0.6788273825402977 0.7317610923363136" />
            </geometry>
        </collision>
    </link>
    <joint name="5_6" type="revolute">
       <parent link="5"/>
       <child  link="6"/>
       <origin rpy="0 0 0" xyz="0 -0.3503560235594876 0.24357936246278145" />
     <axis xyz="0 1 1"/>
       <limit effort="0.0" lower="-3.14159" upper="3.14159" velocity="0.0"/>
    </joint>
    <link name="7">
        <inertial>
            <origin xyz="0 -0.46029099155483455 0.24406532944184728" rpy="0 0 0"/>
            <mass value="1" />
            <inertia ixx="100" ixy="0" ixz="0" iyy="100" iyz="0" izz="100" />
        </inertial>
        <visual>
            <origin xyz="0 -0.46029099155483455 0.24406532944184728" rpy="0 0 0"/>
            <geometry>
                <box size="0.555909138439001 0.9205819831096691 0.48813065888369456" />
            </geometry>
            <material name="Green">
                <color rgba="0 128 0 1"/>
            </material>
        </visual>
        <collision>
            <origin xyz="0 -0.46029099155483455 0.24406532944184728" rpy="0 0 0"/>
            <geometry>
                <box size="0.555909138439001 0.9205819831096691 0.48813065888369456" />
            </geometry>
        </collision>
    </link>
    <joint name="6_7" type="revolute">
       <parent link="6"/>
       <child  link="7"/>
       <origin rpy="0 0 0" xyz="0 -0.6788273825402977 0.7317610923363136" />
     <axis xyz="1 1 1"/>
       <limit effort="0.0" lower="-3.14159" upper="3.14159" velocity="0.0"/>
    </joint>
</robot>