<robot name = "robot">
    <link name="0">
        <inertial>
            <origin xyz="0 0 0.35" rpy="0 0 0"/>
            <mass value="1" />
            <inertia ixx="100" ixy="0" ixz="0" iyy="100" iyz="0" izz="100" />
        </inertial>
        <visual>
            <origin xyz="0 0 0.35" rpy="0 0 0"/>
            <geometry>
                <box size="0.7 0.7 0.7" />
            </geometry>
            <material name="Green">
                <color rgba="0 128 0 1"/>
            </material>
        </visual>
        <collision>
            <origin xyz="0 0 0.35" rpy="0 0 0"/>
            <geometry>
                <box size="0.7 0.7 0.7" />
            </geometry>
        </collision>
    </link>
    <link name="1">
        <inertial>
            <origin xyz="-0.14318416408509765 0 0.40917389166931256" rpy="0 0 0"/>
            <mass value="1" />
            <inertia ixx="100" ixy="0" ixz="0" iyy="100" iyz="0" izz="100" />
        </inertial>
        <visual>
            <origin xyz="-0.14318416408509765 0 0.40917389166931256" rpy="0 0 0"/>
            <geometry>
                <box size="0.2863683281701953 0.035492511049510234 0.8183477833386251" />
            </geometry>
            <material name="Blue">
                <color rgba="0 0 255 1"/>
            </material>
        </visual>
        <collision>
            <origin xyz="-0.14318416408509765 0 0.40917389166931256" rpy="0 0 0"/>
            <geometry>
                <box size="0.2863683281701953 0.035492511049510234 0.8183477833386251" />
            </geometry>
        </collision>
    </link>
    <joint name="0_1" type="revolute">
       <parent link="0"/>
       <child  link="1"/>
       <origin rpy="0 0 0" xyz="-0.35 0 0.7" />
     <axis xyz="1 1 0"/>
       <limit effort="0.0" lower="-3.14159" upper="3.14159" velocity="0.0"/>
    </joint>
    <link name="2">
        <inertial>
            <origin xyz="-0.43759197958156204 0 0.013149197775624233" rpy="0 0 0"/>
            <mass value="1" />
            <inertia ixx="100" ixy="0" ixz="0" iyy="100" iyz="0" izz="100" />
        </inertial>
        <visual>
            <origin xyz="-0.43759197958156204 0 0.013149197775624233" rpy="0 0 0"/>
            <geometry>
                <box size="0.8751839591631241 0.667831022319017 0.026298395551248466" />
            </geometry>
            <material name="Green">
                <color rgba="0 128 0 1"/>
            </material>
        </visual>
        <collision>
            <origin xyz="-0.43759197958156204 0 0.013149197775624233" rpy="0 0 0"/>
            <geometry>
                <box size="0.8751839591631241 0.667831022319017 0.026298395551248466" />
            </geometry>
        </collision>
    </link>
    <joint name="1_2" type="revolute">
       <parent link="1"/>
       <child  link="2"/>
       <origin rpy="0 0 0" xyz="-0.2863683281701953 0 0.8183477833386251" />
     <axis xyz="1 0 0"/>
       <limit effort="0.0" lower="-3.14159" upper="3.14159" velocity="0.0"/>
    </joint>
    <link name="3">
        <inertial>
            <origin xyz="-0.1693660145134221 0 0.0811630444489832" rpy="0 0 0"/>
            <mass value="1" />
            <inertia ixx="100" ixy="0" ixz="0" iyy="100" iyz="0" izz="100" />
        </inertial>
        <visual>
            <origin xyz="-0.1693660145134221 0 0.0811630444489832" rpy="0 0 0"/>
            <geometry>
                <box size="0.3387320290268442 0.6117822181257189 0.1623260888979664" />
            </geometry>
            <material name="Blue">
                <color rgba="0 0 255 1"/>
            </material>
        </visual>
        <collision>
            <origin xyz="-0.1693660145134221 0 0.0811630444489832" rpy="0 0 0"/>
            <geometry>
                <box size="0.3387320290268442 0.6117822181257189 0.1623260888979664" />
            </geometry>
        </collision>
    </link>
    <joint name="2_3" type="revolute">
       <parent link="2"/>
       <child  link="3"/>
       <origin rpy="0 0 0" xyz="-0.8751839591631241 0 0.026298395551248466" />
     <axis xyz="0 0 1"/>
       <limit effort="0.0" lower="-3.14159" upper="3.14159" velocity="0.0"/>
    </joint>
    <link name="4">
        <inertial>
            <origin xyz="-0.016532481735026527 0 0.10244419442715053" rpy="0 0 0"/>
            <mass value="1" />
            <inertia ixx="100" ixy="0" ixz="0" iyy="100" iyz="0" izz="100" />
        </inertial>
        <visual>
            <origin xyz="-0.016532481735026527 0 0.10244419442715053" rpy="0 0 0"/>
            <geometry>
                <box size="0.033064963470053055 0.4754106292579894 0.20488838885430105" />
            </geometry>
            <material name="Green">
                <color rgba="0 128 0 1"/>
            </material>
        </visual>
        <collision>
            <origin xyz="-0.016532481735026527 0 0.10244419442715053" rpy="0 0 0"/>
            <geometry>
                <box size="0.033064963470053055 0.4754106292579894 0.20488838885430105" />
            </geometry>
        </collision>
    </link>
    <joint name="3_4" type="revolute">
       <parent link="3"/>
       <child  link="4"/>
       <origin rpy="0 0 0" xyz="-0.3387320290268442 0 0.1623260888979664" />
     <axis xyz="1 0 0"/>
       <limit effort="0.0" lower="-3.14159" upper="3.14159" velocity="0.0"/>
    </joint>
    <link name="5">
        <inertial>
            <origin xyz="-0.3940240417213716 0 0.22802428534965807" rpy="0 0 0"/>
            <mass value="1" />
            <inertia ixx="100" ixy="0" ixz="0" iyy="100" iyz="0" izz="100" />
        </inertial>
        <visual>
            <origin xyz="-0.3940240417213716 0 0.22802428534965807" rpy="0 0 0"/>
            <geometry>
                <box size="0.7880480834427432 0.22102780169346148 0.45604857069931615" />
            </geometry>
            <material name="Green">
                <color rgba="0 128 0 1"/>
            </material>
        </visual>
        <collision>
            <origin xyz="-0.3940240417213716 0 0.22802428534965807" rpy="0 0 0"/>
            <geometry>
                <box size="0.7880480834427432 0.22102780169346148 0.45604857069931615" />
            </geometry>
        </collision>
    </link>
    <joint name="4_5" type="revolute">
       <parent link="4"/>
       <child  link="5"/>
       <origin rpy="0 0 0" xyz="-0.033064963470053055 0 0.20488838885430105" />
     <axis xyz="1 0 1"/>
       <limit effort="0.0" lower="-3.14159" upper="3.14159" velocity="0.0"/>
    </joint>
    <link name="6">
        <inertial>
            <origin xyz="0.0543294175874115 0 0.05978550854215792" rpy="0 0 0"/>
            <mass value="1" />
            <inertia ixx="100" ixy="0" ixz="0" iyy="100" iyz="0" izz="100" />
        </inertial>
        <visual>
            <origin xyz="0.0543294175874115 0 0.05978550854215792" rpy="0 0 0"/>
            <geometry>
                <box size="0.108658835174823 0.6935408511146233 0.11957101708431583" />
            </geometry>
            <material name="Blue">
                <color rgba="0 0 255 1"/>
            </material>
        </visual>
        <collision>
            <origin xyz="0.0543294175874115 0 0.05978550854215792" rpy="0 0 0"/>
            <geometry>
                <box size="0.108658835174823 0.6935408511146233 0.11957101708431583" />
            </geometry>
        </collision>
    </link>
    <joint name="0_6" type="revolute">
       <parent link="0"/>
       <child  link="6"/>
       <origin rpy="0 0 0" xyz="0.35 0 0.7" />
     <axis xyz="0 1 0"/>
       <limit effort="0.0" lower="-3.14159" upper="3.14159" velocity="0.0"/>
    </joint>
    <link name="7">
        <inertial>
            <origin xyz="0.460172440565422 0 0.3913236831768814" rpy="0 0 0"/>
            <mass value="1" />
            <inertia ixx="100" ixy="0" ixz="0" iyy="100" iyz="0" izz="100" />
        </inertial>
        <visual>
            <origin xyz="0.460172440565422 0 0.3913236831768814" rpy="0 0 0"/>
            <geometry>
                <box size="0.920344881130844 0.8356926765366145 0.7826473663537628" />
            </geometry>
            <material name="Green">
                <color rgba="0 128 0 1"/>
            </material>
        </visual>
        <collision>
            <origin xyz="0.460172440565422 0 0.3913236831768814" rpy="0 0 0"/>
            <geometry>
                <box size="0.920344881130844 0.8356926765366145 0.7826473663537628" />
            </geometry>
        </collision>
    </link>
    <joint name="6_7" type="revolute">
       <parent link="6"/>
       <child  link="7"/>
       <origin rpy="0 0 0" xyz="0.108658835174823 0 0.11957101708431583" />
     <axis xyz="0 1 0"/>
       <limit effort="0.0" lower="-3.14159" upper="3.14159" velocity="0.0"/>
    </joint>
    <link name="8">
        <inertial>
            <origin xyz="0 -0.11612006221320864 0.027615501468945258" rpy="0 0 0"/>
            <mass value="1" />
            <inertia ixx="100" ixy="0" ixz="0" iyy="100" iyz="0" izz="100" />
        </inertial>
        <visual>
            <origin xyz="0 -0.11612006221320864 0.027615501468945258" rpy="0 0 0"/>
            <geometry>
                <box size="0.4698477823253996 0.23224012442641728 0.055231002937890517" />
            </geometry>
            <material name="Green">
                <color rgba="0 128 0 1"/>
            </material>
        </visual>
        <collision>
            <origin xyz="0 -0.11612006221320864 0.027615501468945258" rpy="0 0 0"/>
            <geometry>
                <box size="0.4698477823253996 0.23224012442641728 0.055231002937890517" />
            </geometry>
        </collision>
    </link>
    <joint name="0_8" type="revolute">
       <parent link="0"/>
       <child  link="8"/>
       <origin rpy="0 0 0" xyz="0 -0.35 0.7" />
     <axis xyz="1 0 0"/>
       <limit effort="0.0" lower="-3.14159" upper="3.14159" velocity="0.0"/>
    </joint>
    <link name="9">
        <inertial>
            <origin xyz="0 0.3325682490065632 0.048512474754560664" rpy="0 0 0"/>
            <mass value="1" />
            <inertia ixx="100" ixy="0" ixz="0" iyy="100" iyz="0" izz="100" />
        </inertial>
        <visual>
            <origin xyz="0 0.3325682490065632 0.048512474754560664" rpy="0 0 0"/>
            <geometry>
                <box size="0.21830077009882165 0.6651364980131264 0.09702494950912133" />
            </geometry>
            <material name="Green">
                <color rgba="0 128 0 1"/>
            </material>
        </visual>
        <collision>
            <origin xyz="0 0.3325682490065632 0.048512474754560664" rpy="0 0 0"/>
            <geometry>
                <box size="0.21830077009882165 0.6651364980131264 0.09702494950912133" />
            </geometry>
        </collision>
    </link>
    <joint name="0_9" type="revolute">
       <parent link="0"/>
       <child  link="9"/>
       <origin rpy="0 0 0" xyz="0 0.35 0.7" />
     <axis xyz="0 0 1"/>
       <limit effort="0.0" lower="-3.14159" upper="3.14159" velocity="0.0"/>
    </joint>
    <link name="10">
        <inertial>
            <origin xyz="0 0.06008014359089581 0.04030359135699585" rpy="0 0 0"/>
            <mass value="1" />
            <inertia ixx="100" ixy="0" ixz="0" iyy="100" iyz="0" izz="100" />
        </inertial>
        <visual>
            <origin xyz="0 0.06008014359089581 0.04030359135699585" rpy="0 0 0"/>
            <geometry>
                <box size="0.45759652664778605 0.12016028718179161 0.0806071827139917" />
            </geometry>
            <material name="Blue">
                <color rgba="0 0 255 1"/>
            </material>
        </visual>
        <collision>
            <origin xyz="0 0.06008014359089581 0.04030359135699585" rpy="0 0 0"/>
            <geometry>
                <box size="0.45759652664778605 0.12016028718179161 0.0806071827139917" />
            </geometry>
        </collision>
    </link>
    <joint name="9_10" type="revolute">
       <parent link="9"/>
       <child  link="10"/>
       <origin rpy="0 0 0" xyz="0 0.6651364980131264 0.09702494950912133" />
     <axis xyz="0 1 1"/>
       <limit effort="0.0" lower="-3.14159" upper="3.14159" velocity="0.0"/>
    </joint>
    <link name="11">
        <inertial>
            <origin xyz="0 0.4184740099929919 0.3721885047925146" rpy="0 0 0"/>
            <mass value="1" />
            <inertia ixx="100" ixy="0" ixz="0" iyy="100" iyz="0" izz="100" />
        </inertial>
        <visual>
            <origin xyz="0 0.4184740099929919 0.3721885047925146" rpy="0 0 0"/>
            <geometry>
                <box size="0.4869773313895489 0.8369480199859838 0.7443770095850292" />
            </geometry>
            <material name="Green">
                <color rgba="0 128 0 1"/>
            </material>
        </visual>
        <collision>
            <origin xyz="0 0.4184740099929919 0.3721885047925146" rpy="0 0 0"/>
            <geometry>
                <box size="0.4869773313895489 0.8369480199859838 0.7443770095850292" />
            </geometry>
        </collision>
    </link>
    <joint name="10_11" type="revolute">
       <parent link="10"/>
       <child  link="11"/>
       <origin rpy="0 0 0" xyz="0 0.12016028718179161 0.0806071827139917" />
     <axis xyz="1 0 0"/>
       <limit effort="0.0" lower="-3.14159" upper="3.14159" velocity="0.0"/>
    </joint>
</robot>