<robot name = "robot">
    <link name="0">
        <inertial>
            <origin xyz="0 0 0.4129624975133738" rpy="0 0 0"/>
            <mass value="1" />
            <inertia ixx="100" ixy="0" ixz="0" iyy="100" iyz="0" izz="100" />
        </inertial>
        <visual>
            <origin xyz="0 0 0.4129624975133738" rpy="0 0 0"/>
            <geometry>
                <box size="1.2391187698714796 0.7065693625194378 0.8259249950267477" />
            </geometry>
            <material name="Blue">
                <color rgba="0 0 255 1"/>
            </material>
        </visual>
        <collision>
            <origin xyz="0 0 0.4129624975133738" rpy="0 0 0"/>
            <geometry>
                <box size="1.2391187698714796 0.7065693625194378 0.8259249950267477" />
            </geometry>
        </collision>
    </link>
    <link name="1">
        <inertial>
            <origin xyz="0 0 0.5492358639437083" rpy="0 0 0"/>
            <mass value="1" />
            <inertia ixx="100" ixy="0" ixz="0" iyy="100" iyz="0" izz="100" />
        </inertial>
        <visual>
            <origin xyz="0 0 0.5492358639437083" rpy="0 0 0"/>
            <geometry>
                <box size="1.2372748194440653 1.1061537155206913 1.0984717278874165" />
            </geometry>
            <material name="Blue">
                <color rgba="0 0 255 1"/>
            </material>
        </visual>
        <collision>
            <origin xyz="0 0 0.5492358639437083" rpy="0 0 0"/>
            <geometry>
                <box size="1.2372748194440653 1.1061537155206913 1.0984717278874165" />
            </geometry>
        </collision>
    </link>
    <joint name="0_1" type="revolute">
       <parent link="0"/>
       <child  link="1"/>
       <origin rpy="0 0 0" xyz="0 0 0.8259249950267477" />
     <axis xyz="1 1 1"/>
       <limit effort="0.0" lower="-3.14159" upper="3.14159" velocity="0.0"/>
    </joint>
    <link name="2">
        <inertial>
            <origin xyz="0 0 0.7398770184669045" rpy="0 0 0"/>
            <mass value="1" />
            <inertia ixx="100" ixy="0" ixz="0" iyy="100" iyz="0" izz="100" />
        </inertial>
        <visual>
            <origin xyz="0 0 0.7398770184669045" rpy="0 0 0"/>
            <geometry>
                <box size="0.7375032563962547 0.6006932830500076 1.479754036933809" />
            </geometry>
            <material name="Green">
                <color rgba="0 128 0 1"/>
            </material>
        </visual>
        <collision>
            <origin xyz="0 0 0.7398770184669045" rpy="0 0 0"/>
            <geometry>
                <box size="0.7375032563962547 0.6006932830500076 1.479754036933809" />
            </geometry>
        </collision>
    </link>
    <joint name="1_2" type="revolute">
       <parent link="1"/>
       <child  link="2"/>
       <origin rpy="0 0 0" xyz="0 0 1.0984717278874165" />
     <axis xyz="0 0 1"/>
       <limit effort="0.0" lower="-3.14159" upper="3.14159" velocity="0.0"/>
    </joint>
    <link name="3">
        <inertial>
            <origin xyz="-0.5897000972380638 0 0.5525078899218379" rpy="0 0 0"/>
            <mass value="1" />
            <inertia ixx="100" ixy="0" ixz="0" iyy="100" iyz="0" izz="100" />
        </inertial>
        <visual>
            <origin xyz="-0.5897000972380638 0 0.5525078899218379" rpy="0 0 0"/>
            <geometry>
                <box size="1.1794001944761277 0.630341699426851 1.1050157798436757" />
            </geometry>
            <material name="Blue">
                <color rgba="0 0 255 1"/>
            </material>
        </visual>
        <collision>
            <origin xyz="-0.5897000972380638 0 0.5525078899218379" rpy="0 0 0"/>
            <geometry>
                <box size="1.1794001944761277 0.630341699426851 1.1050157798436757" />
            </geometry>
        </collision>
    </link>
    <joint name="2_3" type="revolute">
       <parent link="2"/>
       <child  link="3"/>
       <origin rpy="0 0 0" xyz="-0.36875162819812735 0 0" />
     <axis xyz="1 1 0"/>
       <limit effort="0.0" lower="-3.14159" upper="3.14159" velocity="0.0"/>
    </joint>
    <link name="4">
        <inertial>
            <origin xyz="-0.2507325161014715 0 0.5787439855183769" rpy="0 0 0"/>
            <mass value="1" />
            <inertia ixx="100" ixy="0" ixz="0" iyy="100" iyz="0" izz="100" />
        </inertial>
        <visual>
            <origin xyz="-0.2507325161014715 0 0.5787439855183769" rpy="0 0 0"/>
            <geometry>
                <box size="0.501465032202943 0.9542569308716612 1.1574879710367538" />
            </geometry>
            <material name="Blue">
                <color rgba="0 0 255 1"/>
            </material>
        </visual>
        <collision>
            <origin xyz="-0.2507325161014715 0 0.5787439855183769" rpy="0 0 0"/>
            <geometry>
                <box size="0.501465032202943 0.9542569308716612 1.1574879710367538" />
            </geometry>
        </collision>
    </link>
    <joint name="3_4" type="revolute">
       <parent link="3"/>
       <child  link="4"/>
       <origin rpy="0 0 0" xyz="-1.1794001944761277 0 0" />
     <axis xyz="0 1 0"/>
       <limit effort="0.0" lower="-3.14159" upper="3.14159" velocity="0.0"/>
    </joint>
    <link name="5">
        <inertial>
            <origin xyz="-0.44061798235439575 0 0.43939718639184394" rpy="0 0 0"/>
            <mass value="1" />
            <inertia ixx="100" ixy="0" ixz="0" iyy="100" iyz="0" izz="100" />
        </inertial>
        <visual>
            <origin xyz="-0.44061798235439575 0 0.43939718639184394" rpy="0 0 0"/>
            <geometry>
                <box size="0.8812359647087915 0.5377250001120618 0.8787943727836879" />
            </geometry>
            <material name="Green">
                <color rgba="0 128 0 1"/>
            </material>
        </visual>
        <collision>
            <origin xyz="-0.44061798235439575 0 0.43939718639184394" rpy="0 0 0"/>
            <geometry>
                <box size="0.8812359647087915 0.5377250001120618 0.8787943727836879" />
            </geometry>
        </collision>
    </link>
    <joint name="4_5" type="revolute">
       <parent link="4"/>
       <child  link="5"/>
       <origin rpy="0 0 0" xyz="-0.501465032202943 0 0" />
     <axis xyz="1 0 1"/>
       <limit effort="0.0" lower="-3.14159" upper="3.14159" velocity="0.0"/>
    </joint>
    <link name="6">
        <inertial>
            <origin xyz="-0.442406830755927 0 0.6811978498293416" rpy="0 0 0"/>
            <mass value="1" />
            <inertia ixx="100" ixy="0" ixz="0" iyy="100" iyz="0" izz="100" />
        </inertial>
        <visual>
            <origin xyz="-0.442406830755927 0 0.6811978498293416" rpy="0 0 0"/>
            <geometry>
                <box size="0.884813661511854 1.3284479488243852 1.3623956996586832" />
            </geometry>
            <material name="Blue">
                <color rgba="0 0 255 1"/>
            </material>
        </visual>
        <collision>
            <origin xyz="-0.442406830755927 0 0.6811978498293416" rpy="0 0 0"/>
            <geometry>
                <box size="0.884813661511854 1.3284479488243852 1.3623956996586832" />
            </geometry>
        </collision>
    </link>
    <joint name="5_6" type="revolute">
       <parent link="5"/>
       <child  link="6"/>
       <origin rpy="0 0 0" xyz="-0.8812359647087915 0 0" />
     <axis xyz="0 1 0"/>
       <limit effort="0.0" lower="-3.14159" upper="3.14159" velocity="0.0"/>
    </joint>
    <link name="7">
        <inertial>
            <origin xyz="-0.2690924279235115 0 0.7315326567663643" rpy="0 0 0"/>
            <mass value="1" />
            <inertia ixx="100" ixy="0" ixz="0" iyy="100" iyz="0" izz="100" />
        </inertial>
        <visual>
            <origin xyz="-0.2690924279235115 0 0.7315326567663643" rpy="0 0 0"/>
            <geometry>
                <box size="0.538184855847023 0.8576383148853813 1.4630653135327285" />
            </geometry>
            <material name="Blue">
                <color rgba="0 0 255 1"/>
            </material>
        </visual>
        <collision>
            <origin xyz="-0.2690924279235115 0 0.7315326567663643" rpy="0 0 0"/>
            <geometry>
                <box size="0.538184855847023 0.8576383148853813 1.4630653135327285" />
            </geometry>
        </collision>
    </link>
    <joint name="6_7" type="revolute">
       <parent link="6"/>
       <child  link="7"/>
       <origin rpy="0 0 0" xyz="-0.884813661511854 0 0" />
     <axis xyz="1 0 0"/>
       <limit effort="0.0" lower="-3.14159" upper="3.14159" velocity="0.0"/>
    </joint>
    <link name="8">
        <inertial>
            <origin xyz="-0.4766239134848549 0 0.6444304759867804" rpy="0 0 0"/>
            <mass value="1" />
            <inertia ixx="100" ixy="0" ixz="0" iyy="100" iyz="0" izz="100" />
        </inertial>
        <visual>
            <origin xyz="-0.4766239134848549 0 0.6444304759867804" rpy="0 0 0"/>
            <geometry>
                <box size="0.9532478269697098 0.6376276006162079 1.2888609519735608" />
            </geometry>
            <material name="Green">
                <color rgba="0 128 0 1"/>
            </material>
        </visual>
        <collision>
            <origin xyz="-0.4766239134848549 0 0.6444304759867804" rpy="0 0 0"/>
            <geometry>
                <box size="0.9532478269697098 0.6376276006162079 1.2888609519735608" />
            </geometry>
        </collision>
    </link>
    <joint name="7_8" type="revolute">
       <parent link="7"/>
       <child  link="8"/>
       <origin rpy="0 0 0" xyz="-0.538184855847023 0 0" />
     <axis xyz="1 0 1"/>
       <limit effort="0.0" lower="-3.14159" upper="3.14159" velocity="0.0"/>
    </joint>
    <link name="9">
        <inertial>
            <origin xyz="0 0 -1.0609045827604584" rpy="0 0 0"/>
            <mass value="1" />
            <inertia ixx="100" ixy="0" ixz="0" iyy="100" iyz="0" izz="100" />
        </inertial>
        <visual>
            <origin xyz="0 0 -1.0609045827604584" rpy="0 0 0"/>
            <geometry>
                <box size="0.5279824300687771 0.942675180696254 2.121809165520917" />
            </geometry>
            <material name="Green">
                <color rgba="0 128 0 1"/>
            </material>
        </visual>
        <collision>
            <origin xyz="0 0 -1.0609045827604584" rpy="0 0 0"/>
            <geometry>
                <box size="0.5279824300687771 0.942675180696254 2.121809165520917" />
            </geometry>
        </collision>
    </link>
    <joint name="8_9" type="revolute">
       <parent link="8"/>
       <child  link="9"/>
       <origin rpy="0 0 0" xyz="-0.4766239134848549 0 0" />
     <axis xyz="0 1 0"/>
       <limit effort="0.0" lower="-3.14159" upper="3.14159" velocity="0.0"/>
    </joint>
    <link name="10">
        <inertial>
            <origin xyz="0 0 -0.1888736310298982" rpy="0 0 0"/>
            <mass value="1" />
            <inertia ixx="100" ixy="0" ixz="0" iyy="100" iyz="0" izz="100" />
        </inertial>
        <visual>
            <origin xyz="0 0 -0.1888736310298982" rpy="0 0 0"/>
            <geometry>
                <box size="1.0445797569951343 1.031270192238777 0.3777472620597964" />
            </geometry>
            <material name="Green">
                <color rgba="0 128 0 1"/>
            </material>
        </visual>
        <collision>
            <origin xyz="0 0 -0.1888736310298982" rpy="0 0 0"/>
            <geometry>
                <box size="1.0445797569951343 1.031270192238777 0.3777472620597964" />
            </geometry>
        </collision>
    </link>
    <joint name="9_10" type="revolute">
       <parent link="9"/>
       <child  link="10"/>
       <origin rpy="0 0 0" xyz="0 0 -2.121809165520917" />
     <axis xyz="1 0 1"/>
       <limit effort="0.0" lower="-3.14159" upper="3.14159" velocity="0.0"/>
    </joint>
    <link name="11">
        <inertial>
            <origin xyz="0 0 -0.38028327697619124" rpy="0 0 0"/>
            <mass value="1" />
            <inertia ixx="100" ixy="0" ixz="0" iyy="100" iyz="0" izz="100" />
        </inertial>
        <visual>
            <origin xyz="0 0 -0.38028327697619124" rpy="0 0 0"/>
            <geometry>
                <box size="1.255880672457229 1.3914711683856196 0.7605665539523825" />
            </geometry>
            <material name="Green">
                <color rgba="0 128 0 1"/>
            </material>
        </visual>
        <collision>
            <origin xyz="0 0 -0.38028327697619124" rpy="0 0 0"/>
            <geometry>
                <box size="1.255880672457229 1.3914711683856196 0.7605665539523825" />
            </geometry>
        </collision>
    </link>
    <joint name="10_11" type="revolute">
       <parent link="10"/>
       <child  link="11"/>
       <origin rpy="0 0 0" xyz="0 0 -0.3777472620597964" />
     <axis xyz="1 0 0"/>
       <limit effort="0.0" lower="-3.14159" upper="3.14159" velocity="0.0"/>
    </joint>
    <link name="12">
        <inertial>
            <origin xyz="0.7274105865119436 0 0.7345427768740498" rpy="0 0 0"/>
            <mass value="1" />
            <inertia ixx="100" ixy="0" ixz="0" iyy="100" iyz="0" izz="100" />
        </inertial>
        <visual>
            <origin xyz="0.7274105865119436 0 0.7345427768740498" rpy="0 0 0"/>
            <geometry>
                <box size="1.4548211730238871 0.8040684025991731 1.4690855537480996" />
            </geometry>
            <material name="Blue">
                <color rgba="0 0 255 1"/>
            </material>
        </visual>
        <collision>
            <origin xyz="0.7274105865119436 0 0.7345427768740498" rpy="0 0 0"/>
            <geometry>
                <box size="1.4548211730238871 0.8040684025991731 1.4690855537480996" />
            </geometry>
        </collision>
    </link>
    <joint name="2_12" type="revolute">
       <parent link="2"/>
       <child  link="12"/>
       <origin rpy="0 0 0" xyz="0.36875162819812735 0 0" />
     <axis xyz="1 0 0"/>
       <limit effort="0.0" lower="-3.14159" upper="3.14159" velocity="0.0"/>
    </joint>
    <link name="13">
        <inertial>
            <origin xyz="0.2740718508867733 0 0.575180064283525" rpy="0 0 0"/>
            <mass value="1" />
            <inertia ixx="100" ixy="0" ixz="0" iyy="100" iyz="0" izz="100" />
        </inertial>
        <visual>
            <origin xyz="0.2740718508867733 0 0.575180064283525" rpy="0 0 0"/>
            <geometry>
                <box size="0.5481437017735467 1.4343062907252184 1.15036012856705" />
            </geometry>
            <material name="Blue">
                <color rgba="0 0 255 1"/>
            </material>
        </visual>
        <collision>
            <origin xyz="0.2740718508867733 0 0.575180064283525" rpy="0 0 0"/>
            <geometry>
                <box size="0.5481437017735467 1.4343062907252184 1.15036012856705" />
            </geometry>
        </collision>
    </link>
    <joint name="12_13" type="revolute">
       <parent link="12"/>
       <child  link="13"/>
       <origin rpy="0 0 0" xyz="1.4548211730238871 0 0" />
     <axis xyz="1 1 1"/>
       <limit effort="0.0" lower="-3.14159" upper="3.14159" velocity="0.0"/>
    </joint>
    <link name="14">
        <inertial>
            <origin xyz="0.7018818261995835 0 0.5188879484308667" rpy="0 0 0"/>
            <mass value="1" />
            <inertia ixx="100" ixy="0" ixz="0" iyy="100" iyz="0" izz="100" />
        </inertial>
        <visual>
            <origin xyz="0.7018818261995835 0 0.5188879484308667" rpy="0 0 0"/>
            <geometry>
                <box size="1.403763652399167 1.2336118306567825 1.0377758968617334" />
            </geometry>
            <material name="Green">
                <color rgba="0 128 0 1"/>
            </material>
        </visual>
        <collision>
            <origin xyz="0.7018818261995835 0 0.5188879484308667" rpy="0 0 0"/>
            <geometry>
                <box size="1.403763652399167 1.2336118306567825 1.0377758968617334" />
            </geometry>
        </collision>
    </link>
    <joint name="13_14" type="revolute">
       <parent link="13"/>
       <child  link="14"/>
       <origin rpy="0 0 0" xyz="0.5481437017735467 0 0" />
     <axis xyz="0 1 1"/>
       <limit effort="0.0" lower="-3.14159" upper="3.14159" velocity="0.0"/>
    </joint>
    <link name="15">
        <inertial>
            <origin xyz="0.705410747918327 0 0.7274714703516632" rpy="0 0 0"/>
            <mass value="1" />
            <inertia ixx="100" ixy="0" ixz="0" iyy="100" iyz="0" izz="100" />
        </inertial>
        <visual>
            <origin xyz="0.705410747918327 0 0.7274714703516632" rpy="0 0 0"/>
            <geometry>
                <box size="1.410821495836654 0.9652251699329083 1.4549429407033263" />
            </geometry>
            <material name="Green">
                <color rgba="0 128 0 1"/>
            </material>
        </visual>
        <collision>
            <origin xyz="0.705410747918327 0 0.7274714703516632" rpy="0 0 0"/>
            <geometry>
                <box size="1.410821495836654 0.9652251699329083 1.4549429407033263" />
            </geometry>
        </collision>
    </link>
    <joint name="14_15" type="revolute">
       <parent link="14"/>
       <child  link="15"/>
       <origin rpy="0 0 0" xyz="1.403763652399167 0 0" />
     <axis xyz="0 1 0"/>
       <limit effort="0.0" lower="-3.14159" upper="3.14159" velocity="0.0"/>
    </joint>
    <link name="16">
        <inertial>
            <origin xyz="0.41679334476358104 0 0.37240647040179453" rpy="0 0 0"/>
            <mass value="1" />
            <inertia ixx="100" ixy="0" ixz="0" iyy="100" iyz="0" izz="100" />
        </inertial>
        <visual>
            <origin xyz="0.41679334476358104 0 0.37240647040179453" rpy="0 0 0"/>
            <geometry>
                <box size="0.8335866895271621 0.7422798057760375 0.7448129408035891" />
            </geometry>
            <material name="Green">
                <color rgba="0 128 0 1"/>
            </material>
        </visual>
        <collision>
            <origin xyz="0.41679334476358104 0 0.37240647040179453" rpy="0 0 0"/>
            <geometry>
                <box size="0.8335866895271621 0.7422798057760375 0.7448129408035891" />
            </geometry>
        </collision>
    </link>
    <joint name="15_16" type="revolute">
       <parent link="15"/>
       <child  link="16"/>
       <origin rpy="0 0 0" xyz="1.410821495836654 0 0" />
     <axis xyz="1 1 1"/>
       <limit effort="0.0" lower="-3.14159" upper="3.14159" velocity="0.0"/>
    </joint>
    <link name="17">
        <inertial>
            <origin xyz="0.25708423075446085 0 0.2888716362693993" rpy="0 0 0"/>
            <mass value="1" />
            <inertia ixx="100" ixy="0" ixz="0" iyy="100" iyz="0" izz="100" />
        </inertial>
        <visual>
            <origin xyz="0.25708423075446085 0 0.2888716362693993" rpy="0 0 0"/>
            <geometry>
                <box size="0.5141684615089217 1.3520521548578648 0.5777432725387986" />
            </geometry>
            <material name="Blue">
                <color rgba="0 0 255 1"/>
            </material>
        </visual>
        <collision>
            <origin xyz="0.25708423075446085 0 0.2888716362693993" rpy="0 0 0"/>
            <geometry>
                <box size="0.5141684615089217 1.3520521548578648 0.5777432725387986" />
            </geometry>
        </collision>
    </link>
    <joint name="16_17" type="revolute">
       <parent link="16"/>
       <child  link="17"/>
       <origin rpy="0 0 0" xyz="0.8335866895271621 0 0" />
     <axis xyz="1 0 0"/>
       <limit effort="0.0" lower="-3.14159" upper="3.14159" velocity="0.0"/>
    </joint>
    <link name="18">
        <inertial>
            <origin xyz="0 0 -0.3432361737622353" rpy="0 0 0"/>
            <mass value="1" />
            <inertia ixx="100" ixy="0" ixz="0" iyy="100" iyz="0" izz="100" />
        </inertial>
        <visual>
            <origin xyz="0 0 -0.3432361737622353" rpy="0 0 0"/>
            <geometry>
                <box size="1.234860341850791 1.2215763035946297 0.6864723475244706" />
            </geometry>
            <material name="Green">
                <color rgba="0 128 0 1"/>
            </material>
        </visual>
        <collision>
            <origin xyz="0 0 -0.3432361737622353" rpy="0 0 0"/>
            <geometry>
                <box size="1.234860341850791 1.2215763035946297 0.6864723475244706" />
            </geometry>
        </collision>
    </link>
    <joint name="17_18" type="revolute">
       <parent link="17"/>
       <child  link="18"/>
       <origin rpy="0 0 0" xyz="0.25708423075446085 0 0" />
     <axis xyz="1 0 1"/>
       <limit effort="0.0" lower="-3.14159" upper="3.14159" velocity="0.0"/>
    </joint>
    <link name="19">
        <inertial>
            <origin xyz="0 0 -0.3504955993932064" rpy="0 0 0"/>
            <mass value="1" />
            <inertia ixx="100" ixy="0" ixz="0" iyy="100" iyz="0" izz="100" />
        </inertial>
        <visual>
            <origin xyz="0 0 -0.3504955993932064" rpy="0 0 0"/>
            <geometry>
                <box size="0.527199156064046 1.2345157187520974 0.7009911987864128" />
            </geometry>
            <material name="Blue">
                <color rgba="0 0 255 1"/>
            </material>
        </visual>
        <collision>
            <origin xyz="0 0 -0.3504955993932064" rpy="0 0 0"/>
            <geometry>
                <box size="0.527199156064046 1.2345157187520974 0.7009911987864128" />
            </geometry>
        </collision>
    </link>
    <joint name="18_19" type="revolute">
       <parent link="18"/>
       <child  link="19"/>
       <origin rpy="0 0 0" xyz="0 0 -0.6864723475244706" />
     <axis xyz="0 0 1"/>
       <limit effort="0.0" lower="-3.14159" upper="3.14159" velocity="0.0"/>
    </joint>
    <link name="20">
        <inertial>
            <origin xyz="0 0 -0.9363297176111061" rpy="0 0 0"/>
            <mass value="1" />
            <inertia ixx="100" ixy="0" ixz="0" iyy="100" iyz="0" izz="100" />
        </inertial>
        <visual>
            <origin xyz="0 0 -0.9363297176111061" rpy="0 0 0"/>
            <geometry>
                <box size="0.7521850923929466 0.6972413568031435 1.8726594352222121" />
            </geometry>
            <material name="Blue">
                <color rgba="0 0 255 1"/>
            </material>
        </visual>
        <collision>
            <origin xyz="0 0 -0.9363297176111061" rpy="0 0 0"/>
            <geometry>
                <box size="0.7521850923929466 0.6972413568031435 1.8726594352222121" />
            </geometry>
        </collision>
    </link>
    <joint name="19_20" type="revolute">
       <parent link="19"/>
       <child  link="20"/>
       <origin rpy="0 0 0" xyz="0 0 -0.7009911987864128" />
     <axis xyz="0 1 1"/>
       <limit effort="0.0" lower="-3.14159" upper="3.14159" velocity="0.0"/>
    </joint>
    <link name="21">
        <inertial>
            <origin xyz="0 -0.328730563072526 0.6566001205218077" rpy="0 0 0"/>
            <mass value="1" />
            <inertia ixx="100" ixy="0" ixz="0" iyy="100" iyz="0" izz="100" />
        </inertial>
        <visual>
            <origin xyz="0 -0.328730563072526 0.6566001205218077" rpy="0 0 0"/>
            <geometry>
                <box size="0.5152791043415436 0.657461126145052 1.3132002410436154" />
            </geometry>
            <material name="Green">
                <color rgba="0 128 0 1"/>
            </material>
        </visual>
        <collision>
            <origin xyz="0 -0.328730563072526 0.6566001205218077" rpy="0 0 0"/>
            <geometry>
                <box size="0.5152791043415436 0.657461126145052 1.3132002410436154" />
            </geometry>
        </collision>
    </link>
    <joint name="2_21" type="revolute">
       <parent link="2"/>
       <child  link="21"/>
       <origin rpy="0 0 0" xyz="0 -0.3003466415250038 0" />
     <axis xyz="1 1 1"/>
       <limit effort="0.0" lower="-3.14159" upper="3.14159" velocity="0.0"/>
    </joint>
    <link name="22">
        <inertial>
            <origin xyz="0 -0.359885370708478 0.5415323120981211" rpy="0 0 0"/>
            <mass value="1" />
            <inertia ixx="100" ixy="0" ixz="0" iyy="100" iyz="0" izz="100" />
        </inertial>
        <visual>
            <origin xyz="0 -0.359885370708478 0.5415323120981211" rpy="0 0 0"/>
            <geometry>
                <box size="1.3872742801962907 0.719770741416956 1.0830646241962423" />
            </geometry>
            <material name="Blue">
                <color rgba="0 0 255 1"/>
            </material>
        </visual>
        <collision>
            <origin xyz="0 -0.359885370708478 0.5415323120981211" rpy="0 0 0"/>
            <geometry>
                <box size="1.3872742801962907 0.719770741416956 1.0830646241962423" />
            </geometry>
        </collision>
    </link>
    <joint name="21_22" type="revolute">
       <parent link="21"/>
       <child  link="22"/>
       <origin rpy="0 0 0" xyz="0 -0.657461126145052 0" />
     <axis xyz="0 0 1"/>
       <limit effort="0.0" lower="-3.14159" upper="3.14159" velocity="0.0"/>
    </joint>
    <link name="23">
        <inertial>
            <origin xyz="0 -0.4618684239079197 0.3626841450525972" rpy="0 0 0"/>
            <mass value="1" />
            <inertia ixx="100" ixy="0" ixz="0" iyy="100" iyz="0" izz="100" />
        </inertial>
        <visual>
            <origin xyz="0 -0.4618684239079197 0.3626841450525972" rpy="0 0 0"/>
            <geometry>
                <box size="0.5410923555428342 0.9237368478158394 0.7253682901051944" />
            </geometry>
            <material name="Green">
                <color rgba="0 128 0 1"/>
            </material>
        </visual>
        <collision>
            <origin xyz="0 -0.4618684239079197 0.3626841450525972" rpy="0 0 0"/>
            <geometry>
                <box size="0.5410923555428342 0.9237368478158394 0.7253682901051944" />
            </geometry>
        </collision>
    </link>
    <joint name="22_23" type="revolute">
       <parent link="22"/>
       <child  link="23"/>
       <origin rpy="0 0 0" xyz="0 -0.719770741416956 0" />
     <axis xyz="0 1 0"/>
       <limit effort="0.0" lower="-3.14159" upper="3.14159" velocity="0.0"/>
    </joint>
    <link name="24">
        <inertial>
            <origin xyz="0 -0.37373317529805533 0.5021106669562734" rpy="0 0 0"/>
            <mass value="1" />
            <inertia ixx="100" ixy="0" ixz="0" iyy="100" iyz="0" izz="100" />
        </inertial>
        <visual>
            <origin xyz="0 -0.37373317529805533 0.5021106669562734" rpy="0 0 0"/>
            <geometry>
                <box size="1.2991648874259227 0.7474663505961107 1.0042213339125468" />
            </geometry>
            <material name="Blue">
                <color rgba="0 0 255 1"/>
            </material>
        </visual>
        <collision>
            <origin xyz="0 -0.37373317529805533 0.5021106669562734" rpy="0 0 0"/>
            <geometry>
                <box size="1.2991648874259227 0.7474663505961107 1.0042213339125468" />
            </geometry>
        </collision>
    </link>
    <joint name="23_24" type="revolute">
       <parent link="23"/>
       <child  link="24"/>
       <origin rpy="0 0 0" xyz="0 -0.9237368478158394 0" />
     <axis xyz="0 1 1"/>
       <limit effort="0.0" lower="-3.14159" upper="3.14159" velocity="0.0"/>
    </joint>
    <link name="25">
        <inertial>
            <origin xyz="0 -0.4208121885780804 0.552900198028876" rpy="0 0 0"/>
            <mass value="1" />
            <inertia ixx="100" ixy="0" ixz="0" iyy="100" iyz="0" izz="100" />
        </inertial>
        <visual>
            <origin xyz="0 -0.4208121885780804 0.552900198028876" rpy="0 0 0"/>
            <geometry>
                <box size="1.280573631056665 0.8416243771561608 1.105800396057752" />
            </geometry>
            <material name="Green">
                <color rgba="0 128 0 1"/>
            </material>
        </visual>
        <collision>
            <origin xyz="0 -0.4208121885780804 0.552900198028876" rpy="0 0 0"/>
            <geometry>
                <box size="1.280573631056665 0.8416243771561608 1.105800396057752" />
            </geometry>
        </collision>
    </link>
    <joint name="24_25" type="revolute">
       <parent link="24"/>
       <child  link="25"/>
       <origin rpy="0 0 0" xyz="0 -0.7474663505961107 0" />
     <axis xyz="0 0 1"/>
       <limit effort="0.0" lower="-3.14159" upper="3.14159" velocity="0.0"/>
    </joint>
    <link name="26">
        <inertial>
            <origin xyz="0 -0.3068822622130612 0.5623252804791974" rpy="0 0 0"/>
            <mass value="1" />
            <inertia ixx="100" ixy="0" ixz="0" iyy="100" iyz="0" izz="100" />
        </inertial>
        <visual>
            <origin xyz="0 -0.3068822622130612 0.5623252804791974" rpy="0 0 0"/>
            <geometry>
                <box size="1.247270075433166 0.6137645244261224 1.1246505609583948" />
            </geometry>
            <material name="Green">
                <color rgba="0 128 0 1"/>
            </material>
        </visual>
        <collision>
            <origin xyz="0 -0.3068822622130612 0.5623252804791974" rpy="0 0 0"/>
            <geometry>
                <box size="1.247270075433166 0.6137645244261224 1.1246505609583948" />
            </geometry>
        </collision>
    </link>
    <joint name="25_26" type="revolute">
       <parent link="25"/>
       <child  link="26"/>
       <origin rpy="0 0 0" xyz="0 -0.8416243771561608 0" />
     <axis xyz="0 0 1"/>
       <limit effort="0.0" lower="-3.14159" upper="3.14159" velocity="0.0"/>
    </joint>
    <link name="27">
        <inertial>
            <origin xyz="0 0 -0.8399572150597239" rpy="0 0 0"/>
            <mass value="1" />
            <inertia ixx="100" ixy="0" ixz="0" iyy="100" iyz="0" izz="100" />
        </inertial>
        <visual>
            <origin xyz="0 0 -0.8399572150597239" rpy="0 0 0"/>
            <geometry>
                <box size="0.9979973471316869 0.9876727605125718 1.6799144301194477" />
            </geometry>
            <material name="Green">
                <color rgba="0 128 0 1"/>
            </material>
        </visual>
        <collision>
            <origin xyz="0 0 -0.8399572150597239" rpy="0 0 0"/>
            <geometry>
                <box size="0.9979973471316869 0.9876727605125718 1.6799144301194477" />
            </geometry>
        </collision>
    </link>
    <joint name="26_27" type="revolute">
       <parent link="26"/>
       <child  link="27"/>
       <origin rpy="0 0 0" xyz="0 -0.3068822622130612 0" />
     <axis xyz="1 1 0"/>
       <limit effort="0.0" lower="-3.14159" upper="3.14159" velocity="0.0"/>
    </joint>
    <link name="28">
        <inertial>
            <origin xyz="0 0 -0.21549665100089035" rpy="0 0 0"/>
            <mass value="1" />
            <inertia ixx="100" ixy="0" ixz="0" iyy="100" iyz="0" izz="100" />
        </inertial>
        <visual>
            <origin xyz="0 0 -0.21549665100089035" rpy="0 0 0"/>
            <geometry>
                <box size="0.8359529723392948 1.0925804138151158 0.4309933020017807" />
            </geometry>
            <material name="Green">
                <color rgba="0 128 0 1"/>
            </material>
        </visual>
        <collision>
            <origin xyz="0 0 -0.21549665100089035" rpy="0 0 0"/>
            <geometry>
                <box size="0.8359529723392948 1.0925804138151158 0.4309933020017807" />
            </geometry>
        </collision>
    </link>
    <joint name="27_28" type="revolute">
       <parent link="27"/>
       <child  link="28"/>
       <origin rpy="0 0 0" xyz="0 0 -1.6799144301194477" />
     <axis xyz="1 1 1"/>
       <limit effort="0.0" lower="-3.14159" upper="3.14159" velocity="0.0"/>
    </joint>
    <link name="29">
        <inertial>
            <origin xyz="0 0 -0.5746076247059336" rpy="0 0 0"/>
            <mass value="1" />
            <inertia ixx="100" ixy="0" ixz="0" iyy="100" iyz="0" izz="100" />
        </inertial>
        <visual>
            <origin xyz="0 0 -0.5746076247059336" rpy="0 0 0"/>
            <geometry>
                <box size="1.3640575500261223 0.9955868376955639 1.1492152494118673" />
            </geometry>
            <material name="Green">
                <color rgba="0 128 0 1"/>
            </material>
        </visual>
        <collision>
            <origin xyz="0 0 -0.5746076247059336" rpy="0 0 0"/>
            <geometry>
                <box size="1.3640575500261223 0.9955868376955639 1.1492152494118673" />
            </geometry>
        </collision>
    </link>
    <joint name="28_29" type="revolute">
       <parent link="28"/>
       <child  link="29"/>
       <origin rpy="0 0 0" xyz="0 0 -0.4309933020017807" />
     <axis xyz="1 0 0"/>
       <limit effort="0.0" lower="-3.14159" upper="3.14159" velocity="0.0"/>
    </joint>
    <link name="30">
        <inertial>
            <origin xyz="0 0.43756727470946766 0.5446376007704123" rpy="0 0 0"/>
            <mass value="1" />
            <inertia ixx="100" ixy="0" ixz="0" iyy="100" iyz="0" izz="100" />
        </inertial>
        <visual>
            <origin xyz="0 0.43756727470946766 0.5446376007704123" rpy="0 0 0"/>
            <geometry>
                <box size="0.9022702651433496 0.8751345494189353 1.0892752015408247" />
            </geometry>
            <material name="Green">
                <color rgba="0 128 0 1"/>
            </material>
        </visual>
        <collision>
            <origin xyz="0 0.43756727470946766 0.5446376007704123" rpy="0 0 0"/>
            <geometry>
                <box size="0.9022702651433496 0.8751345494189353 1.0892752015408247" />
            </geometry>
        </collision>
    </link>
    <joint name="2_30" type="revolute">
       <parent link="2"/>
       <child  link="30"/>
       <origin rpy="0 0 0" xyz="0 0.3003466415250038 0" />
     <axis xyz="1 1 0"/>
       <limit effort="0.0" lower="-3.14159" upper="3.14159" velocity="0.0"/>
    </joint>
    <link name="31">
        <inertial>
            <origin xyz="0 0.27872572077630053 0.5666749891850134" rpy="0 0 0"/>
            <mass value="1" />
            <inertia ixx="100" ixy="0" ixz="0" iyy="100" iyz="0" izz="100" />
        </inertial>
        <visual>
            <origin xyz="0 0.27872572077630053 0.5666749891850134" rpy="0 0 0"/>
            <geometry>
                <box size="0.9219752137541035 0.5574514415526011 1.1333499783700267" />
            </geometry>
            <material name="Green">
                <color rgba="0 128 0 1"/>
            </material>
        </visual>
        <collision>
            <origin xyz="0 0.27872572077630053 0.5666749891850134" rpy="0 0 0"/>
            <geometry>
                <box size="0.9219752137541035 0.5574514415526011 1.1333499783700267" />
            </geometry>
        </collision>
    </link>
    <joint name="30_31" type="revolute">
       <parent link="30"/>
       <child  link="31"/>
       <origin rpy="0 0 0" xyz="0 0.8751345494189353 0" />
     <axis xyz="0 1 0"/>
       <limit effort="0.0" lower="-3.14159" upper="3.14159" velocity="0.0"/>
    </joint>
    <link name="32">
        <inertial>
            <origin xyz="0 0.42428560405620663 0.34014194724064384" rpy="0 0 0"/>
            <mass value="1" />
            <inertia ixx="100" ixy="0" ixz="0" iyy="100" iyz="0" izz="100" />
        </inertial>
        <visual>
            <origin xyz="0 0.42428560405620663 0.34014194724064384" rpy="0 0 0"/>
            <geometry>
                <box size="1.2531847916097434 0.8485712081124133 0.6802838944812877" />
            </geometry>
            <material name="Green">
                <color rgba="0 128 0 1"/>
            </material>
        </visual>
        <collision>
            <origin xyz="0 0.42428560405620663 0.34014194724064384" rpy="0 0 0"/>
            <geometry>
                <box size="1.2531847916097434 0.8485712081124133 0.6802838944812877" />
            </geometry>
        </collision>
    </link>
    <joint name="31_32" type="revolute">
       <parent link="31"/>
       <child  link="32"/>
       <origin rpy="0 0 0" xyz="0 0.5574514415526011 0" />
     <axis xyz="1 0 0"/>
       <limit effort="0.0" lower="-3.14159" upper="3.14159" velocity="0.0"/>
    </joint>
    <link name="33">
        <inertial>
            <origin xyz="0 0.28915709697447906 0.650648476905979" rpy="0 0 0"/>
            <mass value="1" />
            <inertia ixx="100" ixy="0" ixz="0" iyy="100" iyz="0" izz="100" />
        </inertial>
        <visual>
            <origin xyz="0 0.28915709697447906 0.650648476905979" rpy="0 0 0"/>
            <geometry>
                <box size="1.0225934225708873 0.5783141939489581 1.301296953811958" />
            </geometry>
            <material name="Green">
                <color rgba="0 128 0 1"/>
            </material>
        </visual>
        <collision>
            <origin xyz="0 0.28915709697447906 0.650648476905979" rpy="0 0 0"/>
            <geometry>
                <box size="1.0225934225708873 0.5783141939489581 1.301296953811958" />
            </geometry>
        </collision>
    </link>
    <joint name="32_33" type="revolute">
       <parent link="32"/>
       <child  link="33"/>
       <origin rpy="0 0 0" xyz="0 0.8485712081124133 0" />
     <axis xyz="0 0 1"/>
       <limit effort="0.0" lower="-3.14159" upper="3.14159" velocity="0.0"/>
    </joint>
    <link name="34">
        <inertial>
            <origin xyz="0 0.6433193982954595 0.7296132185761524" rpy="0 0 0"/>
            <mass value="1" />
            <inertia ixx="100" ixy="0" ixz="0" iyy="100" iyz="0" izz="100" />
        </inertial>
        <visual>
            <origin xyz="0 0.6433193982954595 0.7296132185761524" rpy="0 0 0"/>
            <geometry>
                <box size="1.3052673067705203 1.286638796590919 1.4592264371523047" />
            </geometry>
            <material name="Blue">
                <color rgba="0 0 255 1"/>
            </material>
        </visual>
        <collision>
            <origin xyz="0 0.6433193982954595 0.7296132185761524" rpy="0 0 0"/>
            <geometry>
                <box size="1.3052673067705203 1.286638796590919 1.4592264371523047" />
            </geometry>
        </collision>
    </link>
    <joint name="33_34" type="revolute">
       <parent link="33"/>
       <child  link="34"/>
       <origin rpy="0 0 0" xyz="0 0.5783141939489581 0" />
     <axis xyz="0 1 0"/>
       <limit effort="0.0" lower="-3.14159" upper="3.14159" velocity="0.0"/>
    </joint>
    <link name="35">
        <inertial>
            <origin xyz="0 0.2674538391784627 0.4804327064784402" rpy="0 0 0"/>
            <mass value="1" />
            <inertia ixx="100" ixy="0" ixz="0" iyy="100" iyz="0" izz="100" />
        </inertial>
        <visual>
            <origin xyz="0 0.2674538391784627 0.4804327064784402" rpy="0 0 0"/>
            <geometry>
                <box size="0.9175008595622622 0.5349076783569254 0.9608654129568804" />
            </geometry>
            <material name="Blue">
                <color rgba="0 0 255 1"/>
            </material>
        </visual>
        <collision>
            <origin xyz="0 0.2674538391784627 0.4804327064784402" rpy="0 0 0"/>
            <geometry>
                <box size="0.9175008595622622 0.5349076783569254 0.9608654129568804" />
            </geometry>
        </collision>
    </link>
    <joint name="34_35" type="revolute">
       <parent link="34"/>
       <child  link="35"/>
       <origin rpy="0 0 0" xyz="0 1.286638796590919 0" />
     <axis xyz="1 1 1"/>
       <limit effort="0.0" lower="-3.14159" upper="3.14159" velocity="0.0"/>
    </joint>
    <link name="36">
        <inertial>
            <origin xyz="0 0 -0.8616538472008347" rpy="0 0 0"/>
            <mass value="1" />
            <inertia ixx="100" ixy="0" ixz="0" iyy="100" iyz="0" izz="100" />
        </inertial>
        <visual>
            <origin xyz="0 0 -0.8616538472008347" rpy="0 0 0"/>
            <geometry>
                <box size="1.3300433009085872 0.8067862690128464 1.7233076944016694" />
            </geometry>
            <material name="Blue">
                <color rgba="0 0 255 1"/>
            </material>
        </visual>
        <collision>
            <origin xyz="0 0 -0.8616538472008347" rpy="0 0 0"/>
            <geometry>
                <box size="1.3300433009085872 0.8067862690128464 1.7233076944016694" />
            </geometry>
        </collision>
    </link>
    <joint name="35_36" type="revolute">
       <parent link="35"/>
       <child  link="36"/>
       <origin rpy="0 0 0" xyz="0 0.2674538391784627 0" />
     <axis xyz="1 1 1"/>
       <limit effort="0.0" lower="-3.14159" upper="3.14159" velocity="0.0"/>
    </joint>
    <link name="37">
        <inertial>
            <origin xyz="0 0 -0.3566698949628778" rpy="0 0 0"/>
            <mass value="1" />
            <inertia ixx="100" ixy="0" ixz="0" iyy="100" iyz="0" izz="100" />
        </inertial>
        <visual>
            <origin xyz="0 0 -0.3566698949628778" rpy="0 0 0"/>
            <geometry>
                <box size="1.3549447941834791 1.038695317365263 0.7133397899257556" />
            </geometry>
            <material name="Blue">
                <color rgba="0 0 255 1"/>
            </material>
        </visual>
        <collision>
            <origin xyz="0 0 -0.3566698949628778" rpy="0 0 0"/>
            <geometry>
                <box size="1.3549447941834791 1.038695317365263 0.7133397899257556" />
            </geometry>
        </collision>
    </link>
    <joint name="36_37" type="revolute">
       <parent link="36"/>
       <child  link="37"/>
       <origin rpy="0 0 0" xyz="0 0 -1.7233076944016694" />
     <axis xyz="0 1 0"/>
       <limit effort="0.0" lower="-3.14159" upper="3.14159" velocity="0.0"/>
    </joint>
    <link name="38">
        <inertial>
            <origin xyz="0 0 -0.4117377486028353" rpy="0 0 0"/>
            <mass value="1" />
            <inertia ixx="100" ixy="0" ixz="0" iyy="100" iyz="0" izz="100" />
        </inertial>
        <visual>
            <origin xyz="0 0 -0.4117377486028353" rpy="0 0 0"/>
            <geometry>
                <box size="1.4806711478199854 1.117481228283931 0.8234754972056706" />
            </geometry>
            <material name="Green">
                <color rgba="0 128 0 1"/>
            </material>
        </visual>
        <collision>
            <origin xyz="0 0 -0.4117377486028353" rpy="0 0 0"/>
            <geometry>
                <box size="1.4806711478199854 1.117481228283931 0.8234754972056706" />
            </geometry>
        </collision>
    </link>
    <joint name="37_38" type="revolute">
       <parent link="37"/>
       <child  link="38"/>
       <origin rpy="0 0 0" xyz="0 0 -0.7133397899257556" />
     <axis xyz="0 0 1"/>
       <limit effort="0.0" lower="-3.14159" upper="3.14159" velocity="0.0"/>
    </joint>
</robot>