<robot name = "robot">
    <link name="0">
        <inertial>
            <origin xyz="0 0 3" rpy="0 0 0"/>
            <mass value="1" />
            <inertia ixx="100" ixy="0" ixz="0" iyy="100" iyz="0" izz="100" />
        </inertial>
        <visual>
            <origin xyz="0 0 3" rpy="0 0 0"/>
            <geometry>
                <box size="1.5 1.5 0.8" />
            </geometry>
            <material name="Blue">
                <color rgba="0 0 255 1"/>
            </material>
        </visual>
        <collision>
            <origin xyz="0 0 3" rpy="0 0 0"/>
            <geometry>
                <box size="1.5 1.5 0.8" />
            </geometry>
        </collision>
    </link>
    <link name="1">
        <inertial>
            <origin xyz="-0.05704145253749915 0 0" rpy="0 0 0"/>
            <mass value="1" />
            <inertia ixx="100" ixy="0" ixz="0" iyy="100" iyz="0" izz="100" />
        </inertial>
        <visual>
            <origin xyz="-0.05704145253749915 0 0" rpy="0 0 0"/>
            <geometry>
                <box size="0.1140829050749983 0.41779726769677117 0.03548341213636885" />
            </geometry>
            <material name="Green">
                <color rgba="0 128 0 1"/>
            </material>
        </visual>
        <collision>
            <origin xyz="-0.05704145253749915 0 0" rpy="0 0 0"/>
            <geometry>
                <box size="0.1140829050749983 0.41779726769677117 0.03548341213636885" />
            </geometry>
        </collision>
    </link>
    <joint name="0_1" type="revolute">
       <parent link="0"/>
       <child  link="1"/>
       <origin rpy="0 0 0" xyz="-0.75 0 3" />
     <axis xyz="1 1 1"/>
       <limit effort="0.0" lower="-3.14159" upper="3.14159" velocity="0.0"/>
    </joint>
    <link name="2">
        <inertial>
            <origin xyz="-0.054067498146519455 0 0" rpy="0 0 0"/>
            <mass value="1" />
            <inertia ixx="100" ixy="0" ixz="0" iyy="100" iyz="0" izz="100" />
        </inertial>
        <visual>
            <origin xyz="-0.054067498146519455 0 0" rpy="0 0 0"/>
            <geometry>
                <box size="0.10813499629303891 0.7428400621097343 0.19143340494714545" />
            </geometry>
            <material name="Blue">
                <color rgba="0 0 255 1"/>
            </material>
        </visual>
        <collision>
            <origin xyz="-0.054067498146519455 0 0" rpy="0 0 0"/>
            <geometry>
                <box size="0.10813499629303891 0.7428400621097343 0.19143340494714545" />
            </geometry>
        </collision>
    </link>
    <joint name="1_2" type="revolute">
       <parent link="1"/>
       <child  link="2"/>
       <origin rpy="0 0 0" xyz="-0.1140829050749983 0 0" />
     <axis xyz="1 1 0"/>
       <limit effort="0.0" lower="-3.14159" upper="3.14159" velocity="0.0"/>
    </joint>
    <link name="3">
        <inertial>
            <origin xyz="-0.4260924130616194 0 0" rpy="0 0 0"/>
            <mass value="1" />
            <inertia ixx="100" ixy="0" ixz="0" iyy="100" iyz="0" izz="100" />
        </inertial>
        <visual>
            <origin xyz="-0.4260924130616194 0 0" rpy="0 0 0"/>
            <geometry>
                <box size="0.8521848261232388 0.18540948545506142 0.6913185802513856" />
            </geometry>
            <material name="Green">
                <color rgba="0 128 0 1"/>
            </material>
        </visual>
        <collision>
            <origin xyz="-0.4260924130616194 0 0" rpy="0 0 0"/>
            <geometry>
                <box size="0.8521848261232388 0.18540948545506142 0.6913185802513856" />
            </geometry>
        </collision>
    </link>
    <joint name="2_3" type="revolute">
       <parent link="2"/>
       <child  link="3"/>
       <origin rpy="0 0 0" xyz="-0.10813499629303891 0 0" />
     <axis xyz="1 1 1"/>
       <limit effort="0.0" lower="-3.14159" upper="3.14159" velocity="0.0"/>
    </joint>
    <link name="4">
        <inertial>
            <origin xyz="0 0 -0.43333333333333335" rpy="0 0 0"/>
            <mass value="1" />
            <inertia ixx="100" ixy="0" ixz="0" iyy="100" iyz="0" izz="100" />
        </inertial>
        <visual>
            <origin xyz="0 0 -0.43333333333333335" rpy="0 0 0"/>
            <geometry>
                <box size="0.3941234904540112 0.8914974409595954 0.8666666666666667" />
            </geometry>
            <material name="Green">
                <color rgba="0 128 0 1"/>
            </material>
        </visual>
        <collision>
            <origin xyz="0 0 -0.43333333333333335" rpy="0 0 0"/>
            <geometry>
                <box size="0.3941234904540112 0.8914974409595954 0.8666666666666667" />
            </geometry>
        </collision>
    </link>
    <joint name="3_4" type="revolute">
       <parent link="3"/>
       <child  link="4"/>
       <origin rpy="0 0 0" xyz="-0.4260924130616194 0 -0.3456592901256928" />
     <axis xyz="1 0 0"/>
       <limit effort="0.0" lower="-3.14159" upper="3.14159" velocity="0.0"/>
    </joint>
    <link name="5">
        <inertial>
            <origin xyz="0 0 -0.43333333333333335" rpy="0 0 0"/>
            <mass value="1" />
            <inertia ixx="100" ixy="0" ixz="0" iyy="100" iyz="0" izz="100" />
        </inertial>
        <visual>
            <origin xyz="0 0 -0.43333333333333335" rpy="0 0 0"/>
            <geometry>
                <box size="0.7867884598346957 0.6413512399573851 0.8666666666666667" />
            </geometry>
            <material name="Green">
                <color rgba="0 128 0 1"/>
            </material>
        </visual>
        <collision>
            <origin xyz="0 0 -0.43333333333333335" rpy="0 0 0"/>
            <geometry>
                <box size="0.7867884598346957 0.6413512399573851 0.8666666666666667" />
            </geometry>
        </collision>
    </link>
    <joint name="4_5" type="revolute">
       <parent link="4"/>
       <child  link="5"/>
       <origin rpy="0 0 0" xyz="0 0 -0.8666666666666667" />
     <axis xyz="1 1 1"/>
       <limit effort="0.0" lower="-3.14159" upper="3.14159" velocity="0.0"/>
    </joint>
    <link name="6">
        <inertial>
            <origin xyz="0 0 -0.43333333333333335" rpy="0 0 0"/>
            <mass value="1" />
            <inertia ixx="100" ixy="0" ixz="0" iyy="100" iyz="0" izz="100" />
        </inertial>
        <visual>
            <origin xyz="0 0 -0.43333333333333335" rpy="0 0 0"/>
            <geometry>
                <box size="0.9410819428317783 0.3965913350031993 0.8666666666666667" />
            </geometry>
            <material name="Green">
                <color rgba="0 128 0 1"/>
            </material>
        </visual>
        <collision>
            <origin xyz="0 0 -0.43333333333333335" rpy="0 0 0"/>
            <geometry>
                <box size="0.9410819428317783 0.3965913350031993 0.8666666666666667" />
            </geometry>
        </collision>
    </link>
    <joint name="5_6" type="revolute">
       <parent link="5"/>
       <child  link="6"/>
       <origin rpy="0 0 0" xyz="0 0 -0.8666666666666667" />
     <axis xyz="0 0 1"/>
       <limit effort="0.0" lower="-3.14159" upper="3.14159" velocity="0.0"/>
    </joint>
    <link name="7">
        <inertial>
            <origin xyz="0.2828497983385653 0 0" rpy="0 0 0"/>
            <mass value="1" />
            <inertia ixx="100" ixy="0" ixz="0" iyy="100" iyz="0" izz="100" />
        </inertial>
        <visual>
            <origin xyz="0.2828497983385653 0 0" rpy="0 0 0"/>
            <geometry>
                <box size="0.5656995966771305 0.27777211554412706 0.8689689966744778" />
            </geometry>
            <material name="Blue">
                <color rgba="0 0 255 1"/>
            </material>
        </visual>
        <collision>
            <origin xyz="0.2828497983385653 0 0" rpy="0 0 0"/>
            <geometry>
                <box size="0.5656995966771305 0.27777211554412706 0.8689689966744778" />
            </geometry>
        </collision>
    </link>
    <joint name="0_7" type="revolute">
       <parent link="0"/>
       <child  link="7"/>
       <origin rpy="0 0 0" xyz="0.75 0 3" />
     <axis xyz="1 1 1"/>
       <limit effort="0.0" lower="-3.14159" upper="3.14159" velocity="0.0"/>
    </joint>
    <link name="8">
        <inertial>
            <origin xyz="0.09220734884108223 0 0" rpy="0 0 0"/>
            <mass value="1" />
            <inertia ixx="100" ixy="0" ixz="0" iyy="100" iyz="0" izz="100" />
        </inertial>
        <visual>
            <origin xyz="0.09220734884108223 0 0" rpy="0 0 0"/>
            <geometry>
                <box size="0.18441469768216445 0.2595464514233806 0.26009122310695565" />
            </geometry>
            <material name="Green">
                <color rgba="0 128 0 1"/>
            </material>
        </visual>
        <collision>
            <origin xyz="0.09220734884108223 0 0" rpy="0 0 0"/>
            <geometry>
                <box size="0.18441469768216445 0.2595464514233806 0.26009122310695565" />
            </geometry>
        </collision>
    </link>
    <joint name="7_8" type="revolute">
       <parent link="7"/>
       <child  link="8"/>
       <origin rpy="0 0 0" xyz="0.5656995966771305 0 0" />
     <axis xyz="0 1 0"/>
       <limit effort="0.0" lower="-3.14159" upper="3.14159" velocity="0.0"/>
    </joint>
    <link name="9">
        <inertial>
            <origin xyz="0.33292510290706917 0 0" rpy="0 0 0"/>
            <mass value="1" />
            <inertia ixx="100" ixy="0" ixz="0" iyy="100" iyz="0" izz="100" />
        </inertial>
        <visual>
            <origin xyz="0.33292510290706917 0 0" rpy="0 0 0"/>
            <geometry>
                <box size="0.6658502058141383 0.9079880333373318 0.5042930310296564" />
            </geometry>
            <material name="Blue">
                <color rgba="0 0 255 1"/>
            </material>
        </visual>
        <collision>
            <origin xyz="0.33292510290706917 0 0" rpy="0 0 0"/>
            <geometry>
                <box size="0.6658502058141383 0.9079880333373318 0.5042930310296564" />
            </geometry>
        </collision>
    </link>
    <joint name="8_9" type="revolute">
       <parent link="8"/>
       <child  link="9"/>
       <origin rpy="0 0 0" xyz="0.18441469768216445 0 0" />
     <axis xyz="0 1 0"/>
       <limit effort="0.0" lower="-3.14159" upper="3.14159" velocity="0.0"/>
    </joint>
    <link name="10">
        <inertial>
            <origin xyz="0 0 -0.43333333333333335" rpy="0 0 0"/>
            <mass value="1" />
            <inertia ixx="100" ixy="0" ixz="0" iyy="100" iyz="0" izz="100" />
        </inertial>
        <visual>
            <origin xyz="0 0 -0.43333333333333335" rpy="0 0 0"/>
            <geometry>
                <box size="0.052067311965088514 0.8529945007306978 0.8666666666666667" />
            </geometry>
            <material name="Green">
                <color rgba="0 128 0 1"/>
            </material>
        </visual>
        <collision>
            <origin xyz="0 0 -0.43333333333333335" rpy="0 0 0"/>
            <geometry>
                <box size="0.052067311965088514 0.8529945007306978 0.8666666666666667" />
            </geometry>
        </collision>
    </link>
    <joint name="9_10" type="revolute">
       <parent link="9"/>
       <child  link="10"/>
       <origin rpy="0 0 0" xyz="0.33292510290706917 0 -0.2521465155148282" />
     <axis xyz="1 0 0"/>
       <limit effort="0.0" lower="-3.14159" upper="3.14159" velocity="0.0"/>
    </joint>
    <link name="11">
        <inertial>
            <origin xyz="0 0 -0.43333333333333335" rpy="0 0 0"/>
            <mass value="1" />
            <inertia ixx="100" ixy="0" ixz="0" iyy="100" iyz="0" izz="100" />
        </inertial>
        <visual>
            <origin xyz="0 0 -0.43333333333333335" rpy="0 0 0"/>
            <geometry>
                <box size="0.5029453510693842 0.46026830530513874 0.8666666666666667" />
            </geometry>
            <material name="Green">
                <color rgba="0 128 0 1"/>
            </material>
        </visual>
        <collision>
            <origin xyz="0 0 -0.43333333333333335" rpy="0 0 0"/>
            <geometry>
                <box size="0.5029453510693842 0.46026830530513874 0.8666666666666667" />
            </geometry>
        </collision>
    </link>
    <joint name="10_11" type="revolute">
       <parent link="10"/>
       <child  link="11"/>
       <origin rpy="0 0 0" xyz="0 0 -0.8666666666666667" />
     <axis xyz="1 1 0"/>
       <limit effort="0.0" lower="-3.14159" upper="3.14159" velocity="0.0"/>
    </joint>
    <link name="12">
        <inertial>
            <origin xyz="0 0 -0.43333333333333335" rpy="0 0 0"/>
            <mass value="1" />
            <inertia ixx="100" ixy="0" ixz="0" iyy="100" iyz="0" izz="100" />
        </inertial>
        <visual>
            <origin xyz="0 0 -0.43333333333333335" rpy="0 0 0"/>
            <geometry>
                <box size="0.7825498828409412 0.8178029972860928 0.8666666666666667" />
            </geometry>
            <material name="Green">
                <color rgba="0 128 0 1"/>
            </material>
        </visual>
        <collision>
            <origin xyz="0 0 -0.43333333333333335" rpy="0 0 0"/>
            <geometry>
                <box size="0.7825498828409412 0.8178029972860928 0.8666666666666667" />
            </geometry>
        </collision>
    </link>
    <joint name="11_12" type="revolute">
       <parent link="11"/>
       <child  link="12"/>
       <origin rpy="0 0 0" xyz="0 0 -0.8666666666666667" />
     <axis xyz="0 1 1"/>
       <limit effort="0.0" lower="-3.14159" upper="3.14159" velocity="0.0"/>
    </joint>
    <link name="13">
        <inertial>
            <origin xyz="0 -0.14319861908004533 0" rpy="0 0 0"/>
            <mass value="1" />
            <inertia ixx="100" ixy="0" ixz="0" iyy="100" iyz="0" izz="100" />
        </inertial>
        <visual>
            <origin xyz="0 -0.14319861908004533 0" rpy="0 0 0"/>
            <geometry>
                <box size="0.6503151497528489 0.28639723816009066 0.3401272733906734" />
            </geometry>
            <material name="Blue">
                <color rgba="0 0 255 1"/>
            </material>
        </visual>
        <collision>
            <origin xyz="0 -0.14319861908004533 0" rpy="0 0 0"/>
            <geometry>
                <box size="0.6503151497528489 0.28639723816009066 0.3401272733906734" />
            </geometry>
        </collision>
    </link>
    <joint name="0_13" type="revolute">
       <parent link="0"/>
       <child  link="13"/>
       <origin rpy="0 0 0" xyz="0 -0.75 3" />
     <axis xyz="0 0 1"/>
       <limit effort="0.0" lower="-3.14159" upper="3.14159" velocity="0.0"/>
    </joint>
    <link name="14">
        <inertial>
            <origin xyz="0 -0.014212757586337998 0" rpy="0 0 0"/>
            <mass value="1" />
            <inertia ixx="100" ixy="0" ixz="0" iyy="100" iyz="0" izz="100" />
        </inertial>
        <visual>
            <origin xyz="0 -0.014212757586337998 0" rpy="0 0 0"/>
            <geometry>
                <box size="0.1098820764498405 0.028425515172675997 0.9559707240889208" />
            </geometry>
            <material name="Green">
                <color rgba="0 128 0 1"/>
            </material>
        </visual>
        <collision>
            <origin xyz="0 -0.014212757586337998 0" rpy="0 0 0"/>
            <geometry>
                <box size="0.1098820764498405 0.028425515172675997 0.9559707240889208" />
            </geometry>
        </collision>
    </link>
    <joint name="13_14" type="revolute">
       <parent link="13"/>
       <child  link="14"/>
       <origin rpy="0 0 0" xyz="0 -0.28639723816009066 0" />
     <axis xyz="1 1 1"/>
       <limit effort="0.0" lower="-3.14159" upper="3.14159" velocity="0.0"/>
    </joint>
    <link name="15">
        <inertial>
            <origin xyz="0 -0.21987758958874587 0" rpy="0 0 0"/>
            <mass value="1" />
            <inertia ixx="100" ixy="0" ixz="0" iyy="100" iyz="0" izz="100" />
        </inertial>
        <visual>
            <origin xyz="0 -0.21987758958874587 0" rpy="0 0 0"/>
            <geometry>
                <box size="0.8358250592549923 0.43975517917749174 0.5233084680582275" />
            </geometry>
            <material name="Green">
                <color rgba="0 128 0 1"/>
            </material>
        </visual>
        <collision>
            <origin xyz="0 -0.21987758958874587 0" rpy="0 0 0"/>
            <geometry>
                <box size="0.8358250592549923 0.43975517917749174 0.5233084680582275" />
            </geometry>
        </collision>
    </link>
    <joint name="14_15" type="revolute">
       <parent link="14"/>
       <child  link="15"/>
       <origin rpy="0 0 0" xyz="0 -0.028425515172675997 0" />
     <axis xyz="0 1 0"/>
       <limit effort="0.0" lower="-3.14159" upper="3.14159" velocity="0.0"/>
    </joint>
    <link name="16">
        <inertial>
            <origin xyz="0 0 -0.43333333333333335" rpy="0 0 0"/>
            <mass value="1" />
            <inertia ixx="100" ixy="0" ixz="0" iyy="100" iyz="0" izz="100" />
        </inertial>
        <visual>
            <origin xyz="0 0 -0.43333333333333335" rpy="0 0 0"/>
            <geometry>
                <box size="0.2822941003981012 0.0679819180573209 0.8666666666666667" />
            </geometry>
            <material name="Green">
                <color rgba="0 128 0 1"/>
            </material>
        </visual>
        <collision>
            <origin xyz="0 0 -0.43333333333333335" rpy="0 0 0"/>
            <geometry>
                <box size="0.2822941003981012 0.0679819180573209 0.8666666666666667" />
            </geometry>
        </collision>
    </link>
    <joint name="15_16" type="revolute">
       <parent link="15"/>
       <child  link="16"/>
       <origin rpy="0 0 0" xyz="0 -0.21987758958874587 -0.26165423402911375" />
     <axis xyz="1 0 0"/>
       <limit effort="0.0" lower="-3.14159" upper="3.14159" velocity="0.0"/>
    </joint>
    <link name="17">
        <inertial>
            <origin xyz="0 0 -0.43333333333333335" rpy="0 0 0"/>
            <mass value="1" />
            <inertia ixx="100" ixy="0" ixz="0" iyy="100" iyz="0" izz="100" />
        </inertial>
        <visual>
            <origin xyz="0 0 -0.43333333333333335" rpy="0 0 0"/>
            <geometry>
                <box size="0.6814638814952302 0.7686984592578145 0.8666666666666667" />
            </geometry>
            <material name="Green">
                <color rgba="0 128 0 1"/>
            </material>
        </visual>
        <collision>
            <origin xyz="0 0 -0.43333333333333335" rpy="0 0 0"/>
            <geometry>
                <box size="0.6814638814952302 0.7686984592578145 0.8666666666666667" />
            </geometry>
        </collision>
    </link>
    <joint name="16_17" type="revolute">
       <parent link="16"/>
       <child  link="17"/>
       <origin rpy="0 0 0" xyz="0 0 -0.8666666666666667" />
     <axis xyz="0 1 1"/>
       <limit effort="0.0" lower="-3.14159" upper="3.14159" velocity="0.0"/>
    </joint>
    <link name="18">
        <inertial>
            <origin xyz="0 0 -0.43333333333333335" rpy="0 0 0"/>
            <mass value="1" />
            <inertia ixx="100" ixy="0" ixz="0" iyy="100" iyz="0" izz="100" />
        </inertial>
        <visual>
            <origin xyz="0 0 -0.43333333333333335" rpy="0 0 0"/>
            <geometry>
                <box size="0.09969527052134097 0.08706044352854037 0.8666666666666667" />
            </geometry>
            <material name="Green">
                <color rgba="0 128 0 1"/>
            </material>
        </visual>
        <collision>
            <origin xyz="0 0 -0.43333333333333335" rpy="0 0 0"/>
            <geometry>
                <box size="0.09969527052134097 0.08706044352854037 0.8666666666666667" />
            </geometry>
        </collision>
    </link>
    <joint name="17_18" type="revolute">
       <parent link="17"/>
       <child  link="18"/>
       <origin rpy="0 0 0" xyz="0 0 -0.8666666666666667" />
     <axis xyz="1 0 0"/>
       <limit effort="0.0" lower="-3.14159" upper="3.14159" velocity="0.0"/>
    </joint>
    <link name="19">
        <inertial>
            <origin xyz="0 0.2490807903025974 0" rpy="0 0 0"/>
            <mass value="1" />
            <inertia ixx="100" ixy="0" ixz="0" iyy="100" iyz="0" izz="100" />
        </inertial>
        <visual>
            <origin xyz="0 0.2490807903025974 0" rpy="0 0 0"/>
            <geometry>
                <box size="0.5806173510594439 0.4981615806051948 0.2161291753469914" />
            </geometry>
            <material name="Blue">
                <color rgba="0 0 255 1"/>
            </material>
        </visual>
        <collision>
            <origin xyz="0 0.2490807903025974 0" rpy="0 0 0"/>
            <geometry>
                <box size="0.5806173510594439 0.4981615806051948 0.2161291753469914" />
            </geometry>
        </collision>
    </link>
    <joint name="0_19" type="revolute">
       <parent link="0"/>
       <child  link="19"/>
       <origin rpy="0 0 0" xyz="0 0.75 3" />
     <axis xyz="1 0 0"/>
       <limit effort="0.0" lower="-3.14159" upper="3.14159" velocity="0.0"/>
    </joint>
    <link name="20">
        <inertial>
            <origin xyz="0 0.3426215507342942 0" rpy="0 0 0"/>
            <mass value="1" />
            <inertia ixx="100" ixy="0" ixz="0" iyy="100" iyz="0" izz="100" />
        </inertial>
        <visual>
            <origin xyz="0 0.3426215507342942 0" rpy="0 0 0"/>
            <geometry>
                <box size="0.7615415421621499 0.6852431014685884 0.04408029237942124" />
            </geometry>
            <material name="Green">
                <color rgba="0 128 0 1"/>
            </material>
        </visual>
        <collision>
            <origin xyz="0 0.3426215507342942 0" rpy="0 0 0"/>
            <geometry>
                <box size="0.7615415421621499 0.6852431014685884 0.04408029237942124" />
            </geometry>
        </collision>
    </link>
    <joint name="19_20" type="revolute">
       <parent link="19"/>
       <child  link="20"/>
       <origin rpy="0 0 0" xyz="0 0.4981615806051948 0" />
     <axis xyz="0 0 1"/>
       <limit effort="0.0" lower="-3.14159" upper="3.14159" velocity="0.0"/>
    </joint>
    <link name="21">
        <inertial>
            <origin xyz="0 0.015429891810576801 0" rpy="0 0 0"/>
            <mass value="1" />
            <inertia ixx="100" ixy="0" ixz="0" iyy="100" iyz="0" izz="100" />
        </inertial>
        <visual>
            <origin xyz="0 0.015429891810576801 0" rpy="0 0 0"/>
            <geometry>
                <box size="0.8319392388608117 0.030859783621153603 0.8174084704276801" />
            </geometry>
            <material name="Green">
                <color rgba="0 128 0 1"/>
            </material>
        </visual>
        <collision>
            <origin xyz="0 0.015429891810576801 0" rpy="0 0 0"/>
            <geometry>
                <box size="0.8319392388608117 0.030859783621153603 0.8174084704276801" />
            </geometry>
        </collision>
    </link>
    <joint name="20_21" type="revolute">
       <parent link="20"/>
       <child  link="21"/>
       <origin rpy="0 0 0" xyz="0 0.6852431014685884 0" />
     <axis xyz="0 1 0"/>
       <limit effort="0.0" lower="-3.14159" upper="3.14159" velocity="0.0"/>
    </joint>
    <link name="22">
        <inertial>
            <origin xyz="0 0 -0.43333333333333335" rpy="0 0 0"/>
            <mass value="1" />
            <inertia ixx="100" ixy="0" ixz="0" iyy="100" iyz="0" izz="100" />
        </inertial>
        <visual>
            <origin xyz="0 0 -0.43333333333333335" rpy="0 0 0"/>
            <geometry>
                <box size="0.607000205278758 0.6049258346098215 0.8666666666666667" />
            </geometry>
            <material name="Green">
                <color rgba="0 128 0 1"/>
            </material>
        </visual>
        <collision>
            <origin xyz="0 0 -0.43333333333333335" rpy="0 0 0"/>
            <geometry>
                <box size="0.607000205278758 0.6049258346098215 0.8666666666666667" />
            </geometry>
        </collision>
    </link>
    <joint name="21_22" type="revolute">
       <parent link="21"/>
       <child  link="22"/>
       <origin rpy="0 0 0" xyz="0 0.015429891810576801 -0.40870423521384003" />
     <axis xyz="1 0 0"/>
       <limit effort="0.0" lower="-3.14159" upper="3.14159" velocity="0.0"/>
    </joint>
    <link name="23">
        <inertial>
            <origin xyz="0 0 -0.43333333333333335" rpy="0 0 0"/>
            <mass value="1" />
            <inertia ixx="100" ixy="0" ixz="0" iyy="100" iyz="0" izz="100" />
        </inertial>
        <visual>
            <origin xyz="0 0 -0.43333333333333335" rpy="0 0 0"/>
            <geometry>
                <box size="0.19990678120041117 0.8780775926053809 0.8666666666666667" />
            </geometry>
            <material name="Green">
                <color rgba="0 128 0 1"/>
            </material>
        </visual>
        <collision>
            <origin xyz="0 0 -0.43333333333333335" rpy="0 0 0"/>
            <geometry>
                <box size="0.19990678120041117 0.8780775926053809 0.8666666666666667" />
            </geometry>
        </collision>
    </link>
    <joint name="22_23" type="revolute">
       <parent link="22"/>
       <child  link="23"/>
       <origin rpy="0 0 0" xyz="0 0 -0.8666666666666667" />
     <axis xyz="0 0 1"/>
       <limit effort="0.0" lower="-3.14159" upper="3.14159" velocity="0.0"/>
    </joint>
    <link name="24">
        <inertial>
            <origin xyz="0 0 -0.43333333333333335" rpy="0 0 0"/>
            <mass value="1" />
            <inertia ixx="100" ixy="0" ixz="0" iyy="100" iyz="0" izz="100" />
        </inertial>
        <visual>
            <origin xyz="0 0 -0.43333333333333335" rpy="0 0 0"/>
            <geometry>
                <box size="0.4174162611083547 0.1003245358704955 0.8666666666666667" />
            </geometry>
            <material name="Green">
                <color rgba="0 128 0 1"/>
            </material>
        </visual>
        <collision>
            <origin xyz="0 0 -0.43333333333333335" rpy="0 0 0"/>
            <geometry>
                <box size="0.4174162611083547 0.1003245358704955 0.8666666666666667" />
            </geometry>
        </collision>
    </link>
    <joint name="23_24" type="revolute">
       <parent link="23"/>
       <child  link="24"/>
       <origin rpy="0 0 0" xyz="0 0 -0.8666666666666667" />
     <axis xyz="1 1 1"/>
       <limit effort="0.0" lower="-3.14159" upper="3.14159" velocity="0.0"/>
    </joint>
</robot>