<robot name = "robot">
    <link name="0">
        <inertial>
            <origin xyz="0 0 3" rpy="0 0 0"/>
            <mass value="1" />
            <inertia ixx="100" ixy="0" ixz="0" iyy="100" iyz="0" izz="100" />
        </inertial>
        <visual>
            <origin xyz="0 0 3" rpy="0 0 0"/>
            <geometry>
                <box size="1.5 1.5 0.8" />
            </geometry>
            <material name="Blue">
                <color rgba="0 0 255 1"/>
            </material>
        </visual>
        <collision>
            <origin xyz="0 0 3" rpy="0 0 0"/>
            <geometry>
                <box size="1.5 1.5 0.8" />
            </geometry>
        </collision>
    </link>
    <link name="1">
        <inertial>
            <origin xyz="-0.2743173732143225 0 0" rpy="0 0 0"/>
            <mass value="1" />
            <inertia ixx="100" ixy="0" ixz="0" iyy="100" iyz="0" izz="100" />
        </inertial>
        <visual>
            <origin xyz="-0.2743173732143225 0 0" rpy="0 0 0"/>
            <geometry>
                <box size="0.548634746428645 0.49081664088021393 0.735913253332806" />
            </geometry>
            <material name="Blue">
                <color rgba="0 0 255 1"/>
            </material>
        </visual>
        <collision>
            <origin xyz="-0.2743173732143225 0 0" rpy="0 0 0"/>
            <geometry>
                <box size="0.548634746428645 0.49081664088021393 0.735913253332806" />
            </geometry>
        </collision>
    </link>
    <joint name="0_1" type="revolute">
       <parent link="0"/>
       <child  link="1"/>
       <origin rpy="0 0 0" xyz="-0.75 0 3" />
     <axis xyz="1 0 1"/>
       <limit effort="0.0" lower="-3.14159" upper="3.14159" velocity="0.0"/>
    </joint>
    <link name="2">
        <inertial>
            <origin xyz="-0.38582770329292215 0 0" rpy="0 0 0"/>
            <mass value="1" />
            <inertia ixx="100" ixy="0" ixz="0" iyy="100" iyz="0" izz="100" />
        </inertial>
        <visual>
            <origin xyz="-0.38582770329292215 0 0" rpy="0 0 0"/>
            <geometry>
                <box size="0.7716554065858443 0.5320949718031717 0.5371001450279637" />
            </geometry>
            <material name="Green">
                <color rgba="0 128 0 1"/>
            </material>
        </visual>
        <collision>
            <origin xyz="-0.38582770329292215 0 0" rpy="0 0 0"/>
            <geometry>
                <box size="0.7716554065858443 0.5320949718031717 0.5371001450279637" />
            </geometry>
        </collision>
    </link>
    <joint name="1_2" type="revolute">
       <parent link="1"/>
       <child  link="2"/>
       <origin rpy="0 0 0" xyz="-0.548634746428645 0 0" />
     <axis xyz="1 0 0"/>
       <limit effort="0.0" lower="-3.14159" upper="3.14159" velocity="0.0"/>
    </joint>
    <link name="3">
        <inertial>
            <origin xyz="-0.14853599693080405 0 0" rpy="0 0 0"/>
            <mass value="1" />
            <inertia ixx="100" ixy="0" ixz="0" iyy="100" iyz="0" izz="100" />
        </inertial>
        <visual>
            <origin xyz="-0.14853599693080405 0 0" rpy="0 0 0"/>
            <geometry>
                <box size="0.2970719938616081 0.12459003433186311 0.5707875940576025" />
            </geometry>
            <material name="Blue">
                <color rgba="0 0 255 1"/>
            </material>
        </visual>
        <collision>
            <origin xyz="-0.14853599693080405 0 0" rpy="0 0 0"/>
            <geometry>
                <box size="0.2970719938616081 0.12459003433186311 0.5707875940576025" />
            </geometry>
        </collision>
    </link>
    <joint name="2_3" type="revolute">
       <parent link="2"/>
       <child  link="3"/>
       <origin rpy="0 0 0" xyz="-0.7716554065858443 0 0" />
     <axis xyz="1 1 0"/>
       <limit effort="0.0" lower="-3.14159" upper="3.14159" velocity="0.0"/>
    </joint>
    <link name="4">
        <inertial>
            <origin xyz="-0.41013075062795223 0 0" rpy="0 0 0"/>
            <mass value="1" />
            <inertia ixx="100" ixy="0" ixz="0" iyy="100" iyz="0" izz="100" />
        </inertial>
        <visual>
            <origin xyz="-0.41013075062795223 0 0" rpy="0 0 0"/>
            <geometry>
                <box size="0.8202615012559045 0.9713176650494088 0.3637275626129076" />
            </geometry>
            <material name="Blue">
                <color rgba="0 0 255 1"/>
            </material>
        </visual>
        <collision>
            <origin xyz="-0.41013075062795223 0 0" rpy="0 0 0"/>
            <geometry>
                <box size="0.8202615012559045 0.9713176650494088 0.3637275626129076" />
            </geometry>
        </collision>
    </link>
    <joint name="3_4" type="revolute">
       <parent link="3"/>
       <child  link="4"/>
       <origin rpy="0 0 0" xyz="-0.2970719938616081 0 0" />
     <axis xyz="1 0 0"/>
       <limit effort="0.0" lower="-3.14159" upper="3.14159" velocity="0.0"/>
    </joint>
    <link name="5">
        <inertial>
            <origin xyz="-0.2780824591897526 0 0" rpy="0 0 0"/>
            <mass value="1" />
            <inertia ixx="100" ixy="0" ixz="0" iyy="100" iyz="0" izz="100" />
        </inertial>
        <visual>
            <origin xyz="-0.2780824591897526 0 0" rpy="0 0 0"/>
            <geometry>
                <box size="0.5561649183795052 0.6901826506127309 0.7938037154010142" />
            </geometry>
            <material name="Blue">
                <color rgba="0 0 255 1"/>
            </material>
        </visual>
        <collision>
            <origin xyz="-0.2780824591897526 0 0" rpy="0 0 0"/>
            <geometry>
                <box size="0.5561649183795052 0.6901826506127309 0.7938037154010142" />
            </geometry>
        </collision>
    </link>
    <joint name="4_5" type="revolute">
       <parent link="4"/>
       <child  link="5"/>
       <origin rpy="0 0 0" xyz="-0.8202615012559045 0 0" />
     <axis xyz="1 0 0"/>
       <limit effort="0.0" lower="-3.14159" upper="3.14159" velocity="0.0"/>
    </joint>
    <link name="6">
        <inertial>
            <origin xyz="0 0 -0.6112436462970348" rpy="0 0 0"/>
            <mass value="1" />
            <inertia ixx="100" ixy="0" ixz="0" iyy="100" iyz="0" izz="100" />
        </inertial>
        <visual>
            <origin xyz="0 0 -0.6112436462970348" rpy="0 0 0"/>
            <geometry>
                <box size="0.09567796614682123 0.7464937303093473 1.2224872925940695" />
            </geometry>
            <material name="Green">
                <color rgba="0 128 0 1"/>
            </material>
        </visual>
        <collision>
            <origin xyz="0 0 -0.6112436462970348" rpy="0 0 0"/>
            <geometry>
                <box size="0.09567796614682123 0.7464937303093473 1.2224872925940695" />
            </geometry>
        </collision>
    </link>
    <joint name="5_6" type="revolute">
       <parent link="5"/>
       <child  link="6"/>
       <origin rpy="0 0 0" xyz="-0.2780824591897526 0 -0.3969018577005071" />
     <axis xyz="1 1 1"/>
       <limit effort="0.0" lower="-3.14159" upper="3.14159" velocity="0.0"/>
    </joint>
    <link name="7">
        <inertial>
            <origin xyz="0 0 -0.14826183079852334" rpy="0 0 0"/>
            <mass value="1" />
            <inertia ixx="100" ixy="0" ixz="0" iyy="100" iyz="0" izz="100" />
        </inertial>
        <visual>
            <origin xyz="0 0 -0.14826183079852334" rpy="0 0 0"/>
            <geometry>
                <box size="0.13577283336596357 0.869637429404045 0.2965236615970467" />
            </geometry>
            <material name="Blue">
                <color rgba="0 0 255 1"/>
            </material>
        </visual>
        <collision>
            <origin xyz="0 0 -0.14826183079852334" rpy="0 0 0"/>
            <geometry>
                <box size="0.13577283336596357 0.869637429404045 0.2965236615970467" />
            </geometry>
        </collision>
    </link>
    <joint name="6_7" type="revolute">
       <parent link="6"/>
       <child  link="7"/>
       <origin rpy="0 0 0" xyz="0 0 -1.2224872925940695" />
     <axis xyz="0 1 0"/>
       <limit effort="0.0" lower="-3.14159" upper="3.14159" velocity="0.0"/>
    </joint>
    <link name="8">
        <inertial>
            <origin xyz="0 0 -0.540494522904442" rpy="0 0 0"/>
            <mass value="1" />
            <inertia ixx="100" ixy="0" ixz="0" iyy="100" iyz="0" izz="100" />
        </inertial>
        <visual>
            <origin xyz="0 0 -0.540494522904442" rpy="0 0 0"/>
            <geometry>
                <box size="0.8572347404994358 0.35111754974836573 1.080989045808884" />
            </geometry>
            <material name="Green">
                <color rgba="0 128 0 1"/>
            </material>
        </visual>
        <collision>
            <origin xyz="0 0 -0.540494522904442" rpy="0 0 0"/>
            <geometry>
                <box size="0.8572347404994358 0.35111754974836573 1.080989045808884" />
            </geometry>
        </collision>
    </link>
    <joint name="7_8" type="revolute">
       <parent link="7"/>
       <child  link="8"/>
       <origin rpy="0 0 0" xyz="0 0 -0.2965236615970467" />
     <axis xyz="1 0 0"/>
       <limit effort="0.0" lower="-3.14159" upper="3.14159" velocity="0.0"/>
    </joint>
    <link name="9">
        <inertial>
            <origin xyz="0.3206345911219925 0 0" rpy="0 0 0"/>
            <mass value="1" />
            <inertia ixx="100" ixy="0" ixz="0" iyy="100" iyz="0" izz="100" />
        </inertial>
        <visual>
            <origin xyz="0.3206345911219925 0 0" rpy="0 0 0"/>
            <geometry>
                <box size="0.641269182243985 0.22305547711358376 0.6439560060634671" />
            </geometry>
            <material name="Blue">
                <color rgba="0 0 255 1"/>
            </material>
        </visual>
        <collision>
            <origin xyz="0.3206345911219925 0 0" rpy="0 0 0"/>
            <geometry>
                <box size="0.641269182243985 0.22305547711358376 0.6439560060634671" />
            </geometry>
        </collision>
    </link>
    <joint name="0_9" type="revolute">
       <parent link="0"/>
       <child  link="9"/>
       <origin rpy="0 0 0" xyz="0.75 0 3" />
     <axis xyz="1 1 1"/>
       <limit effort="0.0" lower="-3.14159" upper="3.14159" velocity="0.0"/>
    </joint>
    <link name="10">
        <inertial>
            <origin xyz="0.26283041769745297 0 0" rpy="0 0 0"/>
            <mass value="1" />
            <inertia ixx="100" ixy="0" ixz="0" iyy="100" iyz="0" izz="100" />
        </inertial>
        <visual>
            <origin xyz="0.26283041769745297 0 0" rpy="0 0 0"/>
            <geometry>
                <box size="0.5256608353949059 0.7178446054353962 0.47627516923343216" />
            </geometry>
            <material name="Green">
                <color rgba="0 128 0 1"/>
            </material>
        </visual>
        <collision>
            <origin xyz="0.26283041769745297 0 0" rpy="0 0 0"/>
            <geometry>
                <box size="0.5256608353949059 0.7178446054353962 0.47627516923343216" />
            </geometry>
        </collision>
    </link>
    <joint name="9_10" type="revolute">
       <parent link="9"/>
       <child  link="10"/>
       <origin rpy="0 0 0" xyz="0.641269182243985 0 0" />
     <axis xyz="1 1 0"/>
       <limit effort="0.0" lower="-3.14159" upper="3.14159" velocity="0.0"/>
    </joint>
    <link name="11">
        <inertial>
            <origin xyz="0.1720070288451651 0 0" rpy="0 0 0"/>
            <mass value="1" />
            <inertia ixx="100" ixy="0" ixz="0" iyy="100" iyz="0" izz="100" />
        </inertial>
        <visual>
            <origin xyz="0.1720070288451651 0 0" rpy="0 0 0"/>
            <geometry>
                <box size="0.3440140576903302 0.10395950355343342 0.5129439276555321" />
            </geometry>
            <material name="Blue">
                <color rgba="0 0 255 1"/>
            </material>
        </visual>
        <collision>
            <origin xyz="0.1720070288451651 0 0" rpy="0 0 0"/>
            <geometry>
                <box size="0.3440140576903302 0.10395950355343342 0.5129439276555321" />
            </geometry>
        </collision>
    </link>
    <joint name="10_11" type="revolute">
       <parent link="10"/>
       <child  link="11"/>
       <origin rpy="0 0 0" xyz="0.5256608353949059 0 0" />
     <axis xyz="1 0 0"/>
       <limit effort="0.0" lower="-3.14159" upper="3.14159" velocity="0.0"/>
    </joint>
    <link name="12">
        <inertial>
            <origin xyz="0.07481525635269576 0 0" rpy="0 0 0"/>
            <mass value="1" />
            <inertia ixx="100" ixy="0" ixz="0" iyy="100" iyz="0" izz="100" />
        </inertial>
        <visual>
            <origin xyz="0.07481525635269576 0 0" rpy="0 0 0"/>
            <geometry>
                <box size="0.14963051270539152 0.38004919315199637 0.5178547732615079" />
            </geometry>
            <material name="Blue">
                <color rgba="0 0 255 1"/>
            </material>
        </visual>
        <collision>
            <origin xyz="0.07481525635269576 0 0" rpy="0 0 0"/>
            <geometry>
                <box size="0.14963051270539152 0.38004919315199637 0.5178547732615079" />
            </geometry>
        </collision>
    </link>
    <joint name="11_12" type="revolute">
       <parent link="11"/>
       <child  link="12"/>
       <origin rpy="0 0 0" xyz="0.3440140576903302 0 0" />
     <axis xyz="1 0 1"/>
       <limit effort="0.0" lower="-3.14159" upper="3.14159" velocity="0.0"/>
    </joint>
    <link name="13">
        <inertial>
            <origin xyz="0.154432577865232 0 0" rpy="0 0 0"/>
            <mass value="1" />
            <inertia ixx="100" ixy="0" ixz="0" iyy="100" iyz="0" izz="100" />
        </inertial>
        <visual>
            <origin xyz="0.154432577865232 0 0" rpy="0 0 0"/>
            <geometry>
                <box size="0.308865155730464 0.5893993190769607 0.37866232809372136" />
            </geometry>
            <material name="Green">
                <color rgba="0 128 0 1"/>
            </material>
        </visual>
        <collision>
            <origin xyz="0.154432577865232 0 0" rpy="0 0 0"/>
            <geometry>
                <box size="0.308865155730464 0.5893993190769607 0.37866232809372136" />
            </geometry>
        </collision>
    </link>
    <joint name="12_13" type="revolute">
       <parent link="12"/>
       <child  link="13"/>
       <origin rpy="0 0 0" xyz="0.14963051270539152 0 0" />
     <axis xyz="1 1 1"/>
       <limit effort="0.0" lower="-3.14159" upper="3.14159" velocity="0.0"/>
    </joint>
    <link name="14">
        <inertial>
            <origin xyz="0 0 -0.48597716611561864" rpy="0 0 0"/>
            <mass value="1" />
            <inertia ixx="100" ixy="0" ixz="0" iyy="100" iyz="0" izz="100" />
        </inertial>
        <visual>
            <origin xyz="0 0 -0.48597716611561864" rpy="0 0 0"/>
            <geometry>
                <box size="0.71481063672252 0.023513514336841568 0.9719543322312373" />
            </geometry>
            <material name="Green">
                <color rgba="0 128 0 1"/>
            </material>
        </visual>
        <collision>
            <origin xyz="0 0 -0.48597716611561864" rpy="0 0 0"/>
            <geometry>
                <box size="0.71481063672252 0.023513514336841568 0.9719543322312373" />
            </geometry>
        </collision>
    </link>
    <joint name="13_14" type="revolute">
       <parent link="13"/>
       <child  link="14"/>
       <origin rpy="0 0 0" xyz="0.154432577865232 0 -0.18933116404686068" />
     <axis xyz="1 0 0"/>
       <limit effort="0.0" lower="-3.14159" upper="3.14159" velocity="0.0"/>
    </joint>
    <link name="15">
        <inertial>
            <origin xyz="0 0 -0.08365571738983714" rpy="0 0 0"/>
            <mass value="1" />
            <inertia ixx="100" ixy="0" ixz="0" iyy="100" iyz="0" izz="100" />
        </inertial>
        <visual>
            <origin xyz="0 0 -0.08365571738983714" rpy="0 0 0"/>
            <geometry>
                <box size="0.9338931903689978 0.2665703049380883 0.16731143477967428" />
            </geometry>
            <material name="Blue">
                <color rgba="0 0 255 1"/>
            </material>
        </visual>
        <collision>
            <origin xyz="0 0 -0.08365571738983714" rpy="0 0 0"/>
            <geometry>
                <box size="0.9338931903689978 0.2665703049380883 0.16731143477967428" />
            </geometry>
        </collision>
    </link>
    <joint name="14_15" type="revolute">
       <parent link="14"/>
       <child  link="15"/>
       <origin rpy="0 0 0" xyz="0 0 -0.9719543322312373" />
     <axis xyz="1 0 0"/>
       <limit effort="0.0" lower="-3.14159" upper="3.14159" velocity="0.0"/>
    </joint>
    <link name="16">
        <inertial>
            <origin xyz="0 0 -0.7303671164945442" rpy="0 0 0"/>
            <mass value="1" />
            <inertia ixx="100" ixy="0" ixz="0" iyy="100" iyz="0" izz="100" />
        </inertial>
        <visual>
            <origin xyz="0 0 -0.7303671164945442" rpy="0 0 0"/>
            <geometry>
                <box size="0.9153889820528474 0.6162208287410924 1.4607342329890884" />
            </geometry>
            <material name="Blue">
                <color rgba="0 0 255 1"/>
            </material>
        </visual>
        <collision>
            <origin xyz="0 0 -0.7303671164945442" rpy="0 0 0"/>
            <geometry>
                <box size="0.9153889820528474 0.6162208287410924 1.4607342329890884" />
            </geometry>
        </collision>
    </link>
    <joint name="15_16" type="revolute">
       <parent link="15"/>
       <child  link="16"/>
       <origin rpy="0 0 0" xyz="0 0 -0.16731143477967428" />
     <axis xyz="1 0 1"/>
       <limit effort="0.0" lower="-3.14159" upper="3.14159" velocity="0.0"/>
    </joint>
    <link name="17">
        <inertial>
            <origin xyz="0 -0.17775186726927472 0" rpy="0 0 0"/>
            <mass value="1" />
            <inertia ixx="100" ixy="0" ixz="0" iyy="100" iyz="0" izz="100" />
        </inertial>
        <visual>
            <origin xyz="0 -0.17775186726927472 0" rpy="0 0 0"/>
            <geometry>
                <box size="0.6719683890917847 0.35550373453854944 0.17668338131850247" />
            </geometry>
            <material name="Blue">
                <color rgba="0 0 255 1"/>
            </material>
        </visual>
        <collision>
            <origin xyz="0 -0.17775186726927472 0" rpy="0 0 0"/>
            <geometry>
                <box size="0.6719683890917847 0.35550373453854944 0.17668338131850247" />
            </geometry>
        </collision>
    </link>
    <joint name="0_17" type="revolute">
       <parent link="0"/>
       <child  link="17"/>
       <origin rpy="0 0 0" xyz="0 -0.75 3" />
     <axis xyz="1 1 1"/>
       <limit effort="0.0" lower="-3.14159" upper="3.14159" velocity="0.0"/>
    </joint>
    <link name="18">
        <inertial>
            <origin xyz="0 -0.3443020686034245 0" rpy="0 0 0"/>
            <mass value="1" />
            <inertia ixx="100" ixy="0" ixz="0" iyy="100" iyz="0" izz="100" />
        </inertial>
        <visual>
            <origin xyz="0 -0.3443020686034245 0" rpy="0 0 0"/>
            <geometry>
                <box size="0.3675313120993148 0.688604137206849 0.9599085427931238" />
            </geometry>
            <material name="Green">
                <color rgba="0 128 0 1"/>
            </material>
        </visual>
        <collision>
            <origin xyz="0 -0.3443020686034245 0" rpy="0 0 0"/>
            <geometry>
                <box size="0.3675313120993148 0.688604137206849 0.9599085427931238" />
            </geometry>
        </collision>
    </link>
    <joint name="17_18" type="revolute">
       <parent link="17"/>
       <child  link="18"/>
       <origin rpy="0 0 0" xyz="0 -0.35550373453854944 0" />
     <axis xyz="0 1 0"/>
       <limit effort="0.0" lower="-3.14159" upper="3.14159" velocity="0.0"/>
    </joint>
    <link name="19">
        <inertial>
            <origin xyz="0 -0.19330489286041103 0" rpy="0 0 0"/>
            <mass value="1" />
            <inertia ixx="100" ixy="0" ixz="0" iyy="100" iyz="0" izz="100" />
        </inertial>
        <visual>
            <origin xyz="0 -0.19330489286041103 0" rpy="0 0 0"/>
            <geometry>
                <box size="0.9309209544609894 0.38660978572082205 0.14342209360003755" />
            </geometry>
            <material name="Green">
                <color rgba="0 128 0 1"/>
            </material>
        </visual>
        <collision>
            <origin xyz="0 -0.19330489286041103 0" rpy="0 0 0"/>
            <geometry>
                <box size="0.9309209544609894 0.38660978572082205 0.14342209360003755" />
            </geometry>
        </collision>
    </link>
    <joint name="18_19" type="revolute">
       <parent link="18"/>
       <child  link="19"/>
       <origin rpy="0 0 0" xyz="0 -0.688604137206849 0" />
     <axis xyz="1 1 0"/>
       <limit effort="0.0" lower="-3.14159" upper="3.14159" velocity="0.0"/>
    </joint>
    <link name="20">
        <inertial>
            <origin xyz="0 -0.34155538954690046 0" rpy="0 0 0"/>
            <mass value="1" />
            <inertia ixx="100" ixy="0" ixz="0" iyy="100" iyz="0" izz="100" />
        </inertial>
        <visual>
            <origin xyz="0 -0.34155538954690046 0" rpy="0 0 0"/>
            <geometry>
                <box size="0.49265941282205017 0.6831107790938009 0.4659454017051502" />
            </geometry>
            <material name="Blue">
                <color rgba="0 0 255 1"/>
            </material>
        </visual>
        <collision>
            <origin xyz="0 -0.34155538954690046 0" rpy="0 0 0"/>
            <geometry>
                <box size="0.49265941282205017 0.6831107790938009 0.4659454017051502" />
            </geometry>
        </collision>
    </link>
    <joint name="19_20" type="revolute">
       <parent link="19"/>
       <child  link="20"/>
       <origin rpy="0 0 0" xyz="0 -0.38660978572082205 0" />
     <axis xyz="0 1 0"/>
       <limit effort="0.0" lower="-3.14159" upper="3.14159" velocity="0.0"/>
    </joint>
    <link name="21">
        <inertial>
            <origin xyz="0 -0.39351627592079613 0" rpy="0 0 0"/>
            <mass value="1" />
            <inertia ixx="100" ixy="0" ixz="0" iyy="100" iyz="0" izz="100" />
        </inertial>
        <visual>
            <origin xyz="0 -0.39351627592079613 0" rpy="0 0 0"/>
            <geometry>
                <box size="0.5361125533157545 0.7870325518415923 0.7695903098333144" />
            </geometry>
            <material name="Green">
                <color rgba="0 128 0 1"/>
            </material>
        </visual>
        <collision>
            <origin xyz="0 -0.39351627592079613 0" rpy="0 0 0"/>
            <geometry>
                <box size="0.5361125533157545 0.7870325518415923 0.7695903098333144" />
            </geometry>
        </collision>
    </link>
    <joint name="20_21" type="revolute">
       <parent link="20"/>
       <child  link="21"/>
       <origin rpy="0 0 0" xyz="0 -0.6831107790938009 0" />
     <axis xyz="1 0 1"/>
       <limit effort="0.0" lower="-3.14159" upper="3.14159" velocity="0.0"/>
    </joint>
    <link name="22">
        <inertial>
            <origin xyz="0 0 -0.6593332503214627" rpy="0 0 0"/>
            <mass value="1" />
            <inertia ixx="100" ixy="0" ixz="0" iyy="100" iyz="0" izz="100" />
        </inertial>
        <visual>
            <origin xyz="0 0 -0.6593332503214627" rpy="0 0 0"/>
            <geometry>
                <box size="0.3404689354288436 0.211627866435248 1.3186665006429255" />
            </geometry>
            <material name="Blue">
                <color rgba="0 0 255 1"/>
            </material>
        </visual>
        <collision>
            <origin xyz="0 0 -0.6593332503214627" rpy="0 0 0"/>
            <geometry>
                <box size="0.3404689354288436 0.211627866435248 1.3186665006429255" />
            </geometry>
        </collision>
    </link>
    <joint name="21_22" type="revolute">
       <parent link="21"/>
       <child  link="22"/>
       <origin rpy="0 0 0" xyz="0 -0.39351627592079613 -0.3847951549166572" />
     <axis xyz="1 0 0"/>
       <limit effort="0.0" lower="-3.14159" upper="3.14159" velocity="0.0"/>
    </joint>
    <link name="23">
        <inertial>
            <origin xyz="0 0 -0.1782056920861084" rpy="0 0 0"/>
            <mass value="1" />
            <inertia ixx="100" ixy="0" ixz="0" iyy="100" iyz="0" izz="100" />
        </inertial>
        <visual>
            <origin xyz="0 0 -0.1782056920861084" rpy="0 0 0"/>
            <geometry>
                <box size="0.9383976089569402 0.3092969524975957 0.3564113841722168" />
            </geometry>
            <material name="Green">
                <color rgba="0 128 0 1"/>
            </material>
        </visual>
        <collision>
            <origin xyz="0 0 -0.1782056920861084" rpy="0 0 0"/>
            <geometry>
                <box size="0.9383976089569402 0.3092969524975957 0.3564113841722168" />
            </geometry>
        </collision>
    </link>
    <joint name="22_23" type="revolute">
       <parent link="22"/>
       <child  link="23"/>
       <origin rpy="0 0 0" xyz="0 0 -1.3186665006429255" />
     <axis xyz="0 1 0"/>
       <limit effort="0.0" lower="-3.14159" upper="3.14159" velocity="0.0"/>
    </joint>
    <link name="24">
        <inertial>
            <origin xyz="0 0 -0.46246105759242895" rpy="0 0 0"/>
            <mass value="1" />
            <inertia ixx="100" ixy="0" ixz="0" iyy="100" iyz="0" izz="100" />
        </inertial>
        <visual>
            <origin xyz="0 0 -0.46246105759242895" rpy="0 0 0"/>
            <geometry>
                <box size="0.23602072204583002 0.850003464602221 0.9249221151848579" />
            </geometry>
            <material name="Blue">
                <color rgba="0 0 255 1"/>
            </material>
        </visual>
        <collision>
            <origin xyz="0 0 -0.46246105759242895" rpy="0 0 0"/>
            <geometry>
                <box size="0.23602072204583002 0.850003464602221 0.9249221151848579" />
            </geometry>
        </collision>
    </link>
    <joint name="23_24" type="revolute">
       <parent link="23"/>
       <child  link="24"/>
       <origin rpy="0 0 0" xyz="0 0 -0.3564113841722168" />
     <axis xyz="1 0 1"/>
       <limit effort="0.0" lower="-3.14159" upper="3.14159" velocity="0.0"/>
    </joint>
    <link name="25">
        <inertial>
            <origin xyz="0 0.2629815082008901 0" rpy="0 0 0"/>
            <mass value="1" />
            <inertia ixx="100" ixy="0" ixz="0" iyy="100" iyz="0" izz="100" />
        </inertial>
        <visual>
            <origin xyz="0 0.2629815082008901 0" rpy="0 0 0"/>
            <geometry>
                <box size="0.4347881945184727 0.5259630164017802 0.7852485474021305" />
            </geometry>
            <material name="Green">
                <color rgba="0 128 0 1"/>
            </material>
        </visual>
        <collision>
            <origin xyz="0 0.2629815082008901 0" rpy="0 0 0"/>
            <geometry>
                <box size="0.4347881945184727 0.5259630164017802 0.7852485474021305" />
            </geometry>
        </collision>
    </link>
    <joint name="0_25" type="revolute">
       <parent link="0"/>
       <child  link="25"/>
       <origin rpy="0 0 0" xyz="0 0.75 3" />
     <axis xyz="1 0 0"/>
       <limit effort="0.0" lower="-3.14159" upper="3.14159" velocity="0.0"/>
    </joint>
    <link name="26">
        <inertial>
            <origin xyz="0 0.4327173999446854 0" rpy="0 0 0"/>
            <mass value="1" />
            <inertia ixx="100" ixy="0" ixz="0" iyy="100" iyz="0" izz="100" />
        </inertial>
        <visual>
            <origin xyz="0 0.4327173999446854 0" rpy="0 0 0"/>
            <geometry>
                <box size="0.5307953822852935 0.8654347998893708 0.3644964171836935" />
            </geometry>
            <material name="Blue">
                <color rgba="0 0 255 1"/>
            </material>
        </visual>
        <collision>
            <origin xyz="0 0.4327173999446854 0" rpy="0 0 0"/>
            <geometry>
                <box size="0.5307953822852935 0.8654347998893708 0.3644964171836935" />
            </geometry>
        </collision>
    </link>
    <joint name="25_26" type="revolute">
       <parent link="25"/>
       <child  link="26"/>
       <origin rpy="0 0 0" xyz="0 0.5259630164017802 0" />
     <axis xyz="0 1 1"/>
       <limit effort="0.0" lower="-3.14159" upper="3.14159" velocity="0.0"/>
    </joint>
    <link name="27">
        <inertial>
            <origin xyz="0 0.03868009184367832 0" rpy="0 0 0"/>
            <mass value="1" />
            <inertia ixx="100" ixy="0" ixz="0" iyy="100" iyz="0" izz="100" />
        </inertial>
        <visual>
            <origin xyz="0 0.03868009184367832 0" rpy="0 0 0"/>
            <geometry>
                <box size="0.1383233545446727 0.07736018368735664 0.8574166324604484" />
            </geometry>
            <material name="Green">
                <color rgba="0 128 0 1"/>
            </material>
        </visual>
        <collision>
            <origin xyz="0 0.03868009184367832 0" rpy="0 0 0"/>
            <geometry>
                <box size="0.1383233545446727 0.07736018368735664 0.8574166324604484" />
            </geometry>
        </collision>
    </link>
    <joint name="26_27" type="revolute">
       <parent link="26"/>
       <child  link="27"/>
       <origin rpy="0 0 0" xyz="0 0.8654347998893708 0" />
     <axis xyz="0 0 1"/>
       <limit effort="0.0" lower="-3.14159" upper="3.14159" velocity="0.0"/>
    </joint>
    <link name="28">
        <inertial>
            <origin xyz="0 0.01852802567972106 0" rpy="0 0 0"/>
            <mass value="1" />
            <inertia ixx="100" ixy="0" ixz="0" iyy="100" iyz="0" izz="100" />
        </inertial>
        <visual>
            <origin xyz="0 0.01852802567972106 0" rpy="0 0 0"/>
            <geometry>
                <box size="0.45062736113110047 0.03705605135944212 0.5649153595922038" />
            </geometry>
            <material name="Green">
                <color rgba="0 128 0 1"/>
            </material>
        </visual>
        <collision>
            <origin xyz="0 0.01852802567972106 0" rpy="0 0 0"/>
            <geometry>
                <box size="0.45062736113110047 0.03705605135944212 0.5649153595922038" />
            </geometry>
        </collision>
    </link>
    <joint name="27_28" type="revolute">
       <parent link="27"/>
       <child  link="28"/>
       <origin rpy="0 0 0" xyz="0 0.07736018368735664 0" />
     <axis xyz="1 0 1"/>
       <limit effort="0.0" lower="-3.14159" upper="3.14159" velocity="0.0"/>
    </joint>
    <link name="29">
        <inertial>
            <origin xyz="0 0.12880797766919572 0" rpy="0 0 0"/>
            <mass value="1" />
            <inertia ixx="100" ixy="0" ixz="0" iyy="100" iyz="0" izz="100" />
        </inertial>
        <visual>
            <origin xyz="0 0.12880797766919572 0" rpy="0 0 0"/>
            <geometry>
                <box size="0.44845246909580616 0.25761595533839143 0.6171887404267005" />
            </geometry>
            <material name="Green">
                <color rgba="0 128 0 1"/>
            </material>
        </visual>
        <collision>
            <origin xyz="0 0.12880797766919572 0" rpy="0 0 0"/>
            <geometry>
                <box size="0.44845246909580616 0.25761595533839143 0.6171887404267005" />
            </geometry>
        </collision>
    </link>
    <joint name="28_29" type="revolute">
       <parent link="28"/>
       <child  link="29"/>
       <origin rpy="0 0 0" xyz="0 0.03705605135944212 0" />
     <axis xyz="0 1 1"/>
       <limit effort="0.0" lower="-3.14159" upper="3.14159" velocity="0.0"/>
    </joint>
    <link name="30">
        <inertial>
            <origin xyz="0 0 -0.648500122719944" rpy="0 0 0"/>
            <mass value="1" />
            <inertia ixx="100" ixy="0" ixz="0" iyy="100" iyz="0" izz="100" />
        </inertial>
        <visual>
            <origin xyz="0 0 -0.648500122719944" rpy="0 0 0"/>
            <geometry>
                <box size="0.7613894950783039 0.33826006894059435 1.297000245439888" />
            </geometry>
            <material name="Blue">
                <color rgba="0 0 255 1"/>
            </material>
        </visual>
        <collision>
            <origin xyz="0 0 -0.648500122719944" rpy="0 0 0"/>
            <geometry>
                <box size="0.7613894950783039 0.33826006894059435 1.297000245439888" />
            </geometry>
        </collision>
    </link>
    <joint name="29_30" type="revolute">
       <parent link="29"/>
       <child  link="30"/>
       <origin rpy="0 0 0" xyz="0 0.12880797766919572 -0.30859437021335023" />
     <axis xyz="1 1 1"/>
       <limit effort="0.0" lower="-3.14159" upper="3.14159" velocity="0.0"/>
    </joint>
    <link name="31">
        <inertial>
            <origin xyz="0 0 -0.39973688547772945" rpy="0 0 0"/>
            <mass value="1" />
            <inertia ixx="100" ixy="0" ixz="0" iyy="100" iyz="0" izz="100" />
        </inertial>
        <visual>
            <origin xyz="0 0 -0.39973688547772945" rpy="0 0 0"/>
            <geometry>
                <box size="0.773422425681944 0.16487044189550626 0.7994737709554589" />
            </geometry>
            <material name="Blue">
                <color rgba="0 0 255 1"/>
            </material>
        </visual>
        <collision>
            <origin xyz="0 0 -0.39973688547772945" rpy="0 0 0"/>
            <geometry>
                <box size="0.773422425681944 0.16487044189550626 0.7994737709554589" />
            </geometry>
        </collision>
    </link>
    <joint name="30_31" type="revolute">
       <parent link="30"/>
       <child  link="31"/>
       <origin rpy="0 0 0" xyz="0 0 -1.297000245439888" />
     <axis xyz="0 1 1"/>
       <limit effort="0.0" lower="-3.14159" upper="3.14159" velocity="0.0"/>
    </joint>
    <link name="32">
        <inertial>
            <origin xyz="0 0 -0.25176299180232664" rpy="0 0 0"/>
            <mass value="1" />
            <inertia ixx="100" ixy="0" ixz="0" iyy="100" iyz="0" izz="100" />
        </inertial>
        <visual>
            <origin xyz="0 0 -0.25176299180232664" rpy="0 0 0"/>
            <geometry>
                <box size="0.15139033938726465 0.35048978952825005 0.5035259836046533" />
            </geometry>
            <material name="Blue">
                <color rgba="0 0 255 1"/>
            </material>
        </visual>
        <collision>
            <origin xyz="0 0 -0.25176299180232664" rpy="0 0 0"/>
            <geometry>
                <box size="0.15139033938726465 0.35048978952825005 0.5035259836046533" />
            </geometry>
        </collision>
    </link>
    <joint name="31_32" type="revolute">
       <parent link="31"/>
       <child  link="32"/>
       <origin rpy="0 0 0" xyz="0 0 -0.7994737709554589" />
     <axis xyz="1 1 1"/>
       <limit effort="0.0" lower="-3.14159" upper="3.14159" velocity="0.0"/>
    </joint>
</robot>