<robot name = "robot">
    <link name="0">
        <inertial>
            <origin xyz="0 0 0.35" rpy="0 0 0"/>
            <mass value="1" />
            <inertia ixx="100" ixy="0" ixz="0" iyy="100" iyz="0" izz="100" />
        </inertial>
        <visual>
            <origin xyz="0 0 0.35" rpy="0 0 0"/>
            <geometry>
                <box size="0.7 0.7 0.7" />
            </geometry>
            <material name="Green">
                <color rgba="0 128 0 1"/>
            </material>
        </visual>
        <collision>
            <origin xyz="0 0 0.35" rpy="0 0 0"/>
            <geometry>
                <box size="0.7 0.7 0.7" />
            </geometry>
        </collision>
    </link>
    <link name="1">
        <inertial>
            <origin xyz="-0.3408182278037341 0 0.17399075397840386" rpy="0 0 0"/>
            <mass value="1" />
            <inertia ixx="100" ixy="0" ixz="0" iyy="100" iyz="0" izz="100" />
        </inertial>
        <visual>
            <origin xyz="-0.3408182278037341 0 0.17399075397840386" rpy="0 0 0"/>
            <geometry>
                <box size="0.6816364556074682 0.7171532633675107 0.3479815079568077" />
            </geometry>
            <material name="Blue">
                <color rgba="0 0 255 1"/>
            </material>
        </visual>
        <collision>
            <origin xyz="-0.3408182278037341 0 0.17399075397840386" rpy="0 0 0"/>
            <geometry>
                <box size="0.6816364556074682 0.7171532633675107 0.3479815079568077" />
            </geometry>
        </collision>
    </link>
    <joint name="0_1" type="revolute">
       <parent link="0"/>
       <child  link="1"/>
       <origin rpy="0 0 0" xyz="-0.35 0 0.7" />
     <axis xyz="1 1 0"/>
       <limit effort="0.0" lower="-3.14159" upper="3.14159" velocity="0.0"/>
    </joint>
    <link name="2">
        <inertial>
            <origin xyz="-0.262086983700175 0 0.12759196247327514" rpy="0 0 0"/>
            <mass value="1" />
            <inertia ixx="100" ixy="0" ixz="0" iyy="100" iyz="0" izz="100" />
        </inertial>
        <visual>
            <origin xyz="-0.262086983700175 0 0.12759196247327514" rpy="0 0 0"/>
            <geometry>
                <box size="0.52417396740035 0.09040178960519829 0.2551839249465503" />
            </geometry>
            <material name="Blue">
                <color rgba="0 0 255 1"/>
            </material>
        </visual>
        <collision>
            <origin xyz="-0.262086983700175 0 0.12759196247327514" rpy="0 0 0"/>
            <geometry>
                <box size="0.52417396740035 0.09040178960519829 0.2551839249465503" />
            </geometry>
        </collision>
    </link>
    <joint name="1_2" type="revolute">
       <parent link="1"/>
       <child  link="2"/>
       <origin rpy="0 0 0" xyz="-0.6816364556074682 0 0.3479815079568077" />
     <axis xyz="0 0 1"/>
       <limit effort="0.0" lower="-3.14159" upper="3.14159" velocity="0.0"/>
    </joint>
    <link name="3">
        <inertial>
            <origin xyz="-0.47971941893853576 0 0.3878786251578578" rpy="0 0 0"/>
            <mass value="1" />
            <inertia ixx="100" ixy="0" ixz="0" iyy="100" iyz="0" izz="100" />
        </inertial>
        <visual>
            <origin xyz="-0.47971941893853576 0 0.3878786251578578" rpy="0 0 0"/>
            <geometry>
                <box size="0.9594388378770715 0.13912615902147096 0.7757572503157156" />
            </geometry>
            <material name="Blue">
                <color rgba="0 0 255 1"/>
            </material>
        </visual>
        <collision>
            <origin xyz="-0.47971941893853576 0 0.3878786251578578" rpy="0 0 0"/>
            <geometry>
                <box size="0.9594388378770715 0.13912615902147096 0.7757572503157156" />
            </geometry>
        </collision>
    </link>
    <joint name="2_3" type="revolute">
       <parent link="2"/>
       <child  link="3"/>
       <origin rpy="0 0 0" xyz="-0.52417396740035 0 0.2551839249465503" />
     <axis xyz="0 1 0"/>
       <limit effort="0.0" lower="-3.14159" upper="3.14159" velocity="0.0"/>
    </joint>
    <link name="4">
        <inertial>
            <origin xyz="-0.059546718623536166 0 0.19349365714820227" rpy="0 0 0"/>
            <mass value="1" />
            <inertia ixx="100" ixy="0" ixz="0" iyy="100" iyz="0" izz="100" />
        </inertial>
        <visual>
            <origin xyz="-0.059546718623536166 0 0.19349365714820227" rpy="0 0 0"/>
            <geometry>
                <box size="0.11909343724707233 0.6438881683971543 0.38698731429640454" />
            </geometry>
            <material name="Green">
                <color rgba="0 128 0 1"/>
            </material>
        </visual>
        <collision>
            <origin xyz="-0.059546718623536166 0 0.19349365714820227" rpy="0 0 0"/>
            <geometry>
                <box size="0.11909343724707233 0.6438881683971543 0.38698731429640454" />
            </geometry>
        </collision>
    </link>
    <joint name="3_4" type="revolute">
       <parent link="3"/>
       <child  link="4"/>
       <origin rpy="0 0 0" xyz="-0.9594388378770715 0 0.7757572503157156" />
     <axis xyz="1 0 0"/>
       <limit effort="0.0" lower="-3.14159" upper="3.14159" velocity="0.0"/>
    </joint>
    <link name="5">
        <inertial>
            <origin xyz="-0.22252936605725582 0 0.48560376409814066" rpy="0 0 0"/>
            <mass value="1" />
            <inertia ixx="100" ixy="0" ixz="0" iyy="100" iyz="0" izz="100" />
        </inertial>
        <visual>
            <origin xyz="-0.22252936605725582 0 0.48560376409814066" rpy="0 0 0"/>
            <geometry>
                <box size="0.44505873211451163 0.9243078026249281 0.9712075281962813" />
            </geometry>
            <material name="Green">
                <color rgba="0 128 0 1"/>
            </material>
        </visual>
        <collision>
            <origin xyz="-0.22252936605725582 0 0.48560376409814066" rpy="0 0 0"/>
            <geometry>
                <box size="0.44505873211451163 0.9243078026249281 0.9712075281962813" />
            </geometry>
        </collision>
    </link>
    <joint name="4_5" type="revolute">
       <parent link="4"/>
       <child  link="5"/>
       <origin rpy="0 0 0" xyz="-0.11909343724707233 0 0.38698731429640454" />
     <axis xyz="1 1 1"/>
       <limit effort="0.0" lower="-3.14159" upper="3.14159" velocity="0.0"/>
    </joint>
    <link name="6">
        <inertial>
            <origin xyz="-0.19861998842937578 0 0.21906447457645112" rpy="0 0 0"/>
            <mass value="1" />
            <inertia ixx="100" ixy="0" ixz="0" iyy="100" iyz="0" izz="100" />
        </inertial>
        <visual>
            <origin xyz="-0.19861998842937578 0 0.21906447457645112" rpy="0 0 0"/>
            <geometry>
                <box size="0.39723997685875156 0.9100841680576449 0.43812894915290224" />
            </geometry>
            <material name="Green">
                <color rgba="0 128 0 1"/>
            </material>
        </visual>
        <collision>
            <origin xyz="-0.19861998842937578 0 0.21906447457645112" rpy="0 0 0"/>
            <geometry>
                <box size="0.39723997685875156 0.9100841680576449 0.43812894915290224" />
            </geometry>
        </collision>
    </link>
    <joint name="5_6" type="revolute">
       <parent link="5"/>
       <child  link="6"/>
       <origin rpy="0 0 0" xyz="-0.44505873211451163 0 0.9712075281962813" />
     <axis xyz="1 1 1"/>
       <limit effort="0.0" lower="-3.14159" upper="3.14159" velocity="0.0"/>
    </joint>
</robot>