<robot name = "robot">
    <link name="0">
        <inertial>
            <origin xyz="0 0 3" rpy="0 0 0"/>
            <mass value="1" />
            <inertia ixx="100" ixy="0" ixz="0" iyy="100" iyz="0" izz="100" />
        </inertial>
        <visual>
            <origin xyz="0 0 3" rpy="0 0 0"/>
            <geometry>
                <box size="1.5 1.5 0.8" />
            </geometry>
            <material name="Green">
                <color rgba="0 128 0 1"/>
            </material>
        </visual>
        <collision>
            <origin xyz="0 0 3" rpy="0 0 0"/>
            <geometry>
                <box size="1.5 1.5 0.8" />
            </geometry>
        </collision>
    </link>
    <link name="1">
        <inertial>
            <origin xyz="-0.25824049064729215 0 0" rpy="0 0 0"/>
            <mass value="1" />
            <inertia ixx="100" ixy="0" ixz="0" iyy="100" iyz="0" izz="100" />
        </inertial>
        <visual>
            <origin xyz="-0.25824049064729215 0 0" rpy="0 0 0"/>
            <geometry>
                <box size="0.5164809812945843 0.6604999744612916 0.1726003053103985" />
            </geometry>
            <material name="Green">
                <color rgba="0 128 0 1"/>
            </material>
        </visual>
        <collision>
            <origin xyz="-0.25824049064729215 0 0" rpy="0 0 0"/>
            <geometry>
                <box size="0.5164809812945843 0.6604999744612916 0.1726003053103985" />
            </geometry>
        </collision>
    </link>
    <joint name="0_1" type="revolute">
       <parent link="0"/>
       <child  link="1"/>
       <origin rpy="0 0 0" xyz="-0.75 0 3" />
     <axis xyz="1 0 1"/>
       <limit effort="0.0" lower="-3.14159" upper="3.14159" velocity="0.0"/>
    </joint>
    <link name="2">
        <inertial>
            <origin xyz="-0.41149410069906533 0 0" rpy="0 0 0"/>
            <mass value="1" />
            <inertia ixx="100" ixy="0" ixz="0" iyy="100" iyz="0" izz="100" />
        </inertial>
        <visual>
            <origin xyz="-0.41149410069906533 0 0" rpy="0 0 0"/>
            <geometry>
                <box size="0.8229882013981307 0.31969668108969584 0.496826399209765" />
            </geometry>
            <material name="Green">
                <color rgba="0 128 0 1"/>
            </material>
        </visual>
        <collision>
            <origin xyz="-0.41149410069906533 0 0" rpy="0 0 0"/>
            <geometry>
                <box size="0.8229882013981307 0.31969668108969584 0.496826399209765" />
            </geometry>
        </collision>
    </link>
    <joint name="1_2" type="revolute">
       <parent link="1"/>
       <child  link="2"/>
       <origin rpy="0 0 0" xyz="-0.5164809812945843 0 0" />
     <axis xyz="0 0 1"/>
       <limit effort="0.0" lower="-3.14159" upper="3.14159" velocity="0.0"/>
    </joint>
    <link name="3">
        <inertial>
            <origin xyz="-0.06931525834619384 0 0" rpy="0 0 0"/>
            <mass value="1" />
            <inertia ixx="100" ixy="0" ixz="0" iyy="100" iyz="0" izz="100" />
        </inertial>
        <visual>
            <origin xyz="-0.06931525834619384 0 0" rpy="0 0 0"/>
            <geometry>
                <box size="0.13863051669238768 0.4393421110705249 0.40676081855618074" />
            </geometry>
            <material name="Green">
                <color rgba="0 128 0 1"/>
            </material>
        </visual>
        <collision>
            <origin xyz="-0.06931525834619384 0 0" rpy="0 0 0"/>
            <geometry>
                <box size="0.13863051669238768 0.4393421110705249 0.40676081855618074" />
            </geometry>
        </collision>
    </link>
    <joint name="2_3" type="revolute">
       <parent link="2"/>
       <child  link="3"/>
       <origin rpy="0 0 0" xyz="-0.8229882013981307 0 0" />
     <axis xyz="1 0 1"/>
       <limit effort="0.0" lower="-3.14159" upper="3.14159" velocity="0.0"/>
    </joint>
    <link name="4">
        <inertial>
            <origin xyz="-0.43742950821516113 0 0" rpy="0 0 0"/>
            <mass value="1" />
            <inertia ixx="100" ixy="0" ixz="0" iyy="100" iyz="0" izz="100" />
        </inertial>
        <visual>
            <origin xyz="-0.43742950821516113 0 0" rpy="0 0 0"/>
            <geometry>
                <box size="0.8748590164303223 0.22809080127953574 0.39292333674671864" />
            </geometry>
            <material name="Green">
                <color rgba="0 128 0 1"/>
            </material>
        </visual>
        <collision>
            <origin xyz="-0.43742950821516113 0 0" rpy="0 0 0"/>
            <geometry>
                <box size="0.8748590164303223 0.22809080127953574 0.39292333674671864" />
            </geometry>
        </collision>
    </link>
    <joint name="3_4" type="revolute">
       <parent link="3"/>
       <child  link="4"/>
       <origin rpy="0 0 0" xyz="-0.13863051669238768 0 0" />
     <axis xyz="0 1 0"/>
       <limit effort="0.0" lower="-3.14159" upper="3.14159" velocity="0.0"/>
    </joint>
    <link name="5">
        <inertial>
            <origin xyz="-0.21425408292689863 0 0" rpy="0 0 0"/>
            <mass value="1" />
            <inertia ixx="100" ixy="0" ixz="0" iyy="100" iyz="0" izz="100" />
        </inertial>
        <visual>
            <origin xyz="-0.21425408292689863 0 0" rpy="0 0 0"/>
            <geometry>
                <box size="0.42850816585379725 0.22665788948985122 0.6257976941412576" />
            </geometry>
            <material name="Blue">
                <color rgba="0 0 255 1"/>
            </material>
        </visual>
        <collision>
            <origin xyz="-0.21425408292689863 0 0" rpy="0 0 0"/>
            <geometry>
                <box size="0.42850816585379725 0.22665788948985122 0.6257976941412576" />
            </geometry>
        </collision>
    </link>
    <joint name="4_5" type="revolute">
       <parent link="4"/>
       <child  link="5"/>
       <origin rpy="0 0 0" xyz="-0.8748590164303223 0 0" />
     <axis xyz="1 0 1"/>
       <limit effort="0.0" lower="-3.14159" upper="3.14159" velocity="0.0"/>
    </joint>
    <link name="6">
        <inertial>
            <origin xyz="0 0 -1.2317189196106757" rpy="0 0 0"/>
            <mass value="1" />
            <inertia ixx="100" ixy="0" ixz="0" iyy="100" iyz="0" izz="100" />
        </inertial>
        <visual>
            <origin xyz="0 0 -1.2317189196106757" rpy="0 0 0"/>
            <geometry>
                <box size="0.7955401673680925 0.7386113528644872 2.4634378392213514" />
            </geometry>
            <material name="Blue">
                <color rgba="0 0 255 1"/>
            </material>
        </visual>
        <collision>
            <origin xyz="0 0 -1.2317189196106757" rpy="0 0 0"/>
            <geometry>
                <box size="0.7955401673680925 0.7386113528644872 2.4634378392213514" />
            </geometry>
        </collision>
    </link>
    <joint name="5_6" type="revolute">
       <parent link="5"/>
       <child  link="6"/>
       <origin rpy="0 0 0" xyz="-0.21425408292689863 0 -0.3128988470706288" />
     <axis xyz="0 1 1"/>
       <limit effort="0.0" lower="-3.14159" upper="3.14159" velocity="0.0"/>
    </joint>
    <link name="7">
        <inertial>
            <origin xyz="0 0 -0.03031238469168583" rpy="0 0 0"/>
            <mass value="1" />
            <inertia ixx="100" ixy="0" ixz="0" iyy="100" iyz="0" izz="100" />
        </inertial>
        <visual>
            <origin xyz="0 0 -0.03031238469168583" rpy="0 0 0"/>
            <geometry>
                <box size="0.5642205394300648 0.9559268532494318 0.06062476938337166" />
            </geometry>
            <material name="Green">
                <color rgba="0 128 0 1"/>
            </material>
        </visual>
        <collision>
            <origin xyz="0 0 -0.03031238469168583" rpy="0 0 0"/>
            <geometry>
                <box size="0.5642205394300648 0.9559268532494318 0.06062476938337166" />
            </geometry>
        </collision>
    </link>
    <joint name="6_7" type="revolute">
       <parent link="6"/>
       <child  link="7"/>
       <origin rpy="0 0 0" xyz="0 0 -2.4634378392213514" />
     <axis xyz="0 0 1"/>
       <limit effort="0.0" lower="-3.14159" upper="3.14159" velocity="0.0"/>
    </joint>
    <link name="8">
        <inertial>
            <origin xyz="0 0 -0.03796869569763851" rpy="0 0 0"/>
            <mass value="1" />
            <inertia ixx="100" ixy="0" ixz="0" iyy="100" iyz="0" izz="100" />
        </inertial>
        <visual>
            <origin xyz="0 0 -0.03796869569763851" rpy="0 0 0"/>
            <geometry>
                <box size="0.5424221189143649 0.24169995861726046 0.07593739139527703" />
            </geometry>
            <material name="Blue">
                <color rgba="0 0 255 1"/>
            </material>
        </visual>
        <collision>
            <origin xyz="0 0 -0.03796869569763851" rpy="0 0 0"/>
            <geometry>
                <box size="0.5424221189143649 0.24169995861726046 0.07593739139527703" />
            </geometry>
        </collision>
    </link>
    <joint name="7_8" type="revolute">
       <parent link="7"/>
       <child  link="8"/>
       <origin rpy="0 0 0" xyz="0 0 -0.06062476938337166" />
     <axis xyz="0 1 1"/>
       <limit effort="0.0" lower="-3.14159" upper="3.14159" velocity="0.0"/>
    </joint>
    <link name="9">
        <inertial>
            <origin xyz="0.2340826774948418 0 0" rpy="0 0 0"/>
            <mass value="1" />
            <inertia ixx="100" ixy="0" ixz="0" iyy="100" iyz="0" izz="100" />
        </inertial>
        <visual>
            <origin xyz="0.2340826774948418 0 0" rpy="0 0 0"/>
            <geometry>
                <box size="0.4681653549896836 0.9355374426106422 0.5466566795446389" />
            </geometry>
            <material name="Blue">
                <color rgba="0 0 255 1"/>
            </material>
        </visual>
        <collision>
            <origin xyz="0.2340826774948418 0 0" rpy="0 0 0"/>
            <geometry>
                <box size="0.4681653549896836 0.9355374426106422 0.5466566795446389" />
            </geometry>
        </collision>
    </link>
    <joint name="0_9" type="revolute">
       <parent link="0"/>
       <child  link="9"/>
       <origin rpy="0 0 0" xyz="0.75 0 3" />
     <axis xyz="1 1 0"/>
       <limit effort="0.0" lower="-3.14159" upper="3.14159" velocity="0.0"/>
    </joint>
    <link name="10">
        <inertial>
            <origin xyz="0.017529565094183852 0 0" rpy="0 0 0"/>
            <mass value="1" />
            <inertia ixx="100" ixy="0" ixz="0" iyy="100" iyz="0" izz="100" />
        </inertial>
        <visual>
            <origin xyz="0.017529565094183852 0 0" rpy="0 0 0"/>
            <geometry>
                <box size="0.035059130188367704 0.6808447021735592 0.5666081810651512" />
            </geometry>
            <material name="Green">
                <color rgba="0 128 0 1"/>
            </material>
        </visual>
        <collision>
            <origin xyz="0.017529565094183852 0 0" rpy="0 0 0"/>
            <geometry>
                <box size="0.035059130188367704 0.6808447021735592 0.5666081810651512" />
            </geometry>
        </collision>
    </link>
    <joint name="9_10" type="revolute">
       <parent link="9"/>
       <child  link="10"/>
       <origin rpy="0 0 0" xyz="0.4681653549896836 0 0" />
     <axis xyz="1 0 1"/>
       <limit effort="0.0" lower="-3.14159" upper="3.14159" velocity="0.0"/>
    </joint>
    <link name="11">
        <inertial>
            <origin xyz="0.23758163089277362 0 0" rpy="0 0 0"/>
            <mass value="1" />
            <inertia ixx="100" ixy="0" ixz="0" iyy="100" iyz="0" izz="100" />
        </inertial>
        <visual>
            <origin xyz="0.23758163089277362 0 0" rpy="0 0 0"/>
            <geometry>
                <box size="0.47516326178554724 0.92696818392926 0.08077016361845413" />
            </geometry>
            <material name="Green">
                <color rgba="0 128 0 1"/>
            </material>
        </visual>
        <collision>
            <origin xyz="0.23758163089277362 0 0" rpy="0 0 0"/>
            <geometry>
                <box size="0.47516326178554724 0.92696818392926 0.08077016361845413" />
            </geometry>
        </collision>
    </link>
    <joint name="10_11" type="revolute">
       <parent link="10"/>
       <child  link="11"/>
       <origin rpy="0 0 0" xyz="0.035059130188367704 0 0" />
     <axis xyz="0 0 1"/>
       <limit effort="0.0" lower="-3.14159" upper="3.14159" velocity="0.0"/>
    </joint>
    <link name="12">
        <inertial>
            <origin xyz="0.2758346752034808 0 0" rpy="0 0 0"/>
            <mass value="1" />
            <inertia ixx="100" ixy="0" ixz="0" iyy="100" iyz="0" izz="100" />
        </inertial>
        <visual>
            <origin xyz="0.2758346752034808 0 0" rpy="0 0 0"/>
            <geometry>
                <box size="0.5516693504069616 0.8454313616523231 0.11063010086734992" />
            </geometry>
            <material name="Blue">
                <color rgba="0 0 255 1"/>
            </material>
        </visual>
        <collision>
            <origin xyz="0.2758346752034808 0 0" rpy="0 0 0"/>
            <geometry>
                <box size="0.5516693504069616 0.8454313616523231 0.11063010086734992" />
            </geometry>
        </collision>
    </link>
    <joint name="11_12" type="revolute">
       <parent link="11"/>
       <child  link="12"/>
       <origin rpy="0 0 0" xyz="0.47516326178554724 0 0" />
     <axis xyz="0 1 1"/>
       <limit effort="0.0" lower="-3.14159" upper="3.14159" velocity="0.0"/>
    </joint>
    <link name="13">
        <inertial>
            <origin xyz="0.47204541258387683 0 0" rpy="0 0 0"/>
            <mass value="1" />
            <inertia ixx="100" ixy="0" ixz="0" iyy="100" iyz="0" izz="100" />
        </inertial>
        <visual>
            <origin xyz="0.47204541258387683 0 0" rpy="0 0 0"/>
            <geometry>
                <box size="0.9440908251677537 0.9521585005874239 0.6567724498908755" />
            </geometry>
            <material name="Blue">
                <color rgba="0 0 255 1"/>
            </material>
        </visual>
        <collision>
            <origin xyz="0.47204541258387683 0 0" rpy="0 0 0"/>
            <geometry>
                <box size="0.9440908251677537 0.9521585005874239 0.6567724498908755" />
            </geometry>
        </collision>
    </link>
    <joint name="12_13" type="revolute">
       <parent link="12"/>
       <child  link="13"/>
       <origin rpy="0 0 0" xyz="0.5516693504069616 0 0" />
     <axis xyz="0 1 0"/>
       <limit effort="0.0" lower="-3.14159" upper="3.14159" velocity="0.0"/>
    </joint>
    <link name="14">
        <inertial>
            <origin xyz="0 0 -0.19800342339886765" rpy="0 0 0"/>
            <mass value="1" />
            <inertia ixx="100" ixy="0" ixz="0" iyy="100" iyz="0" izz="100" />
        </inertial>
        <visual>
            <origin xyz="0 0 -0.19800342339886765" rpy="0 0 0"/>
            <geometry>
                <box size="0.04213083830276754 0.20042292069028367 0.3960068467977353" />
            </geometry>
            <material name="Blue">
                <color rgba="0 0 255 1"/>
            </material>
        </visual>
        <collision>
            <origin xyz="0 0 -0.19800342339886765" rpy="0 0 0"/>
            <geometry>
                <box size="0.04213083830276754 0.20042292069028367 0.3960068467977353" />
            </geometry>
        </collision>
    </link>
    <joint name="13_14" type="revolute">
       <parent link="13"/>
       <child  link="14"/>
       <origin rpy="0 0 0" xyz="0.47204541258387683 0 -0.32838622494543773" />
     <axis xyz="1 0 0"/>
       <limit effort="0.0" lower="-3.14159" upper="3.14159" velocity="0.0"/>
    </joint>
    <link name="15">
        <inertial>
            <origin xyz="0 0 -0.5893725798094587" rpy="0 0 0"/>
            <mass value="1" />
            <inertia ixx="100" ixy="0" ixz="0" iyy="100" iyz="0" izz="100" />
        </inertial>
        <visual>
            <origin xyz="0 0 -0.5893725798094587" rpy="0 0 0"/>
            <geometry>
                <box size="0.4910182675373864 0.4476400590581102 1.1787451596189173" />
            </geometry>
            <material name="Blue">
                <color rgba="0 0 255 1"/>
            </material>
        </visual>
        <collision>
            <origin xyz="0 0 -0.5893725798094587" rpy="0 0 0"/>
            <geometry>
                <box size="0.4910182675373864 0.4476400590581102 1.1787451596189173" />
            </geometry>
        </collision>
    </link>
    <joint name="14_15" type="revolute">
       <parent link="14"/>
       <child  link="15"/>
       <origin rpy="0 0 0" xyz="0 0 -0.3960068467977353" />
     <axis xyz="0 1 1"/>
       <limit effort="0.0" lower="-3.14159" upper="3.14159" velocity="0.0"/>
    </joint>
    <link name="16">
        <inertial>
            <origin xyz="0 0 -0.5126239967916737" rpy="0 0 0"/>
            <mass value="1" />
            <inertia ixx="100" ixy="0" ixz="0" iyy="100" iyz="0" izz="100" />
        </inertial>
        <visual>
            <origin xyz="0 0 -0.5126239967916737" rpy="0 0 0"/>
            <geometry>
                <box size="0.3447215924708805 0.2629037401170351 1.0252479935833474" />
            </geometry>
            <material name="Blue">
                <color rgba="0 0 255 1"/>
            </material>
        </visual>
        <collision>
            <origin xyz="0 0 -0.5126239967916737" rpy="0 0 0"/>
            <geometry>
                <box size="0.3447215924708805 0.2629037401170351 1.0252479935833474" />
            </geometry>
        </collision>
    </link>
    <joint name="15_16" type="revolute">
       <parent link="15"/>
       <child  link="16"/>
       <origin rpy="0 0 0" xyz="0 0 -1.1787451596189173" />
     <axis xyz="0 1 0"/>
       <limit effort="0.0" lower="-3.14159" upper="3.14159" velocity="0.0"/>
    </joint>
    <link name="17">
        <inertial>
            <origin xyz="0 -0.30984847822283246 0" rpy="0 0 0"/>
            <mass value="1" />
            <inertia ixx="100" ixy="0" ixz="0" iyy="100" iyz="0" izz="100" />
        </inertial>
        <visual>
            <origin xyz="0 -0.30984847822283246 0" rpy="0 0 0"/>
            <geometry>
                <box size="0.45763465234154876 0.6196969564456649 0.4175236118072744" />
            </geometry>
            <material name="Blue">
                <color rgba="0 0 255 1"/>
            </material>
        </visual>
        <collision>
            <origin xyz="0 -0.30984847822283246 0" rpy="0 0 0"/>
            <geometry>
                <box size="0.45763465234154876 0.6196969564456649 0.4175236118072744" />
            </geometry>
        </collision>
    </link>
    <joint name="0_17" type="revolute">
       <parent link="0"/>
       <child  link="17"/>
       <origin rpy="0 0 0" xyz="0 -0.75 3" />
     <axis xyz="0 0 1"/>
       <limit effort="0.0" lower="-3.14159" upper="3.14159" velocity="0.0"/>
    </joint>
    <link name="18">
        <inertial>
            <origin xyz="0 -0.2685410022436148 0" rpy="0 0 0"/>
            <mass value="1" />
            <inertia ixx="100" ixy="0" ixz="0" iyy="100" iyz="0" izz="100" />
        </inertial>
        <visual>
            <origin xyz="0 -0.2685410022436148 0" rpy="0 0 0"/>
            <geometry>
                <box size="0.03925006093540184 0.5370820044872296 0.10976675467161368" />
            </geometry>
            <material name="Blue">
                <color rgba="0 0 255 1"/>
            </material>
        </visual>
        <collision>
            <origin xyz="0 -0.2685410022436148 0" rpy="0 0 0"/>
            <geometry>
                <box size="0.03925006093540184 0.5370820044872296 0.10976675467161368" />
            </geometry>
        </collision>
    </link>
    <joint name="17_18" type="revolute">
       <parent link="17"/>
       <child  link="18"/>
       <origin rpy="0 0 0" xyz="0 -0.6196969564456649 0" />
     <axis xyz="1 0 1"/>
       <limit effort="0.0" lower="-3.14159" upper="3.14159" velocity="0.0"/>
    </joint>
    <link name="19">
        <inertial>
            <origin xyz="0 -0.1314531206338605 0" rpy="0 0 0"/>
            <mass value="1" />
            <inertia ixx="100" ixy="0" ixz="0" iyy="100" iyz="0" izz="100" />
        </inertial>
        <visual>
            <origin xyz="0 -0.1314531206338605 0" rpy="0 0 0"/>
            <geometry>
                <box size="0.5984282776527878 0.262906241267721 0.04684612810308608" />
            </geometry>
            <material name="Green">
                <color rgba="0 128 0 1"/>
            </material>
        </visual>
        <collision>
            <origin xyz="0 -0.1314531206338605 0" rpy="0 0 0"/>
            <geometry>
                <box size="0.5984282776527878 0.262906241267721 0.04684612810308608" />
            </geometry>
        </collision>
    </link>
    <joint name="18_19" type="revolute">
       <parent link="18"/>
       <child  link="19"/>
       <origin rpy="0 0 0" xyz="0 -0.5370820044872296 0" />
     <axis xyz="1 1 1"/>
       <limit effort="0.0" lower="-3.14159" upper="3.14159" velocity="0.0"/>
    </joint>
    <link name="20">
        <inertial>
            <origin xyz="0 -0.3168564531094575 0" rpy="0 0 0"/>
            <mass value="1" />
            <inertia ixx="100" ixy="0" ixz="0" iyy="100" iyz="0" izz="100" />
        </inertial>
        <visual>
            <origin xyz="0 -0.3168564531094575 0" rpy="0 0 0"/>
            <geometry>
                <box size="0.21050910673674494 0.633712906218915 0.9863516707025007" />
            </geometry>
            <material name="Green">
                <color rgba="0 128 0 1"/>
            </material>
        </visual>
        <collision>
            <origin xyz="0 -0.3168564531094575 0" rpy="0 0 0"/>
            <geometry>
                <box size="0.21050910673674494 0.633712906218915 0.9863516707025007" />
            </geometry>
        </collision>
    </link>
    <joint name="19_20" type="revolute">
       <parent link="19"/>
       <child  link="20"/>
       <origin rpy="0 0 0" xyz="0 -0.262906241267721 0" />
     <axis xyz="1 1 0"/>
       <limit effort="0.0" lower="-3.14159" upper="3.14159" velocity="0.0"/>
    </joint>
    <link name="21">
        <inertial>
            <origin xyz="0 -0.10659499067858252 0" rpy="0 0 0"/>
            <mass value="1" />
            <inertia ixx="100" ixy="0" ixz="0" iyy="100" iyz="0" izz="100" />
        </inertial>
        <visual>
            <origin xyz="0 -0.10659499067858252 0" rpy="0 0 0"/>
            <geometry>
                <box size="0.28701929557320927 0.21318998135716505 0.6385610076099878" />
            </geometry>
            <material name="Green">
                <color rgba="0 128 0 1"/>
            </material>
        </visual>
        <collision>
            <origin xyz="0 -0.10659499067858252 0" rpy="0 0 0"/>
            <geometry>
                <box size="0.28701929557320927 0.21318998135716505 0.6385610076099878" />
            </geometry>
        </collision>
    </link>
    <joint name="20_21" type="revolute">
       <parent link="20"/>
       <child  link="21"/>
       <origin rpy="0 0 0" xyz="0 -0.633712906218915 0" />
     <axis xyz="1 0 1"/>
       <limit effort="0.0" lower="-3.14159" upper="3.14159" velocity="0.0"/>
    </joint>
    <link name="22">
        <inertial>
            <origin xyz="0 0 -0.9763089115898781" rpy="0 0 0"/>
            <mass value="1" />
            <inertia ixx="100" ixy="0" ixz="0" iyy="100" iyz="0" izz="100" />
        </inertial>
        <visual>
            <origin xyz="0 0 -0.9763089115898781" rpy="0 0 0"/>
            <geometry>
                <box size="0.335838936891665 0.30311122984352823 1.9526178231797562" />
            </geometry>
            <material name="Blue">
                <color rgba="0 0 255 1"/>
            </material>
        </visual>
        <collision>
            <origin xyz="0 0 -0.9763089115898781" rpy="0 0 0"/>
            <geometry>
                <box size="0.335838936891665 0.30311122984352823 1.9526178231797562" />
            </geometry>
        </collision>
    </link>
    <joint name="21_22" type="revolute">
       <parent link="21"/>
       <child  link="22"/>
       <origin rpy="0 0 0" xyz="0 -0.10659499067858252 -0.3192805038049939" />
     <axis xyz="1 0 1"/>
       <limit effort="0.0" lower="-3.14159" upper="3.14159" velocity="0.0"/>
    </joint>
    <link name="23">
        <inertial>
            <origin xyz="0 0 -0.048412022941609234" rpy="0 0 0"/>
            <mass value="1" />
            <inertia ixx="100" ixy="0" ixz="0" iyy="100" iyz="0" izz="100" />
        </inertial>
        <visual>
            <origin xyz="0 0 -0.048412022941609234" rpy="0 0 0"/>
            <geometry>
                <box size="0.06543856005657656 0.5429420216179733 0.09682404588321847" />
            </geometry>
            <material name="Blue">
                <color rgba="0 0 255 1"/>
            </material>
        </visual>
        <collision>
            <origin xyz="0 0 -0.048412022941609234" rpy="0 0 0"/>
            <geometry>
                <box size="0.06543856005657656 0.5429420216179733 0.09682404588321847" />
            </geometry>
        </collision>
    </link>
    <joint name="22_23" type="revolute">
       <parent link="22"/>
       <child  link="23"/>
       <origin rpy="0 0 0" xyz="0 0 -1.9526178231797562" />
     <axis xyz="1 0 0"/>
       <limit effort="0.0" lower="-3.14159" upper="3.14159" velocity="0.0"/>
    </joint>
    <link name="24">
        <inertial>
            <origin xyz="0 0 -0.2752790654685127" rpy="0 0 0"/>
            <mass value="1" />
            <inertia ixx="100" ixy="0" ixz="0" iyy="100" iyz="0" izz="100" />
        </inertial>
        <visual>
            <origin xyz="0 0 -0.2752790654685127" rpy="0 0 0"/>
            <geometry>
                <box size="0.3855391323825761 0.7174124016560139 0.5505581309370254" />
            </geometry>
            <material name="Blue">
                <color rgba="0 0 255 1"/>
            </material>
        </visual>
        <collision>
            <origin xyz="0 0 -0.2752790654685127" rpy="0 0 0"/>
            <geometry>
                <box size="0.3855391323825761 0.7174124016560139 0.5505581309370254" />
            </geometry>
        </collision>
    </link>
    <joint name="23_24" type="revolute">
       <parent link="23"/>
       <child  link="24"/>
       <origin rpy="0 0 0" xyz="0 0 -0.09682404588321847" />
     <axis xyz="1 0 0"/>
       <limit effort="0.0" lower="-3.14159" upper="3.14159" velocity="0.0"/>
    </joint>
    <link name="25">
        <inertial>
            <origin xyz="0 0.3529221141292453 0" rpy="0 0 0"/>
            <mass value="1" />
            <inertia ixx="100" ixy="0" ixz="0" iyy="100" iyz="0" izz="100" />
        </inertial>
        <visual>
            <origin xyz="0 0.3529221141292453 0" rpy="0 0 0"/>
            <geometry>
                <box size="0.5885159201329988 0.7058442282584906 0.3508551530355546" />
            </geometry>
            <material name="Green">
                <color rgba="0 128 0 1"/>
            </material>
        </visual>
        <collision>
            <origin xyz="0 0.3529221141292453 0" rpy="0 0 0"/>
            <geometry>
                <box size="0.5885159201329988 0.7058442282584906 0.3508551530355546" />
            </geometry>
        </collision>
    </link>
    <joint name="0_25" type="revolute">
       <parent link="0"/>
       <child  link="25"/>
       <origin rpy="0 0 0" xyz="0 0.75 3" />
     <axis xyz="0 0 1"/>
       <limit effort="0.0" lower="-3.14159" upper="3.14159" velocity="0.0"/>
    </joint>
    <link name="26">
        <inertial>
            <origin xyz="0 0.23818925880018 0" rpy="0 0 0"/>
            <mass value="1" />
            <inertia ixx="100" ixy="0" ixz="0" iyy="100" iyz="0" izz="100" />
        </inertial>
        <visual>
            <origin xyz="0 0.23818925880018 0" rpy="0 0 0"/>
            <geometry>
                <box size="0.964706424167217 0.47637851760036 0.31691172900752773" />
            </geometry>
            <material name="Green">
                <color rgba="0 128 0 1"/>
            </material>
        </visual>
        <collision>
            <origin xyz="0 0.23818925880018 0" rpy="0 0 0"/>
            <geometry>
                <box size="0.964706424167217 0.47637851760036 0.31691172900752773" />
            </geometry>
        </collision>
    </link>
    <joint name="25_26" type="revolute">
       <parent link="25"/>
       <child  link="26"/>
       <origin rpy="0 0 0" xyz="0 0.7058442282584906 0" />
     <axis xyz="0 1 0"/>
       <limit effort="0.0" lower="-3.14159" upper="3.14159" velocity="0.0"/>
    </joint>
    <link name="27">
        <inertial>
            <origin xyz="0 0.2702927113433215 0" rpy="0 0 0"/>
            <mass value="1" />
            <inertia ixx="100" ixy="0" ixz="0" iyy="100" iyz="0" izz="100" />
        </inertial>
        <visual>
            <origin xyz="0 0.2702927113433215 0" rpy="0 0 0"/>
            <geometry>
                <box size="0.1482559636201447 0.540585422686643 0.22318270332866308" />
            </geometry>
            <material name="Green">
                <color rgba="0 128 0 1"/>
            </material>
        </visual>
        <collision>
            <origin xyz="0 0.2702927113433215 0" rpy="0 0 0"/>
            <geometry>
                <box size="0.1482559636201447 0.540585422686643 0.22318270332866308" />
            </geometry>
        </collision>
    </link>
    <joint name="26_27" type="revolute">
       <parent link="26"/>
       <child  link="27"/>
       <origin rpy="0 0 0" xyz="0 0.47637851760036 0" />
     <axis xyz="1 1 1"/>
       <limit effort="0.0" lower="-3.14159" upper="3.14159" velocity="0.0"/>
    </joint>
    <link name="28">
        <inertial>
            <origin xyz="0 0.17065674173941608 0" rpy="0 0 0"/>
            <mass value="1" />
            <inertia ixx="100" ixy="0" ixz="0" iyy="100" iyz="0" izz="100" />
        </inertial>
        <visual>
            <origin xyz="0 0.17065674173941608 0" rpy="0 0 0"/>
            <geometry>
                <box size="0.2617550648375411 0.34131348347883217 0.5860695036151614" />
            </geometry>
            <material name="Green">
                <color rgba="0 128 0 1"/>
            </material>
        </visual>
        <collision>
            <origin xyz="0 0.17065674173941608 0" rpy="0 0 0"/>
            <geometry>
                <box size="0.2617550648375411 0.34131348347883217 0.5860695036151614" />
            </geometry>
        </collision>
    </link>
    <joint name="27_28" type="revolute">
       <parent link="27"/>
       <child  link="28"/>
       <origin rpy="0 0 0" xyz="0 0.540585422686643 0" />
     <axis xyz="1 1 1"/>
       <limit effort="0.0" lower="-3.14159" upper="3.14159" velocity="0.0"/>
    </joint>
    <link name="29">
        <inertial>
            <origin xyz="0 0.23406673723454496 0" rpy="0 0 0"/>
            <mass value="1" />
            <inertia ixx="100" ixy="0" ixz="0" iyy="100" iyz="0" izz="100" />
        </inertial>
        <visual>
            <origin xyz="0 0.23406673723454496 0" rpy="0 0 0"/>
            <geometry>
                <box size="0.40848468521871895 0.4681334744690899 0.6469106604395063" />
            </geometry>
            <material name="Green">
                <color rgba="0 128 0 1"/>
            </material>
        </visual>
        <collision>
            <origin xyz="0 0.23406673723454496 0" rpy="0 0 0"/>
            <geometry>
                <box size="0.40848468521871895 0.4681334744690899 0.6469106604395063" />
            </geometry>
        </collision>
    </link>
    <joint name="28_29" type="revolute">
       <parent link="28"/>
       <child  link="29"/>
       <origin rpy="0 0 0" xyz="0 0.34131348347883217 0" />
     <axis xyz="1 1 1"/>
       <limit effort="0.0" lower="-3.14159" upper="3.14159" velocity="0.0"/>
    </joint>
    <link name="30">
        <inertial>
            <origin xyz="0 0 -1.1865025313772197" rpy="0 0 0"/>
            <mass value="1" />
            <inertia ixx="100" ixy="0" ixz="0" iyy="100" iyz="0" izz="100" />
        </inertial>
        <visual>
            <origin xyz="0 0 -1.1865025313772197" rpy="0 0 0"/>
            <geometry>
                <box size="0.4509952533120609 0.36002419180906287 2.3730050627544395" />
            </geometry>
            <material name="Blue">
                <color rgba="0 0 255 1"/>
            </material>
        </visual>
        <collision>
            <origin xyz="0 0 -1.1865025313772197" rpy="0 0 0"/>
            <geometry>
                <box size="0.4509952533120609 0.36002419180906287 2.3730050627544395" />
            </geometry>
        </collision>
    </link>
    <joint name="29_30" type="revolute">
       <parent link="29"/>
       <child  link="30"/>
       <origin rpy="0 0 0" xyz="0 0.23406673723454496 -0.32345533021975315" />
     <axis xyz="1 1 1"/>
       <limit effort="0.0" lower="-3.14159" upper="3.14159" velocity="0.0"/>
    </joint>
    <link name="31">
        <inertial>
            <origin xyz="0 0 -0.06868710891634842" rpy="0 0 0"/>
            <mass value="1" />
            <inertia ixx="100" ixy="0" ixz="0" iyy="100" iyz="0" izz="100" />
        </inertial>
        <visual>
            <origin xyz="0 0 -0.06868710891634842" rpy="0 0 0"/>
            <geometry>
                <box size="0.9099654692914926 0.0631093085726121 0.13737421783269685" />
            </geometry>
            <material name="Blue">
                <color rgba="0 0 255 1"/>
            </material>
        </visual>
        <collision>
            <origin xyz="0 0 -0.06868710891634842" rpy="0 0 0"/>
            <geometry>
                <box size="0.9099654692914926 0.0631093085726121 0.13737421783269685" />
            </geometry>
        </collision>
    </link>
    <joint name="30_31" type="revolute">
       <parent link="30"/>
       <child  link="31"/>
       <origin rpy="0 0 0" xyz="0 0 -2.3730050627544395" />
     <axis xyz="1 1 0"/>
       <limit effort="0.0" lower="-3.14159" upper="3.14159" velocity="0.0"/>
    </joint>
    <link name="32">
        <inertial>
            <origin xyz="0 0 -0.04481035970643189" rpy="0 0 0"/>
            <mass value="1" />
            <inertia ixx="100" ixy="0" ixz="0" iyy="100" iyz="0" izz="100" />
        </inertial>
        <visual>
            <origin xyz="0 0 -0.04481035970643189" rpy="0 0 0"/>
            <geometry>
                <box size="0.8578093092887101 0.0001793567211407776 0.08962071941286379" />
            </geometry>
            <material name="Blue">
                <color rgba="0 0 255 1"/>
            </material>
        </visual>
        <collision>
            <origin xyz="0 0 -0.04481035970643189" rpy="0 0 0"/>
            <geometry>
                <box size="0.8578093092887101 0.0001793567211407776 0.08962071941286379" />
            </geometry>
        </collision>
    </link>
    <joint name="31_32" type="revolute">
       <parent link="31"/>
       <child  link="32"/>
       <origin rpy="0 0 0" xyz="0 0 -0.13737421783269685" />
     <axis xyz="1 1 0"/>
       <limit effort="0.0" lower="-3.14159" upper="3.14159" velocity="0.0"/>
    </joint>
</robot>