<robot name = "robot">
    <link name="0">
        <inertial>
            <origin xyz="0 0 3" rpy="0 0 0"/>
            <mass value="1" />
            <inertia ixx="100" ixy="0" ixz="0" iyy="100" iyz="0" izz="100" />
        </inertial>
        <visual>
            <origin xyz="0 0 3" rpy="0 0 0"/>
            <geometry>
                <box size="1.5 1.5 0.8" />
            </geometry>
            <material name="Blue">
                <color rgba="0 0 255 1"/>
            </material>
        </visual>
        <collision>
            <origin xyz="0 0 3" rpy="0 0 0"/>
            <geometry>
                <box size="1.5 1.5 0.8" />
            </geometry>
        </collision>
    </link>
    <link name="1">
        <inertial>
            <origin xyz="-0.04341999537788932 0 0" rpy="0 0 0"/>
            <mass value="1" />
            <inertia ixx="100" ixy="0" ixz="0" iyy="100" iyz="0" izz="100" />
        </inertial>
        <visual>
            <origin xyz="-0.04341999537788932 0 0" rpy="0 0 0"/>
            <geometry>
                <box size="0.08683999075577864 0.20830095582645503 0.12609963441827043" />
            </geometry>
            <material name="Blue">
                <color rgba="0 0 255 1"/>
            </material>
        </visual>
        <collision>
            <origin xyz="-0.04341999537788932 0 0" rpy="0 0 0"/>
            <geometry>
                <box size="0.08683999075577864 0.20830095582645503 0.12609963441827043" />
            </geometry>
        </collision>
    </link>
    <joint name="0_1" type="revolute">
       <parent link="0"/>
       <child  link="1"/>
       <origin rpy="0 0 0" xyz="-0.75 0 3" />
     <axis xyz="1 1 1"/>
       <limit effort="0.0" lower="-3.14159" upper="3.14159" velocity="0.0"/>
    </joint>
    <link name="2">
        <inertial>
            <origin xyz="-0.47609930433053094 0 0" rpy="0 0 0"/>
            <mass value="1" />
            <inertia ixx="100" ixy="0" ixz="0" iyy="100" iyz="0" izz="100" />
        </inertial>
        <visual>
            <origin xyz="-0.47609930433053094 0 0" rpy="0 0 0"/>
            <geometry>
                <box size="0.9521986086610619 0.7251368769002907 0.7644806649728674" />
            </geometry>
            <material name="Green">
                <color rgba="0 128 0 1"/>
            </material>
        </visual>
        <collision>
            <origin xyz="-0.47609930433053094 0 0" rpy="0 0 0"/>
            <geometry>
                <box size="0.9521986086610619 0.7251368769002907 0.7644806649728674" />
            </geometry>
        </collision>
    </link>
    <joint name="1_2" type="revolute">
       <parent link="1"/>
       <child  link="2"/>
       <origin rpy="0 0 0" xyz="-0.08683999075577864 0 0" />
     <axis xyz="1 0 0"/>
       <limit effort="0.0" lower="-3.14159" upper="3.14159" velocity="0.0"/>
    </joint>
    <link name="3">
        <inertial>
            <origin xyz="-0.11915163631341902 0 0" rpy="0 0 0"/>
            <mass value="1" />
            <inertia ixx="100" ixy="0" ixz="0" iyy="100" iyz="0" izz="100" />
        </inertial>
        <visual>
            <origin xyz="-0.11915163631341902 0 0" rpy="0 0 0"/>
            <geometry>
                <box size="0.23830327262683804 0.41773923338665153 0.3073008537837797" />
            </geometry>
            <material name="Blue">
                <color rgba="0 0 255 1"/>
            </material>
        </visual>
        <collision>
            <origin xyz="-0.11915163631341902 0 0" rpy="0 0 0"/>
            <geometry>
                <box size="0.23830327262683804 0.41773923338665153 0.3073008537837797" />
            </geometry>
        </collision>
    </link>
    <joint name="2_3" type="revolute">
       <parent link="2"/>
       <child  link="3"/>
       <origin rpy="0 0 0" xyz="-0.9521986086610619 0 0" />
     <axis xyz="0 1 0"/>
       <limit effort="0.0" lower="-3.14159" upper="3.14159" velocity="0.0"/>
    </joint>
    <link name="4">
        <inertial>
            <origin xyz="-0.24828624242296415 0 0" rpy="0 0 0"/>
            <mass value="1" />
            <inertia ixx="100" ixy="0" ixz="0" iyy="100" iyz="0" izz="100" />
        </inertial>
        <visual>
            <origin xyz="-0.24828624242296415 0 0" rpy="0 0 0"/>
            <geometry>
                <box size="0.4965724848459283 0.5253317063166829 0.644077721099322" />
            </geometry>
            <material name="Green">
                <color rgba="0 128 0 1"/>
            </material>
        </visual>
        <collision>
            <origin xyz="-0.24828624242296415 0 0" rpy="0 0 0"/>
            <geometry>
                <box size="0.4965724848459283 0.5253317063166829 0.644077721099322" />
            </geometry>
        </collision>
    </link>
    <joint name="3_4" type="revolute">
       <parent link="3"/>
       <child  link="4"/>
       <origin rpy="0 0 0" xyz="-0.23830327262683804 0 0" />
     <axis xyz="1 1 1"/>
       <limit effort="0.0" lower="-3.14159" upper="3.14159" velocity="0.0"/>
    </joint>
    <link name="5">
        <inertial>
            <origin xyz="0 0 -0.49387026913192666" rpy="0 0 0"/>
            <mass value="1" />
            <inertia ixx="100" ixy="0" ixz="0" iyy="100" iyz="0" izz="100" />
        </inertial>
        <visual>
            <origin xyz="0 0 -0.49387026913192666" rpy="0 0 0"/>
            <geometry>
                <box size="0.28061802428235094 0.24790608754590837 0.9877405382638533" />
            </geometry>
            <material name="Green">
                <color rgba="0 128 0 1"/>
            </material>
        </visual>
        <collision>
            <origin xyz="0 0 -0.49387026913192666" rpy="0 0 0"/>
            <geometry>
                <box size="0.28061802428235094 0.24790608754590837 0.9877405382638533" />
            </geometry>
        </collision>
    </link>
    <joint name="4_5" type="revolute">
       <parent link="4"/>
       <child  link="5"/>
       <origin rpy="0 0 0" xyz="-0.24828624242296415 0 -0.322038860549661" />
     <axis xyz="0 0 1"/>
       <limit effort="0.0" lower="-3.14159" upper="3.14159" velocity="0.0"/>
    </joint>
    <link name="6">
        <inertial>
            <origin xyz="0 0 -0.7186407686578611" rpy="0 0 0"/>
            <mass value="1" />
            <inertia ixx="100" ixy="0" ixz="0" iyy="100" iyz="0" izz="100" />
        </inertial>
        <visual>
            <origin xyz="0 0 -0.7186407686578611" rpy="0 0 0"/>
            <geometry>
                <box size="0.8245334029585026 0.8965959081635138 1.4372815373157222" />
            </geometry>
            <material name="Green">
                <color rgba="0 128 0 1"/>
            </material>
        </visual>
        <collision>
            <origin xyz="0 0 -0.7186407686578611" rpy="0 0 0"/>
            <geometry>
                <box size="0.8245334029585026 0.8965959081635138 1.4372815373157222" />
            </geometry>
        </collision>
    </link>
    <joint name="5_6" type="revolute">
       <parent link="5"/>
       <child  link="6"/>
       <origin rpy="0 0 0" xyz="0 0 -0.9877405382638533" />
     <axis xyz="1 1 1"/>
       <limit effort="0.0" lower="-3.14159" upper="3.14159" velocity="0.0"/>
    </joint>
    <link name="7">
        <inertial>
            <origin xyz="0 0 -0.0874889622102123" rpy="0 0 0"/>
            <mass value="1" />
            <inertia ixx="100" ixy="0" ixz="0" iyy="100" iyz="0" izz="100" />
        </inertial>
        <visual>
            <origin xyz="0 0 -0.0874889622102123" rpy="0 0 0"/>
            <geometry>
                <box size="0.6774500052679646 0.05431921918827487 0.1749779244204246" />
            </geometry>
            <material name="Green">
                <color rgba="0 128 0 1"/>
            </material>
        </visual>
        <collision>
            <origin xyz="0 0 -0.0874889622102123" rpy="0 0 0"/>
            <geometry>
                <box size="0.6774500052679646 0.05431921918827487 0.1749779244204246" />
            </geometry>
        </collision>
    </link>
    <joint name="6_7" type="revolute">
       <parent link="6"/>
       <child  link="7"/>
       <origin rpy="0 0 0" xyz="0 0 -1.4372815373157222" />
     <axis xyz="1 1 1"/>
       <limit effort="0.0" lower="-3.14159" upper="3.14159" velocity="0.0"/>
    </joint>
    <link name="8">
        <inertial>
            <origin xyz="0.03277525132137876 0 0" rpy="0 0 0"/>
            <mass value="1" />
            <inertia ixx="100" ixy="0" ixz="0" iyy="100" iyz="0" izz="100" />
        </inertial>
        <visual>
            <origin xyz="0.03277525132137876 0 0" rpy="0 0 0"/>
            <geometry>
                <box size="0.06555050264275752 0.46561583293299114 0.9650532523973716" />
            </geometry>
            <material name="Green">
                <color rgba="0 128 0 1"/>
            </material>
        </visual>
        <collision>
            <origin xyz="0.03277525132137876 0 0" rpy="0 0 0"/>
            <geometry>
                <box size="0.06555050264275752 0.46561583293299114 0.9650532523973716" />
            </geometry>
        </collision>
    </link>
    <joint name="0_8" type="revolute">
       <parent link="0"/>
       <child  link="8"/>
       <origin rpy="0 0 0" xyz="0.75 0 3" />
     <axis xyz="1 1 0"/>
       <limit effort="0.0" lower="-3.14159" upper="3.14159" velocity="0.0"/>
    </joint>
    <link name="9">
        <inertial>
            <origin xyz="0.38290843918920503 0 0" rpy="0 0 0"/>
            <mass value="1" />
            <inertia ixx="100" ixy="0" ixz="0" iyy="100" iyz="0" izz="100" />
        </inertial>
        <visual>
            <origin xyz="0.38290843918920503 0 0" rpy="0 0 0"/>
            <geometry>
                <box size="0.7658168783784101 0.11639205671153352 0.9677179573141048" />
            </geometry>
            <material name="Green">
                <color rgba="0 128 0 1"/>
            </material>
        </visual>
        <collision>
            <origin xyz="0.38290843918920503 0 0" rpy="0 0 0"/>
            <geometry>
                <box size="0.7658168783784101 0.11639205671153352 0.9677179573141048" />
            </geometry>
        </collision>
    </link>
    <joint name="8_9" type="revolute">
       <parent link="8"/>
       <child  link="9"/>
       <origin rpy="0 0 0" xyz="0.06555050264275752 0 0" />
     <axis xyz="0 1 1"/>
       <limit effort="0.0" lower="-3.14159" upper="3.14159" velocity="0.0"/>
    </joint>
    <link name="10">
        <inertial>
            <origin xyz="0.14975790716184528 0 0" rpy="0 0 0"/>
            <mass value="1" />
            <inertia ixx="100" ixy="0" ixz="0" iyy="100" iyz="0" izz="100" />
        </inertial>
        <visual>
            <origin xyz="0.14975790716184528 0 0" rpy="0 0 0"/>
            <geometry>
                <box size="0.29951581432369057 0.7876011491759026 0.08388494145033909" />
            </geometry>
            <material name="Green">
                <color rgba="0 128 0 1"/>
            </material>
        </visual>
        <collision>
            <origin xyz="0.14975790716184528 0 0" rpy="0 0 0"/>
            <geometry>
                <box size="0.29951581432369057 0.7876011491759026 0.08388494145033909" />
            </geometry>
        </collision>
    </link>
    <joint name="9_10" type="revolute">
       <parent link="9"/>
       <child  link="10"/>
       <origin rpy="0 0 0" xyz="0.7658168783784101 0 0" />
     <axis xyz="0 1 1"/>
       <limit effort="0.0" lower="-3.14159" upper="3.14159" velocity="0.0"/>
    </joint>
    <link name="11">
        <inertial>
            <origin xyz="0.37872933523794405 0 0" rpy="0 0 0"/>
            <mass value="1" />
            <inertia ixx="100" ixy="0" ixz="0" iyy="100" iyz="0" izz="100" />
        </inertial>
        <visual>
            <origin xyz="0.37872933523794405 0 0" rpy="0 0 0"/>
            <geometry>
                <box size="0.7574586704758881 0.9220071990281237 0.5109422320060242" />
            </geometry>
            <material name="Blue">
                <color rgba="0 0 255 1"/>
            </material>
        </visual>
        <collision>
            <origin xyz="0.37872933523794405 0 0" rpy="0 0 0"/>
            <geometry>
                <box size="0.7574586704758881 0.9220071990281237 0.5109422320060242" />
            </geometry>
        </collision>
    </link>
    <joint name="10_11" type="revolute">
       <parent link="10"/>
       <child  link="11"/>
       <origin rpy="0 0 0" xyz="0.29951581432369057 0 0" />
     <axis xyz="1 1 1"/>
       <limit effort="0.0" lower="-3.14159" upper="3.14159" velocity="0.0"/>
    </joint>
    <link name="12">
        <inertial>
            <origin xyz="0 0 -0.5353477812322058" rpy="0 0 0"/>
            <mass value="1" />
            <inertia ixx="100" ixy="0" ixz="0" iyy="100" iyz="0" izz="100" />
        </inertial>
        <visual>
            <origin xyz="0 0 -0.5353477812322058" rpy="0 0 0"/>
            <geometry>
                <box size="0.33424065828232974 0.5512344908436688 1.0706955624644117" />
            </geometry>
            <material name="Green">
                <color rgba="0 128 0 1"/>
            </material>
        </visual>
        <collision>
            <origin xyz="0 0 -0.5353477812322058" rpy="0 0 0"/>
            <geometry>
                <box size="0.33424065828232974 0.5512344908436688 1.0706955624644117" />
            </geometry>
        </collision>
    </link>
    <joint name="11_12" type="revolute">
       <parent link="11"/>
       <child  link="12"/>
       <origin rpy="0 0 0" xyz="0.37872933523794405 0 -0.2554711160030121" />
     <axis xyz="1 0 0"/>
       <limit effort="0.0" lower="-3.14159" upper="3.14159" velocity="0.0"/>
    </joint>
    <link name="13">
        <inertial>
            <origin xyz="0 0 -0.3748646514473759" rpy="0 0 0"/>
            <mass value="1" />
            <inertia ixx="100" ixy="0" ixz="0" iyy="100" iyz="0" izz="100" />
        </inertial>
        <visual>
            <origin xyz="0 0 -0.3748646514473759" rpy="0 0 0"/>
            <geometry>
                <box size="0.15087919574329833 0.23936316918598532 0.7497293028947518" />
            </geometry>
            <material name="Blue">
                <color rgba="0 0 255 1"/>
            </material>
        </visual>
        <collision>
            <origin xyz="0 0 -0.3748646514473759" rpy="0 0 0"/>
            <geometry>
                <box size="0.15087919574329833 0.23936316918598532 0.7497293028947518" />
            </geometry>
        </collision>
    </link>
    <joint name="12_13" type="revolute">
       <parent link="12"/>
       <child  link="13"/>
       <origin rpy="0 0 0" xyz="0 0 -1.0706955624644117" />
     <axis xyz="1 0 0"/>
       <limit effort="0.0" lower="-3.14159" upper="3.14159" velocity="0.0"/>
    </joint>
    <link name="14">
        <inertial>
            <origin xyz="0 0 -0.3897875673204183" rpy="0 0 0"/>
            <mass value="1" />
            <inertia ixx="100" ixy="0" ixz="0" iyy="100" iyz="0" izz="100" />
        </inertial>
        <visual>
            <origin xyz="0 0 -0.3897875673204183" rpy="0 0 0"/>
            <geometry>
                <box size="0.709493844783923 0.4281632483200499 0.7795751346408366" />
            </geometry>
            <material name="Blue">
                <color rgba="0 0 255 1"/>
            </material>
        </visual>
        <collision>
            <origin xyz="0 0 -0.3897875673204183" rpy="0 0 0"/>
            <geometry>
                <box size="0.709493844783923 0.4281632483200499 0.7795751346408366" />
            </geometry>
        </collision>
    </link>
    <joint name="13_14" type="revolute">
       <parent link="13"/>
       <child  link="14"/>
       <origin rpy="0 0 0" xyz="0 0 -0.7497293028947518" />
     <axis xyz="0 1 1"/>
       <limit effort="0.0" lower="-3.14159" upper="3.14159" velocity="0.0"/>
    </joint>
    <link name="15">
        <inertial>
            <origin xyz="0 -0.0165185244933031 0" rpy="0 0 0"/>
            <mass value="1" />
            <inertia ixx="100" ixy="0" ixz="0" iyy="100" iyz="0" izz="100" />
        </inertial>
        <visual>
            <origin xyz="0 -0.0165185244933031 0" rpy="0 0 0"/>
            <geometry>
                <box size="0.6552215564467055 0.0330370489866062 0.5616346764206398" />
            </geometry>
            <material name="Green">
                <color rgba="0 128 0 1"/>
            </material>
        </visual>
        <collision>
            <origin xyz="0 -0.0165185244933031 0" rpy="0 0 0"/>
            <geometry>
                <box size="0.6552215564467055 0.0330370489866062 0.5616346764206398" />
            </geometry>
        </collision>
    </link>
    <joint name="0_15" type="revolute">
       <parent link="0"/>
       <child  link="15"/>
       <origin rpy="0 0 0" xyz="0 -0.75 3" />
     <axis xyz="1 0 0"/>
       <limit effort="0.0" lower="-3.14159" upper="3.14159" velocity="0.0"/>
    </joint>
    <link name="16">
        <inertial>
            <origin xyz="0 -0.22998134261990427 0" rpy="0 0 0"/>
            <mass value="1" />
            <inertia ixx="100" ixy="0" ixz="0" iyy="100" iyz="0" izz="100" />
        </inertial>
        <visual>
            <origin xyz="0 -0.22998134261990427 0" rpy="0 0 0"/>
            <geometry>
                <box size="0.9623807449036501 0.45996268523980854 0.7794538874211884" />
            </geometry>
            <material name="Green">
                <color rgba="0 128 0 1"/>
            </material>
        </visual>
        <collision>
            <origin xyz="0 -0.22998134261990427 0" rpy="0 0 0"/>
            <geometry>
                <box size="0.9623807449036501 0.45996268523980854 0.7794538874211884" />
            </geometry>
        </collision>
    </link>
    <joint name="15_16" type="revolute">
       <parent link="15"/>
       <child  link="16"/>
       <origin rpy="0 0 0" xyz="0 -0.0330370489866062 0" />
     <axis xyz="1 1 1"/>
       <limit effort="0.0" lower="-3.14159" upper="3.14159" velocity="0.0"/>
    </joint>
    <link name="17">
        <inertial>
            <origin xyz="0 -0.3154025789031194 0" rpy="0 0 0"/>
            <mass value="1" />
            <inertia ixx="100" ixy="0" ixz="0" iyy="100" iyz="0" izz="100" />
        </inertial>
        <visual>
            <origin xyz="0 -0.3154025789031194 0" rpy="0 0 0"/>
            <geometry>
                <box size="0.39783972695029635 0.6308051578062388 0.19552568353559396" />
            </geometry>
            <material name="Green">
                <color rgba="0 128 0 1"/>
            </material>
        </visual>
        <collision>
            <origin xyz="0 -0.3154025789031194 0" rpy="0 0 0"/>
            <geometry>
                <box size="0.39783972695029635 0.6308051578062388 0.19552568353559396" />
            </geometry>
        </collision>
    </link>
    <joint name="16_17" type="revolute">
       <parent link="16"/>
       <child  link="17"/>
       <origin rpy="0 0 0" xyz="0 -0.45996268523980854 0" />
     <axis xyz="1 0 0"/>
       <limit effort="0.0" lower="-3.14159" upper="3.14159" velocity="0.0"/>
    </joint>
    <link name="18">
        <inertial>
            <origin xyz="0 -0.038531101406164336 0" rpy="0 0 0"/>
            <mass value="1" />
            <inertia ixx="100" ixy="0" ixz="0" iyy="100" iyz="0" izz="100" />
        </inertial>
        <visual>
            <origin xyz="0 -0.038531101406164336 0" rpy="0 0 0"/>
            <geometry>
                <box size="0.40811967367556967 0.07706220281232867 0.7609420970609861" />
            </geometry>
            <material name="Green">
                <color rgba="0 128 0 1"/>
            </material>
        </visual>
        <collision>
            <origin xyz="0 -0.038531101406164336 0" rpy="0 0 0"/>
            <geometry>
                <box size="0.40811967367556967 0.07706220281232867 0.7609420970609861" />
            </geometry>
        </collision>
    </link>
    <joint name="17_18" type="revolute">
       <parent link="17"/>
       <child  link="18"/>
       <origin rpy="0 0 0" xyz="0 -0.6308051578062388 0" />
     <axis xyz="1 0 0"/>
       <limit effort="0.0" lower="-3.14159" upper="3.14159" velocity="0.0"/>
    </joint>
    <link name="19">
        <inertial>
            <origin xyz="0 0 -1.0640626922212841" rpy="0 0 0"/>
            <mass value="1" />
            <inertia ixx="100" ixy="0" ixz="0" iyy="100" iyz="0" izz="100" />
        </inertial>
        <visual>
            <origin xyz="0 0 -1.0640626922212841" rpy="0 0 0"/>
            <geometry>
                <box size="0.7541998106419341 0.08317687014185038 2.1281253844425683" />
            </geometry>
            <material name="Green">
                <color rgba="0 128 0 1"/>
            </material>
        </visual>
        <collision>
            <origin xyz="0 0 -1.0640626922212841" rpy="0 0 0"/>
            <geometry>
                <box size="0.7541998106419341 0.08317687014185038 2.1281253844425683" />
            </geometry>
        </collision>
    </link>
    <joint name="18_19" type="revolute">
       <parent link="18"/>
       <child  link="19"/>
       <origin rpy="0 0 0" xyz="0 -0.038531101406164336 -0.3804710485304931" />
     <axis xyz="1 1 0"/>
       <limit effort="0.0" lower="-3.14159" upper="3.14159" velocity="0.0"/>
    </joint>
    <link name="20">
        <inertial>
            <origin xyz="0 0 -0.17405684558502818" rpy="0 0 0"/>
            <mass value="1" />
            <inertia ixx="100" ixy="0" ixz="0" iyy="100" iyz="0" izz="100" />
        </inertial>
        <visual>
            <origin xyz="0 0 -0.17405684558502818" rpy="0 0 0"/>
            <geometry>
                <box size="0.6453104375199081 0.7061362661567522 0.34811369117005636" />
            </geometry>
            <material name="Blue">
                <color rgba="0 0 255 1"/>
            </material>
        </visual>
        <collision>
            <origin xyz="0 0 -0.17405684558502818" rpy="0 0 0"/>
            <geometry>
                <box size="0.6453104375199081 0.7061362661567522 0.34811369117005636" />
            </geometry>
        </collision>
    </link>
    <joint name="19_20" type="revolute">
       <parent link="19"/>
       <child  link="20"/>
       <origin rpy="0 0 0" xyz="0 0 -2.1281253844425683" />
     <axis xyz="1 1 0"/>
       <limit effort="0.0" lower="-3.14159" upper="3.14159" velocity="0.0"/>
    </joint>
    <link name="21">
        <inertial>
            <origin xyz="0 0 -0.06188046219368773" rpy="0 0 0"/>
            <mass value="1" />
            <inertia ixx="100" ixy="0" ixz="0" iyy="100" iyz="0" izz="100" />
        </inertial>
        <visual>
            <origin xyz="0 0 -0.06188046219368773" rpy="0 0 0"/>
            <geometry>
                <box size="0.17988215595901436 0.9473946182561328 0.12376092438737546" />
            </geometry>
            <material name="Green">
                <color rgba="0 128 0 1"/>
            </material>
        </visual>
        <collision>
            <origin xyz="0 0 -0.06188046219368773" rpy="0 0 0"/>
            <geometry>
                <box size="0.17988215595901436 0.9473946182561328 0.12376092438737546" />
            </geometry>
        </collision>
    </link>
    <joint name="20_21" type="revolute">
       <parent link="20"/>
       <child  link="21"/>
       <origin rpy="0 0 0" xyz="0 0 -0.34811369117005636" />
     <axis xyz="0 0 1"/>
       <limit effort="0.0" lower="-3.14159" upper="3.14159" velocity="0.0"/>
    </joint>
    <link name="22">
        <inertial>
            <origin xyz="0 0.27720538172772596 0" rpy="0 0 0"/>
            <mass value="1" />
            <inertia ixx="100" ixy="0" ixz="0" iyy="100" iyz="0" izz="100" />
        </inertial>
        <visual>
            <origin xyz="0 0.27720538172772596 0" rpy="0 0 0"/>
            <geometry>
                <box size="0.07667566645113133 0.5544107634554519 0.25264393899266757" />
            </geometry>
            <material name="Green">
                <color rgba="0 128 0 1"/>
            </material>
        </visual>
        <collision>
            <origin xyz="0 0.27720538172772596 0" rpy="0 0 0"/>
            <geometry>
                <box size="0.07667566645113133 0.5544107634554519 0.25264393899266757" />
            </geometry>
        </collision>
    </link>
    <joint name="0_22" type="revolute">
       <parent link="0"/>
       <child  link="22"/>
       <origin rpy="0 0 0" xyz="0 0.75 3" />
     <axis xyz="1 1 1"/>
       <limit effort="0.0" lower="-3.14159" upper="3.14159" velocity="0.0"/>
    </joint>
    <link name="23">
        <inertial>
            <origin xyz="0 0.07187572009567011 0" rpy="0 0 0"/>
            <mass value="1" />
            <inertia ixx="100" ixy="0" ixz="0" iyy="100" iyz="0" izz="100" />
        </inertial>
        <visual>
            <origin xyz="0 0.07187572009567011 0" rpy="0 0 0"/>
            <geometry>
                <box size="0.6480293872269002 0.14375144019134023 0.47393179914527106" />
            </geometry>
            <material name="Green">
                <color rgba="0 128 0 1"/>
            </material>
        </visual>
        <collision>
            <origin xyz="0 0.07187572009567011 0" rpy="0 0 0"/>
            <geometry>
                <box size="0.6480293872269002 0.14375144019134023 0.47393179914527106" />
            </geometry>
        </collision>
    </link>
    <joint name="22_23" type="revolute">
       <parent link="22"/>
       <child  link="23"/>
       <origin rpy="0 0 0" xyz="0 0.5544107634554519 0" />
     <axis xyz="0 1 1"/>
       <limit effort="0.0" lower="-3.14159" upper="3.14159" velocity="0.0"/>
    </joint>
    <link name="24">
        <inertial>
            <origin xyz="0 0.4629680701684928 0" rpy="0 0 0"/>
            <mass value="1" />
            <inertia ixx="100" ixy="0" ixz="0" iyy="100" iyz="0" izz="100" />
        </inertial>
        <visual>
            <origin xyz="0 0.4629680701684928 0" rpy="0 0 0"/>
            <geometry>
                <box size="0.328340513458208 0.9259361403369856 0.12934422394556055" />
            </geometry>
            <material name="Green">
                <color rgba="0 128 0 1"/>
            </material>
        </visual>
        <collision>
            <origin xyz="0 0.4629680701684928 0" rpy="0 0 0"/>
            <geometry>
                <box size="0.328340513458208 0.9259361403369856 0.12934422394556055" />
            </geometry>
        </collision>
    </link>
    <joint name="23_24" type="revolute">
       <parent link="23"/>
       <child  link="24"/>
       <origin rpy="0 0 0" xyz="0 0.14375144019134023 0" />
     <axis xyz="0 1 1"/>
       <limit effort="0.0" lower="-3.14159" upper="3.14159" velocity="0.0"/>
    </joint>
    <link name="25">
        <inertial>
            <origin xyz="0 0.27007407624495705 0" rpy="0 0 0"/>
            <mass value="1" />
            <inertia ixx="100" ixy="0" ixz="0" iyy="100" iyz="0" izz="100" />
        </inertial>
        <visual>
            <origin xyz="0 0.27007407624495705 0" rpy="0 0 0"/>
            <geometry>
                <box size="0.38065691048811867 0.5401481524899141 0.2895666302663469" />
            </geometry>
            <material name="Green">
                <color rgba="0 128 0 1"/>
            </material>
        </visual>
        <collision>
            <origin xyz="0 0.27007407624495705 0" rpy="0 0 0"/>
            <geometry>
                <box size="0.38065691048811867 0.5401481524899141 0.2895666302663469" />
            </geometry>
        </collision>
    </link>
    <joint name="24_25" type="revolute">
       <parent link="24"/>
       <child  link="25"/>
       <origin rpy="0 0 0" xyz="0 0.9259361403369856 0" />
     <axis xyz="1 1 1"/>
       <limit effort="0.0" lower="-3.14159" upper="3.14159" velocity="0.0"/>
    </joint>
    <link name="26">
        <inertial>
            <origin xyz="0 0 -0.7661039838703697" rpy="0 0 0"/>
            <mass value="1" />
            <inertia ixx="100" ixy="0" ixz="0" iyy="100" iyz="0" izz="100" />
        </inertial>
        <visual>
            <origin xyz="0 0 -0.7661039838703697" rpy="0 0 0"/>
            <geometry>
                <box size="0.6963784285440066 0.42271506719240637 1.5322079677407394" />
            </geometry>
            <material name="Blue">
                <color rgba="0 0 255 1"/>
            </material>
        </visual>
        <collision>
            <origin xyz="0 0 -0.7661039838703697" rpy="0 0 0"/>
            <geometry>
                <box size="0.6963784285440066 0.42271506719240637 1.5322079677407394" />
            </geometry>
        </collision>
    </link>
    <joint name="25_26" type="revolute">
       <parent link="25"/>
       <child  link="26"/>
       <origin rpy="0 0 0" xyz="0 0.27007407624495705 -0.14478331513317344" />
     <axis xyz="1 0 0"/>
       <limit effort="0.0" lower="-3.14159" upper="3.14159" velocity="0.0"/>
    </joint>
    <link name="27">
        <inertial>
            <origin xyz="0 0 -0.23856230889962496" rpy="0 0 0"/>
            <mass value="1" />
            <inertia ixx="100" ixy="0" ixz="0" iyy="100" iyz="0" izz="100" />
        </inertial>
        <visual>
            <origin xyz="0 0 -0.23856230889962496" rpy="0 0 0"/>
            <geometry>
                <box size="0.5293296737283341 0.004527627813013524 0.4771246177992499" />
            </geometry>
            <material name="Green">
                <color rgba="0 128 0 1"/>
            </material>
        </visual>
        <collision>
            <origin xyz="0 0 -0.23856230889962496" rpy="0 0 0"/>
            <geometry>
                <box size="0.5293296737283341 0.004527627813013524 0.4771246177992499" />
            </geometry>
        </collision>
    </link>
    <joint name="26_27" type="revolute">
       <parent link="26"/>
       <child  link="27"/>
       <origin rpy="0 0 0" xyz="0 0 -1.5322079677407394" />
     <axis xyz="1 1 0"/>
       <limit effort="0.0" lower="-3.14159" upper="3.14159" velocity="0.0"/>
    </joint>
    <link name="28">
        <inertial>
            <origin xyz="0 0 -0.2953337072300054" rpy="0 0 0"/>
            <mass value="1" />
            <inertia ixx="100" ixy="0" ixz="0" iyy="100" iyz="0" izz="100" />
        </inertial>
        <visual>
            <origin xyz="0 0 -0.2953337072300054" rpy="0 0 0"/>
            <geometry>
                <box size="0.0789596538415901 0.34370231707249566 0.5906674144600108" />
            </geometry>
            <material name="Blue">
                <color rgba="0 0 255 1"/>
            </material>
        </visual>
        <collision>
            <origin xyz="0 0 -0.2953337072300054" rpy="0 0 0"/>
            <geometry>
                <box size="0.0789596538415901 0.34370231707249566 0.5906674144600108" />
            </geometry>
        </collision>
    </link>
    <joint name="27_28" type="revolute">
       <parent link="27"/>
       <child  link="28"/>
       <origin rpy="0 0 0" xyz="0 0 -0.4771246177992499" />
     <axis xyz="1 0 1"/>
       <limit effort="0.0" lower="-3.14159" upper="3.14159" velocity="0.0"/>
    </joint>
</robot>