<robot name = "robot">
    <link name="0">
        <inertial>
            <origin xyz="0 0 0.6752656368756875" rpy="0 0 0"/>
            <mass value="1" />
            <inertia ixx="100" ixy="0" ixz="0" iyy="100" iyz="0" izz="100" />
        </inertial>
        <visual>
            <origin xyz="0 0 0.6752656368756875" rpy="0 0 0"/>
            <geometry>
                <box size="0.7076150161126878 0.9248518381471135 1.350531273751375" />
            </geometry>
            <material name="Blue">
                <color rgba="0 0 255 1"/>
            </material>
        </visual>
        <collision>
            <origin xyz="0 0 0.6752656368756875" rpy="0 0 0"/>
            <geometry>
                <box size="0.7076150161126878 0.9248518381471135 1.350531273751375" />
            </geometry>
        </collision>
    </link>
    <link name="1">
        <inertial>
            <origin xyz="0 0 0.411786111193899" rpy="0 0 0"/>
            <mass value="1" />
            <inertia ixx="100" ixy="0" ixz="0" iyy="100" iyz="0" izz="100" />
        </inertial>
        <visual>
            <origin xyz="0 0 0.411786111193899" rpy="0 0 0"/>
            <geometry>
                <box size="1.1411104296832333 1.028721452066596 0.823572222387798" />
            </geometry>
            <material name="Green">
                <color rgba="0 128 0 1"/>
            </material>
        </visual>
        <collision>
            <origin xyz="0 0 0.411786111193899" rpy="0 0 0"/>
            <geometry>
                <box size="1.1411104296832333 1.028721452066596 0.823572222387798" />
            </geometry>
        </collision>
    </link>
    <joint name="0_1" type="revolute">
       <parent link="0"/>
       <child  link="1"/>
       <origin rpy="0 0 0" xyz="0 0 1.350531273751375" />
     <axis xyz="0 1 0"/>
       <limit effort="0.0" lower="-3.14159" upper="3.14159" velocity="0.0"/>
    </joint>
    <link name="2">
        <inertial>
            <origin xyz="0 0 0.42547876754093134" rpy="0 0 0"/>
            <mass value="1" />
            <inertia ixx="100" ixy="0" ixz="0" iyy="100" iyz="0" izz="100" />
        </inertial>
        <visual>
            <origin xyz="0 0 0.42547876754093134" rpy="0 0 0"/>
            <geometry>
                <box size="1.2736354375643026 0.9937975925921008 0.8509575350818627" />
            </geometry>
            <material name="Green">
                <color rgba="0 128 0 1"/>
            </material>
        </visual>
        <collision>
            <origin xyz="0 0 0.42547876754093134" rpy="0 0 0"/>
            <geometry>
                <box size="1.2736354375643026 0.9937975925921008 0.8509575350818627" />
            </geometry>
        </collision>
    </link>
    <joint name="1_2" type="revolute">
       <parent link="1"/>
       <child  link="2"/>
       <origin rpy="0 0 0" xyz="0 0 0.823572222387798" />
     <axis xyz="1 0 1"/>
       <limit effort="0.0" lower="-3.14159" upper="3.14159" velocity="0.0"/>
    </joint>
    <link name="3">
        <inertial>
            <origin xyz="-0.43632121671765994 0 0.35867341686844173" rpy="0 0 0"/>
            <mass value="1" />
            <inertia ixx="100" ixy="0" ixz="0" iyy="100" iyz="0" izz="100" />
        </inertial>
        <visual>
            <origin xyz="-0.43632121671765994 0 0.35867341686844173" rpy="0 0 0"/>
            <geometry>
                <box size="0.8726424334353199 1.3834792242716658 0.7173468337368835" />
            </geometry>
            <material name="Blue">
                <color rgba="0 0 255 1"/>
            </material>
        </visual>
        <collision>
            <origin xyz="-0.43632121671765994 0 0.35867341686844173" rpy="0 0 0"/>
            <geometry>
                <box size="0.8726424334353199 1.3834792242716658 0.7173468337368835" />
            </geometry>
        </collision>
    </link>
    <joint name="2_3" type="revolute">
       <parent link="2"/>
       <child  link="3"/>
       <origin rpy="0 0 0" xyz="-0.6368177187821513 0 0" />
     <axis xyz="1 1 0"/>
       <limit effort="0.0" lower="-3.14159" upper="3.14159" velocity="0.0"/>
    </joint>
    <link name="4">
        <inertial>
            <origin xyz="-0.43960612625036316 0 0.506469255375749" rpy="0 0 0"/>
            <mass value="1" />
            <inertia ixx="100" ixy="0" ixz="0" iyy="100" iyz="0" izz="100" />
        </inertial>
        <visual>
            <origin xyz="-0.43960612625036316 0 0.506469255375749" rpy="0 0 0"/>
            <geometry>
                <box size="0.8792122525007263 0.7458414268282468 1.012938510751498" />
            </geometry>
            <material name="Green">
                <color rgba="0 128 0 1"/>
            </material>
        </visual>
        <collision>
            <origin xyz="-0.43960612625036316 0 0.506469255375749" rpy="0 0 0"/>
            <geometry>
                <box size="0.8792122525007263 0.7458414268282468 1.012938510751498" />
            </geometry>
        </collision>
    </link>
    <joint name="3_4" type="revolute">
       <parent link="3"/>
       <child  link="4"/>
       <origin rpy="0 0 0" xyz="-0.8726424334353199 0 0" />
     <axis xyz="0 1 1"/>
       <limit effort="0.0" lower="-3.14159" upper="3.14159" velocity="0.0"/>
    </joint>
    <link name="5">
        <inertial>
            <origin xyz="-0.5299796930945635 0 0.7323380512816026" rpy="0 0 0"/>
            <mass value="1" />
            <inertia ixx="100" ixy="0" ixz="0" iyy="100" iyz="0" izz="100" />
        </inertial>
        <visual>
            <origin xyz="-0.5299796930945635 0 0.7323380512816026" rpy="0 0 0"/>
            <geometry>
                <box size="1.059959386189127 1.2344399884280888 1.4646761025632051" />
            </geometry>
            <material name="Green">
                <color rgba="0 128 0 1"/>
            </material>
        </visual>
        <collision>
            <origin xyz="-0.5299796930945635 0 0.7323380512816026" rpy="0 0 0"/>
            <geometry>
                <box size="1.059959386189127 1.2344399884280888 1.4646761025632051" />
            </geometry>
        </collision>
    </link>
    <joint name="4_5" type="revolute">
       <parent link="4"/>
       <child  link="5"/>
       <origin rpy="0 0 0" xyz="-0.8792122525007263 0 0" />
     <axis xyz="1 1 0"/>
       <limit effort="0.0" lower="-3.14159" upper="3.14159" velocity="0.0"/>
    </joint>
    <link name="6">
        <inertial>
            <origin xyz="-0.4555526360496628 0 0.4810434579015324" rpy="0 0 0"/>
            <mass value="1" />
            <inertia ixx="100" ixy="0" ixz="0" iyy="100" iyz="0" izz="100" />
        </inertial>
        <visual>
            <origin xyz="-0.4555526360496628 0 0.4810434579015324" rpy="0 0 0"/>
            <geometry>
                <box size="0.9111052720993256 1.4693220827995903 0.9620869158030648" />
            </geometry>
            <material name="Blue">
                <color rgba="0 0 255 1"/>
            </material>
        </visual>
        <collision>
            <origin xyz="-0.4555526360496628 0 0.4810434579015324" rpy="0 0 0"/>
            <geometry>
                <box size="0.9111052720993256 1.4693220827995903 0.9620869158030648" />
            </geometry>
        </collision>
    </link>
    <joint name="5_6" type="revolute">
       <parent link="5"/>
       <child  link="6"/>
       <origin rpy="0 0 0" xyz="-1.059959386189127 0 0" />
     <axis xyz="1 0 0"/>
       <limit effort="0.0" lower="-3.14159" upper="3.14159" velocity="0.0"/>
    </joint>
    <link name="7">
        <inertial>
            <origin xyz="-0.3758196073230336 0 0.2763962306753345" rpy="0 0 0"/>
            <mass value="1" />
            <inertia ixx="100" ixy="0" ixz="0" iyy="100" iyz="0" izz="100" />
        </inertial>
        <visual>
            <origin xyz="-0.3758196073230336 0 0.2763962306753345" rpy="0 0 0"/>
            <geometry>
                <box size="0.7516392146460672 0.8924179468711169 0.552792461350669" />
            </geometry>
            <material name="Green">
                <color rgba="0 128 0 1"/>
            </material>
        </visual>
        <collision>
            <origin xyz="-0.3758196073230336 0 0.2763962306753345" rpy="0 0 0"/>
            <geometry>
                <box size="0.7516392146460672 0.8924179468711169 0.552792461350669" />
            </geometry>
        </collision>
    </link>
    <joint name="6_7" type="revolute">
       <parent link="6"/>
       <child  link="7"/>
       <origin rpy="0 0 0" xyz="-0.9111052720993256 0 0" />
     <axis xyz="0 1 1"/>
       <limit effort="0.0" lower="-3.14159" upper="3.14159" velocity="0.0"/>
    </joint>
    <link name="8">
        <inertial>
            <origin xyz="-0.3172600253816215 0 0.5781526372332784" rpy="0 0 0"/>
            <mass value="1" />
            <inertia ixx="100" ixy="0" ixz="0" iyy="100" iyz="0" izz="100" />
        </inertial>
        <visual>
            <origin xyz="-0.3172600253816215 0 0.5781526372332784" rpy="0 0 0"/>
            <geometry>
                <box size="0.634520050763243 1.277925855840995 1.1563052744665567" />
            </geometry>
            <material name="Green">
                <color rgba="0 128 0 1"/>
            </material>
        </visual>
        <collision>
            <origin xyz="-0.3172600253816215 0 0.5781526372332784" rpy="0 0 0"/>
            <geometry>
                <box size="0.634520050763243 1.277925855840995 1.1563052744665567" />
            </geometry>
        </collision>
    </link>
    <joint name="7_8" type="revolute">
       <parent link="7"/>
       <child  link="8"/>
       <origin rpy="0 0 0" xyz="-0.7516392146460672 0 0" />
     <axis xyz="1 1 1"/>
       <limit effort="0.0" lower="-3.14159" upper="3.14159" velocity="0.0"/>
    </joint>
    <link name="9">
        <inertial>
            <origin xyz="-0.7487899701879783 0 0.5997460032114288" rpy="0 0 0"/>
            <mass value="1" />
            <inertia ixx="100" ixy="0" ixz="0" iyy="100" iyz="0" izz="100" />
        </inertial>
        <visual>
            <origin xyz="-0.7487899701879783 0 0.5997460032114288" rpy="0 0 0"/>
            <geometry>
                <box size="1.4975799403759567 1.3492935353538433 1.1994920064228576" />
            </geometry>
            <material name="Blue">
                <color rgba="0 0 255 1"/>
            </material>
        </visual>
        <collision>
            <origin xyz="-0.7487899701879783 0 0.5997460032114288" rpy="0 0 0"/>
            <geometry>
                <box size="1.4975799403759567 1.3492935353538433 1.1994920064228576" />
            </geometry>
        </collision>
    </link>
    <joint name="8_9" type="revolute">
       <parent link="8"/>
       <child  link="9"/>
       <origin rpy="0 0 0" xyz="-0.634520050763243 0 0" />
     <axis xyz="0 1 0"/>
       <limit effort="0.0" lower="-3.14159" upper="3.14159" velocity="0.0"/>
    </joint>
    <link name="10">
        <inertial>
            <origin xyz="0 0 -0.629036288249445" rpy="0 0 0"/>
            <mass value="1" />
            <inertia ixx="100" ixy="0" ixz="0" iyy="100" iyz="0" izz="100" />
        </inertial>
        <visual>
            <origin xyz="0 0 -0.629036288249445" rpy="0 0 0"/>
            <geometry>
                <box size="0.5595429646841986 1.317215727995248 1.25807257649889" />
            </geometry>
            <material name="Blue">
                <color rgba="0 0 255 1"/>
            </material>
        </visual>
        <collision>
            <origin xyz="0 0 -0.629036288249445" rpy="0 0 0"/>
            <geometry>
                <box size="0.5595429646841986 1.317215727995248 1.25807257649889" />
            </geometry>
        </collision>
    </link>
    <joint name="9_10" type="revolute">
       <parent link="9"/>
       <child  link="10"/>
       <origin rpy="0 0 0" xyz="-0.7487899701879783 0 0" />
     <axis xyz="0 1 0"/>
       <limit effort="0.0" lower="-3.14159" upper="3.14159" velocity="0.0"/>
    </joint>
    <link name="11">
        <inertial>
            <origin xyz="0 0 -1.0635928318747634" rpy="0 0 0"/>
            <mass value="1" />
            <inertia ixx="100" ixy="0" ixz="0" iyy="100" iyz="0" izz="100" />
        </inertial>
        <visual>
            <origin xyz="0 0 -1.0635928318747634" rpy="0 0 0"/>
            <geometry>
                <box size="0.5956888637331949 0.8758024137737881 2.127185663749527" />
            </geometry>
            <material name="Green">
                <color rgba="0 128 0 1"/>
            </material>
        </visual>
        <collision>
            <origin xyz="0 0 -1.0635928318747634" rpy="0 0 0"/>
            <geometry>
                <box size="0.5956888637331949 0.8758024137737881 2.127185663749527" />
            </geometry>
        </collision>
    </link>
    <joint name="10_11" type="revolute">
       <parent link="10"/>
       <child  link="11"/>
       <origin rpy="0 0 0" xyz="0 0 -1.25807257649889" />
     <axis xyz="1 0 0"/>
       <limit effort="0.0" lower="-3.14159" upper="3.14159" velocity="0.0"/>
    </joint>
    <link name="12">
        <inertial>
            <origin xyz="0 0 -0.09463149610532606" rpy="0 0 0"/>
            <mass value="1" />
            <inertia ixx="100" ixy="0" ixz="0" iyy="100" iyz="0" izz="100" />
        </inertial>
        <visual>
            <origin xyz="0 0 -0.09463149610532606" rpy="0 0 0"/>
            <geometry>
                <box size="1.047224552960359 0.829357552581479 0.18926299221065213" />
            </geometry>
            <material name="Green">
                <color rgba="0 128 0 1"/>
            </material>
        </visual>
        <collision>
            <origin xyz="0 0 -0.09463149610532606" rpy="0 0 0"/>
            <geometry>
                <box size="1.047224552960359 0.829357552581479 0.18926299221065213" />
            </geometry>
        </collision>
    </link>
    <joint name="11_12" type="revolute">
       <parent link="11"/>
       <child  link="12"/>
       <origin rpy="0 0 0" xyz="0 0 -2.127185663749527" />
     <axis xyz="1 1 0"/>
       <limit effort="0.0" lower="-3.14159" upper="3.14159" velocity="0.0"/>
    </joint>
    <link name="13">
        <inertial>
            <origin xyz="0.5489441277702773 0 0.7378590105110222" rpy="0 0 0"/>
            <mass value="1" />
            <inertia ixx="100" ixy="0" ixz="0" iyy="100" iyz="0" izz="100" />
        </inertial>
        <visual>
            <origin xyz="0.5489441277702773 0 0.7378590105110222" rpy="0 0 0"/>
            <geometry>
                <box size="1.0978882555405547 0.9306652485452828 1.4757180210220444" />
            </geometry>
            <material name="Green">
                <color rgba="0 128 0 1"/>
            </material>
        </visual>
        <collision>
            <origin xyz="0.5489441277702773 0 0.7378590105110222" rpy="0 0 0"/>
            <geometry>
                <box size="1.0978882555405547 0.9306652485452828 1.4757180210220444" />
            </geometry>
        </collision>
    </link>
    <joint name="2_13" type="revolute">
       <parent link="2"/>
       <child  link="13"/>
       <origin rpy="0 0 0" xyz="0.6368177187821513 0 0" />
     <axis xyz="1 1 0"/>
       <limit effort="0.0" lower="-3.14159" upper="3.14159" velocity="0.0"/>
    </joint>
    <link name="14">
        <inertial>
            <origin xyz="0.6679551332846739 0 0.27836630313492494" rpy="0 0 0"/>
            <mass value="1" />
            <inertia ixx="100" ixy="0" ixz="0" iyy="100" iyz="0" izz="100" />
        </inertial>
        <visual>
            <origin xyz="0.6679551332846739 0 0.27836630313492494" rpy="0 0 0"/>
            <geometry>
                <box size="1.3359102665693479 1.4144885784486 0.5567326062698499" />
            </geometry>
            <material name="Green">
                <color rgba="0 128 0 1"/>
            </material>
        </visual>
        <collision>
            <origin xyz="0.6679551332846739 0 0.27836630313492494" rpy="0 0 0"/>
            <geometry>
                <box size="1.3359102665693479 1.4144885784486 0.5567326062698499" />
            </geometry>
        </collision>
    </link>
    <joint name="13_14" type="revolute">
       <parent link="13"/>
       <child  link="14"/>
       <origin rpy="0 0 0" xyz="1.0978882555405547 0 0" />
     <axis xyz="0 1 1"/>
       <limit effort="0.0" lower="-3.14159" upper="3.14159" velocity="0.0"/>
    </joint>
    <link name="15">
        <inertial>
            <origin xyz="0.44323604317792115 0 0.4722769370624805" rpy="0 0 0"/>
            <mass value="1" />
            <inertia ixx="100" ixy="0" ixz="0" iyy="100" iyz="0" izz="100" />
        </inertial>
        <visual>
            <origin xyz="0.44323604317792115 0 0.4722769370624805" rpy="0 0 0"/>
            <geometry>
                <box size="0.8864720863558423 0.8238353411628363 0.944553874124961" />
            </geometry>
            <material name="Green">
                <color rgba="0 128 0 1"/>
            </material>
        </visual>
        <collision>
            <origin xyz="0.44323604317792115 0 0.4722769370624805" rpy="0 0 0"/>
            <geometry>
                <box size="0.8864720863558423 0.8238353411628363 0.944553874124961" />
            </geometry>
        </collision>
    </link>
    <joint name="14_15" type="revolute">
       <parent link="14"/>
       <child  link="15"/>
       <origin rpy="0 0 0" xyz="1.3359102665693479 0 0" />
     <axis xyz="1 1 1"/>
       <limit effort="0.0" lower="-3.14159" upper="3.14159" velocity="0.0"/>
    </joint>
    <link name="16">
        <inertial>
            <origin xyz="0.5027384246222899 0 0.400147996823727" rpy="0 0 0"/>
            <mass value="1" />
            <inertia ixx="100" ixy="0" ixz="0" iyy="100" iyz="0" izz="100" />
        </inertial>
        <visual>
            <origin xyz="0.5027384246222899 0 0.400147996823727" rpy="0 0 0"/>
            <geometry>
                <box size="1.0054768492445798 0.9788143653878859 0.800295993647454" />
            </geometry>
            <material name="Green">
                <color rgba="0 128 0 1"/>
            </material>
        </visual>
        <collision>
            <origin xyz="0.5027384246222899 0 0.400147996823727" rpy="0 0 0"/>
            <geometry>
                <box size="1.0054768492445798 0.9788143653878859 0.800295993647454" />
            </geometry>
        </collision>
    </link>
    <joint name="15_16" type="revolute">
       <parent link="15"/>
       <child  link="16"/>
       <origin rpy="0 0 0" xyz="0.8864720863558423 0 0" />
     <axis xyz="0 1 1"/>
       <limit effort="0.0" lower="-3.14159" upper="3.14159" velocity="0.0"/>
    </joint>
    <link name="17">
        <inertial>
            <origin xyz="0.5659017143031109 0 0.25269160468165724" rpy="0 0 0"/>
            <mass value="1" />
            <inertia ixx="100" ixy="0" ixz="0" iyy="100" iyz="0" izz="100" />
        </inertial>
        <visual>
            <origin xyz="0.5659017143031109 0 0.25269160468165724" rpy="0 0 0"/>
            <geometry>
                <box size="1.1318034286062217 0.929107545504162 0.5053832093633145" />
            </geometry>
            <material name="Green">
                <color rgba="0 128 0 1"/>
            </material>
        </visual>
        <collision>
            <origin xyz="0.5659017143031109 0 0.25269160468165724" rpy="0 0 0"/>
            <geometry>
                <box size="1.1318034286062217 0.929107545504162 0.5053832093633145" />
            </geometry>
        </collision>
    </link>
    <joint name="16_17" type="revolute">
       <parent link="16"/>
       <child  link="17"/>
       <origin rpy="0 0 0" xyz="1.0054768492445798 0 0" />
     <axis xyz="1 1 0"/>
       <limit effort="0.0" lower="-3.14159" upper="3.14159" velocity="0.0"/>
    </joint>
    <link name="18">
        <inertial>
            <origin xyz="0.7037241389934326 0 0.44492445161860655" rpy="0 0 0"/>
            <mass value="1" />
            <inertia ixx="100" ixy="0" ixz="0" iyy="100" iyz="0" izz="100" />
        </inertial>
        <visual>
            <origin xyz="0.7037241389934326 0 0.44492445161860655" rpy="0 0 0"/>
            <geometry>
                <box size="1.4074482779868651 0.90104613971942 0.8898489032372131" />
            </geometry>
            <material name="Green">
                <color rgba="0 128 0 1"/>
            </material>
        </visual>
        <collision>
            <origin xyz="0.7037241389934326 0 0.44492445161860655" rpy="0 0 0"/>
            <geometry>
                <box size="1.4074482779868651 0.90104613971942 0.8898489032372131" />
            </geometry>
        </collision>
    </link>
    <joint name="17_18" type="revolute">
       <parent link="17"/>
       <child  link="18"/>
       <origin rpy="0 0 0" xyz="1.1318034286062217 0 0" />
     <axis xyz="0 1 0"/>
       <limit effort="0.0" lower="-3.14159" upper="3.14159" velocity="0.0"/>
    </joint>
    <link name="19">
        <inertial>
            <origin xyz="0.6878140545359273 0 0.6568713232131627" rpy="0 0 0"/>
            <mass value="1" />
            <inertia ixx="100" ixy="0" ixz="0" iyy="100" iyz="0" izz="100" />
        </inertial>
        <visual>
            <origin xyz="0.6878140545359273 0 0.6568713232131627" rpy="0 0 0"/>
            <geometry>
                <box size="1.3756281090718545 0.5539755627232384 1.3137426464263253" />
            </geometry>
            <material name="Blue">
                <color rgba="0 0 255 1"/>
            </material>
        </visual>
        <collision>
            <origin xyz="0.6878140545359273 0 0.6568713232131627" rpy="0 0 0"/>
            <geometry>
                <box size="1.3756281090718545 0.5539755627232384 1.3137426464263253" />
            </geometry>
        </collision>
    </link>
    <joint name="18_19" type="revolute">
       <parent link="18"/>
       <child  link="19"/>
       <origin rpy="0 0 0" xyz="1.4074482779868651 0 0" />
     <axis xyz="1 1 1"/>
       <limit effort="0.0" lower="-3.14159" upper="3.14159" velocity="0.0"/>
    </joint>
    <link name="20">
        <inertial>
            <origin xyz="0 0 -1.2955783276227928" rpy="0 0 0"/>
            <mass value="1" />
            <inertia ixx="100" ixy="0" ixz="0" iyy="100" iyz="0" izz="100" />
        </inertial>
        <visual>
            <origin xyz="0 0 -1.2955783276227928" rpy="0 0 0"/>
            <geometry>
                <box size="1.0513972780265213 0.7283938616558222 2.5911566552455856" />
            </geometry>
            <material name="Green">
                <color rgba="0 128 0 1"/>
            </material>
        </visual>
        <collision>
            <origin xyz="0 0 -1.2955783276227928" rpy="0 0 0"/>
            <geometry>
                <box size="1.0513972780265213 0.7283938616558222 2.5911566552455856" />
            </geometry>
        </collision>
    </link>
    <joint name="19_20" type="revolute">
       <parent link="19"/>
       <child  link="20"/>
       <origin rpy="0 0 0" xyz="0.6878140545359273 0 0" />
     <axis xyz="0 0 1"/>
       <limit effort="0.0" lower="-3.14159" upper="3.14159" velocity="0.0"/>
    </joint>
    <link name="21">
        <inertial>
            <origin xyz="0 0 -0.19214122068226133" rpy="0 0 0"/>
            <mass value="1" />
            <inertia ixx="100" ixy="0" ixz="0" iyy="100" iyz="0" izz="100" />
        </inertial>
        <visual>
            <origin xyz="0 0 -0.19214122068226133" rpy="0 0 0"/>
            <geometry>
                <box size="0.7925243572689745 0.8055887555365716 0.38428244136452266" />
            </geometry>
            <material name="Green">
                <color rgba="0 128 0 1"/>
            </material>
        </visual>
        <collision>
            <origin xyz="0 0 -0.19214122068226133" rpy="0 0 0"/>
            <geometry>
                <box size="0.7925243572689745 0.8055887555365716 0.38428244136452266" />
            </geometry>
        </collision>
    </link>
    <joint name="20_21" type="revolute">
       <parent link="20"/>
       <child  link="21"/>
       <origin rpy="0 0 0" xyz="0 0 -2.5911566552455856" />
     <axis xyz="0 1 0"/>
       <limit effort="0.0" lower="-3.14159" upper="3.14159" velocity="0.0"/>
    </joint>
    <link name="22">
        <inertial>
            <origin xyz="0 0 -0.2995410679244802" rpy="0 0 0"/>
            <mass value="1" />
            <inertia ixx="100" ixy="0" ixz="0" iyy="100" iyz="0" izz="100" />
        </inertial>
        <visual>
            <origin xyz="0 0 -0.2995410679244802" rpy="0 0 0"/>
            <geometry>
                <box size="0.8948231458259773 1.252903960785987 0.5990821358489604" />
            </geometry>
            <material name="Green">
                <color rgba="0 128 0 1"/>
            </material>
        </visual>
        <collision>
            <origin xyz="0 0 -0.2995410679244802" rpy="0 0 0"/>
            <geometry>
                <box size="0.8948231458259773 1.252903960785987 0.5990821358489604" />
            </geometry>
        </collision>
    </link>
    <joint name="21_22" type="revolute">
       <parent link="21"/>
       <child  link="22"/>
       <origin rpy="0 0 0" xyz="0 0 -0.38428244136452266" />
     <axis xyz="1 1 0"/>
       <limit effort="0.0" lower="-3.14159" upper="3.14159" velocity="0.0"/>
    </joint>
    <link name="23">
        <inertial>
            <origin xyz="0 -0.2865271249571672 0.5019630360217004" rpy="0 0 0"/>
            <mass value="1" />
            <inertia ixx="100" ixy="0" ixz="0" iyy="100" iyz="0" izz="100" />
        </inertial>
        <visual>
            <origin xyz="0 -0.2865271249571672 0.5019630360217004" rpy="0 0 0"/>
            <geometry>
                <box size="1.0317714381685033 0.5730542499143344 1.003926072043401" />
            </geometry>
            <material name="Green">
                <color rgba="0 128 0 1"/>
            </material>
        </visual>
        <collision>
            <origin xyz="0 -0.2865271249571672 0.5019630360217004" rpy="0 0 0"/>
            <geometry>
                <box size="1.0317714381685033 0.5730542499143344 1.003926072043401" />
            </geometry>
        </collision>
    </link>
    <joint name="2_23" type="revolute">
       <parent link="2"/>
       <child  link="23"/>
       <origin rpy="0 0 0" xyz="0 -0.4968987962960504 0" />
     <axis xyz="0 1 0"/>
       <limit effort="0.0" lower="-3.14159" upper="3.14159" velocity="0.0"/>
    </joint>
    <link name="24">
        <inertial>
            <origin xyz="0 -0.739896013055539 0.6159931058894594" rpy="0 0 0"/>
            <mass value="1" />
            <inertia ixx="100" ixy="0" ixz="0" iyy="100" iyz="0" izz="100" />
        </inertial>
        <visual>
            <origin xyz="0 -0.739896013055539 0.6159931058894594" rpy="0 0 0"/>
            <geometry>
                <box size="0.5746934263671625 1.479792026111078 1.2319862117789189" />
            </geometry>
            <material name="Green">
                <color rgba="0 128 0 1"/>
            </material>
        </visual>
        <collision>
            <origin xyz="0 -0.739896013055539 0.6159931058894594" rpy="0 0 0"/>
            <geometry>
                <box size="0.5746934263671625 1.479792026111078 1.2319862117789189" />
            </geometry>
        </collision>
    </link>
    <joint name="23_24" type="revolute">
       <parent link="23"/>
       <child  link="24"/>
       <origin rpy="0 0 0" xyz="0 -0.5730542499143344 0" />
     <axis xyz="0 1 0"/>
       <limit effort="0.0" lower="-3.14159" upper="3.14159" velocity="0.0"/>
    </joint>
    <link name="25">
        <inertial>
            <origin xyz="0 -0.4313736217287512 0.49488582834188977" rpy="0 0 0"/>
            <mass value="1" />
            <inertia ixx="100" ixy="0" ixz="0" iyy="100" iyz="0" izz="100" />
        </inertial>
        <visual>
            <origin xyz="0 -0.4313736217287512 0.49488582834188977" rpy="0 0 0"/>
            <geometry>
                <box size="0.7285963859979327 0.8627472434575024 0.9897716566837795" />
            </geometry>
            <material name="Blue">
                <color rgba="0 0 255 1"/>
            </material>
        </visual>
        <collision>
            <origin xyz="0 -0.4313736217287512 0.49488582834188977" rpy="0 0 0"/>
            <geometry>
                <box size="0.7285963859979327 0.8627472434575024 0.9897716566837795" />
            </geometry>
        </collision>
    </link>
    <joint name="24_25" type="revolute">
       <parent link="24"/>
       <child  link="25"/>
       <origin rpy="0 0 0" xyz="0 -1.479792026111078 0" />
     <axis xyz="1 0 0"/>
       <limit effort="0.0" lower="-3.14159" upper="3.14159" velocity="0.0"/>
    </joint>
    <link name="26">
        <inertial>
            <origin xyz="0 -0.30404238350271484 0.5393360256871536" rpy="0 0 0"/>
            <mass value="1" />
            <inertia ixx="100" ixy="0" ixz="0" iyy="100" iyz="0" izz="100" />
        </inertial>
        <visual>
            <origin xyz="0 -0.30404238350271484 0.5393360256871536" rpy="0 0 0"/>
            <geometry>
                <box size="1.2389365453173342 0.6080847670054297 1.078672051374307" />
            </geometry>
            <material name="Green">
                <color rgba="0 128 0 1"/>
            </material>
        </visual>
        <collision>
            <origin xyz="0 -0.30404238350271484 0.5393360256871536" rpy="0 0 0"/>
            <geometry>
                <box size="1.2389365453173342 0.6080847670054297 1.078672051374307" />
            </geometry>
        </collision>
    </link>
    <joint name="25_26" type="revolute">
       <parent link="25"/>
       <child  link="26"/>
       <origin rpy="0 0 0" xyz="0 -0.8627472434575024 0" />
     <axis xyz="0 1 0"/>
       <limit effort="0.0" lower="-3.14159" upper="3.14159" velocity="0.0"/>
    </joint>
    <link name="27">
        <inertial>
            <origin xyz="0 -0.5173450856763626 0.6300653501842866" rpy="0 0 0"/>
            <mass value="1" />
            <inertia ixx="100" ixy="0" ixz="0" iyy="100" iyz="0" izz="100" />
        </inertial>
        <visual>
            <origin xyz="0 -0.5173450856763626 0.6300653501842866" rpy="0 0 0"/>
            <geometry>
                <box size="0.9027186019964868 1.0346901713527252 1.260130700368573" />
            </geometry>
            <material name="Green">
                <color rgba="0 128 0 1"/>
            </material>
        </visual>
        <collision>
            <origin xyz="0 -0.5173450856763626 0.6300653501842866" rpy="0 0 0"/>
            <geometry>
                <box size="0.9027186019964868 1.0346901713527252 1.260130700368573" />
            </geometry>
        </collision>
    </link>
    <joint name="26_27" type="revolute">
       <parent link="26"/>
       <child  link="27"/>
       <origin rpy="0 0 0" xyz="0 -0.6080847670054297 0" />
     <axis xyz="1 0 1"/>
       <limit effort="0.0" lower="-3.14159" upper="3.14159" velocity="0.0"/>
    </joint>
    <link name="28">
        <inertial>
            <origin xyz="0 -0.5924847704720441 0.46579733908125603" rpy="0 0 0"/>
            <mass value="1" />
            <inertia ixx="100" ixy="0" ixz="0" iyy="100" iyz="0" izz="100" />
        </inertial>
        <visual>
            <origin xyz="0 -0.5924847704720441 0.46579733908125603" rpy="0 0 0"/>
            <geometry>
                <box size="0.8082719683092392 1.1849695409440881 0.9315946781625121" />
            </geometry>
            <material name="Blue">
                <color rgba="0 0 255 1"/>
            </material>
        </visual>
        <collision>
            <origin xyz="0 -0.5924847704720441 0.46579733908125603" rpy="0 0 0"/>
            <geometry>
                <box size="0.8082719683092392 1.1849695409440881 0.9315946781625121" />
            </geometry>
        </collision>
    </link>
    <joint name="27_28" type="revolute">
       <parent link="27"/>
       <child  link="28"/>
       <origin rpy="0 0 0" xyz="0 -1.0346901713527252 0" />
     <axis xyz="0 1 0"/>
       <limit effort="0.0" lower="-3.14159" upper="3.14159" velocity="0.0"/>
    </joint>
    <link name="29">
        <inertial>
            <origin xyz="0 -0.5896613916935486 0.31515535922835425" rpy="0 0 0"/>
            <mass value="1" />
            <inertia ixx="100" ixy="0" ixz="0" iyy="100" iyz="0" izz="100" />
        </inertial>
        <visual>
            <origin xyz="0 -0.5896613916935486 0.31515535922835425" rpy="0 0 0"/>
            <geometry>
                <box size="1.454379927573404 1.1793227833870972 0.6303107184567085" />
            </geometry>
            <material name="Blue">
                <color rgba="0 0 255 1"/>
            </material>
        </visual>
        <collision>
            <origin xyz="0 -0.5896613916935486 0.31515535922835425" rpy="0 0 0"/>
            <geometry>
                <box size="1.454379927573404 1.1793227833870972 0.6303107184567085" />
            </geometry>
        </collision>
    </link>
    <joint name="28_29" type="revolute">
       <parent link="28"/>
       <child  link="29"/>
       <origin rpy="0 0 0" xyz="0 -1.1849695409440881 0" />
     <axis xyz="1 0 1"/>
       <limit effort="0.0" lower="-3.14159" upper="3.14159" velocity="0.0"/>
    </joint>
    <link name="30">
        <inertial>
            <origin xyz="0 0 -0.6454373173569093" rpy="0 0 0"/>
            <mass value="1" />
            <inertia ixx="100" ixy="0" ixz="0" iyy="100" iyz="0" izz="100" />
        </inertial>
        <visual>
            <origin xyz="0 0 -0.6454373173569093" rpy="0 0 0"/>
            <geometry>
                <box size="0.9522335678006456 0.8434684988434886 1.2908746347138187" />
            </geometry>
            <material name="Blue">
                <color rgba="0 0 255 1"/>
            </material>
        </visual>
        <collision>
            <origin xyz="0 0 -0.6454373173569093" rpy="0 0 0"/>
            <geometry>
                <box size="0.9522335678006456 0.8434684988434886 1.2908746347138187" />
            </geometry>
        </collision>
    </link>
    <joint name="29_30" type="revolute">
       <parent link="29"/>
       <child  link="30"/>
       <origin rpy="0 0 0" xyz="0 -0.5896613916935486 0" />
     <axis xyz="1 1 1"/>
       <limit effort="0.0" lower="-3.14159" upper="3.14159" velocity="0.0"/>
    </joint>
    <link name="31">
        <inertial>
            <origin xyz="0 0 -0.4530502460290327" rpy="0 0 0"/>
            <mass value="1" />
            <inertia ixx="100" ixy="0" ixz="0" iyy="100" iyz="0" izz="100" />
        </inertial>
        <visual>
            <origin xyz="0 0 -0.4530502460290327" rpy="0 0 0"/>
            <geometry>
                <box size="0.9109070915875972 1.2588415062680722 0.9061004920580654" />
            </geometry>
            <material name="Blue">
                <color rgba="0 0 255 1"/>
            </material>
        </visual>
        <collision>
            <origin xyz="0 0 -0.4530502460290327" rpy="0 0 0"/>
            <geometry>
                <box size="0.9109070915875972 1.2588415062680722 0.9061004920580654" />
            </geometry>
        </collision>
    </link>
    <joint name="30_31" type="revolute">
       <parent link="30"/>
       <child  link="31"/>
       <origin rpy="0 0 0" xyz="0 0 -1.2908746347138187" />
     <axis xyz="0 1 1"/>
       <limit effort="0.0" lower="-3.14159" upper="3.14159" velocity="0.0"/>
    </joint>
    <link name="32">
        <inertial>
            <origin xyz="0 0 -0.6887730528435922" rpy="0 0 0"/>
            <mass value="1" />
            <inertia ixx="100" ixy="0" ixz="0" iyy="100" iyz="0" izz="100" />
        </inertial>
        <visual>
            <origin xyz="0 0 -0.6887730528435922" rpy="0 0 0"/>
            <geometry>
                <box size="0.6319557338234081 0.8268740610158928 1.3775461056871845" />
            </geometry>
            <material name="Blue">
                <color rgba="0 0 255 1"/>
            </material>
        </visual>
        <collision>
            <origin xyz="0 0 -0.6887730528435922" rpy="0 0 0"/>
            <geometry>
                <box size="0.6319557338234081 0.8268740610158928 1.3775461056871845" />
            </geometry>
        </collision>
    </link>
    <joint name="31_32" type="revolute">
       <parent link="31"/>
       <child  link="32"/>
       <origin rpy="0 0 0" xyz="0 0 -0.9061004920580654" />
     <axis xyz="0 0 1"/>
       <limit effort="0.0" lower="-3.14159" upper="3.14159" velocity="0.0"/>
    </joint>
    <link name="33">
        <inertial>
            <origin xyz="0 0.7235521930166446 0.48805027473966084" rpy="0 0 0"/>
            <mass value="1" />
            <inertia ixx="100" ixy="0" ixz="0" iyy="100" iyz="0" izz="100" />
        </inertial>
        <visual>
            <origin xyz="0 0.7235521930166446 0.48805027473966084" rpy="0 0 0"/>
            <geometry>
                <box size="0.7939034402260381 1.4471043860332893 0.9761005494793217" />
            </geometry>
            <material name="Green">
                <color rgba="0 128 0 1"/>
            </material>
        </visual>
        <collision>
            <origin xyz="0 0.7235521930166446 0.48805027473966084" rpy="0 0 0"/>
            <geometry>
                <box size="0.7939034402260381 1.4471043860332893 0.9761005494793217" />
            </geometry>
        </collision>
    </link>
    <joint name="2_33" type="revolute">
       <parent link="2"/>
       <child  link="33"/>
       <origin rpy="0 0 0" xyz="0 0.4968987962960504 0" />
     <axis xyz="0 1 0"/>
       <limit effort="0.0" lower="-3.14159" upper="3.14159" velocity="0.0"/>
    </joint>
    <link name="34">
        <inertial>
            <origin xyz="0 0.4243378635317297 0.6158980205436422" rpy="0 0 0"/>
            <mass value="1" />
            <inertia ixx="100" ixy="0" ixz="0" iyy="100" iyz="0" izz="100" />
        </inertial>
        <visual>
            <origin xyz="0 0.4243378635317297 0.6158980205436422" rpy="0 0 0"/>
            <geometry>
                <box size="0.8293531290173931 0.8486757270634594 1.2317960410872844" />
            </geometry>
            <material name="Blue">
                <color rgba="0 0 255 1"/>
            </material>
        </visual>
        <collision>
            <origin xyz="0 0.4243378635317297 0.6158980205436422" rpy="0 0 0"/>
            <geometry>
                <box size="0.8293531290173931 0.8486757270634594 1.2317960410872844" />
            </geometry>
        </collision>
    </link>
    <joint name="33_34" type="revolute">
       <parent link="33"/>
       <child  link="34"/>
       <origin rpy="0 0 0" xyz="0 1.4471043860332893 0" />
     <axis xyz="1 1 1"/>
       <limit effort="0.0" lower="-3.14159" upper="3.14159" velocity="0.0"/>
    </joint>
    <link name="35">
        <inertial>
            <origin xyz="0 0.5593761137413552 0.4112182582404585" rpy="0 0 0"/>
            <mass value="1" />
            <inertia ixx="100" ixy="0" ixz="0" iyy="100" iyz="0" izz="100" />
        </inertial>
        <visual>
            <origin xyz="0 0.5593761137413552 0.4112182582404585" rpy="0 0 0"/>
            <geometry>
                <box size="1.0552896359357058 1.1187522274827104 0.822436516480917" />
            </geometry>
            <material name="Green">
                <color rgba="0 128 0 1"/>
            </material>
        </visual>
        <collision>
            <origin xyz="0 0.5593761137413552 0.4112182582404585" rpy="0 0 0"/>
            <geometry>
                <box size="1.0552896359357058 1.1187522274827104 0.822436516480917" />
            </geometry>
        </collision>
    </link>
    <joint name="34_35" type="revolute">
       <parent link="34"/>
       <child  link="35"/>
       <origin rpy="0 0 0" xyz="0 0.8486757270634594 0" />
     <axis xyz="0 1 1"/>
       <limit effort="0.0" lower="-3.14159" upper="3.14159" velocity="0.0"/>
    </joint>
    <link name="36">
        <inertial>
            <origin xyz="0 0.4815779893506111 0.5290017220455356" rpy="0 0 0"/>
            <mass value="1" />
            <inertia ixx="100" ixy="0" ixz="0" iyy="100" iyz="0" izz="100" />
        </inertial>
        <visual>
            <origin xyz="0 0.4815779893506111 0.5290017220455356" rpy="0 0 0"/>
            <geometry>
                <box size="0.5781760498172631 0.9631559787012222 1.0580034440910713" />
            </geometry>
            <material name="Blue">
                <color rgba="0 0 255 1"/>
            </material>
        </visual>
        <collision>
            <origin xyz="0 0.4815779893506111 0.5290017220455356" rpy="0 0 0"/>
            <geometry>
                <box size="0.5781760498172631 0.9631559787012222 1.0580034440910713" />
            </geometry>
        </collision>
    </link>
    <joint name="35_36" type="revolute">
       <parent link="35"/>
       <child  link="36"/>
       <origin rpy="0 0 0" xyz="0 1.1187522274827104 0" />
     <axis xyz="0 0 1"/>
       <limit effort="0.0" lower="-3.14159" upper="3.14159" velocity="0.0"/>
    </joint>
    <link name="37">
        <inertial>
            <origin xyz="0 0.40317942321625494 0.3854162129335726" rpy="0 0 0"/>
            <mass value="1" />
            <inertia ixx="100" ixy="0" ixz="0" iyy="100" iyz="0" izz="100" />
        </inertial>
        <visual>
            <origin xyz="0 0.40317942321625494 0.3854162129335726" rpy="0 0 0"/>
            <geometry>
                <box size="0.6156018451744601 0.8063588464325099 0.7708324258671452" />
            </geometry>
            <material name="Blue">
                <color rgba="0 0 255 1"/>
            </material>
        </visual>
        <collision>
            <origin xyz="0 0.40317942321625494 0.3854162129335726" rpy="0 0 0"/>
            <geometry>
                <box size="0.6156018451744601 0.8063588464325099 0.7708324258671452" />
            </geometry>
        </collision>
    </link>
    <joint name="36_37" type="revolute">
       <parent link="36"/>
       <child  link="37"/>
       <origin rpy="0 0 0" xyz="0 0.9631559787012222 0" />
     <axis xyz="0 1 0"/>
       <limit effort="0.0" lower="-3.14159" upper="3.14159" velocity="0.0"/>
    </joint>
    <link name="38">
        <inertial>
            <origin xyz="0 0.6816948763826857 0.41521897766261906" rpy="0 0 0"/>
            <mass value="1" />
            <inertia ixx="100" ixy="0" ixz="0" iyy="100" iyz="0" izz="100" />
        </inertial>
        <visual>
            <origin xyz="0 0.6816948763826857 0.41521897766261906" rpy="0 0 0"/>
            <geometry>
                <box size="0.9383529033586239 1.3633897527653713 0.8304379553252381" />
            </geometry>
            <material name="Blue">
                <color rgba="0 0 255 1"/>
            </material>
        </visual>
        <collision>
            <origin xyz="0 0.6816948763826857 0.41521897766261906" rpy="0 0 0"/>
            <geometry>
                <box size="0.9383529033586239 1.3633897527653713 0.8304379553252381" />
            </geometry>
        </collision>
    </link>
    <joint name="37_38" type="revolute">
       <parent link="37"/>
       <child  link="38"/>
       <origin rpy="0 0 0" xyz="0 0.8063588464325099 0" />
     <axis xyz="1 0 1"/>
       <limit effort="0.0" lower="-3.14159" upper="3.14159" velocity="0.0"/>
    </joint>
    <link name="39">
        <inertial>
            <origin xyz="0 0.48257011504270547 0.528897698517651" rpy="0 0 0"/>
            <mass value="1" />
            <inertia ixx="100" ixy="0" ixz="0" iyy="100" iyz="0" izz="100" />
        </inertial>
        <visual>
            <origin xyz="0 0.48257011504270547 0.528897698517651" rpy="0 0 0"/>
            <geometry>
                <box size="1.2117787800712123 0.9651402300854109 1.057795397035302" />
            </geometry>
            <material name="Green">
                <color rgba="0 128 0 1"/>
            </material>
        </visual>
        <collision>
            <origin xyz="0 0.48257011504270547 0.528897698517651" rpy="0 0 0"/>
            <geometry>
                <box size="1.2117787800712123 0.9651402300854109 1.057795397035302" />
            </geometry>
        </collision>
    </link>
    <joint name="38_39" type="revolute">
       <parent link="38"/>
       <child  link="39"/>
       <origin rpy="0 0 0" xyz="0 1.3633897527653713 0" />
     <axis xyz="1 1 1"/>
       <limit effort="0.0" lower="-3.14159" upper="3.14159" velocity="0.0"/>
    </joint>
    <link name="40">
        <inertial>
            <origin xyz="0 0 -1.1981765159581264" rpy="0 0 0"/>
            <mass value="1" />
            <inertia ixx="100" ixy="0" ixz="0" iyy="100" iyz="0" izz="100" />
        </inertial>
        <visual>
            <origin xyz="0 0 -1.1981765159581264" rpy="0 0 0"/>
            <geometry>
                <box size="1.230000064570951 0.524277026609958 2.3963530319162527" />
            </geometry>
            <material name="Blue">
                <color rgba="0 0 255 1"/>
            </material>
        </visual>
        <collision>
            <origin xyz="0 0 -1.1981765159581264" rpy="0 0 0"/>
            <geometry>
                <box size="1.230000064570951 0.524277026609958 2.3963530319162527" />
            </geometry>
        </collision>
    </link>
    <joint name="39_40" type="revolute">
       <parent link="39"/>
       <child  link="40"/>
       <origin rpy="0 0 0" xyz="0 0.48257011504270547 0" />
     <axis xyz="1 0 1"/>
       <limit effort="0.0" lower="-3.14159" upper="3.14159" velocity="0.0"/>
    </joint>
    <link name="41">
        <inertial>
            <origin xyz="0 0 -0.568399294846152" rpy="0 0 0"/>
            <mass value="1" />
            <inertia ixx="100" ixy="0" ixz="0" iyy="100" iyz="0" izz="100" />
        </inertial>
        <visual>
            <origin xyz="0 0 -0.568399294846152" rpy="0 0 0"/>
            <geometry>
                <box size="1.4426585107622598 0.5457863423554576 1.136798589692304" />
            </geometry>
            <material name="Blue">
                <color rgba="0 0 255 1"/>
            </material>
        </visual>
        <collision>
            <origin xyz="0 0 -0.568399294846152" rpy="0 0 0"/>
            <geometry>
                <box size="1.4426585107622598 0.5457863423554576 1.136798589692304" />
            </geometry>
        </collision>
    </link>
    <joint name="40_41" type="revolute">
       <parent link="40"/>
       <child  link="41"/>
       <origin rpy="0 0 0" xyz="0 0 -2.3963530319162527" />
     <axis xyz="0 0 1"/>
       <limit effort="0.0" lower="-3.14159" upper="3.14159" velocity="0.0"/>
    </joint>
    <link name="42">
        <inertial>
            <origin xyz="0 0 -0.02068480542525597" rpy="0 0 0"/>
            <mass value="1" />
            <inertia ixx="100" ixy="0" ixz="0" iyy="100" iyz="0" izz="100" />
        </inertial>
        <visual>
            <origin xyz="0 0 -0.02068480542525597" rpy="0 0 0"/>
            <geometry>
                <box size="1.0026794712780136 1.4114780337662487 0.04136961085051194" />
            </geometry>
            <material name="Green">
                <color rgba="0 128 0 1"/>
            </material>
        </visual>
        <collision>
            <origin xyz="0 0 -0.02068480542525597" rpy="0 0 0"/>
            <geometry>
                <box size="1.0026794712780136 1.4114780337662487 0.04136961085051194" />
            </geometry>
        </collision>
    </link>
    <joint name="41_42" type="revolute">
       <parent link="41"/>
       <child  link="42"/>
       <origin rpy="0 0 0" xyz="0 0 -1.136798589692304" />
     <axis xyz="1 0 0"/>
       <limit effort="0.0" lower="-3.14159" upper="3.14159" velocity="0.0"/>
    </joint>
</robot>