<robot name = "robot">
    <link name="0">
        <inertial>
            <origin xyz="0 0 0.35" rpy="0 0 0"/>
            <mass value="1" />
            <inertia ixx="100" ixy="0" ixz="0" iyy="100" iyz="0" izz="100" />
        </inertial>
        <visual>
            <origin xyz="0 0 0.35" rpy="0 0 0"/>
            <geometry>
                <box size="0.7 0.7 0.7" />
            </geometry>
            <material name="Green">
                <color rgba="0 128 0 1"/>
            </material>
        </visual>
        <collision>
            <origin xyz="0 0 0.35" rpy="0 0 0"/>
            <geometry>
                <box size="0.7 0.7 0.7" />
            </geometry>
        </collision>
    </link>
    <link name="1">
        <inertial>
            <origin xyz="-0.11892320483183572 0 0.00033030789539356675" rpy="0 0 0"/>
            <mass value="1" />
            <inertia ixx="100" ixy="0" ixz="0" iyy="100" iyz="0" izz="100" />
        </inertial>
        <visual>
            <origin xyz="-0.11892320483183572 0 0.00033030789539356675" rpy="0 0 0"/>
            <geometry>
                <box size="0.23784640966367143 0.9031823230833629 0.0006606157907871335" />
            </geometry>
            <material name="Blue">
                <color rgba="0 0 255 1"/>
            </material>
        </visual>
        <collision>
            <origin xyz="-0.11892320483183572 0 0.00033030789539356675" rpy="0 0 0"/>
            <geometry>
                <box size="0.23784640966367143 0.9031823230833629 0.0006606157907871335" />
            </geometry>
        </collision>
    </link>
    <joint name="0_1" type="revolute">
       <parent link="0"/>
       <child  link="1"/>
       <origin rpy="0 0 0" xyz="-0.35 0 0.7" />
     <axis xyz="1 0 1"/>
       <limit effort="0.0" lower="-3.14159" upper="3.14159" velocity="0.0"/>
    </joint>
    <link name="2">
        <inertial>
            <origin xyz="-0.47605330228257203 0 0.43320062054348896" rpy="0 0 0"/>
            <mass value="1" />
            <inertia ixx="100" ixy="0" ixz="0" iyy="100" iyz="0" izz="100" />
        </inertial>
        <visual>
            <origin xyz="-0.47605330228257203 0 0.43320062054348896" rpy="0 0 0"/>
            <geometry>
                <box size="0.9521066045651441 0.8558547229322963 0.8664012410869779" />
            </geometry>
            <material name="Green">
                <color rgba="0 128 0 1"/>
            </material>
        </visual>
        <collision>
            <origin xyz="-0.47605330228257203 0 0.43320062054348896" rpy="0 0 0"/>
            <geometry>
                <box size="0.9521066045651441 0.8558547229322963 0.8664012410869779" />
            </geometry>
        </collision>
    </link>
    <joint name="1_2" type="revolute">
       <parent link="1"/>
       <child  link="2"/>
       <origin rpy="0 0 0" xyz="-0.23784640966367143 0 0.0006606157907871335" />
     <axis xyz="1 1 1"/>
       <limit effort="0.0" lower="-3.14159" upper="3.14159" velocity="0.0"/>
    </joint>
    <link name="3">
        <inertial>
            <origin xyz="-0.18693982796509068 0 0.3067820455930473" rpy="0 0 0"/>
            <mass value="1" />
            <inertia ixx="100" ixy="0" ixz="0" iyy="100" iyz="0" izz="100" />
        </inertial>
        <visual>
            <origin xyz="-0.18693982796509068 0 0.3067820455930473" rpy="0 0 0"/>
            <geometry>
                <box size="0.37387965593018135 0.03606211058745479 0.6135640911860946" />
            </geometry>
            <material name="Green">
                <color rgba="0 128 0 1"/>
            </material>
        </visual>
        <collision>
            <origin xyz="-0.18693982796509068 0 0.3067820455930473" rpy="0 0 0"/>
            <geometry>
                <box size="0.37387965593018135 0.03606211058745479 0.6135640911860946" />
            </geometry>
        </collision>
    </link>
    <joint name="2_3" type="revolute">
       <parent link="2"/>
       <child  link="3"/>
       <origin rpy="0 0 0" xyz="-0.9521066045651441 0 0.8664012410869779" />
     <axis xyz="0 0 1"/>
       <limit effort="0.0" lower="-3.14159" upper="3.14159" velocity="0.0"/>
    </joint>
    <link name="4">
        <inertial>
            <origin xyz="-0.14764066616155525 0 0.4755514546517142" rpy="0 0 0"/>
            <mass value="1" />
            <inertia ixx="100" ixy="0" ixz="0" iyy="100" iyz="0" izz="100" />
        </inertial>
        <visual>
            <origin xyz="-0.14764066616155525 0 0.4755514546517142" rpy="0 0 0"/>
            <geometry>
                <box size="0.2952813323231105 0.5126476983679332 0.9511029093034284" />
            </geometry>
            <material name="Blue">
                <color rgba="0 0 255 1"/>
            </material>
        </visual>
        <collision>
            <origin xyz="-0.14764066616155525 0 0.4755514546517142" rpy="0 0 0"/>
            <geometry>
                <box size="0.2952813323231105 0.5126476983679332 0.9511029093034284" />
            </geometry>
        </collision>
    </link>
    <joint name="3_4" type="revolute">
       <parent link="3"/>
       <child  link="4"/>
       <origin rpy="0 0 0" xyz="-0.37387965593018135 0 0.6135640911860946" />
     <axis xyz="0 0 1"/>
       <limit effort="0.0" lower="-3.14159" upper="3.14159" velocity="0.0"/>
    </joint>
    <link name="5">
        <inertial>
            <origin xyz="-0.47915025186396454 0 0.20955096337662182" rpy="0 0 0"/>
            <mass value="1" />
            <inertia ixx="100" ixy="0" ixz="0" iyy="100" iyz="0" izz="100" />
        </inertial>
        <visual>
            <origin xyz="-0.47915025186396454 0 0.20955096337662182" rpy="0 0 0"/>
            <geometry>
                <box size="0.9583005037279291 0.8185219997850042 0.41910192675324365" />
            </geometry>
            <material name="Green">
                <color rgba="0 128 0 1"/>
            </material>
        </visual>
        <collision>
            <origin xyz="-0.47915025186396454 0 0.20955096337662182" rpy="0 0 0"/>
            <geometry>
                <box size="0.9583005037279291 0.8185219997850042 0.41910192675324365" />
            </geometry>
        </collision>
    </link>
    <joint name="4_5" type="revolute">
       <parent link="4"/>
       <child  link="5"/>
       <origin rpy="0 0 0" xyz="-0.2952813323231105 0 0.9511029093034284" />
     <axis xyz="1 0 1"/>
       <limit effort="0.0" lower="-3.14159" upper="3.14159" velocity="0.0"/>
    </joint>
    <link name="6">
        <inertial>
            <origin xyz="0.3211482708841028 0 0.07105624361625107" rpy="0 0 0"/>
            <mass value="1" />
            <inertia ixx="100" ixy="0" ixz="0" iyy="100" iyz="0" izz="100" />
        </inertial>
        <visual>
            <origin xyz="0.3211482708841028 0 0.07105624361625107" rpy="0 0 0"/>
            <geometry>
                <box size="0.6422965417682056 0.3694427197238227 0.14211248723250214" />
            </geometry>
            <material name="Blue">
                <color rgba="0 0 255 1"/>
            </material>
        </visual>
        <collision>
            <origin xyz="0.3211482708841028 0 0.07105624361625107" rpy="0 0 0"/>
            <geometry>
                <box size="0.6422965417682056 0.3694427197238227 0.14211248723250214" />
            </geometry>
        </collision>
    </link>
    <joint name="0_6" type="revolute">
       <parent link="0"/>
       <child  link="6"/>
       <origin rpy="0 0 0" xyz="0.35 0 0.7" />
     <axis xyz="0 1 1"/>
       <limit effort="0.0" lower="-3.14159" upper="3.14159" velocity="0.0"/>
    </joint>
    <link name="7">
        <inertial>
            <origin xyz="0.19137318269855952 0 0.09957869338988107" rpy="0 0 0"/>
            <mass value="1" />
            <inertia ixx="100" ixy="0" ixz="0" iyy="100" iyz="0" izz="100" />
        </inertial>
        <visual>
            <origin xyz="0.19137318269855952 0 0.09957869338988107" rpy="0 0 0"/>
            <geometry>
                <box size="0.38274636539711904 0.47703130511352854 0.19915738677976214" />
            </geometry>
            <material name="Green">
                <color rgba="0 128 0 1"/>
            </material>
        </visual>
        <collision>
            <origin xyz="0.19137318269855952 0 0.09957869338988107" rpy="0 0 0"/>
            <geometry>
                <box size="0.38274636539711904 0.47703130511352854 0.19915738677976214" />
            </geometry>
        </collision>
    </link>
    <joint name="6_7" type="revolute">
       <parent link="6"/>
       <child  link="7"/>
       <origin rpy="0 0 0" xyz="0.6422965417682056 0 0.14211248723250214" />
     <axis xyz="1 1 1"/>
       <limit effort="0.0" lower="-3.14159" upper="3.14159" velocity="0.0"/>
    </joint>
    <link name="8">
        <inertial>
            <origin xyz="0.3043049465523332 0 0.4467334995480572" rpy="0 0 0"/>
            <mass value="1" />
            <inertia ixx="100" ixy="0" ixz="0" iyy="100" iyz="0" izz="100" />
        </inertial>
        <visual>
            <origin xyz="0.3043049465523332 0 0.4467334995480572" rpy="0 0 0"/>
            <geometry>
                <box size="0.6086098931046664 0.35111608223046586 0.8934669990961144" />
            </geometry>
            <material name="Blue">
                <color rgba="0 0 255 1"/>
            </material>
        </visual>
        <collision>
            <origin xyz="0.3043049465523332 0 0.4467334995480572" rpy="0 0 0"/>
            <geometry>
                <box size="0.6086098931046664 0.35111608223046586 0.8934669990961144" />
            </geometry>
        </collision>
    </link>
    <joint name="7_8" type="revolute">
       <parent link="7"/>
       <child  link="8"/>
       <origin rpy="0 0 0" xyz="0.38274636539711904 0 0.19915738677976214" />
     <axis xyz="1 0 0"/>
       <limit effort="0.0" lower="-3.14159" upper="3.14159" velocity="0.0"/>
    </joint>
    <link name="9">
        <inertial>
            <origin xyz="0.19092690984874344 0 0.45823806380915655" rpy="0 0 0"/>
            <mass value="1" />
            <inertia ixx="100" ixy="0" ixz="0" iyy="100" iyz="0" izz="100" />
        </inertial>
        <visual>
            <origin xyz="0.19092690984874344 0 0.45823806380915655" rpy="0 0 0"/>
            <geometry>
                <box size="0.3818538196974869 0.3260421720580161 0.9164761276183131" />
            </geometry>
            <material name="Blue">
                <color rgba="0 0 255 1"/>
            </material>
        </visual>
        <collision>
            <origin xyz="0.19092690984874344 0 0.45823806380915655" rpy="0 0 0"/>
            <geometry>
                <box size="0.3818538196974869 0.3260421720580161 0.9164761276183131" />
            </geometry>
        </collision>
    </link>
    <joint name="8_9" type="revolute">
       <parent link="8"/>
       <child  link="9"/>
       <origin rpy="0 0 0" xyz="0.6086098931046664 0 0.8934669990961144" />
     <axis xyz="1 1 1"/>
       <limit effort="0.0" lower="-3.14159" upper="3.14159" velocity="0.0"/>
    </joint>
    <link name="10">
        <inertial>
            <origin xyz="0 -0.3147281478214997 0.44564089016726033" rpy="0 0 0"/>
            <mass value="1" />
            <inertia ixx="100" ixy="0" ixz="0" iyy="100" iyz="0" izz="100" />
        </inertial>
        <visual>
            <origin xyz="0 -0.3147281478214997 0.44564089016726033" rpy="0 0 0"/>
            <geometry>
                <box size="0.14070048425674286 0.6294562956429994 0.8912817803345207" />
            </geometry>
            <material name="Green">
                <color rgba="0 128 0 1"/>
            </material>
        </visual>
        <collision>
            <origin xyz="0 -0.3147281478214997 0.44564089016726033" rpy="0 0 0"/>
            <geometry>
                <box size="0.14070048425674286 0.6294562956429994 0.8912817803345207" />
            </geometry>
        </collision>
    </link>
    <joint name="0_10" type="revolute">
       <parent link="0"/>
       <child  link="10"/>
       <origin rpy="0 0 0" xyz="0 -0.35 0.7" />
     <axis xyz="0 1 1"/>
       <limit effort="0.0" lower="-3.14159" upper="3.14159" velocity="0.0"/>
    </joint>
    <link name="11">
        <inertial>
            <origin xyz="0 -0.4883402147380108 0.2467051010262019" rpy="0 0 0"/>
            <mass value="1" />
            <inertia ixx="100" ixy="0" ixz="0" iyy="100" iyz="0" izz="100" />
        </inertial>
        <visual>
            <origin xyz="0 -0.4883402147380108 0.2467051010262019" rpy="0 0 0"/>
            <geometry>
                <box size="0.4292008908963485 0.9766804294760216 0.4934102020524038" />
            </geometry>
            <material name="Green">
                <color rgba="0 128 0 1"/>
            </material>
        </visual>
        <collision>
            <origin xyz="0 -0.4883402147380108 0.2467051010262019" rpy="0 0 0"/>
            <geometry>
                <box size="0.4292008908963485 0.9766804294760216 0.4934102020524038" />
            </geometry>
        </collision>
    </link>
    <joint name="10_11" type="revolute">
       <parent link="10"/>
       <child  link="11"/>
       <origin rpy="0 0 0" xyz="0 -0.6294562956429994 0.8912817803345207" />
     <axis xyz="0 1 0"/>
       <limit effort="0.0" lower="-3.14159" upper="3.14159" velocity="0.0"/>
    </joint>
    <link name="12">
        <inertial>
            <origin xyz="0 -0.18989026689489014 0.4805695483645966" rpy="0 0 0"/>
            <mass value="1" />
            <inertia ixx="100" ixy="0" ixz="0" iyy="100" iyz="0" izz="100" />
        </inertial>
        <visual>
            <origin xyz="0 -0.18989026689489014 0.4805695483645966" rpy="0 0 0"/>
            <geometry>
                <box size="0.9724546276651214 0.3797805337897803 0.9611390967291932" />
            </geometry>
            <material name="Green">
                <color rgba="0 128 0 1"/>
            </material>
        </visual>
        <collision>
            <origin xyz="0 -0.18989026689489014 0.4805695483645966" rpy="0 0 0"/>
            <geometry>
                <box size="0.9724546276651214 0.3797805337897803 0.9611390967291932" />
            </geometry>
        </collision>
    </link>
    <joint name="11_12" type="revolute">
       <parent link="11"/>
       <child  link="12"/>
       <origin rpy="0 0 0" xyz="0 -0.9766804294760216 0.4934102020524038" />
     <axis xyz="0 1 0"/>
       <limit effort="0.0" lower="-3.14159" upper="3.14159" velocity="0.0"/>
    </joint>
    <link name="13">
        <inertial>
            <origin xyz="0 -0.12991232701028216 0.4904902812123399" rpy="0 0 0"/>
            <mass value="1" />
            <inertia ixx="100" ixy="0" ixz="0" iyy="100" iyz="0" izz="100" />
        </inertial>
        <visual>
            <origin xyz="0 -0.12991232701028216 0.4904902812123399" rpy="0 0 0"/>
            <geometry>
                <box size="0.5958099782016165 0.2598246540205643 0.9809805624246798" />
            </geometry>
            <material name="Blue">
                <color rgba="0 0 255 1"/>
            </material>
        </visual>
        <collision>
            <origin xyz="0 -0.12991232701028216 0.4904902812123399" rpy="0 0 0"/>
            <geometry>
                <box size="0.5958099782016165 0.2598246540205643 0.9809805624246798" />
            </geometry>
        </collision>
    </link>
    <joint name="12_13" type="revolute">
       <parent link="12"/>
       <child  link="13"/>
       <origin rpy="0 0 0" xyz="0 -0.3797805337897803 0.9611390967291932" />
     <axis xyz="1 1 1"/>
       <limit effort="0.0" lower="-3.14159" upper="3.14159" velocity="0.0"/>
    </joint>
</robot>