<robot name = "robot">
    <link name="0">
        <inertial>
            <origin xyz="0 0 1" rpy="0 0 0"/>
            <mass value="1" />
            <inertia ixx="100" ixy="0" ixz="0" iyy="100" iyz="0" izz="100" />
        </inertial>
        <visual>
            <origin xyz="0 0 1" rpy="0 0 0"/>
            <geometry>
                <box size="1.5 1.5 0.8" />
            </geometry>
            <material name="Blue">
                <color rgba="0 0 255 1"/>
            </material>
        </visual>
        <collision>
            <origin xyz="0 0 1" rpy="0 0 0"/>
            <geometry>
                <box size="1.5 1.5 0.8" />
            </geometry>
        </collision>
    </link>
    <link name="1">
        <inertial>
            <origin xyz="-0.14477486337985424 0 0" rpy="0 0 0"/>
            <mass value="1" />
            <inertia ixx="100" ixy="0" ixz="0" iyy="100" iyz="0" izz="100" />
        </inertial>
        <visual>
            <origin xyz="-0.14477486337985424 0 0" rpy="0 0 0"/>
            <geometry>
                <box size="0.28954972675970847 0.5462298976970796 0.29998438775624114" />
            </geometry>
            <material name="Blue">
                <color rgba="0 0 255 1"/>
            </material>
        </visual>
        <collision>
            <origin xyz="-0.14477486337985424 0 0" rpy="0 0 0"/>
            <geometry>
                <box size="0.28954972675970847 0.5462298976970796 0.29998438775624114" />
            </geometry>
        </collision>
    </link>
    <joint name="0_1" type="revolute">
       <parent link="0"/>
       <child  link="1"/>
       <origin rpy="0 0 0" xyz="-0.75 0 1" />
     <axis xyz="0 0 1"/>
       <limit effort="0.0" lower="-3.14159" upper="3.14159" velocity="0.0"/>
    </joint>
    <link name="2">
        <inertial>
            <origin xyz="-0.4497459486727545 0 0" rpy="0 0 0"/>
            <mass value="1" />
            <inertia ixx="100" ixy="0" ixz="0" iyy="100" iyz="0" izz="100" />
        </inertial>
        <visual>
            <origin xyz="-0.4497459486727545 0 0" rpy="0 0 0"/>
            <geometry>
                <box size="0.899491897345509 0.5145713550915615 0.5354963027435317" />
            </geometry>
            <material name="Green">
                <color rgba="0 128 0 1"/>
            </material>
        </visual>
        <collision>
            <origin xyz="-0.4497459486727545 0 0" rpy="0 0 0"/>
            <geometry>
                <box size="0.899491897345509 0.5145713550915615 0.5354963027435317" />
            </geometry>
        </collision>
    </link>
    <joint name="1_2" type="revolute">
       <parent link="1"/>
       <child  link="2"/>
       <origin rpy="0 0 0" xyz="-0.28954972675970847 0 0" />
     <axis xyz="1 1 0"/>
       <limit effort="0.0" lower="-3.14159" upper="3.14159" velocity="0.0"/>
    </joint>
    <link name="3">
        <inertial>
            <origin xyz="-0.4922753235024282 0 0" rpy="0 0 0"/>
            <mass value="1" />
            <inertia ixx="100" ixy="0" ixz="0" iyy="100" iyz="0" izz="100" />
        </inertial>
        <visual>
            <origin xyz="-0.4922753235024282 0 0" rpy="0 0 0"/>
            <geometry>
                <box size="0.9845506470048564 0.3489910907587992 0.8745028535242396" />
            </geometry>
            <material name="Blue">
                <color rgba="0 0 255 1"/>
            </material>
        </visual>
        <collision>
            <origin xyz="-0.4922753235024282 0 0" rpy="0 0 0"/>
            <geometry>
                <box size="0.9845506470048564 0.3489910907587992 0.8745028535242396" />
            </geometry>
        </collision>
    </link>
    <joint name="2_3" type="revolute">
       <parent link="2"/>
       <child  link="3"/>
       <origin rpy="0 0 0" xyz="-0.899491897345509 0 0" />
     <axis xyz="0 1 0"/>
       <limit effort="0.0" lower="-3.14159" upper="3.14159" velocity="0.0"/>
    </joint>
    <link name="4">
        <inertial>
            <origin xyz="-0.02896896115365477 0 0" rpy="0 0 0"/>
            <mass value="1" />
            <inertia ixx="100" ixy="0" ixz="0" iyy="100" iyz="0" izz="100" />
        </inertial>
        <visual>
            <origin xyz="-0.02896896115365477 0 0" rpy="0 0 0"/>
            <geometry>
                <box size="0.05793792230730954 0.37056252698409753 0.5132627941590594" />
            </geometry>
            <material name="Blue">
                <color rgba="0 0 255 1"/>
            </material>
        </visual>
        <collision>
            <origin xyz="-0.02896896115365477 0 0" rpy="0 0 0"/>
            <geometry>
                <box size="0.05793792230730954 0.37056252698409753 0.5132627941590594" />
            </geometry>
        </collision>
    </link>
    <joint name="3_4" type="revolute">
       <parent link="3"/>
       <child  link="4"/>
       <origin rpy="0 0 0" xyz="-0.9845506470048564 0 0" />
     <axis xyz="0 1 0"/>
       <limit effort="0.0" lower="-3.14159" upper="3.14159" velocity="0.0"/>
    </joint>
    <link name="5">
        <inertial>
            <origin xyz="-0.39083395058943465 0 0" rpy="0 0 0"/>
            <mass value="1" />
            <inertia ixx="100" ixy="0" ixz="0" iyy="100" iyz="0" izz="100" />
        </inertial>
        <visual>
            <origin xyz="-0.39083395058943465 0 0" rpy="0 0 0"/>
            <geometry>
                <box size="0.7816679011788693 0.5522827793563279 0.4550660663448527" />
            </geometry>
            <material name="Green">
                <color rgba="0 128 0 1"/>
            </material>
        </visual>
        <collision>
            <origin xyz="-0.39083395058943465 0 0" rpy="0 0 0"/>
            <geometry>
                <box size="0.7816679011788693 0.5522827793563279 0.4550660663448527" />
            </geometry>
        </collision>
    </link>
    <joint name="4_5" type="revolute">
       <parent link="4"/>
       <child  link="5"/>
       <origin rpy="0 0 0" xyz="-0.05793792230730954 0 0" />
     <axis xyz="0 1 1"/>
       <limit effort="0.0" lower="-3.14159" upper="3.14159" velocity="0.0"/>
    </joint>
    <link name="6">
        <inertial>
            <origin xyz="0 0 -0.021687258530322138" rpy="0 0 0"/>
            <mass value="1" />
            <inertia ixx="100" ixy="0" ixz="0" iyy="100" iyz="0" izz="100" />
        </inertial>
        <visual>
            <origin xyz="0 0 -0.021687258530322138" rpy="0 0 0"/>
            <geometry>
                <box size="0.9666073315608652 0.5881264790601387 0.043374517060644276" />
            </geometry>
            <material name="Blue">
                <color rgba="0 0 255 1"/>
            </material>
        </visual>
        <collision>
            <origin xyz="0 0 -0.021687258530322138" rpy="0 0 0"/>
            <geometry>
                <box size="0.9666073315608652 0.5881264790601387 0.043374517060644276" />
            </geometry>
        </collision>
    </link>
    <joint name="5_6" type="revolute">
       <parent link="5"/>
       <child  link="6"/>
       <origin rpy="0 0 0" xyz="-0.39083395058943465 0 -0.22753303317242635" />
     <axis xyz="1 1 0"/>
       <limit effort="0.0" lower="-3.14159" upper="3.14159" velocity="0.0"/>
    </joint>
    <link name="7">
        <inertial>
            <origin xyz="0 0 -0.18861850094293073" rpy="0 0 0"/>
            <mass value="1" />
            <inertia ixx="100" ixy="0" ixz="0" iyy="100" iyz="0" izz="100" />
        </inertial>
        <visual>
            <origin xyz="0 0 -0.18861850094293073" rpy="0 0 0"/>
            <geometry>
                <box size="0.20184065066651424 0.8939902913044733 0.37723700188586146" />
            </geometry>
            <material name="Green">
                <color rgba="0 128 0 1"/>
            </material>
        </visual>
        <collision>
            <origin xyz="0 0 -0.18861850094293073" rpy="0 0 0"/>
            <geometry>
                <box size="0.20184065066651424 0.8939902913044733 0.37723700188586146" />
            </geometry>
        </collision>
    </link>
    <joint name="6_7" type="revolute">
       <parent link="6"/>
       <child  link="7"/>
       <origin rpy="0 0 0" xyz="0 0 -0.043374517060644276" />
     <axis xyz="1 0 0"/>
       <limit effort="0.0" lower="-3.14159" upper="3.14159" velocity="0.0"/>
    </joint>
    <link name="8">
        <inertial>
            <origin xyz="0 0 -0.0896942405267471" rpy="0 0 0"/>
            <mass value="1" />
            <inertia ixx="100" ixy="0" ixz="0" iyy="100" iyz="0" izz="100" />
        </inertial>
        <visual>
            <origin xyz="0 0 -0.0896942405267471" rpy="0 0 0"/>
            <geometry>
                <box size="0.8690107994425785 0.5106153055607217 0.1793884810534942" />
            </geometry>
            <material name="Blue">
                <color rgba="0 0 255 1"/>
            </material>
        </visual>
        <collision>
            <origin xyz="0 0 -0.0896942405267471" rpy="0 0 0"/>
            <geometry>
                <box size="0.8690107994425785 0.5106153055607217 0.1793884810534942" />
            </geometry>
        </collision>
    </link>
    <joint name="7_8" type="revolute">
       <parent link="7"/>
       <child  link="8"/>
       <origin rpy="0 0 0" xyz="0 0 -0.37723700188586146" />
     <axis xyz="0 1 1"/>
       <limit effort="0.0" lower="-3.14159" upper="3.14159" velocity="0.0"/>
    </joint>
    <link name="9">
        <inertial>
            <origin xyz="0.4841556443764222 0 0" rpy="0 0 0"/>
            <mass value="1" />
            <inertia ixx="100" ixy="0" ixz="0" iyy="100" iyz="0" izz="100" />
        </inertial>
        <visual>
            <origin xyz="0.4841556443764222 0 0" rpy="0 0 0"/>
            <geometry>
                <box size="0.9683112887528444 0.12410046131682717 0.05192694652091756" />
            </geometry>
            <material name="Green">
                <color rgba="0 128 0 1"/>
            </material>
        </visual>
        <collision>
            <origin xyz="0.4841556443764222 0 0" rpy="0 0 0"/>
            <geometry>
                <box size="0.9683112887528444 0.12410046131682717 0.05192694652091756" />
            </geometry>
        </collision>
    </link>
    <joint name="0_9" type="revolute">
       <parent link="0"/>
       <child  link="9"/>
       <origin rpy="0 0 0" xyz="0.75 0 1" />
     <axis xyz="0 0 1"/>
       <limit effort="0.0" lower="-3.14159" upper="3.14159" velocity="0.0"/>
    </joint>
    <link name="10">
        <inertial>
            <origin xyz="0.30139772202060006 0 0" rpy="0 0 0"/>
            <mass value="1" />
            <inertia ixx="100" ixy="0" ixz="0" iyy="100" iyz="0" izz="100" />
        </inertial>
        <visual>
            <origin xyz="0.30139772202060006 0 0" rpy="0 0 0"/>
            <geometry>
                <box size="0.6027954440412001 0.4480433683342081 0.0565596508815992" />
            </geometry>
            <material name="Green">
                <color rgba="0 128 0 1"/>
            </material>
        </visual>
        <collision>
            <origin xyz="0.30139772202060006 0 0" rpy="0 0 0"/>
            <geometry>
                <box size="0.6027954440412001 0.4480433683342081 0.0565596508815992" />
            </geometry>
        </collision>
    </link>
    <joint name="9_10" type="revolute">
       <parent link="9"/>
       <child  link="10"/>
       <origin rpy="0 0 0" xyz="0.9683112887528444 0 0" />
     <axis xyz="1 0 1"/>
       <limit effort="0.0" lower="-3.14159" upper="3.14159" velocity="0.0"/>
    </joint>
    <link name="11">
        <inertial>
            <origin xyz="0.13185024653613298 0 0" rpy="0 0 0"/>
            <mass value="1" />
            <inertia ixx="100" ixy="0" ixz="0" iyy="100" iyz="0" izz="100" />
        </inertial>
        <visual>
            <origin xyz="0.13185024653613298 0 0" rpy="0 0 0"/>
            <geometry>
                <box size="0.26370049307226595 0.24325916980306506 0.7528274719519685" />
            </geometry>
            <material name="Blue">
                <color rgba="0 0 255 1"/>
            </material>
        </visual>
        <collision>
            <origin xyz="0.13185024653613298 0 0" rpy="0 0 0"/>
            <geometry>
                <box size="0.26370049307226595 0.24325916980306506 0.7528274719519685" />
            </geometry>
        </collision>
    </link>
    <joint name="10_11" type="revolute">
       <parent link="10"/>
       <child  link="11"/>
       <origin rpy="0 0 0" xyz="0.6027954440412001 0 0" />
     <axis xyz="0 0 1"/>
       <limit effort="0.0" lower="-3.14159" upper="3.14159" velocity="0.0"/>
    </joint>
    <link name="12">
        <inertial>
            <origin xyz="0.2511982515661607 0 0" rpy="0 0 0"/>
            <mass value="1" />
            <inertia ixx="100" ixy="0" ixz="0" iyy="100" iyz="0" izz="100" />
        </inertial>
        <visual>
            <origin xyz="0.2511982515661607 0 0" rpy="0 0 0"/>
            <geometry>
                <box size="0.5023965031323214 0.37464290227860464 0.04807600569374082" />
            </geometry>
            <material name="Green">
                <color rgba="0 128 0 1"/>
            </material>
        </visual>
        <collision>
            <origin xyz="0.2511982515661607 0 0" rpy="0 0 0"/>
            <geometry>
                <box size="0.5023965031323214 0.37464290227860464 0.04807600569374082" />
            </geometry>
        </collision>
    </link>
    <joint name="11_12" type="revolute">
       <parent link="11"/>
       <child  link="12"/>
       <origin rpy="0 0 0" xyz="0.26370049307226595 0 0" />
     <axis xyz="0 1 0"/>
       <limit effort="0.0" lower="-3.14159" upper="3.14159" velocity="0.0"/>
    </joint>
    <link name="13">
        <inertial>
            <origin xyz="0.4293270796878684 0 0" rpy="0 0 0"/>
            <mass value="1" />
            <inertia ixx="100" ixy="0" ixz="0" iyy="100" iyz="0" izz="100" />
        </inertial>
        <visual>
            <origin xyz="0.4293270796878684 0 0" rpy="0 0 0"/>
            <geometry>
                <box size="0.8586541593757367 0.051345926517737284 0.3748045044073762" />
            </geometry>
            <material name="Green">
                <color rgba="0 128 0 1"/>
            </material>
        </visual>
        <collision>
            <origin xyz="0.4293270796878684 0 0" rpy="0 0 0"/>
            <geometry>
                <box size="0.8586541593757367 0.051345926517737284 0.3748045044073762" />
            </geometry>
        </collision>
    </link>
    <joint name="12_13" type="revolute">
       <parent link="12"/>
       <child  link="13"/>
       <origin rpy="0 0 0" xyz="0.5023965031323214 0 0" />
     <axis xyz="1 0 1"/>
       <limit effort="0.0" lower="-3.14159" upper="3.14159" velocity="0.0"/>
    </joint>
    <link name="14">
        <inertial>
            <origin xyz="0 0 -0.14349437083282188" rpy="0 0 0"/>
            <mass value="1" />
            <inertia ixx="100" ixy="0" ixz="0" iyy="100" iyz="0" izz="100" />
        </inertial>
        <visual>
            <origin xyz="0 0 -0.14349437083282188" rpy="0 0 0"/>
            <geometry>
                <box size="0.9591370070423626 0.5463164105612703 0.28698874166564375" />
            </geometry>
            <material name="Blue">
                <color rgba="0 0 255 1"/>
            </material>
        </visual>
        <collision>
            <origin xyz="0 0 -0.14349437083282188" rpy="0 0 0"/>
            <geometry>
                <box size="0.9591370070423626 0.5463164105612703 0.28698874166564375" />
            </geometry>
        </collision>
    </link>
    <joint name="13_14" type="revolute">
       <parent link="13"/>
       <child  link="14"/>
       <origin rpy="0 0 0" xyz="0.4293270796878684 0 -0.1874022522036881" />
     <axis xyz="1 1 1"/>
       <limit effort="0.0" lower="-3.14159" upper="3.14159" velocity="0.0"/>
    </joint>
    <link name="15">
        <inertial>
            <origin xyz="0 0 -0.015309915321489115" rpy="0 0 0"/>
            <mass value="1" />
            <inertia ixx="100" ixy="0" ixz="0" iyy="100" iyz="0" izz="100" />
        </inertial>
        <visual>
            <origin xyz="0 0 -0.015309915321489115" rpy="0 0 0"/>
            <geometry>
                <box size="0.6500477625243074 0.5308382186834986 0.03061983064297823" />
            </geometry>
            <material name="Green">
                <color rgba="0 128 0 1"/>
            </material>
        </visual>
        <collision>
            <origin xyz="0 0 -0.015309915321489115" rpy="0 0 0"/>
            <geometry>
                <box size="0.6500477625243074 0.5308382186834986 0.03061983064297823" />
            </geometry>
        </collision>
    </link>
    <joint name="14_15" type="revolute">
       <parent link="14"/>
       <child  link="15"/>
       <origin rpy="0 0 0" xyz="0 0 -0.28698874166564375" />
     <axis xyz="1 0 0"/>
       <limit effort="0.0" lower="-3.14159" upper="3.14159" velocity="0.0"/>
    </joint>
    <link name="16">
        <inertial>
            <origin xyz="0 0 -0.141195713845689" rpy="0 0 0"/>
            <mass value="1" />
            <inertia ixx="100" ixy="0" ixz="0" iyy="100" iyz="0" izz="100" />
        </inertial>
        <visual>
            <origin xyz="0 0 -0.141195713845689" rpy="0 0 0"/>
            <geometry>
                <box size="0.6080285468406206 0.8745808830455332 0.282391427691378" />
            </geometry>
            <material name="Green">
                <color rgba="0 128 0 1"/>
            </material>
        </visual>
        <collision>
            <origin xyz="0 0 -0.141195713845689" rpy="0 0 0"/>
            <geometry>
                <box size="0.6080285468406206 0.8745808830455332 0.282391427691378" />
            </geometry>
        </collision>
    </link>
    <joint name="15_16" type="revolute">
       <parent link="15"/>
       <child  link="16"/>
       <origin rpy="0 0 0" xyz="0 0 -0.03061983064297823" />
     <axis xyz="0 1 1"/>
       <limit effort="0.0" lower="-3.14159" upper="3.14159" velocity="0.0"/>
    </joint>
    <link name="17">
        <inertial>
            <origin xyz="0 -0.0916966559036394 0" rpy="0 0 0"/>
            <mass value="1" />
            <inertia ixx="100" ixy="0" ixz="0" iyy="100" iyz="0" izz="100" />
        </inertial>
        <visual>
            <origin xyz="0 -0.0916966559036394 0" rpy="0 0 0"/>
            <geometry>
                <box size="0.5408850261640898 0.1833933118072788 0.28011077671894125" />
            </geometry>
            <material name="Green">
                <color rgba="0 128 0 1"/>
            </material>
        </visual>
        <collision>
            <origin xyz="0 -0.0916966559036394 0" rpy="0 0 0"/>
            <geometry>
                <box size="0.5408850261640898 0.1833933118072788 0.28011077671894125" />
            </geometry>
        </collision>
    </link>
    <joint name="0_17" type="revolute">
       <parent link="0"/>
       <child  link="17"/>
       <origin rpy="0 0 0" xyz="0 -0.75 1" />
     <axis xyz="1 1 0"/>
       <limit effort="0.0" lower="-3.14159" upper="3.14159" velocity="0.0"/>
    </joint>
    <link name="18">
        <inertial>
            <origin xyz="0 -0.3479864279121 0" rpy="0 0 0"/>
            <mass value="1" />
            <inertia ixx="100" ixy="0" ixz="0" iyy="100" iyz="0" izz="100" />
        </inertial>
        <visual>
            <origin xyz="0 -0.3479864279121 0" rpy="0 0 0"/>
            <geometry>
                <box size="0.1358704367952731 0.6959728558242 0.23398541815765006" />
            </geometry>
            <material name="Blue">
                <color rgba="0 0 255 1"/>
            </material>
        </visual>
        <collision>
            <origin xyz="0 -0.3479864279121 0" rpy="0 0 0"/>
            <geometry>
                <box size="0.1358704367952731 0.6959728558242 0.23398541815765006" />
            </geometry>
        </collision>
    </link>
    <joint name="17_18" type="revolute">
       <parent link="17"/>
       <child  link="18"/>
       <origin rpy="0 0 0" xyz="0 -0.1833933118072788 0" />
     <axis xyz="1 0 1"/>
       <limit effort="0.0" lower="-3.14159" upper="3.14159" velocity="0.0"/>
    </joint>
    <link name="19">
        <inertial>
            <origin xyz="0 -0.1622783893416498 0" rpy="0 0 0"/>
            <mass value="1" />
            <inertia ixx="100" ixy="0" ixz="0" iyy="100" iyz="0" izz="100" />
        </inertial>
        <visual>
            <origin xyz="0 -0.1622783893416498 0" rpy="0 0 0"/>
            <geometry>
                <box size="0.49511178011536494 0.3245567786832996 0.7952145078214428" />
            </geometry>
            <material name="Green">
                <color rgba="0 128 0 1"/>
            </material>
        </visual>
        <collision>
            <origin xyz="0 -0.1622783893416498 0" rpy="0 0 0"/>
            <geometry>
                <box size="0.49511178011536494 0.3245567786832996 0.7952145078214428" />
            </geometry>
        </collision>
    </link>
    <joint name="18_19" type="revolute">
       <parent link="18"/>
       <child  link="19"/>
       <origin rpy="0 0 0" xyz="0 -0.6959728558242 0" />
     <axis xyz="1 1 0"/>
       <limit effort="0.0" lower="-3.14159" upper="3.14159" velocity="0.0"/>
    </joint>
    <link name="20">
        <inertial>
            <origin xyz="0 -0.4473550612667158 0" rpy="0 0 0"/>
            <mass value="1" />
            <inertia ixx="100" ixy="0" ixz="0" iyy="100" iyz="0" izz="100" />
        </inertial>
        <visual>
            <origin xyz="0 -0.4473550612667158 0" rpy="0 0 0"/>
            <geometry>
                <box size="0.30724840862073266 0.8947101225334316 0.7671233168914953" />
            </geometry>
            <material name="Blue">
                <color rgba="0 0 255 1"/>
            </material>
        </visual>
        <collision>
            <origin xyz="0 -0.4473550612667158 0" rpy="0 0 0"/>
            <geometry>
                <box size="0.30724840862073266 0.8947101225334316 0.7671233168914953" />
            </geometry>
        </collision>
    </link>
    <joint name="19_20" type="revolute">
       <parent link="19"/>
       <child  link="20"/>
       <origin rpy="0 0 0" xyz="0 -0.3245567786832996 0" />
     <axis xyz="1 1 0"/>
       <limit effort="0.0" lower="-3.14159" upper="3.14159" velocity="0.0"/>
    </joint>
    <link name="21">
        <inertial>
            <origin xyz="0 -0.4967477139518421 0" rpy="0 0 0"/>
            <mass value="1" />
            <inertia ixx="100" ixy="0" ixz="0" iyy="100" iyz="0" izz="100" />
        </inertial>
        <visual>
            <origin xyz="0 -0.4967477139518421 0" rpy="0 0 0"/>
            <geometry>
                <box size="0.2366259920338113 0.9934954279036842 0.6356783474765714" />
            </geometry>
            <material name="Green">
                <color rgba="0 128 0 1"/>
            </material>
        </visual>
        <collision>
            <origin xyz="0 -0.4967477139518421 0" rpy="0 0 0"/>
            <geometry>
                <box size="0.2366259920338113 0.9934954279036842 0.6356783474765714" />
            </geometry>
        </collision>
    </link>
    <joint name="20_21" type="revolute">
       <parent link="20"/>
       <child  link="21"/>
       <origin rpy="0 0 0" xyz="0 -0.8947101225334316 0" />
     <axis xyz="0 0 1"/>
       <limit effort="0.0" lower="-3.14159" upper="3.14159" velocity="0.0"/>
    </joint>
    <link name="22">
        <inertial>
            <origin xyz="0 0 -0.012844465318437592" rpy="0 0 0"/>
            <mass value="1" />
            <inertia ixx="100" ixy="0" ixz="0" iyy="100" iyz="0" izz="100" />
        </inertial>
        <visual>
            <origin xyz="0 0 -0.012844465318437592" rpy="0 0 0"/>
            <geometry>
                <box size="0.7627696266282772 0.9680326807214519 0.025688930636875183" />
            </geometry>
            <material name="Blue">
                <color rgba="0 0 255 1"/>
            </material>
        </visual>
        <collision>
            <origin xyz="0 0 -0.012844465318437592" rpy="0 0 0"/>
            <geometry>
                <box size="0.7627696266282772 0.9680326807214519 0.025688930636875183" />
            </geometry>
        </collision>
    </link>
    <joint name="21_22" type="revolute">
       <parent link="21"/>
       <child  link="22"/>
       <origin rpy="0 0 0" xyz="0 -0.4967477139518421 -0.3178391737382857" />
     <axis xyz="1 1 1"/>
       <limit effort="0.0" lower="-3.14159" upper="3.14159" velocity="0.0"/>
    </joint>
    <link name="23">
        <inertial>
            <origin xyz="0 0 -0.03516559037612908" rpy="0 0 0"/>
            <mass value="1" />
            <inertia ixx="100" ixy="0" ixz="0" iyy="100" iyz="0" izz="100" />
        </inertial>
        <visual>
            <origin xyz="0 0 -0.03516559037612908" rpy="0 0 0"/>
            <geometry>
                <box size="0.3167421426925294 0.6811689086568431 0.07033118075225817" />
            </geometry>
            <material name="Green">
                <color rgba="0 128 0 1"/>
            </material>
        </visual>
        <collision>
            <origin xyz="0 0 -0.03516559037612908" rpy="0 0 0"/>
            <geometry>
                <box size="0.3167421426925294 0.6811689086568431 0.07033118075225817" />
            </geometry>
        </collision>
    </link>
    <joint name="22_23" type="revolute">
       <parent link="22"/>
       <child  link="23"/>
       <origin rpy="0 0 0" xyz="0 0 -0.025688930636875183" />
     <axis xyz="0 0 1"/>
       <limit effort="0.0" lower="-3.14159" upper="3.14159" velocity="0.0"/>
    </joint>
    <link name="24">
        <inertial>
            <origin xyz="0 0 -0.2519899443054333" rpy="0 0 0"/>
            <mass value="1" />
            <inertia ixx="100" ixy="0" ixz="0" iyy="100" iyz="0" izz="100" />
        </inertial>
        <visual>
            <origin xyz="0 0 -0.2519899443054333" rpy="0 0 0"/>
            <geometry>
                <box size="0.6979862016870874 0.925954226814328 0.5039798886108666" />
            </geometry>
            <material name="Green">
                <color rgba="0 128 0 1"/>
            </material>
        </visual>
        <collision>
            <origin xyz="0 0 -0.2519899443054333" rpy="0 0 0"/>
            <geometry>
                <box size="0.6979862016870874 0.925954226814328 0.5039798886108666" />
            </geometry>
        </collision>
    </link>
    <joint name="23_24" type="revolute">
       <parent link="23"/>
       <child  link="24"/>
       <origin rpy="0 0 0" xyz="0 0 -0.07033118075225817" />
     <axis xyz="1 0 1"/>
       <limit effort="0.0" lower="-3.14159" upper="3.14159" velocity="0.0"/>
    </joint>
    <link name="25">
        <inertial>
            <origin xyz="0 0.05993548150523431 0" rpy="0 0 0"/>
            <mass value="1" />
            <inertia ixx="100" ixy="0" ixz="0" iyy="100" iyz="0" izz="100" />
        </inertial>
        <visual>
            <origin xyz="0 0.05993548150523431 0" rpy="0 0 0"/>
            <geometry>
                <box size="0.5172486977427876 0.11987096301046862 0.5034572387314452" />
            </geometry>
            <material name="Green">
                <color rgba="0 128 0 1"/>
            </material>
        </visual>
        <collision>
            <origin xyz="0 0.05993548150523431 0" rpy="0 0 0"/>
            <geometry>
                <box size="0.5172486977427876 0.11987096301046862 0.5034572387314452" />
            </geometry>
        </collision>
    </link>
    <joint name="0_25" type="revolute">
       <parent link="0"/>
       <child  link="25"/>
       <origin rpy="0 0 0" xyz="0 0.75 1" />
     <axis xyz="1 0 0"/>
       <limit effort="0.0" lower="-3.14159" upper="3.14159" velocity="0.0"/>
    </joint>
    <link name="26">
        <inertial>
            <origin xyz="0 0.007767578425682764 0" rpy="0 0 0"/>
            <mass value="1" />
            <inertia ixx="100" ixy="0" ixz="0" iyy="100" iyz="0" izz="100" />
        </inertial>
        <visual>
            <origin xyz="0 0.007767578425682764 0" rpy="0 0 0"/>
            <geometry>
                <box size="0.015302383075487258 0.015535156851365528 0.19781618345487317" />
            </geometry>
            <material name="Green">
                <color rgba="0 128 0 1"/>
            </material>
        </visual>
        <collision>
            <origin xyz="0 0.007767578425682764 0" rpy="0 0 0"/>
            <geometry>
                <box size="0.015302383075487258 0.015535156851365528 0.19781618345487317" />
            </geometry>
        </collision>
    </link>
    <joint name="25_26" type="revolute">
       <parent link="25"/>
       <child  link="26"/>
       <origin rpy="0 0 0" xyz="0 0.11987096301046862 0" />
     <axis xyz="0 0 1"/>
       <limit effort="0.0" lower="-3.14159" upper="3.14159" velocity="0.0"/>
    </joint>
    <link name="27">
        <inertial>
            <origin xyz="0 0.013924006697171198 0" rpy="0 0 0"/>
            <mass value="1" />
            <inertia ixx="100" ixy="0" ixz="0" iyy="100" iyz="0" izz="100" />
        </inertial>
        <visual>
            <origin xyz="0 0.013924006697171198 0" rpy="0 0 0"/>
            <geometry>
                <box size="0.09978541578322431 0.027848013394342397 0.7823184518346653" />
            </geometry>
            <material name="Green">
                <color rgba="0 128 0 1"/>
            </material>
        </visual>
        <collision>
            <origin xyz="0 0.013924006697171198 0" rpy="0 0 0"/>
            <geometry>
                <box size="0.09978541578322431 0.027848013394342397 0.7823184518346653" />
            </geometry>
        </collision>
    </link>
    <joint name="26_27" type="revolute">
       <parent link="26"/>
       <child  link="27"/>
       <origin rpy="0 0 0" xyz="0 0.015535156851365528 0" />
     <axis xyz="0 0 1"/>
       <limit effort="0.0" lower="-3.14159" upper="3.14159" velocity="0.0"/>
    </joint>
    <link name="28">
        <inertial>
            <origin xyz="0 0.3742410041150604 0" rpy="0 0 0"/>
            <mass value="1" />
            <inertia ixx="100" ixy="0" ixz="0" iyy="100" iyz="0" izz="100" />
        </inertial>
        <visual>
            <origin xyz="0 0.3742410041150604 0" rpy="0 0 0"/>
            <geometry>
                <box size="0.4428928737876371 0.7484820082301208 0.4262319442593673" />
            </geometry>
            <material name="Green">
                <color rgba="0 128 0 1"/>
            </material>
        </visual>
        <collision>
            <origin xyz="0 0.3742410041150604 0" rpy="0 0 0"/>
            <geometry>
                <box size="0.4428928737876371 0.7484820082301208 0.4262319442593673" />
            </geometry>
        </collision>
    </link>
    <joint name="27_28" type="revolute">
       <parent link="27"/>
       <child  link="28"/>
       <origin rpy="0 0 0" xyz="0 0.027848013394342397 0" />
     <axis xyz="0 0 1"/>
       <limit effort="0.0" lower="-3.14159" upper="3.14159" velocity="0.0"/>
    </joint>
    <link name="29">
        <inertial>
            <origin xyz="0 0.4556708789800863 0" rpy="0 0 0"/>
            <mass value="1" />
            <inertia ixx="100" ixy="0" ixz="0" iyy="100" iyz="0" izz="100" />
        </inertial>
        <visual>
            <origin xyz="0 0.4556708789800863 0" rpy="0 0 0"/>
            <geometry>
                <box size="0.5317281662491153 0.9113417579601726 0.9666060564916121" />
            </geometry>
            <material name="Green">
                <color rgba="0 128 0 1"/>
            </material>
        </visual>
        <collision>
            <origin xyz="0 0.4556708789800863 0" rpy="0 0 0"/>
            <geometry>
                <box size="0.5317281662491153 0.9113417579601726 0.9666060564916121" />
            </geometry>
        </collision>
    </link>
    <joint name="28_29" type="revolute">
       <parent link="28"/>
       <child  link="29"/>
       <origin rpy="0 0 0" xyz="0 0.7484820082301208 0" />
     <axis xyz="1 0 0"/>
       <limit effort="0.0" lower="-3.14159" upper="3.14159" velocity="0.0"/>
    </joint>
    <link name="30">
        <inertial>
            <origin xyz="0 0 -0.1845351774911471" rpy="0 0 0"/>
            <mass value="1" />
            <inertia ixx="100" ixy="0" ixz="0" iyy="100" iyz="0" izz="100" />
        </inertial>
        <visual>
            <origin xyz="0 0 -0.1845351774911471" rpy="0 0 0"/>
            <geometry>
                <box size="0.6080742464997937 0.709620287168855 0.3690703549822942" />
            </geometry>
            <material name="Blue">
                <color rgba="0 0 255 1"/>
            </material>
        </visual>
        <collision>
            <origin xyz="0 0 -0.1845351774911471" rpy="0 0 0"/>
            <geometry>
                <box size="0.6080742464997937 0.709620287168855 0.3690703549822942" />
            </geometry>
        </collision>
    </link>
    <joint name="29_30" type="revolute">
       <parent link="29"/>
       <child  link="30"/>
       <origin rpy="0 0 0" xyz="0 0.4556708789800863 -0.48330302824580607" />
     <axis xyz="1 0 0"/>
       <limit effort="0.0" lower="-3.14159" upper="3.14159" velocity="0.0"/>
    </joint>
    <link name="31">
        <inertial>
            <origin xyz="0 0 -0.023396591939552965" rpy="0 0 0"/>
            <mass value="1" />
            <inertia ixx="100" ixy="0" ixz="0" iyy="100" iyz="0" izz="100" />
        </inertial>
        <visual>
            <origin xyz="0 0 -0.023396591939552965" rpy="0 0 0"/>
            <geometry>
                <box size="0.4387636861417733 0.3436757186385797 0.04679318387910593" />
            </geometry>
            <material name="Green">
                <color rgba="0 128 0 1"/>
            </material>
        </visual>
        <collision>
            <origin xyz="0 0 -0.023396591939552965" rpy="0 0 0"/>
            <geometry>
                <box size="0.4387636861417733 0.3436757186385797 0.04679318387910593" />
            </geometry>
        </collision>
    </link>
    <joint name="30_31" type="revolute">
       <parent link="30"/>
       <child  link="31"/>
       <origin rpy="0 0 0" xyz="0 0 -0.3690703549822942" />
     <axis xyz="0 0 1"/>
       <limit effort="0.0" lower="-3.14159" upper="3.14159" velocity="0.0"/>
    </joint>
    <link name="32">
        <inertial>
            <origin xyz="0 0 -0.09206823056929994" rpy="0 0 0"/>
            <mass value="1" />
            <inertia ixx="100" ixy="0" ixz="0" iyy="100" iyz="0" izz="100" />
        </inertial>
        <visual>
            <origin xyz="0 0 -0.09206823056929994" rpy="0 0 0"/>
            <geometry>
                <box size="0.4019331747730919 0.7580669776475717 0.18413646113859988" />
            </geometry>
            <material name="Green">
                <color rgba="0 128 0 1"/>
            </material>
        </visual>
        <collision>
            <origin xyz="0 0 -0.09206823056929994" rpy="0 0 0"/>
            <geometry>
                <box size="0.4019331747730919 0.7580669776475717 0.18413646113859988" />
            </geometry>
        </collision>
    </link>
    <joint name="31_32" type="revolute">
       <parent link="31"/>
       <child  link="32"/>
       <origin rpy="0 0 0" xyz="0 0 -0.04679318387910593" />
     <axis xyz="1 0 1"/>
       <limit effort="0.0" lower="-3.14159" upper="3.14159" velocity="0.0"/>
    </joint>
</robot>