<robot name = "robot">
    <link name="0">
        <inertial>
            <origin xyz="0 0 0.35" rpy="0 0 0"/>
            <mass value="1" />
            <inertia ixx="100" ixy="0" ixz="0" iyy="100" iyz="0" izz="100" />
        </inertial>
        <visual>
            <origin xyz="0 0 0.35" rpy="0 0 0"/>
            <geometry>
                <box size="0.7 0.7 0.7" />
            </geometry>
            <material name="Green">
                <color rgba="0 128 0 1"/>
            </material>
        </visual>
        <collision>
            <origin xyz="0 0 0.35" rpy="0 0 0"/>
            <geometry>
                <box size="0.7 0.7 0.7" />
            </geometry>
        </collision>
    </link>
    <link name="1">
        <inertial>
            <origin xyz="-0.1237777442537547 0 0.44948360617992716" rpy="0 0 0"/>
            <mass value="1" />
            <inertia ixx="100" ixy="0" ixz="0" iyy="100" iyz="0" izz="100" />
        </inertial>
        <visual>
            <origin xyz="-0.1237777442537547 0 0.44948360617992716" rpy="0 0 0"/>
            <geometry>
                <box size="0.2475554885075094 0.32390217264830157 0.8989672123598543" />
            </geometry>
            <material name="Blue">
                <color rgba="0 0 255 1"/>
            </material>
        </visual>
        <collision>
            <origin xyz="-0.1237777442537547 0 0.44948360617992716" rpy="0 0 0"/>
            <geometry>
                <box size="0.2475554885075094 0.32390217264830157 0.8989672123598543" />
            </geometry>
        </collision>
    </link>
    <joint name="0_1" type="revolute">
       <parent link="0"/>
       <child  link="1"/>
       <origin rpy="0 0 0" xyz="-0.35 0 0.7" />
     <axis xyz="1 0 0"/>
       <limit effort="0.0" lower="-3.14159" upper="3.14159" velocity="0.0"/>
    </joint>
    <link name="2">
        <inertial>
            <origin xyz="-0.47268137215051226 0 0.2877808220990839" rpy="0 0 0"/>
            <mass value="1" />
            <inertia ixx="100" ixy="0" ixz="0" iyy="100" iyz="0" izz="100" />
        </inertial>
        <visual>
            <origin xyz="-0.47268137215051226 0 0.2877808220990839" rpy="0 0 0"/>
            <geometry>
                <box size="0.9453627443010245 0.5975797659651996 0.5755616441981678" />
            </geometry>
            <material name="Blue">
                <color rgba="0 0 255 1"/>
            </material>
        </visual>
        <collision>
            <origin xyz="-0.47268137215051226 0 0.2877808220990839" rpy="0 0 0"/>
            <geometry>
                <box size="0.9453627443010245 0.5975797659651996 0.5755616441981678" />
            </geometry>
        </collision>
    </link>
    <joint name="1_2" type="revolute">
       <parent link="1"/>
       <child  link="2"/>
       <origin rpy="0 0 0" xyz="-0.2475554885075094 0 0.8989672123598543" />
     <axis xyz="0 0 1"/>
       <limit effort="0.0" lower="-3.14159" upper="3.14159" velocity="0.0"/>
    </joint>
    <link name="3">
        <inertial>
            <origin xyz="-0.016545489149439763 0 0.3829902446484259" rpy="0 0 0"/>
            <mass value="1" />
            <inertia ixx="100" ixy="0" ixz="0" iyy="100" iyz="0" izz="100" />
        </inertial>
        <visual>
            <origin xyz="-0.016545489149439763 0 0.3829902446484259" rpy="0 0 0"/>
            <geometry>
                <box size="0.033090978298879525 0.30482404138373553 0.7659804892968518" />
            </geometry>
            <material name="Green">
                <color rgba="0 128 0 1"/>
            </material>
        </visual>
        <collision>
            <origin xyz="-0.016545489149439763 0 0.3829902446484259" rpy="0 0 0"/>
            <geometry>
                <box size="0.033090978298879525 0.30482404138373553 0.7659804892968518" />
            </geometry>
        </collision>
    </link>
    <joint name="2_3" type="revolute">
       <parent link="2"/>
       <child  link="3"/>
       <origin rpy="0 0 0" xyz="-0.9453627443010245 0 0.5755616441981678" />
     <axis xyz="1 0 0"/>
       <limit effort="0.0" lower="-3.14159" upper="3.14159" velocity="0.0"/>
    </joint>
    <link name="4">
        <inertial>
            <origin xyz="-0.4539901457246725 0 0.19408913233369324" rpy="0 0 0"/>
            <mass value="1" />
            <inertia ixx="100" ixy="0" ixz="0" iyy="100" iyz="0" izz="100" />
        </inertial>
        <visual>
            <origin xyz="-0.4539901457246725 0 0.19408913233369324" rpy="0 0 0"/>
            <geometry>
                <box size="0.907980291449345 0.6192211758663223 0.3881782646673865" />
            </geometry>
            <material name="Green">
                <color rgba="0 128 0 1"/>
            </material>
        </visual>
        <collision>
            <origin xyz="-0.4539901457246725 0 0.19408913233369324" rpy="0 0 0"/>
            <geometry>
                <box size="0.907980291449345 0.6192211758663223 0.3881782646673865" />
            </geometry>
        </collision>
    </link>
    <joint name="3_4" type="revolute">
       <parent link="3"/>
       <child  link="4"/>
       <origin rpy="0 0 0" xyz="-0.033090978298879525 0 0.7659804892968518" />
     <axis xyz="1 1 1"/>
       <limit effort="0.0" lower="-3.14159" upper="3.14159" velocity="0.0"/>
    </joint>
    <link name="5">
        <inertial>
            <origin xyz="-0.2363432610377506 0 0.32142484840645014" rpy="0 0 0"/>
            <mass value="1" />
            <inertia ixx="100" ixy="0" ixz="0" iyy="100" iyz="0" izz="100" />
        </inertial>
        <visual>
            <origin xyz="-0.2363432610377506 0 0.32142484840645014" rpy="0 0 0"/>
            <geometry>
                <box size="0.4726865220755012 0.5741934290148311 0.6428496968129003" />
            </geometry>
            <material name="Blue">
                <color rgba="0 0 255 1"/>
            </material>
        </visual>
        <collision>
            <origin xyz="-0.2363432610377506 0 0.32142484840645014" rpy="0 0 0"/>
            <geometry>
                <box size="0.4726865220755012 0.5741934290148311 0.6428496968129003" />
            </geometry>
        </collision>
    </link>
    <joint name="4_5" type="revolute">
       <parent link="4"/>
       <child  link="5"/>
       <origin rpy="0 0 0" xyz="-0.907980291449345 0 0.3881782646673865" />
     <axis xyz="0 1 0"/>
       <limit effort="0.0" lower="-3.14159" upper="3.14159" velocity="0.0"/>
    </joint>
    <link name="6">
        <inertial>
            <origin xyz="0 -0.09655323071211702 0.029000588111710357" rpy="0 0 0"/>
            <mass value="1" />
            <inertia ixx="100" ixy="0" ixz="0" iyy="100" iyz="0" izz="100" />
        </inertial>
        <visual>
            <origin xyz="0 -0.09655323071211702 0.029000588111710357" rpy="0 0 0"/>
            <geometry>
                <box size="0.22485779431363317 0.19310646142423404 0.058001176223420714" />
            </geometry>
            <material name="Green">
                <color rgba="0 128 0 1"/>
            </material>
        </visual>
        <collision>
            <origin xyz="0 -0.09655323071211702 0.029000588111710357" rpy="0 0 0"/>
            <geometry>
                <box size="0.22485779431363317 0.19310646142423404 0.058001176223420714" />
            </geometry>
        </collision>
    </link>
    <joint name="0_6" type="revolute">
       <parent link="0"/>
       <child  link="6"/>
       <origin rpy="0 0 0" xyz="0 -0.35 0.7" />
     <axis xyz="1 0 0"/>
       <limit effort="0.0" lower="-3.14159" upper="3.14159" velocity="0.0"/>
    </joint>
    <link name="7">
        <inertial>
            <origin xyz="0 -0.43534881123345875 0.29749016024024405" rpy="0 0 0"/>
            <mass value="1" />
            <inertia ixx="100" ixy="0" ixz="0" iyy="100" iyz="0" izz="100" />
        </inertial>
        <visual>
            <origin xyz="0 -0.43534881123345875 0.29749016024024405" rpy="0 0 0"/>
            <geometry>
                <box size="0.9053995754325951 0.8706976224669175 0.5949803204804881" />
            </geometry>
            <material name="Green">
                <color rgba="0 128 0 1"/>
            </material>
        </visual>
        <collision>
            <origin xyz="0 -0.43534881123345875 0.29749016024024405" rpy="0 0 0"/>
            <geometry>
                <box size="0.9053995754325951 0.8706976224669175 0.5949803204804881" />
            </geometry>
        </collision>
    </link>
    <joint name="6_7" type="revolute">
       <parent link="6"/>
       <child  link="7"/>
       <origin rpy="0 0 0" xyz="0 -0.19310646142423404 0.058001176223420714" />
     <axis xyz="1 1 1"/>
       <limit effort="0.0" lower="-3.14159" upper="3.14159" velocity="0.0"/>
    </joint>
    <link name="8">
        <inertial>
            <origin xyz="0 0.40963086488596684 0.30193331946862606" rpy="0 0 0"/>
            <mass value="1" />
            <inertia ixx="100" ixy="0" ixz="0" iyy="100" iyz="0" izz="100" />
        </inertial>
        <visual>
            <origin xyz="0 0.40963086488596684 0.30193331946862606" rpy="0 0 0"/>
            <geometry>
                <box size="0.5157052709359831 0.8192617297719337 0.6038666389372521" />
            </geometry>
            <material name="Green">
                <color rgba="0 128 0 1"/>
            </material>
        </visual>
        <collision>
            <origin xyz="0 0.40963086488596684 0.30193331946862606" rpy="0 0 0"/>
            <geometry>
                <box size="0.5157052709359831 0.8192617297719337 0.6038666389372521" />
            </geometry>
        </collision>
    </link>
    <joint name="0_8" type="revolute">
       <parent link="0"/>
       <child  link="8"/>
       <origin rpy="0 0 0" xyz="0 0.35 0.7" />
     <axis xyz="1 1 0"/>
       <limit effort="0.0" lower="-3.14159" upper="3.14159" velocity="0.0"/>
    </joint>
    <link name="9">
        <inertial>
            <origin xyz="0 0.006717358650637717 0.20576376657452383" rpy="0 0 0"/>
            <mass value="1" />
            <inertia ixx="100" ixy="0" ixz="0" iyy="100" iyz="0" izz="100" />
        </inertial>
        <visual>
            <origin xyz="0 0.006717358650637717 0.20576376657452383" rpy="0 0 0"/>
            <geometry>
                <box size="0.7157095417260868 0.013434717301275434 0.41152753314904766" />
            </geometry>
            <material name="Blue">
                <color rgba="0 0 255 1"/>
            </material>
        </visual>
        <collision>
            <origin xyz="0 0.006717358650637717 0.20576376657452383" rpy="0 0 0"/>
            <geometry>
                <box size="0.7157095417260868 0.013434717301275434 0.41152753314904766" />
            </geometry>
        </collision>
    </link>
    <joint name="8_9" type="revolute">
       <parent link="8"/>
       <child  link="9"/>
       <origin rpy="0 0 0" xyz="0 0.8192617297719337 0.6038666389372521" />
     <axis xyz="1 1 0"/>
       <limit effort="0.0" lower="-3.14159" upper="3.14159" velocity="0.0"/>
    </joint>
    <link name="10">
        <inertial>
            <origin xyz="0 0.37041309190263183 0.1708121461277523" rpy="0 0 0"/>
            <mass value="1" />
            <inertia ixx="100" ixy="0" ixz="0" iyy="100" iyz="0" izz="100" />
        </inertial>
        <visual>
            <origin xyz="0 0.37041309190263183 0.1708121461277523" rpy="0 0 0"/>
            <geometry>
                <box size="0.8241477306523219 0.7408261838052637 0.3416242922555046" />
            </geometry>
            <material name="Blue">
                <color rgba="0 0 255 1"/>
            </material>
        </visual>
        <collision>
            <origin xyz="0 0.37041309190263183 0.1708121461277523" rpy="0 0 0"/>
            <geometry>
                <box size="0.8241477306523219 0.7408261838052637 0.3416242922555046" />
            </geometry>
        </collision>
    </link>
    <joint name="9_10" type="revolute">
       <parent link="9"/>
       <child  link="10"/>
       <origin rpy="0 0 0" xyz="0 0.013434717301275434 0.41152753314904766" />
     <axis xyz="0 1 1"/>
       <limit effort="0.0" lower="-3.14159" upper="3.14159" velocity="0.0"/>
    </joint>
</robot>