<robot name = "robot">
    <link name="0">
        <inertial>
            <origin xyz="0 0 3" rpy="0 0 0"/>
            <mass value="1" />
            <inertia ixx="100" ixy="0" ixz="0" iyy="100" iyz="0" izz="100" />
        </inertial>
        <visual>
            <origin xyz="0 0 3" rpy="0 0 0"/>
            <geometry>
                <box size="1.5 1.5 0.8" />
            </geometry>
            <material name="Blue">
                <color rgba="0 0 255 1"/>
            </material>
        </visual>
        <collision>
            <origin xyz="0 0 3" rpy="0 0 0"/>
            <geometry>
                <box size="1.5 1.5 0.8" />
            </geometry>
        </collision>
    </link>
    <link name="1">
        <inertial>
            <origin xyz="-0.37069460651675995 0 0" rpy="0 0 0"/>
            <mass value="1" />
            <inertia ixx="100" ixy="0" ixz="0" iyy="100" iyz="0" izz="100" />
        </inertial>
        <visual>
            <origin xyz="-0.37069460651675995 0 0" rpy="0 0 0"/>
            <geometry>
                <box size="0.7413892130335199 0.20705018286976684 0.9554501597575592" />
            </geometry>
            <material name="Blue">
                <color rgba="0 0 255 1"/>
            </material>
        </visual>
        <collision>
            <origin xyz="-0.37069460651675995 0 0" rpy="0 0 0"/>
            <geometry>
                <box size="0.7413892130335199 0.20705018286976684 0.9554501597575592" />
            </geometry>
        </collision>
    </link>
    <joint name="0_1" type="revolute">
       <parent link="0"/>
       <child  link="1"/>
       <origin rpy="0 0 0" xyz="-0.75 0 3" />
     <axis xyz="0 1 0"/>
       <limit effort="0.0" lower="-3.14159" upper="3.14159" velocity="0.0"/>
    </joint>
    <link name="2">
        <inertial>
            <origin xyz="-0.3864536582510198 0 0" rpy="0 0 0"/>
            <mass value="1" />
            <inertia ixx="100" ixy="0" ixz="0" iyy="100" iyz="0" izz="100" />
        </inertial>
        <visual>
            <origin xyz="-0.3864536582510198 0 0" rpy="0 0 0"/>
            <geometry>
                <box size="0.7729073165020396 0.006613930873738738 0.9521999253149412" />
            </geometry>
            <material name="Blue">
                <color rgba="0 0 255 1"/>
            </material>
        </visual>
        <collision>
            <origin xyz="-0.3864536582510198 0 0" rpy="0 0 0"/>
            <geometry>
                <box size="0.7729073165020396 0.006613930873738738 0.9521999253149412" />
            </geometry>
        </collision>
    </link>
    <joint name="1_2" type="revolute">
       <parent link="1"/>
       <child  link="2"/>
       <origin rpy="0 0 0" xyz="-0.7413892130335199 0 0" />
     <axis xyz="1 0 0"/>
       <limit effort="0.0" lower="-3.14159" upper="3.14159" velocity="0.0"/>
    </joint>
    <link name="3">
        <inertial>
            <origin xyz="0 0 -1.202223171453255" rpy="0 0 0"/>
            <mass value="1" />
            <inertia ixx="100" ixy="0" ixz="0" iyy="100" iyz="0" izz="100" />
        </inertial>
        <visual>
            <origin xyz="0 0 -1.202223171453255" rpy="0 0 0"/>
            <geometry>
                <box size="0.607029862893664 0.7226544184416467 2.40444634290651" />
            </geometry>
            <material name="Green">
                <color rgba="0 128 0 1"/>
            </material>
        </visual>
        <collision>
            <origin xyz="0 0 -1.202223171453255" rpy="0 0 0"/>
            <geometry>
                <box size="0.607029862893664 0.7226544184416467 2.40444634290651" />
            </geometry>
        </collision>
    </link>
    <joint name="2_3" type="revolute">
       <parent link="2"/>
       <child  link="3"/>
       <origin rpy="0 0 0" xyz="-0.3864536582510198 0 -0.4760999626574706" />
     <axis xyz="0 1 1"/>
       <limit effort="0.0" lower="-3.14159" upper="3.14159" velocity="0.0"/>
    </joint>
    <link name="4">
        <inertial>
            <origin xyz="0 0 -0.09091723656614215" rpy="0 0 0"/>
            <mass value="1" />
            <inertia ixx="100" ixy="0" ixz="0" iyy="100" iyz="0" izz="100" />
        </inertial>
        <visual>
            <origin xyz="0 0 -0.09091723656614215" rpy="0 0 0"/>
            <geometry>
                <box size="0.48172712336838963 0.9993172935098266 0.1818344731322843" />
            </geometry>
            <material name="Blue">
                <color rgba="0 0 255 1"/>
            </material>
        </visual>
        <collision>
            <origin xyz="0 0 -0.09091723656614215" rpy="0 0 0"/>
            <geometry>
                <box size="0.48172712336838963 0.9993172935098266 0.1818344731322843" />
            </geometry>
        </collision>
    </link>
    <joint name="3_4" type="revolute">
       <parent link="3"/>
       <child  link="4"/>
       <origin rpy="0 0 0" xyz="0 0 -2.40444634290651" />
     <axis xyz="0 0 1"/>
       <limit effort="0.0" lower="-3.14159" upper="3.14159" velocity="0.0"/>
    </joint>
    <link name="5">
        <inertial>
            <origin xyz="0 0 -0.00685959198060293" rpy="0 0 0"/>
            <mass value="1" />
            <inertia ixx="100" ixy="0" ixz="0" iyy="100" iyz="0" izz="100" />
        </inertial>
        <visual>
            <origin xyz="0 0 -0.00685959198060293" rpy="0 0 0"/>
            <geometry>
                <box size="0.694280295131426 0.6828982838147776 0.01371918396120586" />
            </geometry>
            <material name="Blue">
                <color rgba="0 0 255 1"/>
            </material>
        </visual>
        <collision>
            <origin xyz="0 0 -0.00685959198060293" rpy="0 0 0"/>
            <geometry>
                <box size="0.694280295131426 0.6828982838147776 0.01371918396120586" />
            </geometry>
        </collision>
    </link>
    <joint name="4_5" type="revolute">
       <parent link="4"/>
       <child  link="5"/>
       <origin rpy="0 0 0" xyz="0 0 -0.1818344731322843" />
     <axis xyz="1 0 0"/>
       <limit effort="0.0" lower="-3.14159" upper="3.14159" velocity="0.0"/>
    </joint>
    <link name="6">
        <inertial>
            <origin xyz="0.36841035025346425 0 0" rpy="0 0 0"/>
            <mass value="1" />
            <inertia ixx="100" ixy="0" ixz="0" iyy="100" iyz="0" izz="100" />
        </inertial>
        <visual>
            <origin xyz="0.36841035025346425 0 0" rpy="0 0 0"/>
            <geometry>
                <box size="0.7368207005069285 0.14437224385862946 0.5401709093729729" />
            </geometry>
            <material name="Green">
                <color rgba="0 128 0 1"/>
            </material>
        </visual>
        <collision>
            <origin xyz="0.36841035025346425 0 0" rpy="0 0 0"/>
            <geometry>
                <box size="0.7368207005069285 0.14437224385862946 0.5401709093729729" />
            </geometry>
        </collision>
    </link>
    <joint name="0_6" type="revolute">
       <parent link="0"/>
       <child  link="6"/>
       <origin rpy="0 0 0" xyz="0.75 0 3" />
     <axis xyz="0 1 0"/>
       <limit effort="0.0" lower="-3.14159" upper="3.14159" velocity="0.0"/>
    </joint>
    <link name="7">
        <inertial>
            <origin xyz="0.13598790678069167 0 0" rpy="0 0 0"/>
            <mass value="1" />
            <inertia ixx="100" ixy="0" ixz="0" iyy="100" iyz="0" izz="100" />
        </inertial>
        <visual>
            <origin xyz="0.13598790678069167 0 0" rpy="0 0 0"/>
            <geometry>
                <box size="0.27197581356138334 0.39329104324905817 0.6274942519805372" />
            </geometry>
            <material name="Green">
                <color rgba="0 128 0 1"/>
            </material>
        </visual>
        <collision>
            <origin xyz="0.13598790678069167 0 0" rpy="0 0 0"/>
            <geometry>
                <box size="0.27197581356138334 0.39329104324905817 0.6274942519805372" />
            </geometry>
        </collision>
    </link>
    <joint name="6_7" type="revolute">
       <parent link="6"/>
       <child  link="7"/>
       <origin rpy="0 0 0" xyz="0.7368207005069285 0 0" />
     <axis xyz="0 1 1"/>
       <limit effort="0.0" lower="-3.14159" upper="3.14159" velocity="0.0"/>
    </joint>
    <link name="8">
        <inertial>
            <origin xyz="0 0 -0.8264226480589983" rpy="0 0 0"/>
            <mass value="1" />
            <inertia ixx="100" ixy="0" ixz="0" iyy="100" iyz="0" izz="100" />
        </inertial>
        <visual>
            <origin xyz="0 0 -0.8264226480589983" rpy="0 0 0"/>
            <geometry>
                <box size="0.9882307839224356 0.0766248145290046 1.6528452961179967" />
            </geometry>
            <material name="Blue">
                <color rgba="0 0 255 1"/>
            </material>
        </visual>
        <collision>
            <origin xyz="0 0 -0.8264226480589983" rpy="0 0 0"/>
            <geometry>
                <box size="0.9882307839224356 0.0766248145290046 1.6528452961179967" />
            </geometry>
        </collision>
    </link>
    <joint name="7_8" type="revolute">
       <parent link="7"/>
       <child  link="8"/>
       <origin rpy="0 0 0" xyz="0.13598790678069167 0 -0.3137471259902686" />
     <axis xyz="1 1 0"/>
       <limit effort="0.0" lower="-3.14159" upper="3.14159" velocity="0.0"/>
    </joint>
    <link name="9">
        <inertial>
            <origin xyz="0 0 -0.4645872380144684" rpy="0 0 0"/>
            <mass value="1" />
            <inertia ixx="100" ixy="0" ixz="0" iyy="100" iyz="0" izz="100" />
        </inertial>
        <visual>
            <origin xyz="0 0 -0.4645872380144684" rpy="0 0 0"/>
            <geometry>
                <box size="0.6172446398944612 0.43228176829889764 0.9291744760289368" />
            </geometry>
            <material name="Blue">
                <color rgba="0 0 255 1"/>
            </material>
        </visual>
        <collision>
            <origin xyz="0 0 -0.4645872380144684" rpy="0 0 0"/>
            <geometry>
                <box size="0.6172446398944612 0.43228176829889764 0.9291744760289368" />
            </geometry>
        </collision>
    </link>
    <joint name="8_9" type="revolute">
       <parent link="8"/>
       <child  link="9"/>
       <origin rpy="0 0 0" xyz="0 0 -1.6528452961179967" />
     <axis xyz="0 1 1"/>
       <limit effort="0.0" lower="-3.14159" upper="3.14159" velocity="0.0"/>
    </joint>
    <link name="10">
        <inertial>
            <origin xyz="0 0 -0.008990113926533316" rpy="0 0 0"/>
            <mass value="1" />
            <inertia ixx="100" ixy="0" ixz="0" iyy="100" iyz="0" izz="100" />
        </inertial>
        <visual>
            <origin xyz="0 0 -0.008990113926533316" rpy="0 0 0"/>
            <geometry>
                <box size="0.7823485154007369 0.146166709221771 0.017980227853066633" />
            </geometry>
            <material name="Green">
                <color rgba="0 128 0 1"/>
            </material>
        </visual>
        <collision>
            <origin xyz="0 0 -0.008990113926533316" rpy="0 0 0"/>
            <geometry>
                <box size="0.7823485154007369 0.146166709221771 0.017980227853066633" />
            </geometry>
        </collision>
    </link>
    <joint name="9_10" type="revolute">
       <parent link="9"/>
       <child  link="10"/>
       <origin rpy="0 0 0" xyz="0 0 -0.9291744760289368" />
     <axis xyz="1 0 1"/>
       <limit effort="0.0" lower="-3.14159" upper="3.14159" velocity="0.0"/>
    </joint>
    <link name="11">
        <inertial>
            <origin xyz="0 -0.20360288711185193 0" rpy="0 0 0"/>
            <mass value="1" />
            <inertia ixx="100" ixy="0" ixz="0" iyy="100" iyz="0" izz="100" />
        </inertial>
        <visual>
            <origin xyz="0 -0.20360288711185193 0" rpy="0 0 0"/>
            <geometry>
                <box size="0.058564009576889564 0.40720577422370385 0.22750226010361774" />
            </geometry>
            <material name="Green">
                <color rgba="0 128 0 1"/>
            </material>
        </visual>
        <collision>
            <origin xyz="0 -0.20360288711185193 0" rpy="0 0 0"/>
            <geometry>
                <box size="0.058564009576889564 0.40720577422370385 0.22750226010361774" />
            </geometry>
        </collision>
    </link>
    <joint name="0_11" type="revolute">
       <parent link="0"/>
       <child  link="11"/>
       <origin rpy="0 0 0" xyz="0 -0.75 3" />
     <axis xyz="0 0 1"/>
       <limit effort="0.0" lower="-3.14159" upper="3.14159" velocity="0.0"/>
    </joint>
    <link name="12">
        <inertial>
            <origin xyz="0 -0.4522732959792121 0" rpy="0 0 0"/>
            <mass value="1" />
            <inertia ixx="100" ixy="0" ixz="0" iyy="100" iyz="0" izz="100" />
        </inertial>
        <visual>
            <origin xyz="0 -0.4522732959792121 0" rpy="0 0 0"/>
            <geometry>
                <box size="0.6801850686777455 0.9045465919584242 0.8452121809195875" />
            </geometry>
            <material name="Green">
                <color rgba="0 128 0 1"/>
            </material>
        </visual>
        <collision>
            <origin xyz="0 -0.4522732959792121 0" rpy="0 0 0"/>
            <geometry>
                <box size="0.6801850686777455 0.9045465919584242 0.8452121809195875" />
            </geometry>
        </collision>
    </link>
    <joint name="11_12" type="revolute">
       <parent link="11"/>
       <child  link="12"/>
       <origin rpy="0 0 0" xyz="0 -0.40720577422370385 0" />
     <axis xyz="1 1 1"/>
       <limit effort="0.0" lower="-3.14159" upper="3.14159" velocity="0.0"/>
    </joint>
    <link name="13">
        <inertial>
            <origin xyz="0 0 -0.471722555302093" rpy="0 0 0"/>
            <mass value="1" />
            <inertia ixx="100" ixy="0" ixz="0" iyy="100" iyz="0" izz="100" />
        </inertial>
        <visual>
            <origin xyz="0 0 -0.471722555302093" rpy="0 0 0"/>
            <geometry>
                <box size="0.798350853880641 0.8631314336171133 0.943445110604186" />
            </geometry>
            <material name="Green">
                <color rgba="0 128 0 1"/>
            </material>
        </visual>
        <collision>
            <origin xyz="0 0 -0.471722555302093" rpy="0 0 0"/>
            <geometry>
                <box size="0.798350853880641 0.8631314336171133 0.943445110604186" />
            </geometry>
        </collision>
    </link>
    <joint name="12_13" type="revolute">
       <parent link="12"/>
       <child  link="13"/>
       <origin rpy="0 0 0" xyz="0 -0.4522732959792121 -0.42260609045979375" />
     <axis xyz="1 1 0"/>
       <limit effort="0.0" lower="-3.14159" upper="3.14159" velocity="0.0"/>
    </joint>
    <link name="14">
        <inertial>
            <origin xyz="0 0 -0.706768977759157" rpy="0 0 0"/>
            <mass value="1" />
            <inertia ixx="100" ixy="0" ixz="0" iyy="100" iyz="0" izz="100" />
        </inertial>
        <visual>
            <origin xyz="0 0 -0.706768977759157" rpy="0 0 0"/>
            <geometry>
                <box size="0.5592081428360037 0.8365339594052246 1.413537955518314" />
            </geometry>
            <material name="Green">
                <color rgba="0 128 0 1"/>
            </material>
        </visual>
        <collision>
            <origin xyz="0 0 -0.706768977759157" rpy="0 0 0"/>
            <geometry>
                <box size="0.5592081428360037 0.8365339594052246 1.413537955518314" />
            </geometry>
        </collision>
    </link>
    <joint name="13_14" type="revolute">
       <parent link="13"/>
       <child  link="14"/>
       <origin rpy="0 0 0" xyz="0 0 -0.943445110604186" />
     <axis xyz="0 0 1"/>
       <limit effort="0.0" lower="-3.14159" upper="3.14159" velocity="0.0"/>
    </joint>
    <link name="15">
        <inertial>
            <origin xyz="0 0 -0.12150846693875006" rpy="0 0 0"/>
            <mass value="1" />
            <inertia ixx="100" ixy="0" ixz="0" iyy="100" iyz="0" izz="100" />
        </inertial>
        <visual>
            <origin xyz="0 0 -0.12150846693875006" rpy="0 0 0"/>
            <geometry>
                <box size="0.7768344668315491 0.21297059764690807 0.24301693387750012" />
            </geometry>
            <material name="Green">
                <color rgba="0 128 0 1"/>
            </material>
        </visual>
        <collision>
            <origin xyz="0 0 -0.12150846693875006" rpy="0 0 0"/>
            <geometry>
                <box size="0.7768344668315491 0.21297059764690807 0.24301693387750012" />
            </geometry>
        </collision>
    </link>
    <joint name="14_15" type="revolute">
       <parent link="14"/>
       <child  link="15"/>
       <origin rpy="0 0 0" xyz="0 0 -1.413537955518314" />
     <axis xyz="1 0 0"/>
       <limit effort="0.0" lower="-3.14159" upper="3.14159" velocity="0.0"/>
    </joint>
    <link name="16">
        <inertial>
            <origin xyz="0 0.10722202098914058 0" rpy="0 0 0"/>
            <mass value="1" />
            <inertia ixx="100" ixy="0" ixz="0" iyy="100" iyz="0" izz="100" />
        </inertial>
        <visual>
            <origin xyz="0 0.10722202098914058 0" rpy="0 0 0"/>
            <geometry>
                <box size="0.555649869965671 0.21444404197828115 0.09186982883451733" />
            </geometry>
            <material name="Blue">
                <color rgba="0 0 255 1"/>
            </material>
        </visual>
        <collision>
            <origin xyz="0 0.10722202098914058 0" rpy="0 0 0"/>
            <geometry>
                <box size="0.555649869965671 0.21444404197828115 0.09186982883451733" />
            </geometry>
        </collision>
    </link>
    <joint name="0_16" type="revolute">
       <parent link="0"/>
       <child  link="16"/>
       <origin rpy="0 0 0" xyz="0 0.75 3" />
     <axis xyz="0 0 1"/>
       <limit effort="0.0" lower="-3.14159" upper="3.14159" velocity="0.0"/>
    </joint>
    <link name="17">
        <inertial>
            <origin xyz="0 0.4076358751801879 0" rpy="0 0 0"/>
            <mass value="1" />
            <inertia ixx="100" ixy="0" ixz="0" iyy="100" iyz="0" izz="100" />
        </inertial>
        <visual>
            <origin xyz="0 0.4076358751801879 0" rpy="0 0 0"/>
            <geometry>
                <box size="0.29415047328457766 0.8152717503603758 0.13634611766778815" />
            </geometry>
            <material name="Green">
                <color rgba="0 128 0 1"/>
            </material>
        </visual>
        <collision>
            <origin xyz="0 0.4076358751801879 0" rpy="0 0 0"/>
            <geometry>
                <box size="0.29415047328457766 0.8152717503603758 0.13634611766778815" />
            </geometry>
        </collision>
    </link>
    <joint name="16_17" type="revolute">
       <parent link="16"/>
       <child  link="17"/>
       <origin rpy="0 0 0" xyz="0 0.21444404197828115 0" />
     <axis xyz="1 0 0"/>
       <limit effort="0.0" lower="-3.14159" upper="3.14159" velocity="0.0"/>
    </joint>
    <link name="18">
        <inertial>
            <origin xyz="0 0 -0.9040516537419714" rpy="0 0 0"/>
            <mass value="1" />
            <inertia ixx="100" ixy="0" ixz="0" iyy="100" iyz="0" izz="100" />
        </inertial>
        <visual>
            <origin xyz="0 0 -0.9040516537419714" rpy="0 0 0"/>
            <geometry>
                <box size="0.4458107794622592 0.16189499809802788 1.8081033074839428" />
            </geometry>
            <material name="Blue">
                <color rgba="0 0 255 1"/>
            </material>
        </visual>
        <collision>
            <origin xyz="0 0 -0.9040516537419714" rpy="0 0 0"/>
            <geometry>
                <box size="0.4458107794622592 0.16189499809802788 1.8081033074839428" />
            </geometry>
        </collision>
    </link>
    <joint name="17_18" type="revolute">
       <parent link="17"/>
       <child  link="18"/>
       <origin rpy="0 0 0" xyz="0 0.4076358751801879 -0.06817305883389407" />
     <axis xyz="0 0 1"/>
       <limit effort="0.0" lower="-3.14159" upper="3.14159" velocity="0.0"/>
    </joint>
    <link name="19">
        <inertial>
            <origin xyz="0 0 -0.33806756720399017" rpy="0 0 0"/>
            <mass value="1" />
            <inertia ixx="100" ixy="0" ixz="0" iyy="100" iyz="0" izz="100" />
        </inertial>
        <visual>
            <origin xyz="0 0 -0.33806756720399017" rpy="0 0 0"/>
            <geometry>
                <box size="0.19328634492139096 0.921707418976747 0.6761351344079803" />
            </geometry>
            <material name="Blue">
                <color rgba="0 0 255 1"/>
            </material>
        </visual>
        <collision>
            <origin xyz="0 0 -0.33806756720399017" rpy="0 0 0"/>
            <geometry>
                <box size="0.19328634492139096 0.921707418976747 0.6761351344079803" />
            </geometry>
        </collision>
    </link>
    <joint name="18_19" type="revolute">
       <parent link="18"/>
       <child  link="19"/>
       <origin rpy="0 0 0" xyz="0 0 -1.8081033074839428" />
     <axis xyz="0 1 0"/>
       <limit effort="0.0" lower="-3.14159" upper="3.14159" velocity="0.0"/>
    </joint>
    <link name="20">
        <inertial>
            <origin xyz="0 0 -0.05788077905403849" rpy="0 0 0"/>
            <mass value="1" />
            <inertia ixx="100" ixy="0" ixz="0" iyy="100" iyz="0" izz="100" />
        </inertial>
        <visual>
            <origin xyz="0 0 -0.05788077905403849" rpy="0 0 0"/>
            <geometry>
                <box size="0.11933206537230623 0.07546461316560538 0.11576155810807698" />
            </geometry>
            <material name="Blue">
                <color rgba="0 0 255 1"/>
            </material>
        </visual>
        <collision>
            <origin xyz="0 0 -0.05788077905403849" rpy="0 0 0"/>
            <geometry>
                <box size="0.11933206537230623 0.07546461316560538 0.11576155810807698" />
            </geometry>
        </collision>
    </link>
    <joint name="19_20" type="revolute">
       <parent link="19"/>
       <child  link="20"/>
       <origin rpy="0 0 0" xyz="0 0 -0.6761351344079803" />
     <axis xyz="1 1 1"/>
       <limit effort="0.0" lower="-3.14159" upper="3.14159" velocity="0.0"/>
    </joint>
</robot>