<robot name = "robot">
    <link name="0">
        <inertial>
            <origin xyz="0 0 0.6500935444356781" rpy="0 0 0"/>
            <mass value="1" />
            <inertia ixx="100" ixy="0" ixz="0" iyy="100" iyz="0" izz="100" />
        </inertial>
        <visual>
            <origin xyz="0 0 0.6500935444356781" rpy="0 0 0"/>
            <geometry>
                <box size="0.907930350570267 0.6963626324332751 1.3001870888713563" />
            </geometry>
            <material name="Blue">
                <color rgba="0 0 255 1"/>
            </material>
        </visual>
        <collision>
            <origin xyz="0 0 0.6500935444356781" rpy="0 0 0"/>
            <geometry>
                <box size="0.907930350570267 0.6963626324332751 1.3001870888713563" />
            </geometry>
        </collision>
    </link>
    <link name="1">
        <inertial>
            <origin xyz="0 0 0.6571964491915716" rpy="0 0 0"/>
            <mass value="1" />
            <inertia ixx="100" ixy="0" ixz="0" iyy="100" iyz="0" izz="100" />
        </inertial>
        <visual>
            <origin xyz="0 0 0.6571964491915716" rpy="0 0 0"/>
            <geometry>
                <box size="1.1122485717030712 0.8022922369050779 1.3143928983831432" />
            </geometry>
            <material name="Blue">
                <color rgba="0 0 255 1"/>
            </material>
        </visual>
        <collision>
            <origin xyz="0 0 0.6571964491915716" rpy="0 0 0"/>
            <geometry>
                <box size="1.1122485717030712 0.8022922369050779 1.3143928983831432" />
            </geometry>
        </collision>
    </link>
    <joint name="0_1" type="revolute">
       <parent link="0"/>
       <child  link="1"/>
       <origin rpy="0 0 0" xyz="0 0 1.3001870888713563" />
     <axis xyz="1 0 1"/>
       <limit effort="0.0" lower="-3.14159" upper="3.14159" velocity="0.0"/>
    </joint>
    <link name="2">
        <inertial>
            <origin xyz="0 0 0.32082736707396675" rpy="0 0 0"/>
            <mass value="1" />
            <inertia ixx="100" ixy="0" ixz="0" iyy="100" iyz="0" izz="100" />
        </inertial>
        <visual>
            <origin xyz="0 0 0.32082736707396675" rpy="0 0 0"/>
            <geometry>
                <box size="1.1257880597602068 1.4306986191209412 0.6416547341479335" />
            </geometry>
            <material name="Green">
                <color rgba="0 128 0 1"/>
            </material>
        </visual>
        <collision>
            <origin xyz="0 0 0.32082736707396675" rpy="0 0 0"/>
            <geometry>
                <box size="1.1257880597602068 1.4306986191209412 0.6416547341479335" />
            </geometry>
        </collision>
    </link>
    <joint name="1_2" type="revolute">
       <parent link="1"/>
       <child  link="2"/>
       <origin rpy="0 0 0" xyz="0 0 1.3143928983831432" />
     <axis xyz="1 1 0"/>
       <limit effort="0.0" lower="-3.14159" upper="3.14159" velocity="0.0"/>
    </joint>
    <link name="3">
        <inertial>
            <origin xyz="-0.6559212315351002 0 0.6368567893383268" rpy="0 0 0"/>
            <mass value="1" />
            <inertia ixx="100" ixy="0" ixz="0" iyy="100" iyz="0" izz="100" />
        </inertial>
        <visual>
            <origin xyz="-0.6559212315351002 0 0.6368567893383268" rpy="0 0 0"/>
            <geometry>
                <box size="1.3118424630702004 0.7149800105253455 1.2737135786766536" />
            </geometry>
            <material name="Blue">
                <color rgba="0 0 255 1"/>
            </material>
        </visual>
        <collision>
            <origin xyz="-0.6559212315351002 0 0.6368567893383268" rpy="0 0 0"/>
            <geometry>
                <box size="1.3118424630702004 0.7149800105253455 1.2737135786766536" />
            </geometry>
        </collision>
    </link>
    <joint name="2_3" type="revolute">
       <parent link="2"/>
       <child  link="3"/>
       <origin rpy="0 0 0" xyz="-0.5628940298801034 0 0" />
     <axis xyz="1 0 0"/>
       <limit effort="0.0" lower="-3.14159" upper="3.14159" velocity="0.0"/>
    </joint>
    <link name="4">
        <inertial>
            <origin xyz="-0.7451059790845633 0 0.7050614689477346" rpy="0 0 0"/>
            <mass value="1" />
            <inertia ixx="100" ixy="0" ixz="0" iyy="100" iyz="0" izz="100" />
        </inertial>
        <visual>
            <origin xyz="-0.7451059790845633 0 0.7050614689477346" rpy="0 0 0"/>
            <geometry>
                <box size="1.4902119581691267 1.3179396561439933 1.4101229378954692" />
            </geometry>
            <material name="Blue">
                <color rgba="0 0 255 1"/>
            </material>
        </visual>
        <collision>
            <origin xyz="-0.7451059790845633 0 0.7050614689477346" rpy="0 0 0"/>
            <geometry>
                <box size="1.4902119581691267 1.3179396561439933 1.4101229378954692" />
            </geometry>
        </collision>
    </link>
    <joint name="3_4" type="revolute">
       <parent link="3"/>
       <child  link="4"/>
       <origin rpy="0 0 0" xyz="-1.3118424630702004 0 0" />
     <axis xyz="0 0 1"/>
       <limit effort="0.0" lower="-3.14159" upper="3.14159" velocity="0.0"/>
    </joint>
    <link name="5">
        <inertial>
            <origin xyz="-0.2569211064595977 0 0.28204593552177004" rpy="0 0 0"/>
            <mass value="1" />
            <inertia ixx="100" ixy="0" ixz="0" iyy="100" iyz="0" izz="100" />
        </inertial>
        <visual>
            <origin xyz="-0.2569211064595977 0 0.28204593552177004" rpy="0 0 0"/>
            <geometry>
                <box size="0.5138422129191954 1.2334036412560387 0.5640918710435401" />
            </geometry>
            <material name="Green">
                <color rgba="0 128 0 1"/>
            </material>
        </visual>
        <collision>
            <origin xyz="-0.2569211064595977 0 0.28204593552177004" rpy="0 0 0"/>
            <geometry>
                <box size="0.5138422129191954 1.2334036412560387 0.5640918710435401" />
            </geometry>
        </collision>
    </link>
    <joint name="4_5" type="revolute">
       <parent link="4"/>
       <child  link="5"/>
       <origin rpy="0 0 0" xyz="-1.4902119581691267 0 0" />
     <axis xyz="0 1 0"/>
       <limit effort="0.0" lower="-3.14159" upper="3.14159" velocity="0.0"/>
    </joint>
    <link name="6">
        <inertial>
            <origin xyz="0 0 -0.37432437014979886" rpy="0 0 0"/>
            <mass value="1" />
            <inertia ixx="100" ixy="0" ixz="0" iyy="100" iyz="0" izz="100" />
        </inertial>
        <visual>
            <origin xyz="0 0 -0.37432437014979886" rpy="0 0 0"/>
            <geometry>
                <box size="0.9987935592957611 1.1916024221947246 0.7486487402995977" />
            </geometry>
            <material name="Blue">
                <color rgba="0 0 255 1"/>
            </material>
        </visual>
        <collision>
            <origin xyz="0 0 -0.37432437014979886" rpy="0 0 0"/>
            <geometry>
                <box size="0.9987935592957611 1.1916024221947246 0.7486487402995977" />
            </geometry>
        </collision>
    </link>
    <joint name="5_6" type="revolute">
       <parent link="5"/>
       <child  link="6"/>
       <origin rpy="0 0 0" xyz="-0.2569211064595977 0 0" />
     <axis xyz="1 1 0"/>
       <limit effort="0.0" lower="-3.14159" upper="3.14159" velocity="0.0"/>
    </joint>
    <link name="7">
        <inertial>
            <origin xyz="0 0 -0.34170855444249976" rpy="0 0 0"/>
            <mass value="1" />
            <inertia ixx="100" ixy="0" ixz="0" iyy="100" iyz="0" izz="100" />
        </inertial>
        <visual>
            <origin xyz="0 0 -0.34170855444249976" rpy="0 0 0"/>
            <geometry>
                <box size="1.0633590159650306 0.531268133611482 0.6834171088849995" />
            </geometry>
            <material name="Blue">
                <color rgba="0 0 255 1"/>
            </material>
        </visual>
        <collision>
            <origin xyz="0 0 -0.34170855444249976" rpy="0 0 0"/>
            <geometry>
                <box size="1.0633590159650306 0.531268133611482 0.6834171088849995" />
            </geometry>
        </collision>
    </link>
    <joint name="6_7" type="revolute">
       <parent link="6"/>
       <child  link="7"/>
       <origin rpy="0 0 0" xyz="0 0 -0.7486487402995977" />
     <axis xyz="0 1 0"/>
       <limit effort="0.0" lower="-3.14159" upper="3.14159" velocity="0.0"/>
    </joint>
    <link name="8">
        <inertial>
            <origin xyz="0 0 -1.123553391870718" rpy="0 0 0"/>
            <mass value="1" />
            <inertia ixx="100" ixy="0" ixz="0" iyy="100" iyz="0" izz="100" />
        </inertial>
        <visual>
            <origin xyz="0 0 -1.123553391870718" rpy="0 0 0"/>
            <geometry>
                <box size="1.0224502562409132 0.8635124657016948 2.247106783741436" />
            </geometry>
            <material name="Green">
                <color rgba="0 128 0 1"/>
            </material>
        </visual>
        <collision>
            <origin xyz="0 0 -1.123553391870718" rpy="0 0 0"/>
            <geometry>
                <box size="1.0224502562409132 0.8635124657016948 2.247106783741436" />
            </geometry>
        </collision>
    </link>
    <joint name="7_8" type="revolute">
       <parent link="7"/>
       <child  link="8"/>
       <origin rpy="0 0 0" xyz="0 0 -0.6834171088849995" />
     <axis xyz="1 1 1"/>
       <limit effort="0.0" lower="-3.14159" upper="3.14159" velocity="0.0"/>
    </joint>
    <link name="9">
        <inertial>
            <origin xyz="0.5594818077482654 0 0.2571370307346231" rpy="0 0 0"/>
            <mass value="1" />
            <inertia ixx="100" ixy="0" ixz="0" iyy="100" iyz="0" izz="100" />
        </inertial>
        <visual>
            <origin xyz="0.5594818077482654 0 0.2571370307346231" rpy="0 0 0"/>
            <geometry>
                <box size="1.1189636154965308 1.124228027336708 0.5142740614692461" />
            </geometry>
            <material name="Blue">
                <color rgba="0 0 255 1"/>
            </material>
        </visual>
        <collision>
            <origin xyz="0.5594818077482654 0 0.2571370307346231" rpy="0 0 0"/>
            <geometry>
                <box size="1.1189636154965308 1.124228027336708 0.5142740614692461" />
            </geometry>
        </collision>
    </link>
    <joint name="2_9" type="revolute">
       <parent link="2"/>
       <child  link="9"/>
       <origin rpy="0 0 0" xyz="0.5628940298801034 0 0" />
     <axis xyz="0 0 1"/>
       <limit effort="0.0" lower="-3.14159" upper="3.14159" velocity="0.0"/>
    </joint>
    <link name="10">
        <inertial>
            <origin xyz="0.37997985866125844 0 0.7259433268701933" rpy="0 0 0"/>
            <mass value="1" />
            <inertia ixx="100" ixy="0" ixz="0" iyy="100" iyz="0" izz="100" />
        </inertial>
        <visual>
            <origin xyz="0.37997985866125844 0 0.7259433268701933" rpy="0 0 0"/>
            <geometry>
                <box size="0.7599597173225169 0.5348146859784508 1.4518866537403865" />
            </geometry>
            <material name="Blue">
                <color rgba="0 0 255 1"/>
            </material>
        </visual>
        <collision>
            <origin xyz="0.37997985866125844 0 0.7259433268701933" rpy="0 0 0"/>
            <geometry>
                <box size="0.7599597173225169 0.5348146859784508 1.4518866537403865" />
            </geometry>
        </collision>
    </link>
    <joint name="9_10" type="revolute">
       <parent link="9"/>
       <child  link="10"/>
       <origin rpy="0 0 0" xyz="1.1189636154965308 0 0" />
     <axis xyz="1 0 1"/>
       <limit effort="0.0" lower="-3.14159" upper="3.14159" velocity="0.0"/>
    </joint>
    <link name="11">
        <inertial>
            <origin xyz="0.2823874016916292 0 0.5455627586153057" rpy="0 0 0"/>
            <mass value="1" />
            <inertia ixx="100" ixy="0" ixz="0" iyy="100" iyz="0" izz="100" />
        </inertial>
        <visual>
            <origin xyz="0.2823874016916292 0 0.5455627586153057" rpy="0 0 0"/>
            <geometry>
                <box size="0.5647748033832584 1.3691079893053113 1.0911255172306114" />
            </geometry>
            <material name="Green">
                <color rgba="0 128 0 1"/>
            </material>
        </visual>
        <collision>
            <origin xyz="0.2823874016916292 0 0.5455627586153057" rpy="0 0 0"/>
            <geometry>
                <box size="0.5647748033832584 1.3691079893053113 1.0911255172306114" />
            </geometry>
        </collision>
    </link>
    <joint name="10_11" type="revolute">
       <parent link="10"/>
       <child  link="11"/>
       <origin rpy="0 0 0" xyz="0.7599597173225169 0 0" />
     <axis xyz="1 0 0"/>
       <limit effort="0.0" lower="-3.14159" upper="3.14159" velocity="0.0"/>
    </joint>
    <link name="12">
        <inertial>
            <origin xyz="0 0 -0.2162722177783386" rpy="0 0 0"/>
            <mass value="1" />
            <inertia ixx="100" ixy="0" ixz="0" iyy="100" iyz="0" izz="100" />
        </inertial>
        <visual>
            <origin xyz="0 0 -0.2162722177783386" rpy="0 0 0"/>
            <geometry>
                <box size="0.6668101508283161 0.904126395368041 0.4325444355566772" />
            </geometry>
            <material name="Green">
                <color rgba="0 128 0 1"/>
            </material>
        </visual>
        <collision>
            <origin xyz="0 0 -0.2162722177783386" rpy="0 0 0"/>
            <geometry>
                <box size="0.6668101508283161 0.904126395368041 0.4325444355566772" />
            </geometry>
        </collision>
    </link>
    <joint name="11_12" type="revolute">
       <parent link="11"/>
       <child  link="12"/>
       <origin rpy="0 0 0" xyz="0.2823874016916292 0 0" />
     <axis xyz="0 1 1"/>
       <limit effort="0.0" lower="-3.14159" upper="3.14159" velocity="0.0"/>
    </joint>
    <link name="13">
        <inertial>
            <origin xyz="0 0 -1.6123405822952883" rpy="0 0 0"/>
            <mass value="1" />
            <inertia ixx="100" ixy="0" ixz="0" iyy="100" iyz="0" izz="100" />
        </inertial>
        <visual>
            <origin xyz="0 0 -1.6123405822952883" rpy="0 0 0"/>
            <geometry>
                <box size="1.360808617152124 1.1286257358467076 3.2246811645905766" />
            </geometry>
            <material name="Green">
                <color rgba="0 128 0 1"/>
            </material>
        </visual>
        <collision>
            <origin xyz="0 0 -1.6123405822952883" rpy="0 0 0"/>
            <geometry>
                <box size="1.360808617152124 1.1286257358467076 3.2246811645905766" />
            </geometry>
        </collision>
    </link>
    <joint name="12_13" type="revolute">
       <parent link="12"/>
       <child  link="13"/>
       <origin rpy="0 0 0" xyz="0 0 -0.4325444355566772" />
     <axis xyz="1 1 0"/>
       <limit effort="0.0" lower="-3.14159" upper="3.14159" velocity="0.0"/>
    </joint>
    <link name="14">
        <inertial>
            <origin xyz="0 0 -0.010973516389389593" rpy="0 0 0"/>
            <mass value="1" />
            <inertia ixx="100" ixy="0" ixz="0" iyy="100" iyz="0" izz="100" />
        </inertial>
        <visual>
            <origin xyz="0 0 -0.010973516389389593" rpy="0 0 0"/>
            <geometry>
                <box size="0.58723505233419 1.3716124587796896 0.021947032778779185" />
            </geometry>
            <material name="Blue">
                <color rgba="0 0 255 1"/>
            </material>
        </visual>
        <collision>
            <origin xyz="0 0 -0.010973516389389593" rpy="0 0 0"/>
            <geometry>
                <box size="0.58723505233419 1.3716124587796896 0.021947032778779185" />
            </geometry>
        </collision>
    </link>
    <joint name="13_14" type="revolute">
       <parent link="13"/>
       <child  link="14"/>
       <origin rpy="0 0 0" xyz="0 0 -3.2246811645905766" />
     <axis xyz="0 0 1"/>
       <limit effort="0.0" lower="-3.14159" upper="3.14159" velocity="0.0"/>
    </joint>
    <link name="15">
        <inertial>
            <origin xyz="0 -0.34260581832709136 0.5385630283941905" rpy="0 0 0"/>
            <mass value="1" />
            <inertia ixx="100" ixy="0" ixz="0" iyy="100" iyz="0" izz="100" />
        </inertial>
        <visual>
            <origin xyz="0 -0.34260581832709136 0.5385630283941905" rpy="0 0 0"/>
            <geometry>
                <box size="1.109779760321305 0.6852116366541827 1.077126056788381" />
            </geometry>
            <material name="Green">
                <color rgba="0 128 0 1"/>
            </material>
        </visual>
        <collision>
            <origin xyz="0 -0.34260581832709136 0.5385630283941905" rpy="0 0 0"/>
            <geometry>
                <box size="1.109779760321305 0.6852116366541827 1.077126056788381" />
            </geometry>
        </collision>
    </link>
    <joint name="2_15" type="revolute">
       <parent link="2"/>
       <child  link="15"/>
       <origin rpy="0 0 0" xyz="0 -0.7153493095604706 0" />
     <axis xyz="0 0 1"/>
       <limit effort="0.0" lower="-3.14159" upper="3.14159" velocity="0.0"/>
    </joint>
    <link name="16">
        <inertial>
            <origin xyz="0 -0.2813243202537165 0.666014139794928" rpy="0 0 0"/>
            <mass value="1" />
            <inertia ixx="100" ixy="0" ixz="0" iyy="100" iyz="0" izz="100" />
        </inertial>
        <visual>
            <origin xyz="0 -0.2813243202537165 0.666014139794928" rpy="0 0 0"/>
            <geometry>
                <box size="0.6385188544910142 0.562648640507433 1.332028279589856" />
            </geometry>
            <material name="Green">
                <color rgba="0 128 0 1"/>
            </material>
        </visual>
        <collision>
            <origin xyz="0 -0.2813243202537165 0.666014139794928" rpy="0 0 0"/>
            <geometry>
                <box size="0.6385188544910142 0.562648640507433 1.332028279589856" />
            </geometry>
        </collision>
    </link>
    <joint name="15_16" type="revolute">
       <parent link="15"/>
       <child  link="16"/>
       <origin rpy="0 0 0" xyz="0 -0.6852116366541827 0" />
     <axis xyz="1 0 0"/>
       <limit effort="0.0" lower="-3.14159" upper="3.14159" velocity="0.0"/>
    </joint>
    <link name="17">
        <inertial>
            <origin xyz="0 -0.3495242224458632 0.5899127358866572" rpy="0 0 0"/>
            <mass value="1" />
            <inertia ixx="100" ixy="0" ixz="0" iyy="100" iyz="0" izz="100" />
        </inertial>
        <visual>
            <origin xyz="0 -0.3495242224458632 0.5899127358866572" rpy="0 0 0"/>
            <geometry>
                <box size="1.170570957530604 0.6990484448917264 1.1798254717733143" />
            </geometry>
            <material name="Blue">
                <color rgba="0 0 255 1"/>
            </material>
        </visual>
        <collision>
            <origin xyz="0 -0.3495242224458632 0.5899127358866572" rpy="0 0 0"/>
            <geometry>
                <box size="1.170570957530604 0.6990484448917264 1.1798254717733143" />
            </geometry>
        </collision>
    </link>
    <joint name="16_17" type="revolute">
       <parent link="16"/>
       <child  link="17"/>
       <origin rpy="0 0 0" xyz="0 -0.562648640507433 0" />
     <axis xyz="1 1 0"/>
       <limit effort="0.0" lower="-3.14159" upper="3.14159" velocity="0.0"/>
    </joint>
    <link name="18">
        <inertial>
            <origin xyz="0 0 -1.1398707485729656" rpy="0 0 0"/>
            <mass value="1" />
            <inertia ixx="100" ixy="0" ixz="0" iyy="100" iyz="0" izz="100" />
        </inertial>
        <visual>
            <origin xyz="0 0 -1.1398707485729656" rpy="0 0 0"/>
            <geometry>
                <box size="1.0719034790031547 1.0366773253530515 2.279741497145931" />
            </geometry>
            <material name="Blue">
                <color rgba="0 0 255 1"/>
            </material>
        </visual>
        <collision>
            <origin xyz="0 0 -1.1398707485729656" rpy="0 0 0"/>
            <geometry>
                <box size="1.0719034790031547 1.0366773253530515 2.279741497145931" />
            </geometry>
        </collision>
    </link>
    <joint name="17_18" type="revolute">
       <parent link="17"/>
       <child  link="18"/>
       <origin rpy="0 0 0" xyz="0 -0.3495242224458632 0" />
     <axis xyz="1 0 0"/>
       <limit effort="0.0" lower="-3.14159" upper="3.14159" velocity="0.0"/>
    </joint>
    <link name="19">
        <inertial>
            <origin xyz="0 0 -0.2297647640472408" rpy="0 0 0"/>
            <mass value="1" />
            <inertia ixx="100" ixy="0" ixz="0" iyy="100" iyz="0" izz="100" />
        </inertial>
        <visual>
            <origin xyz="0 0 -0.2297647640472408" rpy="0 0 0"/>
            <geometry>
                <box size="1.403048339577487 0.9131608576159458 0.4595295280944816" />
            </geometry>
            <material name="Blue">
                <color rgba="0 0 255 1"/>
            </material>
        </visual>
        <collision>
            <origin xyz="0 0 -0.2297647640472408" rpy="0 0 0"/>
            <geometry>
                <box size="1.403048339577487 0.9131608576159458 0.4595295280944816" />
            </geometry>
        </collision>
    </link>
    <joint name="18_19" type="revolute">
       <parent link="18"/>
       <child  link="19"/>
       <origin rpy="0 0 0" xyz="0 0 -2.279741497145931" />
     <axis xyz="0 1 0"/>
       <limit effort="0.0" lower="-3.14159" upper="3.14159" velocity="0.0"/>
    </joint>
    <link name="20">
        <inertial>
            <origin xyz="0 0 -0.4699508038428103" rpy="0 0 0"/>
            <mass value="1" />
            <inertia ixx="100" ixy="0" ixz="0" iyy="100" iyz="0" izz="100" />
        </inertial>
        <visual>
            <origin xyz="0 0 -0.4699508038428103" rpy="0 0 0"/>
            <geometry>
                <box size="1.327499944905092 1.3685256723575798 0.9399016076856206" />
            </geometry>
            <material name="Blue">
                <color rgba="0 0 255 1"/>
            </material>
        </visual>
        <collision>
            <origin xyz="0 0 -0.4699508038428103" rpy="0 0 0"/>
            <geometry>
                <box size="1.327499944905092 1.3685256723575798 0.9399016076856206" />
            </geometry>
        </collision>
    </link>
    <joint name="19_20" type="revolute">
       <parent link="19"/>
       <child  link="20"/>
       <origin rpy="0 0 0" xyz="0 0 -0.4595295280944816" />
     <axis xyz="0 1 1"/>
       <limit effort="0.0" lower="-3.14159" upper="3.14159" velocity="0.0"/>
    </joint>
    <link name="21">
        <inertial>
            <origin xyz="0 0.5031250656850235 0.3427913078751779" rpy="0 0 0"/>
            <mass value="1" />
            <inertia ixx="100" ixy="0" ixz="0" iyy="100" iyz="0" izz="100" />
        </inertial>
        <visual>
            <origin xyz="0 0.5031250656850235 0.3427913078751779" rpy="0 0 0"/>
            <geometry>
                <box size="0.8349416505454946 1.006250131370047 0.6855826157503558" />
            </geometry>
            <material name="Blue">
                <color rgba="0 0 255 1"/>
            </material>
        </visual>
        <collision>
            <origin xyz="0 0.5031250656850235 0.3427913078751779" rpy="0 0 0"/>
            <geometry>
                <box size="0.8349416505454946 1.006250131370047 0.6855826157503558" />
            </geometry>
        </collision>
    </link>
    <joint name="2_21" type="revolute">
       <parent link="2"/>
       <child  link="21"/>
       <origin rpy="0 0 0" xyz="0 0.7153493095604706 0" />
     <axis xyz="1 0 1"/>
       <limit effort="0.0" lower="-3.14159" upper="3.14159" velocity="0.0"/>
    </joint>
    <link name="22">
        <inertial>
            <origin xyz="0 0.30258217541899673 0.4057707091675122" rpy="0 0 0"/>
            <mass value="1" />
            <inertia ixx="100" ixy="0" ixz="0" iyy="100" iyz="0" izz="100" />
        </inertial>
        <visual>
            <origin xyz="0 0.30258217541899673 0.4057707091675122" rpy="0 0 0"/>
            <geometry>
                <box size="0.8742840717100587 0.6051643508379935 0.8115414183350244" />
            </geometry>
            <material name="Green">
                <color rgba="0 128 0 1"/>
            </material>
        </visual>
        <collision>
            <origin xyz="0 0.30258217541899673 0.4057707091675122" rpy="0 0 0"/>
            <geometry>
                <box size="0.8742840717100587 0.6051643508379935 0.8115414183350244" />
            </geometry>
        </collision>
    </link>
    <joint name="21_22" type="revolute">
       <parent link="21"/>
       <child  link="22"/>
       <origin rpy="0 0 0" xyz="0 1.006250131370047 0" />
     <axis xyz="1 0 1"/>
       <limit effort="0.0" lower="-3.14159" upper="3.14159" velocity="0.0"/>
    </joint>
    <link name="23">
        <inertial>
            <origin xyz="0 0.4984106448092494 0.6539502303576006" rpy="0 0 0"/>
            <mass value="1" />
            <inertia ixx="100" ixy="0" ixz="0" iyy="100" iyz="0" izz="100" />
        </inertial>
        <visual>
            <origin xyz="0 0.4984106448092494 0.6539502303576006" rpy="0 0 0"/>
            <geometry>
                <box size="0.9704381988786615 0.9968212896184988 1.3079004607152012" />
            </geometry>
            <material name="Green">
                <color rgba="0 128 0 1"/>
            </material>
        </visual>
        <collision>
            <origin xyz="0 0.4984106448092494 0.6539502303576006" rpy="0 0 0"/>
            <geometry>
                <box size="0.9704381988786615 0.9968212896184988 1.3079004607152012" />
            </geometry>
        </collision>
    </link>
    <joint name="22_23" type="revolute">
       <parent link="22"/>
       <child  link="23"/>
       <origin rpy="0 0 0" xyz="0 0.6051643508379935 0" />
     <axis xyz="1 1 1"/>
       <limit effort="0.0" lower="-3.14159" upper="3.14159" velocity="0.0"/>
    </joint>
    <link name="24">
        <inertial>
            <origin xyz="0 0 -0.12466131754159405" rpy="0 0 0"/>
            <mass value="1" />
            <inertia ixx="100" ixy="0" ixz="0" iyy="100" iyz="0" izz="100" />
        </inertial>
        <visual>
            <origin xyz="0 0 -0.12466131754159405" rpy="0 0 0"/>
            <geometry>
                <box size="0.8237945091460263 1.206004121861392 0.2493226350831881" />
            </geometry>
            <material name="Green">
                <color rgba="0 128 0 1"/>
            </material>
        </visual>
        <collision>
            <origin xyz="0 0 -0.12466131754159405" rpy="0 0 0"/>
            <geometry>
                <box size="0.8237945091460263 1.206004121861392 0.2493226350831881" />
            </geometry>
        </collision>
    </link>
    <joint name="23_24" type="revolute">
       <parent link="23"/>
       <child  link="24"/>
       <origin rpy="0 0 0" xyz="0 0.4984106448092494 0" />
     <axis xyz="1 0 0"/>
       <limit effort="0.0" lower="-3.14159" upper="3.14159" velocity="0.0"/>
    </joint>
    <link name="25">
        <inertial>
            <origin xyz="0 0 -0.8226329544213881" rpy="0 0 0"/>
            <mass value="1" />
            <inertia ixx="100" ixy="0" ixz="0" iyy="100" iyz="0" izz="100" />
        </inertial>
        <visual>
            <origin xyz="0 0 -0.8226329544213881" rpy="0 0 0"/>
            <geometry>
                <box size="0.9853595602592383 1.1636508063357938 1.6452659088427761" />
            </geometry>
            <material name="Blue">
                <color rgba="0 0 255 1"/>
            </material>
        </visual>
        <collision>
            <origin xyz="0 0 -0.8226329544213881" rpy="0 0 0"/>
            <geometry>
                <box size="0.9853595602592383 1.1636508063357938 1.6452659088427761" />
            </geometry>
        </collision>
    </link>
    <joint name="24_25" type="revolute">
       <parent link="24"/>
       <child  link="25"/>
       <origin rpy="0 0 0" xyz="0 0 -0.2493226350831881" />
     <axis xyz="0 0 1"/>
       <limit effort="0.0" lower="-3.14159" upper="3.14159" velocity="0.0"/>
    </joint>
    <link name="26">
        <inertial>
            <origin xyz="0 0 -0.8922920445000345" rpy="0 0 0"/>
            <mass value="1" />
            <inertia ixx="100" ixy="0" ixz="0" iyy="100" iyz="0" izz="100" />
        </inertial>
        <visual>
            <origin xyz="0 0 -0.8922920445000345" rpy="0 0 0"/>
            <geometry>
                <box size="1.2106359188984115 1.4091880748465764 1.784584089000069" />
            </geometry>
            <material name="Green">
                <color rgba="0 128 0 1"/>
            </material>
        </visual>
        <collision>
            <origin xyz="0 0 -0.8922920445000345" rpy="0 0 0"/>
            <geometry>
                <box size="1.2106359188984115 1.4091880748465764 1.784584089000069" />
            </geometry>
        </collision>
    </link>
    <joint name="25_26" type="revolute">
       <parent link="25"/>
       <child  link="26"/>
       <origin rpy="0 0 0" xyz="0 0 -1.6452659088427761" />
     <axis xyz="0 1 1"/>
       <limit effort="0.0" lower="-3.14159" upper="3.14159" velocity="0.0"/>
    </joint>
</robot>