<robot name = "robot">
    <link name="0">
        <inertial>
            <origin xyz="0 0 0.35" rpy="0 0 0"/>
            <mass value="1" />
            <inertia ixx="100" ixy="0" ixz="0" iyy="100" iyz="0" izz="100" />
        </inertial>
        <visual>
            <origin xyz="0 0 0.35" rpy="0 0 0"/>
            <geometry>
                <box size="0.7 0.7 0.7" />
            </geometry>
            <material name="Blue">
                <color rgba="0 0 255 1"/>
            </material>
        </visual>
        <collision>
            <origin xyz="0 0 0.35" rpy="0 0 0"/>
            <geometry>
                <box size="0.7 0.7 0.7" />
            </geometry>
        </collision>
    </link>
    <link name="1">
        <inertial>
            <origin xyz="-0.00932311402219621 0 0.1873558496361779" rpy="0 0 0"/>
            <mass value="1" />
            <inertia ixx="100" ixy="0" ixz="0" iyy="100" iyz="0" izz="100" />
        </inertial>
        <visual>
            <origin xyz="-0.00932311402219621 0 0.1873558496361779" rpy="0 0 0"/>
            <geometry>
                <box size="0.01864622804439242 0.38971169592664723 0.3747116992723558" />
            </geometry>
            <material name="Blue">
                <color rgba="0 0 255 1"/>
            </material>
        </visual>
        <collision>
            <origin xyz="-0.00932311402219621 0 0.1873558496361779" rpy="0 0 0"/>
            <geometry>
                <box size="0.01864622804439242 0.38971169592664723 0.3747116992723558" />
            </geometry>
        </collision>
    </link>
    <joint name="0_1" type="revolute">
       <parent link="0"/>
       <child  link="1"/>
       <origin rpy="0 0 0" xyz="-0.35 0 0.7" />
     <axis xyz="0 1 0"/>
       <limit effort="0.0" lower="-3.14159" upper="3.14159" velocity="0.0"/>
    </joint>
    <link name="2">
        <inertial>
            <origin xyz="-0.3270490577083789 0 0.28736446435868357" rpy="0 0 0"/>
            <mass value="1" />
            <inertia ixx="100" ixy="0" ixz="0" iyy="100" iyz="0" izz="100" />
        </inertial>
        <visual>
            <origin xyz="-0.3270490577083789 0 0.28736446435868357" rpy="0 0 0"/>
            <geometry>
                <box size="0.6540981154167578 0.7597187096740546 0.5747289287173671" />
            </geometry>
            <material name="Green">
                <color rgba="0 128 0 1"/>
            </material>
        </visual>
        <collision>
            <origin xyz="-0.3270490577083789 0 0.28736446435868357" rpy="0 0 0"/>
            <geometry>
                <box size="0.6540981154167578 0.7597187096740546 0.5747289287173671" />
            </geometry>
        </collision>
    </link>
    <joint name="1_2" type="revolute">
       <parent link="1"/>
       <child  link="2"/>
       <origin rpy="0 0 0" xyz="-0.01864622804439242 0 0.3747116992723558" />
     <axis xyz="1 0 1"/>
       <limit effort="0.0" lower="-3.14159" upper="3.14159" velocity="0.0"/>
    </joint>
    <link name="3">
        <inertial>
            <origin xyz="-0.36401009204684576 0 0.13384743074527827" rpy="0 0 0"/>
            <mass value="1" />
            <inertia ixx="100" ixy="0" ixz="0" iyy="100" iyz="0" izz="100" />
        </inertial>
        <visual>
            <origin xyz="-0.36401009204684576 0 0.13384743074527827" rpy="0 0 0"/>
            <geometry>
                <box size="0.7280201840936915 0.35683692735564865 0.26769486149055655" />
            </geometry>
            <material name="Blue">
                <color rgba="0 0 255 1"/>
            </material>
        </visual>
        <collision>
            <origin xyz="-0.36401009204684576 0 0.13384743074527827" rpy="0 0 0"/>
            <geometry>
                <box size="0.7280201840936915 0.35683692735564865 0.26769486149055655" />
            </geometry>
        </collision>
    </link>
    <joint name="2_3" type="revolute">
       <parent link="2"/>
       <child  link="3"/>
       <origin rpy="0 0 0" xyz="-0.6540981154167578 0 0.5747289287173671" />
     <axis xyz="1 1 0"/>
       <limit effort="0.0" lower="-3.14159" upper="3.14159" velocity="0.0"/>
    </joint>
    <link name="4">
        <inertial>
            <origin xyz="-0.16063905159357517 0 0.06866506957483293" rpy="0 0 0"/>
            <mass value="1" />
            <inertia ixx="100" ixy="0" ixz="0" iyy="100" iyz="0" izz="100" />
        </inertial>
        <visual>
            <origin xyz="-0.16063905159357517 0 0.06866506957483293" rpy="0 0 0"/>
            <geometry>
                <box size="0.32127810318715033 0.30644464618982936 0.13733013914966585" />
            </geometry>
            <material name="Blue">
                <color rgba="0 0 255 1"/>
            </material>
        </visual>
        <collision>
            <origin xyz="-0.16063905159357517 0 0.06866506957483293" rpy="0 0 0"/>
            <geometry>
                <box size="0.32127810318715033 0.30644464618982936 0.13733013914966585" />
            </geometry>
        </collision>
    </link>
    <joint name="3_4" type="revolute">
       <parent link="3"/>
       <child  link="4"/>
       <origin rpy="0 0 0" xyz="-0.7280201840936915 0 0.26769486149055655" />
     <axis xyz="1 1 0"/>
       <limit effort="0.0" lower="-3.14159" upper="3.14159" velocity="0.0"/>
    </joint>
    <link name="5">
        <inertial>
            <origin xyz="-0.4836471563096512 0 0.42225385110000946" rpy="0 0 0"/>
            <mass value="1" />
            <inertia ixx="100" ixy="0" ixz="0" iyy="100" iyz="0" izz="100" />
        </inertial>
        <visual>
            <origin xyz="-0.4836471563096512 0 0.42225385110000946" rpy="0 0 0"/>
            <geometry>
                <box size="0.9672943126193024 0.6510530912712681 0.8445077022000189" />
            </geometry>
            <material name="Green">
                <color rgba="0 128 0 1"/>
            </material>
        </visual>
        <collision>
            <origin xyz="-0.4836471563096512 0 0.42225385110000946" rpy="0 0 0"/>
            <geometry>
                <box size="0.9672943126193024 0.6510530912712681 0.8445077022000189" />
            </geometry>
        </collision>
    </link>
    <joint name="4_5" type="revolute">
       <parent link="4"/>
       <child  link="5"/>
       <origin rpy="0 0 0" xyz="-0.32127810318715033 0 0.13733013914966585" />
     <axis xyz="0 1 0"/>
       <limit effort="0.0" lower="-3.14159" upper="3.14159" velocity="0.0"/>
    </joint>
    <link name="6">
        <inertial>
            <origin xyz="0.03176172652240761 0 0.2786125094737592" rpy="0 0 0"/>
            <mass value="1" />
            <inertia ixx="100" ixy="0" ixz="0" iyy="100" iyz="0" izz="100" />
        </inertial>
        <visual>
            <origin xyz="0.03176172652240761 0 0.2786125094737592" rpy="0 0 0"/>
            <geometry>
                <box size="0.06352345304481521 0.7637877519351215 0.5572250189475184" />
            </geometry>
            <material name="Blue">
                <color rgba="0 0 255 1"/>
            </material>
        </visual>
        <collision>
            <origin xyz="0.03176172652240761 0 0.2786125094737592" rpy="0 0 0"/>
            <geometry>
                <box size="0.06352345304481521 0.7637877519351215 0.5572250189475184" />
            </geometry>
        </collision>
    </link>
    <joint name="0_6" type="revolute">
       <parent link="0"/>
       <child  link="6"/>
       <origin rpy="0 0 0" xyz="0.35 0 0.7" />
     <axis xyz="1 1 1"/>
       <limit effort="0.0" lower="-3.14159" upper="3.14159" velocity="0.0"/>
    </joint>
    <link name="7">
        <inertial>
            <origin xyz="0.41323695464860044 0 0.26275817152952696" rpy="0 0 0"/>
            <mass value="1" />
            <inertia ixx="100" ixy="0" ixz="0" iyy="100" iyz="0" izz="100" />
        </inertial>
        <visual>
            <origin xyz="0.41323695464860044 0 0.26275817152952696" rpy="0 0 0"/>
            <geometry>
                <box size="0.8264739092972009 0.43595507636515907 0.5255163430590539" />
            </geometry>
            <material name="Green">
                <color rgba="0 128 0 1"/>
            </material>
        </visual>
        <collision>
            <origin xyz="0.41323695464860044 0 0.26275817152952696" rpy="0 0 0"/>
            <geometry>
                <box size="0.8264739092972009 0.43595507636515907 0.5255163430590539" />
            </geometry>
        </collision>
    </link>
    <joint name="6_7" type="revolute">
       <parent link="6"/>
       <child  link="7"/>
       <origin rpy="0 0 0" xyz="0.06352345304481521 0 0.5572250189475184" />
     <axis xyz="1 0 1"/>
       <limit effort="0.0" lower="-3.14159" upper="3.14159" velocity="0.0"/>
    </joint>
    <link name="8">
        <inertial>
            <origin xyz="0 0.22866194711578292 0.2147286315195367" rpy="0 0 0"/>
            <mass value="1" />
            <inertia ixx="100" ixy="0" ixz="0" iyy="100" iyz="0" izz="100" />
        </inertial>
        <visual>
            <origin xyz="0 0.22866194711578292 0.2147286315195367" rpy="0 0 0"/>
            <geometry>
                <box size="0.7646836261342285 0.45732389423156583 0.4294572630390734" />
            </geometry>
            <material name="Green">
                <color rgba="0 128 0 1"/>
            </material>
        </visual>
        <collision>
            <origin xyz="0 0.22866194711578292 0.2147286315195367" rpy="0 0 0"/>
            <geometry>
                <box size="0.7646836261342285 0.45732389423156583 0.4294572630390734" />
            </geometry>
        </collision>
    </link>
    <joint name="0_8" type="revolute">
       <parent link="0"/>
       <child  link="8"/>
       <origin rpy="0 0 0" xyz="0 0.35 0.7" />
     <axis xyz="0 1 1"/>
       <limit effort="0.0" lower="-3.14159" upper="3.14159" velocity="0.0"/>
    </joint>
</robot>