<robot name = "robot">
    <link name="0">
        <inertial>
            <origin xyz="0 0 0.5" rpy="0 0 0"/>
            <mass value="1" />
            <inertia ixx="100" ixy="0" ixz="0" iyy="100" iyz="0" izz="100" />
        </inertial>
        <visual>
            <origin xyz="0 0 0.5" rpy="0 0 0"/>
            <geometry>
                <box size="1 1 1" />
            </geometry>
            <material name="Blue">
                <color rgba="0 0 255 1"/>
            </material>
        </visual>
        <collision>
            <origin xyz="0 0 0.5" rpy="0 0 0"/>
            <geometry>
                <box size="1 1 1" />
            </geometry>
        </collision>
    </link>
    <link name="1">
        <inertial>
            <origin xyz="0 0 0.5" rpy="0 0 0"/>
            <mass value="1" />
            <inertia ixx="100" ixy="0" ixz="0" iyy="100" iyz="0" izz="100" />
        </inertial>
        <visual>
            <origin xyz="0 0 0.5" rpy="0 0 0"/>
            <geometry>
                <box size="1 1 1" />
            </geometry>
            <material name="Green">
                <color rgba="0 128 0 1"/>
            </material>
        </visual>
        <collision>
            <origin xyz="0 0 0.5" rpy="0 0 0"/>
            <geometry>
                <box size="1 1 1" />
            </geometry>
        </collision>
    </link>
    <joint name="0_1" type="revolute">
       <parent link="0"/>
       <child  link="1"/>
       <origin rpy="0 0 0" xyz="0 0 1" />
     <axis xyz="1 0 0"/>
       <limit effort="0.0" lower="-3.14159" upper="3.14159" velocity="0.0"/>
    </joint>
    <link name="2">
        <inertial>
            <origin xyz="0 0 0.5" rpy="0 0 0"/>
            <mass value="1" />
            <inertia ixx="100" ixy="0" ixz="0" iyy="100" iyz="0" izz="100" />
        </inertial>
        <visual>
            <origin xyz="0 0 0.5" rpy="0 0 0"/>
            <geometry>
                <box size="1 1 1" />
            </geometry>
            <material name="Green">
                <color rgba="0 128 0 1"/>
            </material>
        </visual>
        <collision>
            <origin xyz="0 0 0.5" rpy="0 0 0"/>
            <geometry>
                <box size="1 1 1" />
            </geometry>
        </collision>
    </link>
    <joint name="1_2" type="revolute">
       <parent link="1"/>
       <child  link="2"/>
       <origin rpy="0 0 0" xyz="0 0 1" />
     <axis xyz="0 1 0"/>
       <limit effort="0.0" lower="-3.14159" upper="3.14159" velocity="0.0"/>
    </joint>
    <link name="3">
        <inertial>
            <origin xyz="0 0 0.5" rpy="0 0 0"/>
            <mass value="1" />
            <inertia ixx="100" ixy="0" ixz="0" iyy="100" iyz="0" izz="100" />
        </inertial>
        <visual>
            <origin xyz="0 0 0.5" rpy="0 0 0"/>
            <geometry>
                <box size="1 1 1" />
            </geometry>
            <material name="Green">
                <color rgba="0 128 0 1"/>
            </material>
        </visual>
        <collision>
            <origin xyz="0 0 0.5" rpy="0 0 0"/>
            <geometry>
                <box size="1 1 1" />
            </geometry>
        </collision>
    </link>
    <joint name="2_3" type="revolute">
       <parent link="2"/>
       <child  link="3"/>
       <origin rpy="0 0 0" xyz="0 0 1" />
     <axis xyz="0 1 0"/>
       <limit effort="0.0" lower="-3.14159" upper="3.14159" velocity="0.0"/>
    </joint>
    <link name="4">
        <inertial>
            <origin xyz="0 0 0.5" rpy="0 0 0"/>
            <mass value="1" />
            <inertia ixx="100" ixy="0" ixz="0" iyy="100" iyz="0" izz="100" />
        </inertial>
        <visual>
            <origin xyz="0 0 0.5" rpy="0 0 0"/>
            <geometry>
                <box size="1 1 1" />
            </geometry>
            <material name="Blue">
                <color rgba="0 0 255 1"/>
            </material>
        </visual>
        <collision>
            <origin xyz="0 0 0.5" rpy="0 0 0"/>
            <geometry>
                <box size="1 1 1" />
            </geometry>
        </collision>
    </link>
    <joint name="3_4" type="revolute">
       <parent link="3"/>
       <child  link="4"/>
       <origin rpy="0 0 0" xyz="0 0 1" />
     <axis xyz="0 0 1"/>
       <limit effort="0.0" lower="-3.14159" upper="3.14159" velocity="0.0"/>
    </joint>
    <link name="5">
        <inertial>
            <origin xyz="0 0 0.5" rpy="0 0 0"/>
            <mass value="1" />
            <inertia ixx="100" ixy="0" ixz="0" iyy="100" iyz="0" izz="100" />
        </inertial>
        <visual>
            <origin xyz="0 0 0.5" rpy="0 0 0"/>
            <geometry>
                <box size="1 1 1" />
            </geometry>
            <material name="Blue">
                <color rgba="0 0 255 1"/>
            </material>
        </visual>
        <collision>
            <origin xyz="0 0 0.5" rpy="0 0 0"/>
            <geometry>
                <box size="1 1 1" />
            </geometry>
        </collision>
    </link>
    <joint name="4_5" type="revolute">
       <parent link="4"/>
       <child  link="5"/>
       <origin rpy="0 0 0" xyz="0 0 1" />
     <axis xyz="0 0 1"/>
       <limit effort="0.0" lower="-3.14159" upper="3.14159" velocity="0.0"/>
    </joint>
    <link name="6">
        <inertial>
            <origin xyz="0 0 0.5" rpy="0 0 0"/>
            <mass value="1" />
            <inertia ixx="100" ixy="0" ixz="0" iyy="100" iyz="0" izz="100" />
        </inertial>
        <visual>
            <origin xyz="0 0 0.5" rpy="0 0 0"/>
            <geometry>
                <box size="1 1 1" />
            </geometry>
            <material name="Blue">
                <color rgba="0 0 255 1"/>
            </material>
        </visual>
        <collision>
            <origin xyz="0 0 0.5" rpy="0 0 0"/>
            <geometry>
                <box size="1 1 1" />
            </geometry>
        </collision>
    </link>
    <joint name="5_6" type="revolute">
       <parent link="5"/>
       <child  link="6"/>
       <origin rpy="0 0 0" xyz="0 0 1" />
     <axis xyz="0 1 1"/>
       <limit effort="0.0" lower="-3.14159" upper="3.14159" velocity="0.0"/>
    </joint>
    <link name="7">
        <inertial>
            <origin xyz="0 0.4030331738202604 0" rpy="0 0 0"/>
            <mass value="1" />
            <inertia ixx="100" ixy="0" ixz="0" iyy="100" iyz="0" izz="100" />
        </inertial>
        <visual>
            <origin xyz="0 0.4030331738202604 0" rpy="0 0 0"/>
            <geometry>
                <box size="0.5315949677710285 0.8060663476405208 0.20040427254176674" />
            </geometry>
            <material name="Green">
                <color rgba="0 128 0 1"/>
            </material>
        </visual>
        <collision>
            <origin xyz="0 0.4030331738202604 0" rpy="0 0 0"/>
            <geometry>
                <box size="0.5315949677710285 0.8060663476405208 0.20040427254176674" />
            </geometry>
        </collision>
    </link>
    <joint name="1_7" type="revolute">
       <parent link="1"/>
       <child  link="7"/>
       <origin rpy="0 0 0" xyz="0 0.5 0.5" />
     <axis xyz="1 0 0"/>
       <limit effort="0.0" lower="-3.14159" upper="3.14159" velocity="0.0"/>
    </joint>
    <link name="8">
        <inertial>
            <origin xyz="0 0.30490459540468745 0" rpy="0 0 0"/>
            <mass value="1" />
            <inertia ixx="100" ixy="0" ixz="0" iyy="100" iyz="0" izz="100" />
        </inertial>
        <visual>
            <origin xyz="0 0.30490459540468745 0" rpy="0 0 0"/>
            <geometry>
                <box size="0.7415012546175808 0.6098091908093749 0.7285924391075145" />
            </geometry>
            <material name="Green">
                <color rgba="0 128 0 1"/>
            </material>
        </visual>
        <collision>
            <origin xyz="0 0.30490459540468745 0" rpy="0 0 0"/>
            <geometry>
                <box size="0.7415012546175808 0.6098091908093749 0.7285924391075145" />
            </geometry>
        </collision>
    </link>
    <joint name="7_8" type="revolute">
       <parent link="7"/>
       <child  link="8"/>
       <origin rpy="0 0 0" xyz="0 0.8060663476405208 0" />
     <axis xyz="0 0 1"/>
       <limit effort="0.0" lower="-3.14159" upper="3.14159" velocity="0.0"/>
    </joint>
    <link name="9">
        <inertial>
            <origin xyz="0 0.43615222595072467 0" rpy="0 0 0"/>
            <mass value="1" />
            <inertia ixx="100" ixy="0" ixz="0" iyy="100" iyz="0" izz="100" />
        </inertial>
        <visual>
            <origin xyz="0 0.43615222595072467 0" rpy="0 0 0"/>
            <geometry>
                <box size="0.9198264075027995 0.8723044519014493 0.632751672684787" />
            </geometry>
            <material name="Blue">
                <color rgba="0 0 255 1"/>
            </material>
        </visual>
        <collision>
            <origin xyz="0 0.43615222595072467 0" rpy="0 0 0"/>
            <geometry>
                <box size="0.9198264075027995 0.8723044519014493 0.632751672684787" />
            </geometry>
        </collision>
    </link>
    <joint name="8_9" type="revolute">
       <parent link="8"/>
       <child  link="9"/>
       <origin rpy="0 0 0" xyz="0 0.6098091908093749 0" />
     <axis xyz="1 1 0"/>
       <limit effort="0.0" lower="-3.14159" upper="3.14159" velocity="0.0"/>
    </joint>
    <link name="10">
        <inertial>
            <origin xyz="0 0.4434677779977749 0" rpy="0 0 0"/>
            <mass value="1" />
            <inertia ixx="100" ixy="0" ixz="0" iyy="100" iyz="0" izz="100" />
        </inertial>
        <visual>
            <origin xyz="0 0.4434677779977749 0" rpy="0 0 0"/>
            <geometry>
                <box size="0.9011992503543738 0.8869355559955499 0.8103593755943503" />
            </geometry>
            <material name="Blue">
                <color rgba="0 0 255 1"/>
            </material>
        </visual>
        <collision>
            <origin xyz="0 0.4434677779977749 0" rpy="0 0 0"/>
            <geometry>
                <box size="0.9011992503543738 0.8869355559955499 0.8103593755943503" />
            </geometry>
        </collision>
    </link>
    <joint name="9_10" type="revolute">
       <parent link="9"/>
       <child  link="10"/>
       <origin rpy="0 0 0" xyz="0 0.8723044519014493 0" />
     <axis xyz="1 0 1"/>
       <limit effort="0.0" lower="-3.14159" upper="3.14159" velocity="0.0"/>
    </joint>
    <link name="11">
        <inertial>
            <origin xyz="0 0.3506066435011264 0" rpy="0 0 0"/>
            <mass value="1" />
            <inertia ixx="100" ixy="0" ixz="0" iyy="100" iyz="0" izz="100" />
        </inertial>
        <visual>
            <origin xyz="0 0.3506066435011264 0" rpy="0 0 0"/>
            <geometry>
                <box size="0.7079780228788236 0.7012132870022528 0.5130545991137891" />
            </geometry>
            <material name="Green">
                <color rgba="0 128 0 1"/>
            </material>
        </visual>
        <collision>
            <origin xyz="0 0.3506066435011264 0" rpy="0 0 0"/>
            <geometry>
                <box size="0.7079780228788236 0.7012132870022528 0.5130545991137891" />
            </geometry>
        </collision>
    </link>
    <joint name="10_11" type="revolute">
       <parent link="10"/>
       <child  link="11"/>
       <origin rpy="0 0 0" xyz="0 0.8869355559955499 0" />
     <axis xyz="0 1 0"/>
       <limit effort="0.0" lower="-3.14159" upper="3.14159" velocity="0.0"/>
    </joint>
    <link name="12">
        <inertial>
            <origin xyz="0 -0.29787798030247387 0" rpy="0 0 0"/>
            <mass value="1" />
            <inertia ixx="100" ixy="0" ixz="0" iyy="100" iyz="0" izz="100" />
        </inertial>
        <visual>
            <origin xyz="0 -0.29787798030247387 0" rpy="0 0 0"/>
            <geometry>
                <box size="0.6395192087516973 0.5957559606049477 -0.7245721608649791" />
            </geometry>
            <material name="Blue">
                <color rgba="0 0 255 1"/>
            </material>
        </visual>
        <collision>
            <origin xyz="0 -0.29787798030247387 0" rpy="0 0 0"/>
            <geometry>
                <box size="0.6395192087516973 0.5957559606049477 -0.7245721608649791" />
            </geometry>
        </collision>
    </link>
    <joint name="2_12" type="revolute">
       <parent link="2"/>
       <child  link="12"/>
       <origin rpy="0 0 0" xyz="0 -0.5 0.5" />
     <axis xyz="0 1 0"/>
       <limit effort="0.0" lower="-3.14159" upper="3.14159" velocity="0.0"/>
    </joint>
    <link name="13">
        <inertial>
            <origin xyz="0 -0.4479575394198219 0" rpy="0 0 0"/>
            <mass value="1" />
            <inertia ixx="100" ixy="0" ixz="0" iyy="100" iyz="0" izz="100" />
        </inertial>
        <visual>
            <origin xyz="0 -0.4479575394198219 0" rpy="0 0 0"/>
            <geometry>
                <box size="0.7133393947864348 0.8959150788396438 0.9417435722954098" />
            </geometry>
            <material name="Green">
                <color rgba="0 128 0 1"/>
            </material>
        </visual>
        <collision>
            <origin xyz="0 -0.4479575394198219 0" rpy="0 0 0"/>
            <geometry>
                <box size="0.7133393947864348 0.8959150788396438 0.9417435722954098" />
            </geometry>
        </collision>
    </link>
    <joint name="12_13" type="revolute">
       <parent link="12"/>
       <child  link="13"/>
       <origin rpy="0 0 0" xyz="0 -0.5957559606049477 0" />
     <axis xyz="0 1 1"/>
       <limit effort="0.0" lower="-3.14159" upper="3.14159" velocity="0.0"/>
    </joint>
</robot>