<robot name = "robot">
    <link name="0">
        <inertial>
            <origin xyz="0 0 3" rpy="0 0 0"/>
            <mass value="1" />
            <inertia ixx="100" ixy="0" ixz="0" iyy="100" iyz="0" izz="100" />
        </inertial>
        <visual>
            <origin xyz="0 0 3" rpy="0 0 0"/>
            <geometry>
                <box size="1.5 1.5 0.8" />
            </geometry>
            <material name="Green">
                <color rgba="0 128 0 1"/>
            </material>
        </visual>
        <collision>
            <origin xyz="0 0 3" rpy="0 0 0"/>
            <geometry>
                <box size="1.5 1.5 0.8" />
            </geometry>
        </collision>
    </link>
    <link name="1">
        <inertial>
            <origin xyz="-0.3258705616669197 0 0" rpy="0 0 0"/>
            <mass value="1" />
            <inertia ixx="100" ixy="0" ixz="0" iyy="100" iyz="0" izz="100" />
        </inertial>
        <visual>
            <origin xyz="-0.3258705616669197 0 0" rpy="0 0 0"/>
            <geometry>
                <box size="0.6517411233338394 0.6283800934316837 0.510496209093488" />
            </geometry>
            <material name="Green">
                <color rgba="0 128 0 1"/>
            </material>
        </visual>
        <collision>
            <origin xyz="-0.3258705616669197 0 0" rpy="0 0 0"/>
            <geometry>
                <box size="0.6517411233338394 0.6283800934316837 0.510496209093488" />
            </geometry>
        </collision>
    </link>
    <joint name="0_1" type="revolute">
       <parent link="0"/>
       <child  link="1"/>
       <origin rpy="0 0 0" xyz="-0.75 0 3" />
     <axis xyz="1 1 0"/>
       <limit effort="0.0" lower="-3.14159" upper="3.14159" velocity="0.0"/>
    </joint>
    <link name="2">
        <inertial>
            <origin xyz="-0.3350662899475404 0 0" rpy="0 0 0"/>
            <mass value="1" />
            <inertia ixx="100" ixy="0" ixz="0" iyy="100" iyz="0" izz="100" />
        </inertial>
        <visual>
            <origin xyz="-0.3350662899475404 0 0" rpy="0 0 0"/>
            <geometry>
                <box size="0.6701325798950808 0.6455652851716609 0.4518983937415877" />
            </geometry>
            <material name="Green">
                <color rgba="0 128 0 1"/>
            </material>
        </visual>
        <collision>
            <origin xyz="-0.3350662899475404 0 0" rpy="0 0 0"/>
            <geometry>
                <box size="0.6701325798950808 0.6455652851716609 0.4518983937415877" />
            </geometry>
        </collision>
    </link>
    <joint name="1_2" type="revolute">
       <parent link="1"/>
       <child  link="2"/>
       <origin rpy="0 0 0" xyz="-0.6517411233338394 0 0" />
     <axis xyz="1 0 1"/>
       <limit effort="0.0" lower="-3.14159" upper="3.14159" velocity="0.0"/>
    </joint>
    <link name="3">
        <inertial>
            <origin xyz="0 0 -0.9414831247989054" rpy="0 0 0"/>
            <mass value="1" />
            <inertia ixx="100" ixy="0" ixz="0" iyy="100" iyz="0" izz="100" />
        </inertial>
        <visual>
            <origin xyz="0 0 -0.9414831247989054" rpy="0 0 0"/>
            <geometry>
                <box size="0.9441360126926639 0.23323928373368974 1.8829662495978108" />
            </geometry>
            <material name="Blue">
                <color rgba="0 0 255 1"/>
            </material>
        </visual>
        <collision>
            <origin xyz="0 0 -0.9414831247989054" rpy="0 0 0"/>
            <geometry>
                <box size="0.9441360126926639 0.23323928373368974 1.8829662495978108" />
            </geometry>
        </collision>
    </link>
    <joint name="2_3" type="revolute">
       <parent link="2"/>
       <child  link="3"/>
       <origin rpy="0 0 0" xyz="-0.3350662899475404 0 -0.22594919687079384" />
     <axis xyz="1 0 0"/>
       <limit effort="0.0" lower="-3.14159" upper="3.14159" velocity="0.0"/>
    </joint>
    <link name="4">
        <inertial>
            <origin xyz="0 0 -0.0769683765257647" rpy="0 0 0"/>
            <mass value="1" />
            <inertia ixx="100" ixy="0" ixz="0" iyy="100" iyz="0" izz="100" />
        </inertial>
        <visual>
            <origin xyz="0 0 -0.0769683765257647" rpy="0 0 0"/>
            <geometry>
                <box size="0.045363675266066106 0.3257478991936956 0.1539367530515294" />
            </geometry>
            <material name="Green">
                <color rgba="0 128 0 1"/>
            </material>
        </visual>
        <collision>
            <origin xyz="0 0 -0.0769683765257647" rpy="0 0 0"/>
            <geometry>
                <box size="0.045363675266066106 0.3257478991936956 0.1539367530515294" />
            </geometry>
        </collision>
    </link>
    <joint name="3_4" type="revolute">
       <parent link="3"/>
       <child  link="4"/>
       <origin rpy="0 0 0" xyz="0 0 -1.8829662495978108" />
     <axis xyz="1 1 0"/>
       <limit effort="0.0" lower="-3.14159" upper="3.14159" velocity="0.0"/>
    </joint>
    <link name="5">
        <inertial>
            <origin xyz="0 0 -0.28154849867532994" rpy="0 0 0"/>
            <mass value="1" />
            <inertia ixx="100" ixy="0" ixz="0" iyy="100" iyz="0" izz="100" />
        </inertial>
        <visual>
            <origin xyz="0 0 -0.28154849867532994" rpy="0 0 0"/>
            <geometry>
                <box size="0.7567578451293808 0.20753186336075657 0.5630969973506599" />
            </geometry>
            <material name="Green">
                <color rgba="0 128 0 1"/>
            </material>
        </visual>
        <collision>
            <origin xyz="0 0 -0.28154849867532994" rpy="0 0 0"/>
            <geometry>
                <box size="0.7567578451293808 0.20753186336075657 0.5630969973506599" />
            </geometry>
        </collision>
    </link>
    <joint name="4_5" type="revolute">
       <parent link="4"/>
       <child  link="5"/>
       <origin rpy="0 0 0" xyz="0 0 -0.1539367530515294" />
     <axis xyz="1 0 1"/>
       <limit effort="0.0" lower="-3.14159" upper="3.14159" velocity="0.0"/>
    </joint>
    <link name="6">
        <inertial>
            <origin xyz="0.2950703812954615 0 0" rpy="0 0 0"/>
            <mass value="1" />
            <inertia ixx="100" ixy="0" ixz="0" iyy="100" iyz="0" izz="100" />
        </inertial>
        <visual>
            <origin xyz="0.2950703812954615 0 0" rpy="0 0 0"/>
            <geometry>
                <box size="0.590140762590923 0.6642627088083374 0.29377950506652284" />
            </geometry>
            <material name="Blue">
                <color rgba="0 0 255 1"/>
            </material>
        </visual>
        <collision>
            <origin xyz="0.2950703812954615 0 0" rpy="0 0 0"/>
            <geometry>
                <box size="0.590140762590923 0.6642627088083374 0.29377950506652284" />
            </geometry>
        </collision>
    </link>
    <joint name="0_6" type="revolute">
       <parent link="0"/>
       <child  link="6"/>
       <origin rpy="0 0 0" xyz="0.75 0 3" />
     <axis xyz="1 0 0"/>
       <limit effort="0.0" lower="-3.14159" upper="3.14159" velocity="0.0"/>
    </joint>
    <link name="7">
        <inertial>
            <origin xyz="0.17082048007140493 0 0" rpy="0 0 0"/>
            <mass value="1" />
            <inertia ixx="100" ixy="0" ixz="0" iyy="100" iyz="0" izz="100" />
        </inertial>
        <visual>
            <origin xyz="0.17082048007140493 0 0" rpy="0 0 0"/>
            <geometry>
                <box size="0.34164096014280987 0.07276084377136849 0.08844142271590894" />
            </geometry>
            <material name="Green">
                <color rgba="0 128 0 1"/>
            </material>
        </visual>
        <collision>
            <origin xyz="0.17082048007140493 0 0" rpy="0 0 0"/>
            <geometry>
                <box size="0.34164096014280987 0.07276084377136849 0.08844142271590894" />
            </geometry>
        </collision>
    </link>
    <joint name="6_7" type="revolute">
       <parent link="6"/>
       <child  link="7"/>
       <origin rpy="0 0 0" xyz="0.590140762590923 0 0" />
     <axis xyz="1 0 1"/>
       <limit effort="0.0" lower="-3.14159" upper="3.14159" velocity="0.0"/>
    </joint>
    <link name="8">
        <inertial>
            <origin xyz="0 0 -0.6835724629801946" rpy="0 0 0"/>
            <mass value="1" />
            <inertia ixx="100" ixy="0" ixz="0" iyy="100" iyz="0" izz="100" />
        </inertial>
        <visual>
            <origin xyz="0 0 -0.6835724629801946" rpy="0 0 0"/>
            <geometry>
                <box size="0.29469564808568116 0.5701069215578876 1.3671449259603892" />
            </geometry>
            <material name="Green">
                <color rgba="0 128 0 1"/>
            </material>
        </visual>
        <collision>
            <origin xyz="0 0 -0.6835724629801946" rpy="0 0 0"/>
            <geometry>
                <box size="0.29469564808568116 0.5701069215578876 1.3671449259603892" />
            </geometry>
        </collision>
    </link>
    <joint name="7_8" type="revolute">
       <parent link="7"/>
       <child  link="8"/>
       <origin rpy="0 0 0" xyz="0.17082048007140493 0 -0.04422071135795447" />
     <axis xyz="1 0 0"/>
       <limit effort="0.0" lower="-3.14159" upper="3.14159" velocity="0.0"/>
    </joint>
    <link name="9">
        <inertial>
            <origin xyz="0 0 -0.12663589002215175" rpy="0 0 0"/>
            <mass value="1" />
            <inertia ixx="100" ixy="0" ixz="0" iyy="100" iyz="0" izz="100" />
        </inertial>
        <visual>
            <origin xyz="0 0 -0.12663589002215175" rpy="0 0 0"/>
            <geometry>
                <box size="0.6747110865721472 0.2892814970656188 0.2532717800443035" />
            </geometry>
            <material name="Blue">
                <color rgba="0 0 255 1"/>
            </material>
        </visual>
        <collision>
            <origin xyz="0 0 -0.12663589002215175" rpy="0 0 0"/>
            <geometry>
                <box size="0.6747110865721472 0.2892814970656188 0.2532717800443035" />
            </geometry>
        </collision>
    </link>
    <joint name="8_9" type="revolute">
       <parent link="8"/>
       <child  link="9"/>
       <origin rpy="0 0 0" xyz="0 0 -1.3671449259603892" />
     <axis xyz="1 0 1"/>
       <limit effort="0.0" lower="-3.14159" upper="3.14159" velocity="0.0"/>
    </joint>
    <link name="10">
        <inertial>
            <origin xyz="0 0 -0.4897916469976537" rpy="0 0 0"/>
            <mass value="1" />
            <inertia ixx="100" ixy="0" ixz="0" iyy="100" iyz="0" izz="100" />
        </inertial>
        <visual>
            <origin xyz="0 0 -0.4897916469976537" rpy="0 0 0"/>
            <geometry>
                <box size="0.18630799476948667 0.7224219620760387 0.9795832939953074" />
            </geometry>
            <material name="Green">
                <color rgba="0 128 0 1"/>
            </material>
        </visual>
        <collision>
            <origin xyz="0 0 -0.4897916469976537" rpy="0 0 0"/>
            <geometry>
                <box size="0.18630799476948667 0.7224219620760387 0.9795832939953074" />
            </geometry>
        </collision>
    </link>
    <joint name="9_10" type="revolute">
       <parent link="9"/>
       <child  link="10"/>
       <origin rpy="0 0 0" xyz="0 0 -0.2532717800443035" />
     <axis xyz="0 1 0"/>
       <limit effort="0.0" lower="-3.14159" upper="3.14159" velocity="0.0"/>
    </joint>
    <link name="11">
        <inertial>
            <origin xyz="0 -0.13565494488259622 0" rpy="0 0 0"/>
            <mass value="1" />
            <inertia ixx="100" ixy="0" ixz="0" iyy="100" iyz="0" izz="100" />
        </inertial>
        <visual>
            <origin xyz="0 -0.13565494488259622 0" rpy="0 0 0"/>
            <geometry>
                <box size="0.5553388790967755 0.27130988976519244 0.08911710900821657" />
            </geometry>
            <material name="Blue">
                <color rgba="0 0 255 1"/>
            </material>
        </visual>
        <collision>
            <origin xyz="0 -0.13565494488259622 0" rpy="0 0 0"/>
            <geometry>
                <box size="0.5553388790967755 0.27130988976519244 0.08911710900821657" />
            </geometry>
        </collision>
    </link>
    <joint name="0_11" type="revolute">
       <parent link="0"/>
       <child  link="11"/>
       <origin rpy="0 0 0" xyz="0 -0.75 3" />
     <axis xyz="1 1 0"/>
       <limit effort="0.0" lower="-3.14159" upper="3.14159" velocity="0.0"/>
    </joint>
    <link name="12">
        <inertial>
            <origin xyz="0 -0.4857578851905155 0" rpy="0 0 0"/>
            <mass value="1" />
            <inertia ixx="100" ixy="0" ixz="0" iyy="100" iyz="0" izz="100" />
        </inertial>
        <visual>
            <origin xyz="0 -0.4857578851905155 0" rpy="0 0 0"/>
            <geometry>
                <box size="0.9636665419955415 0.971515770381031 0.39404621464351886" />
            </geometry>
            <material name="Blue">
                <color rgba="0 0 255 1"/>
            </material>
        </visual>
        <collision>
            <origin xyz="0 -0.4857578851905155 0" rpy="0 0 0"/>
            <geometry>
                <box size="0.9636665419955415 0.971515770381031 0.39404621464351886" />
            </geometry>
        </collision>
    </link>
    <joint name="11_12" type="revolute">
       <parent link="11"/>
       <child  link="12"/>
       <origin rpy="0 0 0" xyz="0 -0.27130988976519244 0" />
     <axis xyz="0 1 0"/>
       <limit effort="0.0" lower="-3.14159" upper="3.14159" velocity="0.0"/>
    </joint>
    <link name="13">
        <inertial>
            <origin xyz="0 0 -0.6691963759058736" rpy="0 0 0"/>
            <mass value="1" />
            <inertia ixx="100" ixy="0" ixz="0" iyy="100" iyz="0" izz="100" />
        </inertial>
        <visual>
            <origin xyz="0 0 -0.6691963759058736" rpy="0 0 0"/>
            <geometry>
                <box size="0.998534524270682 0.45908608004458873 1.338392751811747" />
            </geometry>
            <material name="Green">
                <color rgba="0 128 0 1"/>
            </material>
        </visual>
        <collision>
            <origin xyz="0 0 -0.6691963759058736" rpy="0 0 0"/>
            <geometry>
                <box size="0.998534524270682 0.45908608004458873 1.338392751811747" />
            </geometry>
        </collision>
    </link>
    <joint name="12_13" type="revolute">
       <parent link="12"/>
       <child  link="13"/>
       <origin rpy="0 0 0" xyz="0 -0.4857578851905155 -0.19702310732175943" />
     <axis xyz="0 0 1"/>
       <limit effort="0.0" lower="-3.14159" upper="3.14159" velocity="0.0"/>
    </joint>
    <link name="14">
        <inertial>
            <origin xyz="0 0 -0.4594666708935071" rpy="0 0 0"/>
            <mass value="1" />
            <inertia ixx="100" ixy="0" ixz="0" iyy="100" iyz="0" izz="100" />
        </inertial>
        <visual>
            <origin xyz="0 0 -0.4594666708935071" rpy="0 0 0"/>
            <geometry>
                <box size="0.5992060668288807 0.5962535935420517 0.9189333417870142" />
            </geometry>
            <material name="Green">
                <color rgba="0 128 0 1"/>
            </material>
        </visual>
        <collision>
            <origin xyz="0 0 -0.4594666708935071" rpy="0 0 0"/>
            <geometry>
                <box size="0.5992060668288807 0.5962535935420517 0.9189333417870142" />
            </geometry>
        </collision>
    </link>
    <joint name="13_14" type="revolute">
       <parent link="13"/>
       <child  link="14"/>
       <origin rpy="0 0 0" xyz="0 0 -1.338392751811747" />
     <axis xyz="0 1 0"/>
       <limit effort="0.0" lower="-3.14159" upper="3.14159" velocity="0.0"/>
    </joint>
    <link name="15">
        <inertial>
            <origin xyz="0 0 -0.17133695320061937" rpy="0 0 0"/>
            <mass value="1" />
            <inertia ixx="100" ixy="0" ixz="0" iyy="100" iyz="0" izz="100" />
        </inertial>
        <visual>
            <origin xyz="0 0 -0.17133695320061937" rpy="0 0 0"/>
            <geometry>
                <box size="0.34421237322927245 0.3098641921529588 0.34267390640123874" />
            </geometry>
            <material name="Green">
                <color rgba="0 128 0 1"/>
            </material>
        </visual>
        <collision>
            <origin xyz="0 0 -0.17133695320061937" rpy="0 0 0"/>
            <geometry>
                <box size="0.34421237322927245 0.3098641921529588 0.34267390640123874" />
            </geometry>
        </collision>
    </link>
    <joint name="14_15" type="revolute">
       <parent link="14"/>
       <child  link="15"/>
       <origin rpy="0 0 0" xyz="0 0 -0.9189333417870142" />
     <axis xyz="1 0 1"/>
       <limit effort="0.0" lower="-3.14159" upper="3.14159" velocity="0.0"/>
    </joint>
    <link name="16">
        <inertial>
            <origin xyz="0 0.49639767072530183 0" rpy="0 0 0"/>
            <mass value="1" />
            <inertia ixx="100" ixy="0" ixz="0" iyy="100" iyz="0" izz="100" />
        </inertial>
        <visual>
            <origin xyz="0 0.49639767072530183 0" rpy="0 0 0"/>
            <geometry>
                <box size="0.42885195472639315 0.9927953414506037 0.5549872809150816" />
            </geometry>
            <material name="Blue">
                <color rgba="0 0 255 1"/>
            </material>
        </visual>
        <collision>
            <origin xyz="0 0.49639767072530183 0" rpy="0 0 0"/>
            <geometry>
                <box size="0.42885195472639315 0.9927953414506037 0.5549872809150816" />
            </geometry>
        </collision>
    </link>
    <joint name="0_16" type="revolute">
       <parent link="0"/>
       <child  link="16"/>
       <origin rpy="0 0 0" xyz="0 0.75 3" />
     <axis xyz="0 1 0"/>
       <limit effort="0.0" lower="-3.14159" upper="3.14159" velocity="0.0"/>
    </joint>
    <link name="17">
        <inertial>
            <origin xyz="0 0.44350878321569187 0" rpy="0 0 0"/>
            <mass value="1" />
            <inertia ixx="100" ixy="0" ixz="0" iyy="100" iyz="0" izz="100" />
        </inertial>
        <visual>
            <origin xyz="0 0.44350878321569187 0" rpy="0 0 0"/>
            <geometry>
                <box size="0.1950151495791319 0.8870175664313837 0.32876651728228123" />
            </geometry>
            <material name="Green">
                <color rgba="0 128 0 1"/>
            </material>
        </visual>
        <collision>
            <origin xyz="0 0.44350878321569187 0" rpy="0 0 0"/>
            <geometry>
                <box size="0.1950151495791319 0.8870175664313837 0.32876651728228123" />
            </geometry>
        </collision>
    </link>
    <joint name="16_17" type="revolute">
       <parent link="16"/>
       <child  link="17"/>
       <origin rpy="0 0 0" xyz="0 0.9927953414506037 0" />
     <axis xyz="0 1 0"/>
       <limit effort="0.0" lower="-3.14159" upper="3.14159" velocity="0.0"/>
    </joint>
    <link name="18">
        <inertial>
            <origin xyz="0 0 -0.9876164584351316" rpy="0 0 0"/>
            <mass value="1" />
            <inertia ixx="100" ixy="0" ixz="0" iyy="100" iyz="0" izz="100" />
        </inertial>
        <visual>
            <origin xyz="0 0 -0.9876164584351316" rpy="0 0 0"/>
            <geometry>
                <box size="0.684126162757366 0.8020623241223189 1.9752329168702631" />
            </geometry>
            <material name="Green">
                <color rgba="0 128 0 1"/>
            </material>
        </visual>
        <collision>
            <origin xyz="0 0 -0.9876164584351316" rpy="0 0 0"/>
            <geometry>
                <box size="0.684126162757366 0.8020623241223189 1.9752329168702631" />
            </geometry>
        </collision>
    </link>
    <joint name="17_18" type="revolute">
       <parent link="17"/>
       <child  link="18"/>
       <origin rpy="0 0 0" xyz="0 0.44350878321569187 -0.16438325864114062" />
     <axis xyz="1 1 0"/>
       <limit effort="0.0" lower="-3.14159" upper="3.14159" velocity="0.0"/>
    </joint>
    <link name="19">
        <inertial>
            <origin xyz="0 0 -0.22775628529991632" rpy="0 0 0"/>
            <mass value="1" />
            <inertia ixx="100" ixy="0" ixz="0" iyy="100" iyz="0" izz="100" />
        </inertial>
        <visual>
            <origin xyz="0 0 -0.22775628529991632" rpy="0 0 0"/>
            <geometry>
                <box size="0.48884599667760187 0.9113543559825177 0.45551257059983263" />
            </geometry>
            <material name="Green">
                <color rgba="0 128 0 1"/>
            </material>
        </visual>
        <collision>
            <origin xyz="0 0 -0.22775628529991632" rpy="0 0 0"/>
            <geometry>
                <box size="0.48884599667760187 0.9113543559825177 0.45551257059983263" />
            </geometry>
        </collision>
    </link>
    <joint name="18_19" type="revolute">
       <parent link="18"/>
       <child  link="19"/>
       <origin rpy="0 0 0" xyz="0 0 -1.9752329168702631" />
     <axis xyz="1 0 0"/>
       <limit effort="0.0" lower="-3.14159" upper="3.14159" velocity="0.0"/>
    </joint>
    <link name="20">
        <inertial>
            <origin xyz="0 0 -0.08462725626495216" rpy="0 0 0"/>
            <mass value="1" />
            <inertia ixx="100" ixy="0" ixz="0" iyy="100" iyz="0" izz="100" />
        </inertial>
        <visual>
            <origin xyz="0 0 -0.08462725626495216" rpy="0 0 0"/>
            <geometry>
                <box size="0.6836302239207364 0.05412982369782682 0.1692545125299043" />
            </geometry>
            <material name="Green">
                <color rgba="0 128 0 1"/>
            </material>
        </visual>
        <collision>
            <origin xyz="0 0 -0.08462725626495216" rpy="0 0 0"/>
            <geometry>
                <box size="0.6836302239207364 0.05412982369782682 0.1692545125299043" />
            </geometry>
        </collision>
    </link>
    <joint name="19_20" type="revolute">
       <parent link="19"/>
       <child  link="20"/>
       <origin rpy="0 0 0" xyz="0 0 -0.45551257059983263" />
     <axis xyz="0 1 1"/>
       <limit effort="0.0" lower="-3.14159" upper="3.14159" velocity="0.0"/>
    </joint>
</robot>