<robot name = "robot">
    <link name="0">
        <inertial>
            <origin xyz="0 0 3" rpy="0 0 0"/>
            <mass value="1" />
            <inertia ixx="100" ixy="0" ixz="0" iyy="100" iyz="0" izz="100" />
        </inertial>
        <visual>
            <origin xyz="0 0 3" rpy="0 0 0"/>
            <geometry>
                <box size="1.5 1.5 0.8" />
            </geometry>
            <material name="Blue">
                <color rgba="0 0 255 1"/>
            </material>
        </visual>
        <collision>
            <origin xyz="0 0 3" rpy="0 0 0"/>
            <geometry>
                <box size="1.5 1.5 0.8" />
            </geometry>
        </collision>
    </link>
    <link name="1">
        <inertial>
            <origin xyz="-0.4246325118166724 0 0" rpy="0 0 0"/>
            <mass value="1" />
            <inertia ixx="100" ixy="0" ixz="0" iyy="100" iyz="0" izz="100" />
        </inertial>
        <visual>
            <origin xyz="-0.4246325118166724 0 0" rpy="0 0 0"/>
            <geometry>
                <box size="0.8492650236333448 0.29769255721562937 0.8259410869357563" />
            </geometry>
            <material name="Blue">
                <color rgba="0 0 255 1"/>
            </material>
        </visual>
        <collision>
            <origin xyz="-0.4246325118166724 0 0" rpy="0 0 0"/>
            <geometry>
                <box size="0.8492650236333448 0.29769255721562937 0.8259410869357563" />
            </geometry>
        </collision>
    </link>
    <joint name="0_1" type="revolute">
       <parent link="0"/>
       <child  link="1"/>
       <origin rpy="0 0 0" xyz="-0.75 0 3" />
     <axis xyz="0 1 0"/>
       <limit effort="0.0" lower="-3.14159" upper="3.14159" velocity="0.0"/>
    </joint>
    <link name="2">
        <inertial>
            <origin xyz="-0.15137459607519532 0 0" rpy="0 0 0"/>
            <mass value="1" />
            <inertia ixx="100" ixy="0" ixz="0" iyy="100" iyz="0" izz="100" />
        </inertial>
        <visual>
            <origin xyz="-0.15137459607519532 0 0" rpy="0 0 0"/>
            <geometry>
                <box size="0.30274919215039064 0.4997664905818977 0.804756104682622" />
            </geometry>
            <material name="Green">
                <color rgba="0 128 0 1"/>
            </material>
        </visual>
        <collision>
            <origin xyz="-0.15137459607519532 0 0" rpy="0 0 0"/>
            <geometry>
                <box size="0.30274919215039064 0.4997664905818977 0.804756104682622" />
            </geometry>
        </collision>
    </link>
    <joint name="1_2" type="revolute">
       <parent link="1"/>
       <child  link="2"/>
       <origin rpy="0 0 0" xyz="-0.8492650236333448 0 0" />
     <axis xyz="1 0 0"/>
       <limit effort="0.0" lower="-3.14159" upper="3.14159" velocity="0.0"/>
    </joint>
    <link name="3">
        <inertial>
            <origin xyz="-0.13814423009689558 0 0" rpy="0 0 0"/>
            <mass value="1" />
            <inertia ixx="100" ixy="0" ixz="0" iyy="100" iyz="0" izz="100" />
        </inertial>
        <visual>
            <origin xyz="-0.13814423009689558 0 0" rpy="0 0 0"/>
            <geometry>
                <box size="0.27628846019379116 0.6020727329065149 0.23646301412608206" />
            </geometry>
            <material name="Blue">
                <color rgba="0 0 255 1"/>
            </material>
        </visual>
        <collision>
            <origin xyz="-0.13814423009689558 0 0" rpy="0 0 0"/>
            <geometry>
                <box size="0.27628846019379116 0.6020727329065149 0.23646301412608206" />
            </geometry>
        </collision>
    </link>
    <joint name="2_3" type="revolute">
       <parent link="2"/>
       <child  link="3"/>
       <origin rpy="0 0 0" xyz="-0.30274919215039064 0 0" />
     <axis xyz="1 0 0"/>
       <limit effort="0.0" lower="-3.14159" upper="3.14159" velocity="0.0"/>
    </joint>
    <link name="4">
        <inertial>
            <origin xyz="-0.18214790009280524 0 0" rpy="0 0 0"/>
            <mass value="1" />
            <inertia ixx="100" ixy="0" ixz="0" iyy="100" iyz="0" izz="100" />
        </inertial>
        <visual>
            <origin xyz="-0.18214790009280524 0 0" rpy="0 0 0"/>
            <geometry>
                <box size="0.3642958001856105 0.31321647933368657 0.2996765756098132" />
            </geometry>
            <material name="Blue">
                <color rgba="0 0 255 1"/>
            </material>
        </visual>
        <collision>
            <origin xyz="-0.18214790009280524 0 0" rpy="0 0 0"/>
            <geometry>
                <box size="0.3642958001856105 0.31321647933368657 0.2996765756098132" />
            </geometry>
        </collision>
    </link>
    <joint name="3_4" type="revolute">
       <parent link="3"/>
       <child  link="4"/>
       <origin rpy="0 0 0" xyz="-0.27628846019379116 0 0" />
     <axis xyz="1 1 0"/>
       <limit effort="0.0" lower="-3.14159" upper="3.14159" velocity="0.0"/>
    </joint>
    <link name="5">
        <inertial>
            <origin xyz="-0.07289383187892784 0 0" rpy="0 0 0"/>
            <mass value="1" />
            <inertia ixx="100" ixy="0" ixz="0" iyy="100" iyz="0" izz="100" />
        </inertial>
        <visual>
            <origin xyz="-0.07289383187892784 0 0" rpy="0 0 0"/>
            <geometry>
                <box size="0.14578766375785568 0.47123687287286575 0.07670612795469245" />
            </geometry>
            <material name="Blue">
                <color rgba="0 0 255 1"/>
            </material>
        </visual>
        <collision>
            <origin xyz="-0.07289383187892784 0 0" rpy="0 0 0"/>
            <geometry>
                <box size="0.14578766375785568 0.47123687287286575 0.07670612795469245" />
            </geometry>
        </collision>
    </link>
    <joint name="4_5" type="revolute">
       <parent link="4"/>
       <child  link="5"/>
       <origin rpy="0 0 0" xyz="-0.3642958001856105 0 0" />
     <axis xyz="1 0 1"/>
       <limit effort="0.0" lower="-3.14159" upper="3.14159" velocity="0.0"/>
    </joint>
    <link name="6">
        <inertial>
            <origin xyz="0 0 -0.7116042842654603" rpy="0 0 0"/>
            <mass value="1" />
            <inertia ixx="100" ixy="0" ixz="0" iyy="100" iyz="0" izz="100" />
        </inertial>
        <visual>
            <origin xyz="0 0 -0.7116042842654603" rpy="0 0 0"/>
            <geometry>
                <box size="0.15956836642187122 0.012214708413522568 1.4232085685309206" />
            </geometry>
            <material name="Blue">
                <color rgba="0 0 255 1"/>
            </material>
        </visual>
        <collision>
            <origin xyz="0 0 -0.7116042842654603" rpy="0 0 0"/>
            <geometry>
                <box size="0.15956836642187122 0.012214708413522568 1.4232085685309206" />
            </geometry>
        </collision>
    </link>
    <joint name="5_6" type="revolute">
       <parent link="5"/>
       <child  link="6"/>
       <origin rpy="0 0 0" xyz="-0.07289383187892784 0 -0.038353063977346225" />
     <axis xyz="1 1 1"/>
       <limit effort="0.0" lower="-3.14159" upper="3.14159" velocity="0.0"/>
    </joint>
    <link name="7">
        <inertial>
            <origin xyz="0 0 -0.4939725075396121" rpy="0 0 0"/>
            <mass value="1" />
            <inertia ixx="100" ixy="0" ixz="0" iyy="100" iyz="0" izz="100" />
        </inertial>
        <visual>
            <origin xyz="0 0 -0.4939725075396121" rpy="0 0 0"/>
            <geometry>
                <box size="0.21453797741623903 0.3414453465783094 0.9879450150792242" />
            </geometry>
            <material name="Green">
                <color rgba="0 128 0 1"/>
            </material>
        </visual>
        <collision>
            <origin xyz="0 0 -0.4939725075396121" rpy="0 0 0"/>
            <geometry>
                <box size="0.21453797741623903 0.3414453465783094 0.9879450150792242" />
            </geometry>
        </collision>
    </link>
    <joint name="6_7" type="revolute">
       <parent link="6"/>
       <child  link="7"/>
       <origin rpy="0 0 0" xyz="0 0 -1.4232085685309206" />
     <axis xyz="1 0 1"/>
       <limit effort="0.0" lower="-3.14159" upper="3.14159" velocity="0.0"/>
    </joint>
    <link name="8">
        <inertial>
            <origin xyz="0 0 -0.09442320819492767" rpy="0 0 0"/>
            <mass value="1" />
            <inertia ixx="100" ixy="0" ixz="0" iyy="100" iyz="0" izz="100" />
        </inertial>
        <visual>
            <origin xyz="0 0 -0.09442320819492767" rpy="0 0 0"/>
            <geometry>
                <box size="0.07353967993570587 0.2008840949771924 0.18884641638985533" />
            </geometry>
            <material name="Green">
                <color rgba="0 128 0 1"/>
            </material>
        </visual>
        <collision>
            <origin xyz="0 0 -0.09442320819492767" rpy="0 0 0"/>
            <geometry>
                <box size="0.07353967993570587 0.2008840949771924 0.18884641638985533" />
            </geometry>
        </collision>
    </link>
    <joint name="7_8" type="revolute">
       <parent link="7"/>
       <child  link="8"/>
       <origin rpy="0 0 0" xyz="0 0 -0.9879450150792242" />
     <axis xyz="1 0 0"/>
       <limit effort="0.0" lower="-3.14159" upper="3.14159" velocity="0.0"/>
    </joint>
    <link name="9">
        <inertial>
            <origin xyz="0.32022546077212966 0 0" rpy="0 0 0"/>
            <mass value="1" />
            <inertia ixx="100" ixy="0" ixz="0" iyy="100" iyz="0" izz="100" />
        </inertial>
        <visual>
            <origin xyz="0.32022546077212966 0 0" rpy="0 0 0"/>
            <geometry>
                <box size="0.6404509215442593 0.43921444222503003 0.1463979309652046" />
            </geometry>
            <material name="Blue">
                <color rgba="0 0 255 1"/>
            </material>
        </visual>
        <collision>
            <origin xyz="0.32022546077212966 0 0" rpy="0 0 0"/>
            <geometry>
                <box size="0.6404509215442593 0.43921444222503003 0.1463979309652046" />
            </geometry>
        </collision>
    </link>
    <joint name="0_9" type="revolute">
       <parent link="0"/>
       <child  link="9"/>
       <origin rpy="0 0 0" xyz="0.75 0 3" />
     <axis xyz="0 0 1"/>
       <limit effort="0.0" lower="-3.14159" upper="3.14159" velocity="0.0"/>
    </joint>
    <link name="10">
        <inertial>
            <origin xyz="0.17859875854271506 0 0" rpy="0 0 0"/>
            <mass value="1" />
            <inertia ixx="100" ixy="0" ixz="0" iyy="100" iyz="0" izz="100" />
        </inertial>
        <visual>
            <origin xyz="0.17859875854271506 0 0" rpy="0 0 0"/>
            <geometry>
                <box size="0.3571975170854301 0.7922686751802946 0.048781395571657726" />
            </geometry>
            <material name="Green">
                <color rgba="0 128 0 1"/>
            </material>
        </visual>
        <collision>
            <origin xyz="0.17859875854271506 0 0" rpy="0 0 0"/>
            <geometry>
                <box size="0.3571975170854301 0.7922686751802946 0.048781395571657726" />
            </geometry>
        </collision>
    </link>
    <joint name="9_10" type="revolute">
       <parent link="9"/>
       <child  link="10"/>
       <origin rpy="0 0 0" xyz="0.6404509215442593 0 0" />
     <axis xyz="1 1 1"/>
       <limit effort="0.0" lower="-3.14159" upper="3.14159" velocity="0.0"/>
    </joint>
    <link name="11">
        <inertial>
            <origin xyz="0.471462512273362 0 0" rpy="0 0 0"/>
            <mass value="1" />
            <inertia ixx="100" ixy="0" ixz="0" iyy="100" iyz="0" izz="100" />
        </inertial>
        <visual>
            <origin xyz="0.471462512273362 0 0" rpy="0 0 0"/>
            <geometry>
                <box size="0.942925024546724 0.34959697660698463 0.0364200350632351" />
            </geometry>
            <material name="Blue">
                <color rgba="0 0 255 1"/>
            </material>
        </visual>
        <collision>
            <origin xyz="0.471462512273362 0 0" rpy="0 0 0"/>
            <geometry>
                <box size="0.942925024546724 0.34959697660698463 0.0364200350632351" />
            </geometry>
        </collision>
    </link>
    <joint name="10_11" type="revolute">
       <parent link="10"/>
       <child  link="11"/>
       <origin rpy="0 0 0" xyz="0.3571975170854301 0 0" />
     <axis xyz="1 1 0"/>
       <limit effort="0.0" lower="-3.14159" upper="3.14159" velocity="0.0"/>
    </joint>
    <link name="12">
        <inertial>
            <origin xyz="0.495066530921721 0 0" rpy="0 0 0"/>
            <mass value="1" />
            <inertia ixx="100" ixy="0" ixz="0" iyy="100" iyz="0" izz="100" />
        </inertial>
        <visual>
            <origin xyz="0.495066530921721 0 0" rpy="0 0 0"/>
            <geometry>
                <box size="0.990133061843442 0.5172243999436621 0.35369102681202447" />
            </geometry>
            <material name="Blue">
                <color rgba="0 0 255 1"/>
            </material>
        </visual>
        <collision>
            <origin xyz="0.495066530921721 0 0" rpy="0 0 0"/>
            <geometry>
                <box size="0.990133061843442 0.5172243999436621 0.35369102681202447" />
            </geometry>
        </collision>
    </link>
    <joint name="11_12" type="revolute">
       <parent link="11"/>
       <child  link="12"/>
       <origin rpy="0 0 0" xyz="0.942925024546724 0 0" />
     <axis xyz="0 0 1"/>
       <limit effort="0.0" lower="-3.14159" upper="3.14159" velocity="0.0"/>
    </joint>
    <link name="13">
        <inertial>
            <origin xyz="0.2625221276877296 0 0" rpy="0 0 0"/>
            <mass value="1" />
            <inertia ixx="100" ixy="0" ixz="0" iyy="100" iyz="0" izz="100" />
        </inertial>
        <visual>
            <origin xyz="0.2625221276877296 0 0" rpy="0 0 0"/>
            <geometry>
                <box size="0.5250442553754592 0.9720057576094062 0.03778728121515096" />
            </geometry>
            <material name="Green">
                <color rgba="0 128 0 1"/>
            </material>
        </visual>
        <collision>
            <origin xyz="0.2625221276877296 0 0" rpy="0 0 0"/>
            <geometry>
                <box size="0.5250442553754592 0.9720057576094062 0.03778728121515096" />
            </geometry>
        </collision>
    </link>
    <joint name="12_13" type="revolute">
       <parent link="12"/>
       <child  link="13"/>
       <origin rpy="0 0 0" xyz="0.990133061843442 0 0" />
     <axis xyz="1 1 0"/>
       <limit effort="0.0" lower="-3.14159" upper="3.14159" velocity="0.0"/>
    </joint>
    <link name="14">
        <inertial>
            <origin xyz="0 0 -0.8047814264984635" rpy="0 0 0"/>
            <mass value="1" />
            <inertia ixx="100" ixy="0" ixz="0" iyy="100" iyz="0" izz="100" />
        </inertial>
        <visual>
            <origin xyz="0 0 -0.8047814264984635" rpy="0 0 0"/>
            <geometry>
                <box size="0.44923144282751315 0.9945693668717281 1.609562852996927" />
            </geometry>
            <material name="Blue">
                <color rgba="0 0 255 1"/>
            </material>
        </visual>
        <collision>
            <origin xyz="0 0 -0.8047814264984635" rpy="0 0 0"/>
            <geometry>
                <box size="0.44923144282751315 0.9945693668717281 1.609562852996927" />
            </geometry>
        </collision>
    </link>
    <joint name="13_14" type="revolute">
       <parent link="13"/>
       <child  link="14"/>
       <origin rpy="0 0 0" xyz="0.2625221276877296 0 -0.01889364060757548" />
     <axis xyz="1 0 1"/>
       <limit effort="0.0" lower="-3.14159" upper="3.14159" velocity="0.0"/>
    </joint>
    <link name="15">
        <inertial>
            <origin xyz="0 0 -0.2222425520828088" rpy="0 0 0"/>
            <mass value="1" />
            <inertia ixx="100" ixy="0" ixz="0" iyy="100" iyz="0" izz="100" />
        </inertial>
        <visual>
            <origin xyz="0 0 -0.2222425520828088" rpy="0 0 0"/>
            <geometry>
                <box size="0.26911458570967883 0.5933284989792076 0.4444851041656176" />
            </geometry>
            <material name="Blue">
                <color rgba="0 0 255 1"/>
            </material>
        </visual>
        <collision>
            <origin xyz="0 0 -0.2222425520828088" rpy="0 0 0"/>
            <geometry>
                <box size="0.26911458570967883 0.5933284989792076 0.4444851041656176" />
            </geometry>
        </collision>
    </link>
    <joint name="14_15" type="revolute">
       <parent link="14"/>
       <child  link="15"/>
       <origin rpy="0 0 0" xyz="0 0 -1.609562852996927" />
     <axis xyz="0 1 1"/>
       <limit effort="0.0" lower="-3.14159" upper="3.14159" velocity="0.0"/>
    </joint>
    <link name="16">
        <inertial>
            <origin xyz="0 0 -0.27297602141872773" rpy="0 0 0"/>
            <mass value="1" />
            <inertia ixx="100" ixy="0" ixz="0" iyy="100" iyz="0" izz="100" />
        </inertial>
        <visual>
            <origin xyz="0 0 -0.27297602141872773" rpy="0 0 0"/>
            <geometry>
                <box size="0.22542850262260516 0.5049861747165612 0.5459520428374555" />
            </geometry>
            <material name="Green">
                <color rgba="0 128 0 1"/>
            </material>
        </visual>
        <collision>
            <origin xyz="0 0 -0.27297602141872773" rpy="0 0 0"/>
            <geometry>
                <box size="0.22542850262260516 0.5049861747165612 0.5459520428374555" />
            </geometry>
        </collision>
    </link>
    <joint name="15_16" type="revolute">
       <parent link="15"/>
       <child  link="16"/>
       <origin rpy="0 0 0" xyz="0 0 -0.4444851041656176" />
     <axis xyz="1 1 1"/>
       <limit effort="0.0" lower="-3.14159" upper="3.14159" velocity="0.0"/>
    </joint>
    <link name="17">
        <inertial>
            <origin xyz="0 -0.49946734892130207 0" rpy="0 0 0"/>
            <mass value="1" />
            <inertia ixx="100" ixy="0" ixz="0" iyy="100" iyz="0" izz="100" />
        </inertial>
        <visual>
            <origin xyz="0 -0.49946734892130207 0" rpy="0 0 0"/>
            <geometry>
                <box size="0.9357444047618543 0.9989346978426041 0.04567629097263526" />
            </geometry>
            <material name="Blue">
                <color rgba="0 0 255 1"/>
            </material>
        </visual>
        <collision>
            <origin xyz="0 -0.49946734892130207 0" rpy="0 0 0"/>
            <geometry>
                <box size="0.9357444047618543 0.9989346978426041 0.04567629097263526" />
            </geometry>
        </collision>
    </link>
    <joint name="0_17" type="revolute">
       <parent link="0"/>
       <child  link="17"/>
       <origin rpy="0 0 0" xyz="0 -0.75 3" />
     <axis xyz="1 1 0"/>
       <limit effort="0.0" lower="-3.14159" upper="3.14159" velocity="0.0"/>
    </joint>
    <link name="18">
        <inertial>
            <origin xyz="0 -0.09863676305536384 0" rpy="0 0 0"/>
            <mass value="1" />
            <inertia ixx="100" ixy="0" ixz="0" iyy="100" iyz="0" izz="100" />
        </inertial>
        <visual>
            <origin xyz="0 -0.09863676305536384 0" rpy="0 0 0"/>
            <geometry>
                <box size="0.0797181484553684 0.19727352611072768 0.4151641338420674" />
            </geometry>
            <material name="Green">
                <color rgba="0 128 0 1"/>
            </material>
        </visual>
        <collision>
            <origin xyz="0 -0.09863676305536384 0" rpy="0 0 0"/>
            <geometry>
                <box size="0.0797181484553684 0.19727352611072768 0.4151641338420674" />
            </geometry>
        </collision>
    </link>
    <joint name="17_18" type="revolute">
       <parent link="17"/>
       <child  link="18"/>
       <origin rpy="0 0 0" xyz="0 -0.9989346978426041 0" />
     <axis xyz="1 0 1"/>
       <limit effort="0.0" lower="-3.14159" upper="3.14159" velocity="0.0"/>
    </joint>
    <link name="19">
        <inertial>
            <origin xyz="0 -0.3922000570316949 0" rpy="0 0 0"/>
            <mass value="1" />
            <inertia ixx="100" ixy="0" ixz="0" iyy="100" iyz="0" izz="100" />
        </inertial>
        <visual>
            <origin xyz="0 -0.3922000570316949 0" rpy="0 0 0"/>
            <geometry>
                <box size="0.974953397110973 0.7844001140633898 0.8957867084380721" />
            </geometry>
            <material name="Green">
                <color rgba="0 128 0 1"/>
            </material>
        </visual>
        <collision>
            <origin xyz="0 -0.3922000570316949 0" rpy="0 0 0"/>
            <geometry>
                <box size="0.974953397110973 0.7844001140633898 0.8957867084380721" />
            </geometry>
        </collision>
    </link>
    <joint name="18_19" type="revolute">
       <parent link="18"/>
       <child  link="19"/>
       <origin rpy="0 0 0" xyz="0 -0.19727352611072768 0" />
     <axis xyz="1 0 1"/>
       <limit effort="0.0" lower="-3.14159" upper="3.14159" velocity="0.0"/>
    </joint>
    <link name="20">
        <inertial>
            <origin xyz="0 -0.01656549340399943 0" rpy="0 0 0"/>
            <mass value="1" />
            <inertia ixx="100" ixy="0" ixz="0" iyy="100" iyz="0" izz="100" />
        </inertial>
        <visual>
            <origin xyz="0 -0.01656549340399943 0" rpy="0 0 0"/>
            <geometry>
                <box size="0.7597700287536784 0.03313098680799886 0.25057959199203006" />
            </geometry>
            <material name="Blue">
                <color rgba="0 0 255 1"/>
            </material>
        </visual>
        <collision>
            <origin xyz="0 -0.01656549340399943 0" rpy="0 0 0"/>
            <geometry>
                <box size="0.7597700287536784 0.03313098680799886 0.25057959199203006" />
            </geometry>
        </collision>
    </link>
    <joint name="19_20" type="revolute">
       <parent link="19"/>
       <child  link="20"/>
       <origin rpy="0 0 0" xyz="0 -0.7844001140633898 0" />
     <axis xyz="1 1 0"/>
       <limit effort="0.0" lower="-3.14159" upper="3.14159" velocity="0.0"/>
    </joint>
    <link name="21">
        <inertial>
            <origin xyz="0 -0.15904228347569188 0" rpy="0 0 0"/>
            <mass value="1" />
            <inertia ixx="100" ixy="0" ixz="0" iyy="100" iyz="0" izz="100" />
        </inertial>
        <visual>
            <origin xyz="0 -0.15904228347569188 0" rpy="0 0 0"/>
            <geometry>
                <box size="0.8661101715235813 0.31808456695138376 0.12436861015250744" />
            </geometry>
            <material name="Green">
                <color rgba="0 128 0 1"/>
            </material>
        </visual>
        <collision>
            <origin xyz="0 -0.15904228347569188 0" rpy="0 0 0"/>
            <geometry>
                <box size="0.8661101715235813 0.31808456695138376 0.12436861015250744" />
            </geometry>
        </collision>
    </link>
    <joint name="20_21" type="revolute">
       <parent link="20"/>
       <child  link="21"/>
       <origin rpy="0 0 0" xyz="0 -0.03313098680799886 0" />
     <axis xyz="1 0 0"/>
       <limit effort="0.0" lower="-3.14159" upper="3.14159" velocity="0.0"/>
    </joint>
    <link name="22">
        <inertial>
            <origin xyz="0 0 -0.3249770254553657" rpy="0 0 0"/>
            <mass value="1" />
            <inertia ixx="100" ixy="0" ixz="0" iyy="100" iyz="0" izz="100" />
        </inertial>
        <visual>
            <origin xyz="0 0 -0.3249770254553657" rpy="0 0 0"/>
            <geometry>
                <box size="0.22700255826477422 0.6937130490440051 0.6499540509107314" />
            </geometry>
            <material name="Green">
                <color rgba="0 128 0 1"/>
            </material>
        </visual>
        <collision>
            <origin xyz="0 0 -0.3249770254553657" rpy="0 0 0"/>
            <geometry>
                <box size="0.22700255826477422 0.6937130490440051 0.6499540509107314" />
            </geometry>
        </collision>
    </link>
    <joint name="21_22" type="revolute">
       <parent link="21"/>
       <child  link="22"/>
       <origin rpy="0 0 0" xyz="0 -0.15904228347569188 -0.06218430507625372" />
     <axis xyz="0 1 1"/>
       <limit effort="0.0" lower="-3.14159" upper="3.14159" velocity="0.0"/>
    </joint>
    <link name="23">
        <inertial>
            <origin xyz="0 0 -0.2454997696328584" rpy="0 0 0"/>
            <mass value="1" />
            <inertia ixx="100" ixy="0" ixz="0" iyy="100" iyz="0" izz="100" />
        </inertial>
        <visual>
            <origin xyz="0 0 -0.2454997696328584" rpy="0 0 0"/>
            <geometry>
                <box size="0.11772984238972961 0.4716303534466244 0.4909995392657168" />
            </geometry>
            <material name="Green">
                <color rgba="0 128 0 1"/>
            </material>
        </visual>
        <collision>
            <origin xyz="0 0 -0.2454997696328584" rpy="0 0 0"/>
            <geometry>
                <box size="0.11772984238972961 0.4716303534466244 0.4909995392657168" />
            </geometry>
        </collision>
    </link>
    <joint name="22_23" type="revolute">
       <parent link="22"/>
       <child  link="23"/>
       <origin rpy="0 0 0" xyz="0 0 -0.6499540509107314" />
     <axis xyz="1 1 0"/>
       <limit effort="0.0" lower="-3.14159" upper="3.14159" velocity="0.0"/>
    </joint>
    <link name="24">
        <inertial>
            <origin xyz="0 0 -0.7295232049117759" rpy="0 0 0"/>
            <mass value="1" />
            <inertia ixx="100" ixy="0" ixz="0" iyy="100" iyz="0" izz="100" />
        </inertial>
        <visual>
            <origin xyz="0 0 -0.7295232049117759" rpy="0 0 0"/>
            <geometry>
                <box size="0.6209070769089758 0.5402967521839852 1.4590464098235518" />
            </geometry>
            <material name="Blue">
                <color rgba="0 0 255 1"/>
            </material>
        </visual>
        <collision>
            <origin xyz="0 0 -0.7295232049117759" rpy="0 0 0"/>
            <geometry>
                <box size="0.6209070769089758 0.5402967521839852 1.4590464098235518" />
            </geometry>
        </collision>
    </link>
    <joint name="23_24" type="revolute">
       <parent link="23"/>
       <child  link="24"/>
       <origin rpy="0 0 0" xyz="0 0 -0.4909995392657168" />
     <axis xyz="1 1 1"/>
       <limit effort="0.0" lower="-3.14159" upper="3.14159" velocity="0.0"/>
    </joint>
    <link name="25">
        <inertial>
            <origin xyz="0 0.02078711257539745 0" rpy="0 0 0"/>
            <mass value="1" />
            <inertia ixx="100" ixy="0" ixz="0" iyy="100" iyz="0" izz="100" />
        </inertial>
        <visual>
            <origin xyz="0 0.02078711257539745 0" rpy="0 0 0"/>
            <geometry>
                <box size="0.9635701949213292 0.0415742251507949 0.6610766853610677" />
            </geometry>
            <material name="Green">
                <color rgba="0 128 0 1"/>
            </material>
        </visual>
        <collision>
            <origin xyz="0 0.02078711257539745 0" rpy="0 0 0"/>
            <geometry>
                <box size="0.9635701949213292 0.0415742251507949 0.6610766853610677" />
            </geometry>
        </collision>
    </link>
    <joint name="0_25" type="revolute">
       <parent link="0"/>
       <child  link="25"/>
       <origin rpy="0 0 0" xyz="0 0.75 3" />
     <axis xyz="1 0 1"/>
       <limit effort="0.0" lower="-3.14159" upper="3.14159" velocity="0.0"/>
    </joint>
    <link name="26">
        <inertial>
            <origin xyz="0 0.015523140256179513 0" rpy="0 0 0"/>
            <mass value="1" />
            <inertia ixx="100" ixy="0" ixz="0" iyy="100" iyz="0" izz="100" />
        </inertial>
        <visual>
            <origin xyz="0 0.015523140256179513 0" rpy="0 0 0"/>
            <geometry>
                <box size="0.029051484220481205 0.031046280512359026 0.2944461143713045" />
            </geometry>
            <material name="Blue">
                <color rgba="0 0 255 1"/>
            </material>
        </visual>
        <collision>
            <origin xyz="0 0.015523140256179513 0" rpy="0 0 0"/>
            <geometry>
                <box size="0.029051484220481205 0.031046280512359026 0.2944461143713045" />
            </geometry>
        </collision>
    </link>
    <joint name="25_26" type="revolute">
       <parent link="25"/>
       <child  link="26"/>
       <origin rpy="0 0 0" xyz="0 0.0415742251507949 0" />
     <axis xyz="1 1 0"/>
       <limit effort="0.0" lower="-3.14159" upper="3.14159" velocity="0.0"/>
    </joint>
    <link name="27">
        <inertial>
            <origin xyz="0 0.2867859075829934 0" rpy="0 0 0"/>
            <mass value="1" />
            <inertia ixx="100" ixy="0" ixz="0" iyy="100" iyz="0" izz="100" />
        </inertial>
        <visual>
            <origin xyz="0 0.2867859075829934 0" rpy="0 0 0"/>
            <geometry>
                <box size="0.4471542260987713 0.5735718151659868 0.78765476744417" />
            </geometry>
            <material name="Green">
                <color rgba="0 128 0 1"/>
            </material>
        </visual>
        <collision>
            <origin xyz="0 0.2867859075829934 0" rpy="0 0 0"/>
            <geometry>
                <box size="0.4471542260987713 0.5735718151659868 0.78765476744417" />
            </geometry>
        </collision>
    </link>
    <joint name="26_27" type="revolute">
       <parent link="26"/>
       <child  link="27"/>
       <origin rpy="0 0 0" xyz="0 0.031046280512359026 0" />
     <axis xyz="1 0 0"/>
       <limit effort="0.0" lower="-3.14159" upper="3.14159" velocity="0.0"/>
    </joint>
    <link name="28">
        <inertial>
            <origin xyz="0 0.20340936456549752 0" rpy="0 0 0"/>
            <mass value="1" />
            <inertia ixx="100" ixy="0" ixz="0" iyy="100" iyz="0" izz="100" />
        </inertial>
        <visual>
            <origin xyz="0 0.20340936456549752 0" rpy="0 0 0"/>
            <geometry>
                <box size="0.7424125386304367 0.40681872913099504 0.6114931415816848" />
            </geometry>
            <material name="Green">
                <color rgba="0 128 0 1"/>
            </material>
        </visual>
        <collision>
            <origin xyz="0 0.20340936456549752 0" rpy="0 0 0"/>
            <geometry>
                <box size="0.7424125386304367 0.40681872913099504 0.6114931415816848" />
            </geometry>
        </collision>
    </link>
    <joint name="27_28" type="revolute">
       <parent link="27"/>
       <child  link="28"/>
       <origin rpy="0 0 0" xyz="0 0.5735718151659868 0" />
     <axis xyz="0 0 1"/>
       <limit effort="0.0" lower="-3.14159" upper="3.14159" velocity="0.0"/>
    </joint>
    <link name="29">
        <inertial>
            <origin xyz="0 0.1983514761488081 0" rpy="0 0 0"/>
            <mass value="1" />
            <inertia ixx="100" ixy="0" ixz="0" iyy="100" iyz="0" izz="100" />
        </inertial>
        <visual>
            <origin xyz="0 0.1983514761488081 0" rpy="0 0 0"/>
            <geometry>
                <box size="0.13697687468691233 0.3967029522976162 0.8639092038384701" />
            </geometry>
            <material name="Green">
                <color rgba="0 128 0 1"/>
            </material>
        </visual>
        <collision>
            <origin xyz="0 0.1983514761488081 0" rpy="0 0 0"/>
            <geometry>
                <box size="0.13697687468691233 0.3967029522976162 0.8639092038384701" />
            </geometry>
        </collision>
    </link>
    <joint name="28_29" type="revolute">
       <parent link="28"/>
       <child  link="29"/>
       <origin rpy="0 0 0" xyz="0 0.40681872913099504 0" />
     <axis xyz="1 0 1"/>
       <limit effort="0.0" lower="-3.14159" upper="3.14159" velocity="0.0"/>
    </joint>
    <link name="30">
        <inertial>
            <origin xyz="0 0 -0.316743129486636" rpy="0 0 0"/>
            <mass value="1" />
            <inertia ixx="100" ixy="0" ixz="0" iyy="100" iyz="0" izz="100" />
        </inertial>
        <visual>
            <origin xyz="0 0 -0.316743129486636" rpy="0 0 0"/>
            <geometry>
                <box size="0.15460290030523904 0.7007959780204429 0.633486258973272" />
            </geometry>
            <material name="Green">
                <color rgba="0 128 0 1"/>
            </material>
        </visual>
        <collision>
            <origin xyz="0 0 -0.316743129486636" rpy="0 0 0"/>
            <geometry>
                <box size="0.15460290030523904 0.7007959780204429 0.633486258973272" />
            </geometry>
        </collision>
    </link>
    <joint name="29_30" type="revolute">
       <parent link="29"/>
       <child  link="30"/>
       <origin rpy="0 0 0" xyz="0 0.1983514761488081 -0.43195460191923507" />
     <axis xyz="0 1 0"/>
       <limit effort="0.0" lower="-3.14159" upper="3.14159" velocity="0.0"/>
    </joint>
    <link name="31">
        <inertial>
            <origin xyz="0 0 -0.52657523918223" rpy="0 0 0"/>
            <mass value="1" />
            <inertia ixx="100" ixy="0" ixz="0" iyy="100" iyz="0" izz="100" />
        </inertial>
        <visual>
            <origin xyz="0 0 -0.52657523918223" rpy="0 0 0"/>
            <geometry>
                <box size="0.8788538010618321 0.35927467170536953 1.05315047836446" />
            </geometry>
            <material name="Blue">
                <color rgba="0 0 255 1"/>
            </material>
        </visual>
        <collision>
            <origin xyz="0 0 -0.52657523918223" rpy="0 0 0"/>
            <geometry>
                <box size="0.8788538010618321 0.35927467170536953 1.05315047836446" />
            </geometry>
        </collision>
    </link>
    <joint name="30_31" type="revolute">
       <parent link="30"/>
       <child  link="31"/>
       <origin rpy="0 0 0" xyz="0 0 -0.633486258973272" />
     <axis xyz="1 0 1"/>
       <limit effort="0.0" lower="-3.14159" upper="3.14159" velocity="0.0"/>
    </joint>
    <link name="32">
        <inertial>
            <origin xyz="0 0 -0.45668163133113393" rpy="0 0 0"/>
            <mass value="1" />
            <inertia ixx="100" ixy="0" ixz="0" iyy="100" iyz="0" izz="100" />
        </inertial>
        <visual>
            <origin xyz="0 0 -0.45668163133113393" rpy="0 0 0"/>
            <geometry>
                <box size="0.5813495672092729 0.9233818427511727 0.9133632626622679" />
            </geometry>
            <material name="Green">
                <color rgba="0 128 0 1"/>
            </material>
        </visual>
        <collision>
            <origin xyz="0 0 -0.45668163133113393" rpy="0 0 0"/>
            <geometry>
                <box size="0.5813495672092729 0.9233818427511727 0.9133632626622679" />
            </geometry>
        </collision>
    </link>
    <joint name="31_32" type="revolute">
       <parent link="31"/>
       <child  link="32"/>
       <origin rpy="0 0 0" xyz="0 0 -1.05315047836446" />
     <axis xyz="1 1 1"/>
       <limit effort="0.0" lower="-3.14159" upper="3.14159" velocity="0.0"/>
    </joint>
</robot>