<robot name = "robot">
    <link name="0">
        <inertial>
            <origin xyz="0 0 0.35" rpy="0 0 0"/>
            <mass value="1" />
            <inertia ixx="100" ixy="0" ixz="0" iyy="100" iyz="0" izz="100" />
        </inertial>
        <visual>
            <origin xyz="0 0 0.35" rpy="0 0 0"/>
            <geometry>
                <box size="0.7 0.7 0.7" />
            </geometry>
            <material name="Green">
                <color rgba="0 128 0 1"/>
            </material>
        </visual>
        <collision>
            <origin xyz="0 0 0.35" rpy="0 0 0"/>
            <geometry>
                <box size="0.7 0.7 0.7" />
            </geometry>
        </collision>
    </link>
    <link name="1">
        <inertial>
            <origin xyz="-0.04807723063544789 0 0.35768240881773067" rpy="0 0 0"/>
            <mass value="1" />
            <inertia ixx="100" ixy="0" ixz="0" iyy="100" iyz="0" izz="100" />
        </inertial>
        <visual>
            <origin xyz="-0.04807723063544789 0 0.35768240881773067" rpy="0 0 0"/>
            <geometry>
                <box size="0.09615446127089577 0.5165013614937735 0.7153648176354613" />
            </geometry>
            <material name="Blue">
                <color rgba="0 0 255 1"/>
            </material>
        </visual>
        <collision>
            <origin xyz="-0.04807723063544789 0 0.35768240881773067" rpy="0 0 0"/>
            <geometry>
                <box size="0.09615446127089577 0.5165013614937735 0.7153648176354613" />
            </geometry>
        </collision>
    </link>
    <joint name="0_1" type="revolute">
       <parent link="0"/>
       <child  link="1"/>
       <origin rpy="0 0 0" xyz="-0.35 0 0.7" />
     <axis xyz="0 1 1"/>
       <limit effort="0.0" lower="-3.14159" upper="3.14159" velocity="0.0"/>
    </joint>
    <link name="2">
        <inertial>
            <origin xyz="0.38222381634788005 0 0.4372341036615261" rpy="0 0 0"/>
            <mass value="1" />
            <inertia ixx="100" ixy="0" ixz="0" iyy="100" iyz="0" izz="100" />
        </inertial>
        <visual>
            <origin xyz="0.38222381634788005 0 0.4372341036615261" rpy="0 0 0"/>
            <geometry>
                <box size="0.7644476326957601 0.45913742581646 0.8744682073230522" />
            </geometry>
            <material name="Green">
                <color rgba="0 128 0 1"/>
            </material>
        </visual>
        <collision>
            <origin xyz="0.38222381634788005 0 0.4372341036615261" rpy="0 0 0"/>
            <geometry>
                <box size="0.7644476326957601 0.45913742581646 0.8744682073230522" />
            </geometry>
        </collision>
    </link>
    <joint name="0_2" type="revolute">
       <parent link="0"/>
       <child  link="2"/>
       <origin rpy="0 0 0" xyz="0.35 0 0.7" />
     <axis xyz="0 0 1"/>
       <limit effort="0.0" lower="-3.14159" upper="3.14159" velocity="0.0"/>
    </joint>
    <link name="3">
        <inertial>
            <origin xyz="0.3434658125493067 0 0.4424021178723856" rpy="0 0 0"/>
            <mass value="1" />
            <inertia ixx="100" ixy="0" ixz="0" iyy="100" iyz="0" izz="100" />
        </inertial>
        <visual>
            <origin xyz="0.3434658125493067 0 0.4424021178723856" rpy="0 0 0"/>
            <geometry>
                <box size="0.6869316250986134 0.917158740023594 0.8848042357447712" />
            </geometry>
            <material name="Green">
                <color rgba="0 128 0 1"/>
            </material>
        </visual>
        <collision>
            <origin xyz="0.3434658125493067 0 0.4424021178723856" rpy="0 0 0"/>
            <geometry>
                <box size="0.6869316250986134 0.917158740023594 0.8848042357447712" />
            </geometry>
        </collision>
    </link>
    <joint name="2_3" type="revolute">
       <parent link="2"/>
       <child  link="3"/>
       <origin rpy="0 0 0" xyz="0.7644476326957601 0 0.8744682073230522" />
     <axis xyz="0 0 1"/>
       <limit effort="0.0" lower="-3.14159" upper="3.14159" velocity="0.0"/>
    </joint>
    <link name="4">
        <inertial>
            <origin xyz="0.3596909682214904 0 0.28240357621568757" rpy="0 0 0"/>
            <mass value="1" />
            <inertia ixx="100" ixy="0" ixz="0" iyy="100" iyz="0" izz="100" />
        </inertial>
        <visual>
            <origin xyz="0.3596909682214904 0 0.28240357621568757" rpy="0 0 0"/>
            <geometry>
                <box size="0.7193819364429808 0.7188684868021674 0.5648071524313751" />
            </geometry>
            <material name="Green">
                <color rgba="0 128 0 1"/>
            </material>
        </visual>
        <collision>
            <origin xyz="0.3596909682214904 0 0.28240357621568757" rpy="0 0 0"/>
            <geometry>
                <box size="0.7193819364429808 0.7188684868021674 0.5648071524313751" />
            </geometry>
        </collision>
    </link>
    <joint name="3_4" type="revolute">
       <parent link="3"/>
       <child  link="4"/>
       <origin rpy="0 0 0" xyz="0.6869316250986134 0 0.8848042357447712" />
     <axis xyz="0 1 1"/>
       <limit effort="0.0" lower="-3.14159" upper="3.14159" velocity="0.0"/>
    </joint>
</robot>