<robot name = "robot">
    <link name="0">
        <inertial>
            <origin xyz="0 0 0.35" rpy="0 0 0"/>
            <mass value="1" />
            <inertia ixx="100" ixy="0" ixz="0" iyy="100" iyz="0" izz="100" />
        </inertial>
        <visual>
            <origin xyz="0 0 0.35" rpy="0 0 0"/>
            <geometry>
                <box size="0.7 0.7 0.7" />
            </geometry>
            <material name="Green">
                <color rgba="0 128 0 1"/>
            </material>
        </visual>
        <collision>
            <origin xyz="0 0 0.35" rpy="0 0 0"/>
            <geometry>
                <box size="0.7 0.7 0.7" />
            </geometry>
        </collision>
    </link>
    <link name="1">
        <inertial>
            <origin xyz="0.2612569210090594 0 0.29181320844763947" rpy="0 0 0"/>
            <mass value="1" />
            <inertia ixx="100" ixy="0" ixz="0" iyy="100" iyz="0" izz="100" />
        </inertial>
        <visual>
            <origin xyz="0.2612569210090594 0 0.29181320844763947" rpy="0 0 0"/>
            <geometry>
                <box size="0.5225138420181188 0.9686454653720168 0.5836264168952789" />
            </geometry>
            <material name="Green">
                <color rgba="0 128 0 1"/>
            </material>
        </visual>
        <collision>
            <origin xyz="0.2612569210090594 0 0.29181320844763947" rpy="0 0 0"/>
            <geometry>
                <box size="0.5225138420181188 0.9686454653720168 0.5836264168952789" />
            </geometry>
        </collision>
    </link>
    <joint name="0_1" type="revolute">
       <parent link="0"/>
       <child  link="1"/>
       <origin rpy="0 0 0" xyz="0.35 0 0.7" />
     <axis xyz="1 1 1"/>
       <limit effort="0.0" lower="-3.14159" upper="3.14159" velocity="0.0"/>
    </joint>
    <link name="2">
        <inertial>
            <origin xyz="0 0.17476400161512218 0.08625017853975314" rpy="0 0 0"/>
            <mass value="1" />
            <inertia ixx="100" ixy="0" ixz="0" iyy="100" iyz="0" izz="100" />
        </inertial>
        <visual>
            <origin xyz="0 0.17476400161512218 0.08625017853975314" rpy="0 0 0"/>
            <geometry>
                <box size="0.11980146013251769 0.34952800323024436 0.17250035707950628" />
            </geometry>
            <material name="Green">
                <color rgba="0 128 0 1"/>
            </material>
        </visual>
        <collision>
            <origin xyz="0 0.17476400161512218 0.08625017853975314" rpy="0 0 0"/>
            <geometry>
                <box size="0.11980146013251769 0.34952800323024436 0.17250035707950628" />
            </geometry>
        </collision>
    </link>
    <joint name="0_2" type="revolute">
       <parent link="0"/>
       <child  link="2"/>
       <origin rpy="0 0 0" xyz="0 0.35 0.7" />
     <axis xyz="1 0 1"/>
       <limit effort="0.0" lower="-3.14159" upper="3.14159" velocity="0.0"/>
    </joint>
    <link name="3">
        <inertial>
            <origin xyz="0 0.4537097178576863 0.45374742503109355" rpy="0 0 0"/>
            <mass value="1" />
            <inertia ixx="100" ixy="0" ixz="0" iyy="100" iyz="0" izz="100" />
        </inertial>
        <visual>
            <origin xyz="0 0.4537097178576863 0.45374742503109355" rpy="0 0 0"/>
            <geometry>
                <box size="0.5248303759476192 0.9074194357153726 0.9074948500621871" />
            </geometry>
            <material name="Blue">
                <color rgba="0 0 255 1"/>
            </material>
        </visual>
        <collision>
            <origin xyz="0 0.4537097178576863 0.45374742503109355" rpy="0 0 0"/>
            <geometry>
                <box size="0.5248303759476192 0.9074194357153726 0.9074948500621871" />
            </geometry>
        </collision>
    </link>
    <joint name="2_3" type="revolute">
       <parent link="2"/>
       <child  link="3"/>
       <origin rpy="0 0 0" xyz="0 0.34952800323024436 0.17250035707950628" />
     <axis xyz="0 0 1"/>
       <limit effort="0.0" lower="-3.14159" upper="3.14159" velocity="0.0"/>
    </joint>
    <link name="4">
        <inertial>
            <origin xyz="0 0.4270125544562121 0.29757335162653453" rpy="0 0 0"/>
            <mass value="1" />
            <inertia ixx="100" ixy="0" ixz="0" iyy="100" iyz="0" izz="100" />
        </inertial>
        <visual>
            <origin xyz="0 0.4270125544562121 0.29757335162653453" rpy="0 0 0"/>
            <geometry>
                <box size="0.07085365928742327 0.8540251089124242 0.5951467032530691" />
            </geometry>
            <material name="Blue">
                <color rgba="0 0 255 1"/>
            </material>
        </visual>
        <collision>
            <origin xyz="0 0.4270125544562121 0.29757335162653453" rpy="0 0 0"/>
            <geometry>
                <box size="0.07085365928742327 0.8540251089124242 0.5951467032530691" />
            </geometry>
        </collision>
    </link>
    <joint name="3_4" type="revolute">
       <parent link="3"/>
       <child  link="4"/>
       <origin rpy="0 0 0" xyz="0 0.9074194357153726 0.9074948500621871" />
     <axis xyz="1 0 0"/>
       <limit effort="0.0" lower="-3.14159" upper="3.14159" velocity="0.0"/>
    </joint>
</robot>