<robot name = "robot">
    <link name="0">
        <inertial>
            <origin xyz="0 0 0.35" rpy="0 0 0"/>
            <mass value="1" />
            <inertia ixx="100" ixy="0" ixz="0" iyy="100" iyz="0" izz="100" />
        </inertial>
        <visual>
            <origin xyz="0 0 0.35" rpy="0 0 0"/>
            <geometry>
                <box size="0.7 0.7 0.7" />
            </geometry>
            <material name="Green">
                <color rgba="0 128 0 1"/>
            </material>
        </visual>
        <collision>
            <origin xyz="0 0 0.35" rpy="0 0 0"/>
            <geometry>
                <box size="0.7 0.7 0.7" />
            </geometry>
        </collision>
    </link>
    <link name="1">
        <inertial>
            <origin xyz="-0.17532588456016507 0 0.26987281781483136" rpy="0 0 0"/>
            <mass value="1" />
            <inertia ixx="100" ixy="0" ixz="0" iyy="100" iyz="0" izz="100" />
        </inertial>
        <visual>
            <origin xyz="-0.17532588456016507 0 0.26987281781483136" rpy="0 0 0"/>
            <geometry>
                <box size="0.35065176912033014 0.8900416237621592 0.5397456356296627" />
            </geometry>
            <material name="Blue">
                <color rgba="0 0 255 1"/>
            </material>
        </visual>
        <collision>
            <origin xyz="-0.17532588456016507 0 0.26987281781483136" rpy="0 0 0"/>
            <geometry>
                <box size="0.35065176912033014 0.8900416237621592 0.5397456356296627" />
            </geometry>
        </collision>
    </link>
    <joint name="0_1" type="revolute">
       <parent link="0"/>
       <child  link="1"/>
       <origin rpy="0 0 0" xyz="-0.35 0 0.7" />
     <axis xyz="0 1 0"/>
       <limit effort="0.0" lower="-3.14159" upper="3.14159" velocity="0.0"/>
    </joint>
    <link name="2">
        <inertial>
            <origin xyz="-0.46207793807233905 0 0.22510516884429865" rpy="0 0 0"/>
            <mass value="1" />
            <inertia ixx="100" ixy="0" ixz="0" iyy="100" iyz="0" izz="100" />
        </inertial>
        <visual>
            <origin xyz="-0.46207793807233905 0 0.22510516884429865" rpy="0 0 0"/>
            <geometry>
                <box size="0.9241558761446781 0.7542240304477038 0.4502103376885973" />
            </geometry>
            <material name="Green">
                <color rgba="0 128 0 1"/>
            </material>
        </visual>
        <collision>
            <origin xyz="-0.46207793807233905 0 0.22510516884429865" rpy="0 0 0"/>
            <geometry>
                <box size="0.9241558761446781 0.7542240304477038 0.4502103376885973" />
            </geometry>
        </collision>
    </link>
    <joint name="1_2" type="revolute">
       <parent link="1"/>
       <child  link="2"/>
       <origin rpy="0 0 0" xyz="-0.35065176912033014 0 0.5397456356296627" />
     <axis xyz="1 0 0"/>
       <limit effort="0.0" lower="-3.14159" upper="3.14159" velocity="0.0"/>
    </joint>
    <link name="3">
        <inertial>
            <origin xyz="0.3094298020860507 0 0.06802679750303647" rpy="0 0 0"/>
            <mass value="1" />
            <inertia ixx="100" ixy="0" ixz="0" iyy="100" iyz="0" izz="100" />
        </inertial>
        <visual>
            <origin xyz="0.3094298020860507 0 0.06802679750303647" rpy="0 0 0"/>
            <geometry>
                <box size="0.6188596041721014 0.16348269281164018 0.13605359500607295" />
            </geometry>
            <material name="Green">
                <color rgba="0 128 0 1"/>
            </material>
        </visual>
        <collision>
            <origin xyz="0.3094298020860507 0 0.06802679750303647" rpy="0 0 0"/>
            <geometry>
                <box size="0.6188596041721014 0.16348269281164018 0.13605359500607295" />
            </geometry>
        </collision>
    </link>
    <joint name="0_3" type="revolute">
       <parent link="0"/>
       <child  link="3"/>
       <origin rpy="0 0 0" xyz="0.35 0 0.7" />
     <axis xyz="0 1 1"/>
       <limit effort="0.0" lower="-3.14159" upper="3.14159" velocity="0.0"/>
    </joint>
    <link name="4">
        <inertial>
            <origin xyz="0.039118175739829675 0 0.1346303215911583" rpy="0 0 0"/>
            <mass value="1" />
            <inertia ixx="100" ixy="0" ixz="0" iyy="100" iyz="0" izz="100" />
        </inertial>
        <visual>
            <origin xyz="0.039118175739829675 0 0.1346303215911583" rpy="0 0 0"/>
            <geometry>
                <box size="0.07823635147965935 0.6484473769113032 0.2692606431823166" />
            </geometry>
            <material name="Green">
                <color rgba="0 128 0 1"/>
            </material>
        </visual>
        <collision>
            <origin xyz="0.039118175739829675 0 0.1346303215911583" rpy="0 0 0"/>
            <geometry>
                <box size="0.07823635147965935 0.6484473769113032 0.2692606431823166" />
            </geometry>
        </collision>
    </link>
    <joint name="3_4" type="revolute">
       <parent link="3"/>
       <child  link="4"/>
       <origin rpy="0 0 0" xyz="0.6188596041721014 0 0.13605359500607295" />
     <axis xyz="1 1 0"/>
       <limit effort="0.0" lower="-3.14159" upper="3.14159" velocity="0.0"/>
    </joint>
    <link name="5">
        <inertial>
            <origin xyz="0.2208742749061362 0 0.25978421008787106" rpy="0 0 0"/>
            <mass value="1" />
            <inertia ixx="100" ixy="0" ixz="0" iyy="100" iyz="0" izz="100" />
        </inertial>
        <visual>
            <origin xyz="0.2208742749061362 0 0.25978421008787106" rpy="0 0 0"/>
            <geometry>
                <box size="0.4417485498122724 0.7361950861144787 0.5195684201757421" />
            </geometry>
            <material name="Blue">
                <color rgba="0 0 255 1"/>
            </material>
        </visual>
        <collision>
            <origin xyz="0.2208742749061362 0 0.25978421008787106" rpy="0 0 0"/>
            <geometry>
                <box size="0.4417485498122724 0.7361950861144787 0.5195684201757421" />
            </geometry>
        </collision>
    </link>
    <joint name="4_5" type="revolute">
       <parent link="4"/>
       <child  link="5"/>
       <origin rpy="0 0 0" xyz="0.07823635147965935 0 0.2692606431823166" />
     <axis xyz="1 0 1"/>
       <limit effort="0.0" lower="-3.14159" upper="3.14159" velocity="0.0"/>
    </joint>
    <link name="6">
        <inertial>
            <origin xyz="0.2187936301881358 0 0.20526420157324793" rpy="0 0 0"/>
            <mass value="1" />
            <inertia ixx="100" ixy="0" ixz="0" iyy="100" iyz="0" izz="100" />
        </inertial>
        <visual>
            <origin xyz="0.2187936301881358 0 0.20526420157324793" rpy="0 0 0"/>
            <geometry>
                <box size="0.4375872603762716 0.8745124677601195 0.41052840314649586" />
            </geometry>
            <material name="Blue">
                <color rgba="0 0 255 1"/>
            </material>
        </visual>
        <collision>
            <origin xyz="0.2187936301881358 0 0.20526420157324793" rpy="0 0 0"/>
            <geometry>
                <box size="0.4375872603762716 0.8745124677601195 0.41052840314649586" />
            </geometry>
        </collision>
    </link>
    <joint name="5_6" type="revolute">
       <parent link="5"/>
       <child  link="6"/>
       <origin rpy="0 0 0" xyz="0.4417485498122724 0 0.5195684201757421" />
     <axis xyz="0 0 1"/>
       <limit effort="0.0" lower="-3.14159" upper="3.14159" velocity="0.0"/>
    </joint>
    <link name="7">
        <inertial>
            <origin xyz="0.27438617508863217 0 0.06772229993518519" rpy="0 0 0"/>
            <mass value="1" />
            <inertia ixx="100" ixy="0" ixz="0" iyy="100" iyz="0" izz="100" />
        </inertial>
        <visual>
            <origin xyz="0.27438617508863217 0 0.06772229993518519" rpy="0 0 0"/>
            <geometry>
                <box size="0.5487723501772643 0.2921137034311866 0.13544459987037039" />
            </geometry>
            <material name="Green">
                <color rgba="0 128 0 1"/>
            </material>
        </visual>
        <collision>
            <origin xyz="0.27438617508863217 0 0.06772229993518519" rpy="0 0 0"/>
            <geometry>
                <box size="0.5487723501772643 0.2921137034311866 0.13544459987037039" />
            </geometry>
        </collision>
    </link>
    <joint name="6_7" type="revolute">
       <parent link="6"/>
       <child  link="7"/>
       <origin rpy="0 0 0" xyz="0.4375872603762716 0 0.41052840314649586" />
     <axis xyz="0 1 0"/>
       <limit effort="0.0" lower="-3.14159" upper="3.14159" velocity="0.0"/>
    </joint>
    <link name="8">
        <inertial>
            <origin xyz="0 -0.4400193925676097 0.32628463710984595" rpy="0 0 0"/>
            <mass value="1" />
            <inertia ixx="100" ixy="0" ixz="0" iyy="100" iyz="0" izz="100" />
        </inertial>
        <visual>
            <origin xyz="0 -0.4400193925676097 0.32628463710984595" rpy="0 0 0"/>
            <geometry>
                <box size="0.7052587344876844 0.8800387851352194 0.6525692742196919" />
            </geometry>
            <material name="Blue">
                <color rgba="0 0 255 1"/>
            </material>
        </visual>
        <collision>
            <origin xyz="0 -0.4400193925676097 0.32628463710984595" rpy="0 0 0"/>
            <geometry>
                <box size="0.7052587344876844 0.8800387851352194 0.6525692742196919" />
            </geometry>
        </collision>
    </link>
    <joint name="0_8" type="revolute">
       <parent link="0"/>
       <child  link="8"/>
       <origin rpy="0 0 0" xyz="0 -0.35 0.7" />
     <axis xyz="1 0 0"/>
       <limit effort="0.0" lower="-3.14159" upper="3.14159" velocity="0.0"/>
    </joint>
    <link name="9">
        <inertial>
            <origin xyz="0 0.15665572682056333 0.21395184250529475" rpy="0 0 0"/>
            <mass value="1" />
            <inertia ixx="100" ixy="0" ixz="0" iyy="100" iyz="0" izz="100" />
        </inertial>
        <visual>
            <origin xyz="0 0.15665572682056333 0.21395184250529475" rpy="0 0 0"/>
            <geometry>
                <box size="0.6267452044533814 0.31331145364112667 0.4279036850105895" />
            </geometry>
            <material name="Green">
                <color rgba="0 128 0 1"/>
            </material>
        </visual>
        <collision>
            <origin xyz="0 0.15665572682056333 0.21395184250529475" rpy="0 0 0"/>
            <geometry>
                <box size="0.6267452044533814 0.31331145364112667 0.4279036850105895" />
            </geometry>
        </collision>
    </link>
    <joint name="0_9" type="revolute">
       <parent link="0"/>
       <child  link="9"/>
       <origin rpy="0 0 0" xyz="0 0.35 0.7" />
     <axis xyz="0 0 1"/>
       <limit effort="0.0" lower="-3.14159" upper="3.14159" velocity="0.0"/>
    </joint>
    <link name="10">
        <inertial>
            <origin xyz="0 0.42351286859679693 0.22203749701060665" rpy="0 0 0"/>
            <mass value="1" />
            <inertia ixx="100" ixy="0" ixz="0" iyy="100" iyz="0" izz="100" />
        </inertial>
        <visual>
            <origin xyz="0 0.42351286859679693 0.22203749701060665" rpy="0 0 0"/>
            <geometry>
                <box size="0.6174813000036807 0.8470257371935939 0.4440749940212133" />
            </geometry>
            <material name="Blue">
                <color rgba="0 0 255 1"/>
            </material>
        </visual>
        <collision>
            <origin xyz="0 0.42351286859679693 0.22203749701060665" rpy="0 0 0"/>
            <geometry>
                <box size="0.6174813000036807 0.8470257371935939 0.4440749940212133" />
            </geometry>
        </collision>
    </link>
    <joint name="9_10" type="revolute">
       <parent link="9"/>
       <child  link="10"/>
       <origin rpy="0 0 0" xyz="0 0.31331145364112667 0.4279036850105895" />
     <axis xyz="0 1 0"/>
       <limit effort="0.0" lower="-3.14159" upper="3.14159" velocity="0.0"/>
    </joint>
    <link name="11">
        <inertial>
            <origin xyz="0 0.0796443906184155 0.4504869550045476" rpy="0 0 0"/>
            <mass value="1" />
            <inertia ixx="100" ixy="0" ixz="0" iyy="100" iyz="0" izz="100" />
        </inertial>
        <visual>
            <origin xyz="0 0.0796443906184155 0.4504869550045476" rpy="0 0 0"/>
            <geometry>
                <box size="0.8819018771293257 0.159288781236831 0.9009739100090952" />
            </geometry>
            <material name="Green">
                <color rgba="0 128 0 1"/>
            </material>
        </visual>
        <collision>
            <origin xyz="0 0.0796443906184155 0.4504869550045476" rpy="0 0 0"/>
            <geometry>
                <box size="0.8819018771293257 0.159288781236831 0.9009739100090952" />
            </geometry>
        </collision>
    </link>
    <joint name="10_11" type="revolute">
       <parent link="10"/>
       <child  link="11"/>
       <origin rpy="0 0 0" xyz="0 0.8470257371935939 0.4440749940212133" />
     <axis xyz="0 1 1"/>
       <limit effort="0.0" lower="-3.14159" upper="3.14159" velocity="0.0"/>
    </joint>
    <link name="12">
        <inertial>
            <origin xyz="0 0.0965674774059907 0.2829250676024092" rpy="0 0 0"/>
            <mass value="1" />
            <inertia ixx="100" ixy="0" ixz="0" iyy="100" iyz="0" izz="100" />
        </inertial>
        <visual>
            <origin xyz="0 0.0965674774059907 0.2829250676024092" rpy="0 0 0"/>
            <geometry>
                <box size="0.05359563799017919 0.1931349548119814 0.5658501352048184" />
            </geometry>
            <material name="Blue">
                <color rgba="0 0 255 1"/>
            </material>
        </visual>
        <collision>
            <origin xyz="0 0.0965674774059907 0.2829250676024092" rpy="0 0 0"/>
            <geometry>
                <box size="0.05359563799017919 0.1931349548119814 0.5658501352048184" />
            </geometry>
        </collision>
    </link>
    <joint name="11_12" type="revolute">
       <parent link="11"/>
       <child  link="12"/>
       <origin rpy="0 0 0" xyz="0 0.159288781236831 0.9009739100090952" />
     <axis xyz="0 0 1"/>
       <limit effort="0.0" lower="-3.14159" upper="3.14159" velocity="0.0"/>
    </joint>
</robot>