<robot name = "robot">
    <link name="0">
        <inertial>
            <origin xyz="0 0 0.35" rpy="0 0 0"/>
            <mass value="1" />
            <inertia ixx="100" ixy="0" ixz="0" iyy="100" iyz="0" izz="100" />
        </inertial>
        <visual>
            <origin xyz="0 0 0.35" rpy="0 0 0"/>
            <geometry>
                <box size="0.7 0.7 0.7" />
            </geometry>
            <material name="Green">
                <color rgba="0 128 0 1"/>
            </material>
        </visual>
        <collision>
            <origin xyz="0 0 0.35" rpy="0 0 0"/>
            <geometry>
                <box size="0.7 0.7 0.7" />
            </geometry>
        </collision>
    </link>
    <link name="1">
        <inertial>
            <origin xyz="-0.4838284218105826 0 0.12911643654527993" rpy="0 0 0"/>
            <mass value="1" />
            <inertia ixx="100" ixy="0" ixz="0" iyy="100" iyz="0" izz="100" />
        </inertial>
        <visual>
            <origin xyz="-0.4838284218105826 0 0.12911643654527993" rpy="0 0 0"/>
            <geometry>
                <box size="0.9676568436211652 0.4374457596078315 0.25823287309055987" />
            </geometry>
            <material name="Blue">
                <color rgba="0 0 255 1"/>
            </material>
        </visual>
        <collision>
            <origin xyz="-0.4838284218105826 0 0.12911643654527993" rpy="0 0 0"/>
            <geometry>
                <box size="0.9676568436211652 0.4374457596078315 0.25823287309055987" />
            </geometry>
        </collision>
    </link>
    <joint name="0_1" type="revolute">
       <parent link="0"/>
       <child  link="1"/>
       <origin rpy="0 0 0" xyz="-0.35 0 0.7" />
     <axis xyz="1 1 0"/>
       <limit effort="0.0" lower="-3.14159" upper="3.14159" velocity="0.0"/>
    </joint>
    <link name="2">
        <inertial>
            <origin xyz="0.4937279655783072 0 0.1882582814089877" rpy="0 0 0"/>
            <mass value="1" />
            <inertia ixx="100" ixy="0" ixz="0" iyy="100" iyz="0" izz="100" />
        </inertial>
        <visual>
            <origin xyz="0.4937279655783072 0 0.1882582814089877" rpy="0 0 0"/>
            <geometry>
                <box size="0.9874559311566145 0.31487639263311684 0.3765165628179754" />
            </geometry>
            <material name="Green">
                <color rgba="0 128 0 1"/>
            </material>
        </visual>
        <collision>
            <origin xyz="0.4937279655783072 0 0.1882582814089877" rpy="0 0 0"/>
            <geometry>
                <box size="0.9874559311566145 0.31487639263311684 0.3765165628179754" />
            </geometry>
        </collision>
    </link>
    <joint name="0_2" type="revolute">
       <parent link="0"/>
       <child  link="2"/>
       <origin rpy="0 0 0" xyz="0.35 0 0.7" />
     <axis xyz="1 0 1"/>
       <limit effort="0.0" lower="-3.14159" upper="3.14159" velocity="0.0"/>
    </joint>
    <link name="3">
        <inertial>
            <origin xyz="0.2331252148483539 0 0.17628849152052367" rpy="0 0 0"/>
            <mass value="1" />
            <inertia ixx="100" ixy="0" ixz="0" iyy="100" iyz="0" izz="100" />
        </inertial>
        <visual>
            <origin xyz="0.2331252148483539 0 0.17628849152052367" rpy="0 0 0"/>
            <geometry>
                <box size="0.4662504296967078 0.6792813980381086 0.35257698304104734" />
            </geometry>
            <material name="Green">
                <color rgba="0 128 0 1"/>
            </material>
        </visual>
        <collision>
            <origin xyz="0.2331252148483539 0 0.17628849152052367" rpy="0 0 0"/>
            <geometry>
                <box size="0.4662504296967078 0.6792813980381086 0.35257698304104734" />
            </geometry>
        </collision>
    </link>
    <joint name="2_3" type="revolute">
       <parent link="2"/>
       <child  link="3"/>
       <origin rpy="0 0 0" xyz="0.9874559311566145 0 0.3765165628179754" />
     <axis xyz="1 0 1"/>
       <limit effort="0.0" lower="-3.14159" upper="3.14159" velocity="0.0"/>
    </joint>
    <link name="4">
        <inertial>
            <origin xyz="0.2963359378332446 0 0.18197754466997845" rpy="0 0 0"/>
            <mass value="1" />
            <inertia ixx="100" ixy="0" ixz="0" iyy="100" iyz="0" izz="100" />
        </inertial>
        <visual>
            <origin xyz="0.2963359378332446 0 0.18197754466997845" rpy="0 0 0"/>
            <geometry>
                <box size="0.5926718756664892 0.32002538574800654 0.3639550893399569" />
            </geometry>
            <material name="Blue">
                <color rgba="0 0 255 1"/>
            </material>
        </visual>
        <collision>
            <origin xyz="0.2963359378332446 0 0.18197754466997845" rpy="0 0 0"/>
            <geometry>
                <box size="0.5926718756664892 0.32002538574800654 0.3639550893399569" />
            </geometry>
        </collision>
    </link>
    <joint name="3_4" type="revolute">
       <parent link="3"/>
       <child  link="4"/>
       <origin rpy="0 0 0" xyz="0.4662504296967078 0 0.35257698304104734" />
     <axis xyz="0 1 0"/>
       <limit effort="0.0" lower="-3.14159" upper="3.14159" velocity="0.0"/>
    </joint>
    <link name="5">
        <inertial>
            <origin xyz="0.13206862397642422 0 0.05243586291474628" rpy="0 0 0"/>
            <mass value="1" />
            <inertia ixx="100" ixy="0" ixz="0" iyy="100" iyz="0" izz="100" />
        </inertial>
        <visual>
            <origin xyz="0.13206862397642422 0 0.05243586291474628" rpy="0 0 0"/>
            <geometry>
                <box size="0.26413724795284843 0.7873019157138492 0.10487172582949256" />
            </geometry>
            <material name="Green">
                <color rgba="0 128 0 1"/>
            </material>
        </visual>
        <collision>
            <origin xyz="0.13206862397642422 0 0.05243586291474628" rpy="0 0 0"/>
            <geometry>
                <box size="0.26413724795284843 0.7873019157138492 0.10487172582949256" />
            </geometry>
        </collision>
    </link>
    <joint name="4_5" type="revolute">
       <parent link="4"/>
       <child  link="5"/>
       <origin rpy="0 0 0" xyz="0.5926718756664892 0 0.3639550893399569" />
     <axis xyz="1 0 0"/>
       <limit effort="0.0" lower="-3.14159" upper="3.14159" velocity="0.0"/>
    </joint>
    <link name="6">
        <inertial>
            <origin xyz="0 0.2690656308284222 0.22114362250682207" rpy="0 0 0"/>
            <mass value="1" />
            <inertia ixx="100" ixy="0" ixz="0" iyy="100" iyz="0" izz="100" />
        </inertial>
        <visual>
            <origin xyz="0 0.2690656308284222 0.22114362250682207" rpy="0 0 0"/>
            <geometry>
                <box size="0.4640681709198229 0.5381312616568444 0.44228724501364414" />
            </geometry>
            <material name="Green">
                <color rgba="0 128 0 1"/>
            </material>
        </visual>
        <collision>
            <origin xyz="0 0.2690656308284222 0.22114362250682207" rpy="0 0 0"/>
            <geometry>
                <box size="0.4640681709198229 0.5381312616568444 0.44228724501364414" />
            </geometry>
        </collision>
    </link>
    <joint name="0_6" type="revolute">
       <parent link="0"/>
       <child  link="6"/>
       <origin rpy="0 0 0" xyz="0 0.35 0.7" />
     <axis xyz="0 1 0"/>
       <limit effort="0.0" lower="-3.14159" upper="3.14159" velocity="0.0"/>
    </joint>
    <link name="7">
        <inertial>
            <origin xyz="0 0.010013813102634606 0.3003620666338726" rpy="0 0 0"/>
            <mass value="1" />
            <inertia ixx="100" ixy="0" ixz="0" iyy="100" iyz="0" izz="100" />
        </inertial>
        <visual>
            <origin xyz="0 0.010013813102634606 0.3003620666338726" rpy="0 0 0"/>
            <geometry>
                <box size="0.6495389915858686 0.02002762620526921 0.6007241332677452" />
            </geometry>
            <material name="Green">
                <color rgba="0 128 0 1"/>
            </material>
        </visual>
        <collision>
            <origin xyz="0 0.010013813102634606 0.3003620666338726" rpy="0 0 0"/>
            <geometry>
                <box size="0.6495389915858686 0.02002762620526921 0.6007241332677452" />
            </geometry>
        </collision>
    </link>
    <joint name="6_7" type="revolute">
       <parent link="6"/>
       <child  link="7"/>
       <origin rpy="0 0 0" xyz="0 0.5381312616568444 0.44228724501364414" />
     <axis xyz="1 0 0"/>
       <limit effort="0.0" lower="-3.14159" upper="3.14159" velocity="0.0"/>
    </joint>
    <link name="8">
        <inertial>
            <origin xyz="0 0.2601972605676804 0.18720383217925052" rpy="0 0 0"/>
            <mass value="1" />
            <inertia ixx="100" ixy="0" ixz="0" iyy="100" iyz="0" izz="100" />
        </inertial>
        <visual>
            <origin xyz="0 0.2601972605676804 0.18720383217925052" rpy="0 0 0"/>
            <geometry>
                <box size="0.1772403912852265 0.5203945211353608 0.37440766435850104" />
            </geometry>
            <material name="Green">
                <color rgba="0 128 0 1"/>
            </material>
        </visual>
        <collision>
            <origin xyz="0 0.2601972605676804 0.18720383217925052" rpy="0 0 0"/>
            <geometry>
                <box size="0.1772403912852265 0.5203945211353608 0.37440766435850104" />
            </geometry>
        </collision>
    </link>
    <joint name="7_8" type="revolute">
       <parent link="7"/>
       <child  link="8"/>
       <origin rpy="0 0 0" xyz="0 0.02002762620526921 0.6007241332677452" />
     <axis xyz="1 1 0"/>
       <limit effort="0.0" lower="-3.14159" upper="3.14159" velocity="0.0"/>
    </joint>
    <link name="9">
        <inertial>
            <origin xyz="0 0.42776759699244327 0.0846421162782175" rpy="0 0 0"/>
            <mass value="1" />
            <inertia ixx="100" ixy="0" ixz="0" iyy="100" iyz="0" izz="100" />
        </inertial>
        <visual>
            <origin xyz="0 0.42776759699244327 0.0846421162782175" rpy="0 0 0"/>
            <geometry>
                <box size="0.438430732561387 0.8555351939848865 0.169284232556435" />
            </geometry>
            <material name="Green">
                <color rgba="0 128 0 1"/>
            </material>
        </visual>
        <collision>
            <origin xyz="0 0.42776759699244327 0.0846421162782175" rpy="0 0 0"/>
            <geometry>
                <box size="0.438430732561387 0.8555351939848865 0.169284232556435" />
            </geometry>
        </collision>
    </link>
    <joint name="8_9" type="revolute">
       <parent link="8"/>
       <child  link="9"/>
       <origin rpy="0 0 0" xyz="0 0.5203945211353608 0.37440766435850104" />
     <axis xyz="1 0 0"/>
       <limit effort="0.0" lower="-3.14159" upper="3.14159" velocity="0.0"/>
    </joint>
</robot>