<robot name = "robot">
    <link name="0">
        <inertial>
            <origin xyz="0 0 0.35" rpy="0 0 0"/>
            <mass value="1" />
            <inertia ixx="100" ixy="0" ixz="0" iyy="100" iyz="0" izz="100" />
        </inertial>
        <visual>
            <origin xyz="0 0 0.35" rpy="0 0 0"/>
            <geometry>
                <box size="0.7 0.7 0.7" />
            </geometry>
            <material name="Green">
                <color rgba="0 128 0 1"/>
            </material>
        </visual>
        <collision>
            <origin xyz="0 0 0.35" rpy="0 0 0"/>
            <geometry>
                <box size="0.7 0.7 0.7" />
            </geometry>
        </collision>
    </link>
    <link name="1">
        <inertial>
            <origin xyz="-0.021405789968313715 0 0.018043792194945507" rpy="0 0 0"/>
            <mass value="1" />
            <inertia ixx="100" ixy="0" ixz="0" iyy="100" iyz="0" izz="100" />
        </inertial>
        <visual>
            <origin xyz="-0.021405789968313715 0 0.018043792194945507" rpy="0 0 0"/>
            <geometry>
                <box size="0.04281157993662743 0.9657018861823465 0.036087584389891014" />
            </geometry>
            <material name="Green">
                <color rgba="0 128 0 1"/>
            </material>
        </visual>
        <collision>
            <origin xyz="-0.021405789968313715 0 0.018043792194945507" rpy="0 0 0"/>
            <geometry>
                <box size="0.04281157993662743 0.9657018861823465 0.036087584389891014" />
            </geometry>
        </collision>
    </link>
    <joint name="0_1" type="revolute">
       <parent link="0"/>
       <child  link="1"/>
       <origin rpy="0 0 0" xyz="-0.35 0 0.7" />
     <axis xyz="0 0 1"/>
       <limit effort="0.0" lower="-3.14159" upper="3.14159" velocity="0.0"/>
    </joint>
    <link name="2">
        <inertial>
            <origin xyz="-0.24401326667943635 0 0.43885064822518266" rpy="0 0 0"/>
            <mass value="1" />
            <inertia ixx="100" ixy="0" ixz="0" iyy="100" iyz="0" izz="100" />
        </inertial>
        <visual>
            <origin xyz="-0.24401326667943635 0 0.43885064822518266" rpy="0 0 0"/>
            <geometry>
                <box size="0.4880265333588727 0.9886724358919596 0.8777012964503653" />
            </geometry>
            <material name="Green">
                <color rgba="0 128 0 1"/>
            </material>
        </visual>
        <collision>
            <origin xyz="-0.24401326667943635 0 0.43885064822518266" rpy="0 0 0"/>
            <geometry>
                <box size="0.4880265333588727 0.9886724358919596 0.8777012964503653" />
            </geometry>
        </collision>
    </link>
    <joint name="1_2" type="revolute">
       <parent link="1"/>
       <child  link="2"/>
       <origin rpy="0 0 0" xyz="-0.04281157993662743 0 0.036087584389891014" />
     <axis xyz="1 1 1"/>
       <limit effort="0.0" lower="-3.14159" upper="3.14159" velocity="0.0"/>
    </joint>
    <link name="3">
        <inertial>
            <origin xyz="-0.3697697561157019 0 0.4390137225007624" rpy="0 0 0"/>
            <mass value="1" />
            <inertia ixx="100" ixy="0" ixz="0" iyy="100" iyz="0" izz="100" />
        </inertial>
        <visual>
            <origin xyz="-0.3697697561157019 0 0.4390137225007624" rpy="0 0 0"/>
            <geometry>
                <box size="0.7395395122314038 0.9195323853313568 0.8780274450015249" />
            </geometry>
            <material name="Blue">
                <color rgba="0 0 255 1"/>
            </material>
        </visual>
        <collision>
            <origin xyz="-0.3697697561157019 0 0.4390137225007624" rpy="0 0 0"/>
            <geometry>
                <box size="0.7395395122314038 0.9195323853313568 0.8780274450015249" />
            </geometry>
        </collision>
    </link>
    <joint name="2_3" type="revolute">
       <parent link="2"/>
       <child  link="3"/>
       <origin rpy="0 0 0" xyz="-0.4880265333588727 0 0.8777012964503653" />
     <axis xyz="1 0 0"/>
       <limit effort="0.0" lower="-3.14159" upper="3.14159" velocity="0.0"/>
    </joint>
    <link name="4">
        <inertial>
            <origin xyz="0.28506317592211977 0 0.030396722780173246" rpy="0 0 0"/>
            <mass value="1" />
            <inertia ixx="100" ixy="0" ixz="0" iyy="100" iyz="0" izz="100" />
        </inertial>
        <visual>
            <origin xyz="0.28506317592211977 0 0.030396722780173246" rpy="0 0 0"/>
            <geometry>
                <box size="0.5701263518442395 0.8684086256156317 0.06079344556034649" />
            </geometry>
            <material name="Blue">
                <color rgba="0 0 255 1"/>
            </material>
        </visual>
        <collision>
            <origin xyz="0.28506317592211977 0 0.030396722780173246" rpy="0 0 0"/>
            <geometry>
                <box size="0.5701263518442395 0.8684086256156317 0.06079344556034649" />
            </geometry>
        </collision>
    </link>
    <joint name="0_4" type="revolute">
       <parent link="0"/>
       <child  link="4"/>
       <origin rpy="0 0 0" xyz="0.35 0 0.7" />
     <axis xyz="0 1 1"/>
       <limit effort="0.0" lower="-3.14159" upper="3.14159" velocity="0.0"/>
    </joint>
    <link name="5">
        <inertial>
            <origin xyz="0 0.25881441077356665 0.29187532599462374" rpy="0 0 0"/>
            <mass value="1" />
            <inertia ixx="100" ixy="0" ixz="0" iyy="100" iyz="0" izz="100" />
        </inertial>
        <visual>
            <origin xyz="0 0.25881441077356665 0.29187532599462374" rpy="0 0 0"/>
            <geometry>
                <box size="0.7169527715133174 0.5176288215471333 0.5837506519892475" />
            </geometry>
            <material name="Blue">
                <color rgba="0 0 255 1"/>
            </material>
        </visual>
        <collision>
            <origin xyz="0 0.25881441077356665 0.29187532599462374" rpy="0 0 0"/>
            <geometry>
                <box size="0.7169527715133174 0.5176288215471333 0.5837506519892475" />
            </geometry>
        </collision>
    </link>
    <joint name="0_5" type="revolute">
       <parent link="0"/>
       <child  link="5"/>
       <origin rpy="0 0 0" xyz="0 0.35 0.7" />
     <axis xyz="1 1 1"/>
       <limit effort="0.0" lower="-3.14159" upper="3.14159" velocity="0.0"/>
    </joint>
    <link name="6">
        <inertial>
            <origin xyz="0 0.37235048380771585 0.09413976817359015" rpy="0 0 0"/>
            <mass value="1" />
            <inertia ixx="100" ixy="0" ixz="0" iyy="100" iyz="0" izz="100" />
        </inertial>
        <visual>
            <origin xyz="0 0.37235048380771585 0.09413976817359015" rpy="0 0 0"/>
            <geometry>
                <box size="0.5920493668464949 0.7447009676154317 0.1882795363471803" />
            </geometry>
            <material name="Blue">
                <color rgba="0 0 255 1"/>
            </material>
        </visual>
        <collision>
            <origin xyz="0 0.37235048380771585 0.09413976817359015" rpy="0 0 0"/>
            <geometry>
                <box size="0.5920493668464949 0.7447009676154317 0.1882795363471803" />
            </geometry>
        </collision>
    </link>
    <joint name="5_6" type="revolute">
       <parent link="5"/>
       <child  link="6"/>
       <origin rpy="0 0 0" xyz="0 0.5176288215471333 0.5837506519892475" />
     <axis xyz="0 1 1"/>
       <limit effort="0.0" lower="-3.14159" upper="3.14159" velocity="0.0"/>
    </joint>
    <link name="7">
        <inertial>
            <origin xyz="0 0.028413000195198157 0.2698200183013068" rpy="0 0 0"/>
            <mass value="1" />
            <inertia ixx="100" ixy="0" ixz="0" iyy="100" iyz="0" izz="100" />
        </inertial>
        <visual>
            <origin xyz="0 0.028413000195198157 0.2698200183013068" rpy="0 0 0"/>
            <geometry>
                <box size="0.6523151766785202 0.056826000390396314 0.5396400366026136" />
            </geometry>
            <material name="Green">
                <color rgba="0 128 0 1"/>
            </material>
        </visual>
        <collision>
            <origin xyz="0 0.028413000195198157 0.2698200183013068" rpy="0 0 0"/>
            <geometry>
                <box size="0.6523151766785202 0.056826000390396314 0.5396400366026136" />
            </geometry>
        </collision>
    </link>
    <joint name="6_7" type="revolute">
       <parent link="6"/>
       <child  link="7"/>
       <origin rpy="0 0 0" xyz="0 0.7447009676154317 0.1882795363471803" />
     <axis xyz="1 1 1"/>
       <limit effort="0.0" lower="-3.14159" upper="3.14159" velocity="0.0"/>
    </joint>
</robot>