<robot name = "robot">
    <link name="0">
        <inertial>
            <origin xyz="0 0 3" rpy="0 0 0"/>
            <mass value="1" />
            <inertia ixx="100" ixy="0" ixz="0" iyy="100" iyz="0" izz="100" />
        </inertial>
        <visual>
            <origin xyz="0 0 3" rpy="0 0 0"/>
            <geometry>
                <box size="1.5 1.5 0.8" />
            </geometry>
            <material name="Blue">
                <color rgba="0 0 255 1"/>
            </material>
        </visual>
        <collision>
            <origin xyz="0 0 3" rpy="0 0 0"/>
            <geometry>
                <box size="1.5 1.5 0.8" />
            </geometry>
        </collision>
    </link>
    <link name="1">
        <inertial>
            <origin xyz="-0.3127154653506913 0 0" rpy="0 0 0"/>
            <mass value="1" />
            <inertia ixx="100" ixy="0" ixz="0" iyy="100" iyz="0" izz="100" />
        </inertial>
        <visual>
            <origin xyz="-0.3127154653506913 0 0" rpy="0 0 0"/>
            <geometry>
                <box size="0.6254309307013826 0.23953976232578345 0.9790976859960863" />
            </geometry>
            <material name="Blue">
                <color rgba="0 0 255 1"/>
            </material>
        </visual>
        <collision>
            <origin xyz="-0.3127154653506913 0 0" rpy="0 0 0"/>
            <geometry>
                <box size="0.6254309307013826 0.23953976232578345 0.9790976859960863" />
            </geometry>
        </collision>
    </link>
    <joint name="0_1" type="revolute">
       <parent link="0"/>
       <child  link="1"/>
       <origin rpy="0 0 0" xyz="-0.75 0 3" />
     <axis xyz="1 1 1"/>
       <limit effort="0.0" lower="-3.14159" upper="3.14159" velocity="0.0"/>
    </joint>
    <link name="2">
        <inertial>
            <origin xyz="-0.4060253010361889 0 0" rpy="0 0 0"/>
            <mass value="1" />
            <inertia ixx="100" ixy="0" ixz="0" iyy="100" iyz="0" izz="100" />
        </inertial>
        <visual>
            <origin xyz="-0.4060253010361889 0 0" rpy="0 0 0"/>
            <geometry>
                <box size="0.8120506020723778 0.21530324866366535 0.04194378964586998" />
            </geometry>
            <material name="Green">
                <color rgba="0 128 0 1"/>
            </material>
        </visual>
        <collision>
            <origin xyz="-0.4060253010361889 0 0" rpy="0 0 0"/>
            <geometry>
                <box size="0.8120506020723778 0.21530324866366535 0.04194378964586998" />
            </geometry>
        </collision>
    </link>
    <joint name="1_2" type="revolute">
       <parent link="1"/>
       <child  link="2"/>
       <origin rpy="0 0 0" xyz="-0.6254309307013826 0 0" />
     <axis xyz="0 1 0"/>
       <limit effort="0.0" lower="-3.14159" upper="3.14159" velocity="0.0"/>
    </joint>
    <link name="3">
        <inertial>
            <origin xyz="-0.429470163476594 0 0" rpy="0 0 0"/>
            <mass value="1" />
            <inertia ixx="100" ixy="0" ixz="0" iyy="100" iyz="0" izz="100" />
        </inertial>
        <visual>
            <origin xyz="-0.429470163476594 0 0" rpy="0 0 0"/>
            <geometry>
                <box size="0.858940326953188 0.8861276436996582 0.5387913567064617" />
            </geometry>
            <material name="Blue">
                <color rgba="0 0 255 1"/>
            </material>
        </visual>
        <collision>
            <origin xyz="-0.429470163476594 0 0" rpy="0 0 0"/>
            <geometry>
                <box size="0.858940326953188 0.8861276436996582 0.5387913567064617" />
            </geometry>
        </collision>
    </link>
    <joint name="2_3" type="revolute">
       <parent link="2"/>
       <child  link="3"/>
       <origin rpy="0 0 0" xyz="-0.8120506020723778 0 0" />
     <axis xyz="1 1 0"/>
       <limit effort="0.0" lower="-3.14159" upper="3.14159" velocity="0.0"/>
    </joint>
    <link name="4">
        <inertial>
            <origin xyz="-0.43685148517314065 0 0" rpy="0 0 0"/>
            <mass value="1" />
            <inertia ixx="100" ixy="0" ixz="0" iyy="100" iyz="0" izz="100" />
        </inertial>
        <visual>
            <origin xyz="-0.43685148517314065 0 0" rpy="0 0 0"/>
            <geometry>
                <box size="0.8737029703462813 0.8257576969012986 0.0911450008041883" />
            </geometry>
            <material name="Green">
                <color rgba="0 128 0 1"/>
            </material>
        </visual>
        <collision>
            <origin xyz="-0.43685148517314065 0 0" rpy="0 0 0"/>
            <geometry>
                <box size="0.8737029703462813 0.8257576969012986 0.0911450008041883" />
            </geometry>
        </collision>
    </link>
    <joint name="3_4" type="revolute">
       <parent link="3"/>
       <child  link="4"/>
       <origin rpy="0 0 0" xyz="-0.858940326953188 0 0" />
     <axis xyz="1 0 0"/>
       <limit effort="0.0" lower="-3.14159" upper="3.14159" velocity="0.0"/>
    </joint>
    <link name="5">
        <inertial>
            <origin xyz="0 0 -1.0246956760020882" rpy="0 0 0"/>
            <mass value="1" />
            <inertia ixx="100" ixy="0" ixz="0" iyy="100" iyz="0" izz="100" />
        </inertial>
        <visual>
            <origin xyz="0 0 -1.0246956760020882" rpy="0 0 0"/>
            <geometry>
                <box size="0.16688191718721623 0.1214165105476599 2.0493913520041764" />
            </geometry>
            <material name="Green">
                <color rgba="0 128 0 1"/>
            </material>
        </visual>
        <collision>
            <origin xyz="0 0 -1.0246956760020882" rpy="0 0 0"/>
            <geometry>
                <box size="0.16688191718721623 0.1214165105476599 2.0493913520041764" />
            </geometry>
        </collision>
    </link>
    <joint name="4_5" type="revolute">
       <parent link="4"/>
       <child  link="5"/>
       <origin rpy="0 0 0" xyz="-0.43685148517314065 0 -0.04557250040209415" />
     <axis xyz="1 0 1"/>
       <limit effort="0.0" lower="-3.14159" upper="3.14159" velocity="0.0"/>
    </joint>
    <link name="6">
        <inertial>
            <origin xyz="0 0 -0.03650732735629363" rpy="0 0 0"/>
            <mass value="1" />
            <inertia ixx="100" ixy="0" ixz="0" iyy="100" iyz="0" izz="100" />
        </inertial>
        <visual>
            <origin xyz="0 0 -0.03650732735629363" rpy="0 0 0"/>
            <geometry>
                <box size="0.7668165108530908 0.6913280300413688 0.07301465471258727" />
            </geometry>
            <material name="Blue">
                <color rgba="0 0 255 1"/>
            </material>
        </visual>
        <collision>
            <origin xyz="0 0 -0.03650732735629363" rpy="0 0 0"/>
            <geometry>
                <box size="0.7668165108530908 0.6913280300413688 0.07301465471258727" />
            </geometry>
        </collision>
    </link>
    <joint name="5_6" type="revolute">
       <parent link="5"/>
       <child  link="6"/>
       <origin rpy="0 0 0" xyz="0 0 -2.0493913520041764" />
     <axis xyz="1 1 1"/>
       <limit effort="0.0" lower="-3.14159" upper="3.14159" velocity="0.0"/>
    </joint>
    <link name="7">
        <inertial>
            <origin xyz="0 0 -0.2387969966416182" rpy="0 0 0"/>
            <mass value="1" />
            <inertia ixx="100" ixy="0" ixz="0" iyy="100" iyz="0" izz="100" />
        </inertial>
        <visual>
            <origin xyz="0 0 -0.2387969966416182" rpy="0 0 0"/>
            <geometry>
                <box size="0.4350837411066282 0.6833961010718062 0.4775939932832364" />
            </geometry>
            <material name="Blue">
                <color rgba="0 0 255 1"/>
            </material>
        </visual>
        <collision>
            <origin xyz="0 0 -0.2387969966416182" rpy="0 0 0"/>
            <geometry>
                <box size="0.4350837411066282 0.6833961010718062 0.4775939932832364" />
            </geometry>
        </collision>
    </link>
    <joint name="6_7" type="revolute">
       <parent link="6"/>
       <child  link="7"/>
       <origin rpy="0 0 0" xyz="0 0 -0.07301465471258727" />
     <axis xyz="0 0 1"/>
       <limit effort="0.0" lower="-3.14159" upper="3.14159" velocity="0.0"/>
    </joint>
    <link name="8">
        <inertial>
            <origin xyz="0.47844256681828445 0 0" rpy="0 0 0"/>
            <mass value="1" />
            <inertia ixx="100" ixy="0" ixz="0" iyy="100" iyz="0" izz="100" />
        </inertial>
        <visual>
            <origin xyz="0.47844256681828445 0 0" rpy="0 0 0"/>
            <geometry>
                <box size="0.9568851336365689 0.5323965070513189 0.9092680703992605" />
            </geometry>
            <material name="Green">
                <color rgba="0 128 0 1"/>
            </material>
        </visual>
        <collision>
            <origin xyz="0.47844256681828445 0 0" rpy="0 0 0"/>
            <geometry>
                <box size="0.9568851336365689 0.5323965070513189 0.9092680703992605" />
            </geometry>
        </collision>
    </link>
    <joint name="0_8" type="revolute">
       <parent link="0"/>
       <child  link="8"/>
       <origin rpy="0 0 0" xyz="0.75 0 3" />
     <axis xyz="0 1 1"/>
       <limit effort="0.0" lower="-3.14159" upper="3.14159" velocity="0.0"/>
    </joint>
    <link name="9">
        <inertial>
            <origin xyz="0.28374136572493247 0 0" rpy="0 0 0"/>
            <mass value="1" />
            <inertia ixx="100" ixy="0" ixz="0" iyy="100" iyz="0" izz="100" />
        </inertial>
        <visual>
            <origin xyz="0.28374136572493247 0 0" rpy="0 0 0"/>
            <geometry>
                <box size="0.5674827314498649 0.3041358575118125 0.7772207697346413" />
            </geometry>
            <material name="Green">
                <color rgba="0 128 0 1"/>
            </material>
        </visual>
        <collision>
            <origin xyz="0.28374136572493247 0 0" rpy="0 0 0"/>
            <geometry>
                <box size="0.5674827314498649 0.3041358575118125 0.7772207697346413" />
            </geometry>
        </collision>
    </link>
    <joint name="8_9" type="revolute">
       <parent link="8"/>
       <child  link="9"/>
       <origin rpy="0 0 0" xyz="0.9568851336365689 0 0" />
     <axis xyz="1 0 1"/>
       <limit effort="0.0" lower="-3.14159" upper="3.14159" velocity="0.0"/>
    </joint>
    <link name="10">
        <inertial>
            <origin xyz="0.26721497763213053 0 0" rpy="0 0 0"/>
            <mass value="1" />
            <inertia ixx="100" ixy="0" ixz="0" iyy="100" iyz="0" izz="100" />
        </inertial>
        <visual>
            <origin xyz="0.26721497763213053 0 0" rpy="0 0 0"/>
            <geometry>
                <box size="0.5344299552642611 0.45926067855788455 0.2647436673641619" />
            </geometry>
            <material name="Green">
                <color rgba="0 128 0 1"/>
            </material>
        </visual>
        <collision>
            <origin xyz="0.26721497763213053 0 0" rpy="0 0 0"/>
            <geometry>
                <box size="0.5344299552642611 0.45926067855788455 0.2647436673641619" />
            </geometry>
        </collision>
    </link>
    <joint name="9_10" type="revolute">
       <parent link="9"/>
       <child  link="10"/>
       <origin rpy="0 0 0" xyz="0.5674827314498649 0 0" />
     <axis xyz="1 0 1"/>
       <limit effort="0.0" lower="-3.14159" upper="3.14159" velocity="0.0"/>
    </joint>
    <link name="11">
        <inertial>
            <origin xyz="0.4113409485718372 0 0" rpy="0 0 0"/>
            <mass value="1" />
            <inertia ixx="100" ixy="0" ixz="0" iyy="100" iyz="0" izz="100" />
        </inertial>
        <visual>
            <origin xyz="0.4113409485718372 0 0" rpy="0 0 0"/>
            <geometry>
                <box size="0.8226818971436743 0.39113228951298096 0.2418748504764493" />
            </geometry>
            <material name="Blue">
                <color rgba="0 0 255 1"/>
            </material>
        </visual>
        <collision>
            <origin xyz="0.4113409485718372 0 0" rpy="0 0 0"/>
            <geometry>
                <box size="0.8226818971436743 0.39113228951298096 0.2418748504764493" />
            </geometry>
        </collision>
    </link>
    <joint name="10_11" type="revolute">
       <parent link="10"/>
       <child  link="11"/>
       <origin rpy="0 0 0" xyz="0.5344299552642611 0 0" />
     <axis xyz="0 1 0"/>
       <limit effort="0.0" lower="-3.14159" upper="3.14159" velocity="0.0"/>
    </joint>
    <link name="12">
        <inertial>
            <origin xyz="0 0 -0.8036385110864295" rpy="0 0 0"/>
            <mass value="1" />
            <inertia ixx="100" ixy="0" ixz="0" iyy="100" iyz="0" izz="100" />
        </inertial>
        <visual>
            <origin xyz="0 0 -0.8036385110864295" rpy="0 0 0"/>
            <geometry>
                <box size="0.785298998840635 0.9781486762248253 1.607277022172859" />
            </geometry>
            <material name="Blue">
                <color rgba="0 0 255 1"/>
            </material>
        </visual>
        <collision>
            <origin xyz="0 0 -0.8036385110864295" rpy="0 0 0"/>
            <geometry>
                <box size="0.785298998840635 0.9781486762248253 1.607277022172859" />
            </geometry>
        </collision>
    </link>
    <joint name="11_12" type="revolute">
       <parent link="11"/>
       <child  link="12"/>
       <origin rpy="0 0 0" xyz="0.4113409485718372 0 -0.12093742523822465" />
     <axis xyz="0 1 0"/>
       <limit effort="0.0" lower="-3.14159" upper="3.14159" velocity="0.0"/>
    </joint>
    <link name="13">
        <inertial>
            <origin xyz="0 0 -0.4775597507671835" rpy="0 0 0"/>
            <mass value="1" />
            <inertia ixx="100" ixy="0" ixz="0" iyy="100" iyz="0" izz="100" />
        </inertial>
        <visual>
            <origin xyz="0 0 -0.4775597507671835" rpy="0 0 0"/>
            <geometry>
                <box size="0.15867092089491674 0.8979136174603736 0.955119501534367" />
            </geometry>
            <material name="Blue">
                <color rgba="0 0 255 1"/>
            </material>
        </visual>
        <collision>
            <origin xyz="0 0 -0.4775597507671835" rpy="0 0 0"/>
            <geometry>
                <box size="0.15867092089491674 0.8979136174603736 0.955119501534367" />
            </geometry>
        </collision>
    </link>
    <joint name="12_13" type="revolute">
       <parent link="12"/>
       <child  link="13"/>
       <origin rpy="0 0 0" xyz="0 0 -1.607277022172859" />
     <axis xyz="1 0 0"/>
       <limit effort="0.0" lower="-3.14159" upper="3.14159" velocity="0.0"/>
    </joint>
    <link name="14">
        <inertial>
            <origin xyz="0 0 -0.01880173814638708" rpy="0 0 0"/>
            <mass value="1" />
            <inertia ixx="100" ixy="0" ixz="0" iyy="100" iyz="0" izz="100" />
        </inertial>
        <visual>
            <origin xyz="0 0 -0.01880173814638708" rpy="0 0 0"/>
            <geometry>
                <box size="0.1849818357879327 0.7600511196728661 0.03760347629277416" />
            </geometry>
            <material name="Blue">
                <color rgba="0 0 255 1"/>
            </material>
        </visual>
        <collision>
            <origin xyz="0 0 -0.01880173814638708" rpy="0 0 0"/>
            <geometry>
                <box size="0.1849818357879327 0.7600511196728661 0.03760347629277416" />
            </geometry>
        </collision>
    </link>
    <joint name="13_14" type="revolute">
       <parent link="13"/>
       <child  link="14"/>
       <origin rpy="0 0 0" xyz="0 0 -0.955119501534367" />
     <axis xyz="1 0 0"/>
       <limit effort="0.0" lower="-3.14159" upper="3.14159" velocity="0.0"/>
    </joint>
    <link name="15">
        <inertial>
            <origin xyz="0 -0.2683889725772282 0" rpy="0 0 0"/>
            <mass value="1" />
            <inertia ixx="100" ixy="0" ixz="0" iyy="100" iyz="0" izz="100" />
        </inertial>
        <visual>
            <origin xyz="0 -0.2683889725772282 0" rpy="0 0 0"/>
            <geometry>
                <box size="0.3305341546670717 0.5367779451544564 0.008856361551116243" />
            </geometry>
            <material name="Green">
                <color rgba="0 128 0 1"/>
            </material>
        </visual>
        <collision>
            <origin xyz="0 -0.2683889725772282 0" rpy="0 0 0"/>
            <geometry>
                <box size="0.3305341546670717 0.5367779451544564 0.008856361551116243" />
            </geometry>
        </collision>
    </link>
    <joint name="0_15" type="revolute">
       <parent link="0"/>
       <child  link="15"/>
       <origin rpy="0 0 0" xyz="0 -0.75 3" />
     <axis xyz="1 0 0"/>
       <limit effort="0.0" lower="-3.14159" upper="3.14159" velocity="0.0"/>
    </joint>
    <link name="16">
        <inertial>
            <origin xyz="0 -0.0010446496691811635 0" rpy="0 0 0"/>
            <mass value="1" />
            <inertia ixx="100" ixy="0" ixz="0" iyy="100" iyz="0" izz="100" />
        </inertial>
        <visual>
            <origin xyz="0 -0.0010446496691811635 0" rpy="0 0 0"/>
            <geometry>
                <box size="0.2218392658530215 0.002089299338362327 0.2021719696589518" />
            </geometry>
            <material name="Green">
                <color rgba="0 128 0 1"/>
            </material>
        </visual>
        <collision>
            <origin xyz="0 -0.0010446496691811635 0" rpy="0 0 0"/>
            <geometry>
                <box size="0.2218392658530215 0.002089299338362327 0.2021719696589518" />
            </geometry>
        </collision>
    </link>
    <joint name="15_16" type="revolute">
       <parent link="15"/>
       <child  link="16"/>
       <origin rpy="0 0 0" xyz="0 -0.5367779451544564 0" />
     <axis xyz="0 1 1"/>
       <limit effort="0.0" lower="-3.14159" upper="3.14159" velocity="0.0"/>
    </joint>
    <link name="17">
        <inertial>
            <origin xyz="0 -0.37784947756107096 0" rpy="0 0 0"/>
            <mass value="1" />
            <inertia ixx="100" ixy="0" ixz="0" iyy="100" iyz="0" izz="100" />
        </inertial>
        <visual>
            <origin xyz="0 -0.37784947756107096 0" rpy="0 0 0"/>
            <geometry>
                <box size="0.5516361200526106 0.7556989551221419 0.30202971635285825" />
            </geometry>
            <material name="Green">
                <color rgba="0 128 0 1"/>
            </material>
        </visual>
        <collision>
            <origin xyz="0 -0.37784947756107096 0" rpy="0 0 0"/>
            <geometry>
                <box size="0.5516361200526106 0.7556989551221419 0.30202971635285825" />
            </geometry>
        </collision>
    </link>
    <joint name="16_17" type="revolute">
       <parent link="16"/>
       <child  link="17"/>
       <origin rpy="0 0 0" xyz="0 -0.002089299338362327 0" />
     <axis xyz="1 0 1"/>
       <limit effort="0.0" lower="-3.14159" upper="3.14159" velocity="0.0"/>
    </joint>
    <link name="18">
        <inertial>
            <origin xyz="0 -0.3978597781869675 0" rpy="0 0 0"/>
            <mass value="1" />
            <inertia ixx="100" ixy="0" ixz="0" iyy="100" iyz="0" izz="100" />
        </inertial>
        <visual>
            <origin xyz="0 -0.3978597781869675 0" rpy="0 0 0"/>
            <geometry>
                <box size="0.6728744011010227 0.795719556373935 0.44566319294351053" />
            </geometry>
            <material name="Green">
                <color rgba="0 128 0 1"/>
            </material>
        </visual>
        <collision>
            <origin xyz="0 -0.3978597781869675 0" rpy="0 0 0"/>
            <geometry>
                <box size="0.6728744011010227 0.795719556373935 0.44566319294351053" />
            </geometry>
        </collision>
    </link>
    <joint name="17_18" type="revolute">
       <parent link="17"/>
       <child  link="18"/>
       <origin rpy="0 0 0" xyz="0 -0.7556989551221419 0" />
     <axis xyz="1 1 0"/>
       <limit effort="0.0" lower="-3.14159" upper="3.14159" velocity="0.0"/>
    </joint>
    <link name="19">
        <inertial>
            <origin xyz="0 0 -0.728568557731952" rpy="0 0 0"/>
            <mass value="1" />
            <inertia ixx="100" ixy="0" ixz="0" iyy="100" iyz="0" izz="100" />
        </inertial>
        <visual>
            <origin xyz="0 0 -0.728568557731952" rpy="0 0 0"/>
            <geometry>
                <box size="0.9685412338002518 0.5535787318714109 1.457137115463904" />
            </geometry>
            <material name="Blue">
                <color rgba="0 0 255 1"/>
            </material>
        </visual>
        <collision>
            <origin xyz="0 0 -0.728568557731952" rpy="0 0 0"/>
            <geometry>
                <box size="0.9685412338002518 0.5535787318714109 1.457137115463904" />
            </geometry>
        </collision>
    </link>
    <joint name="18_19" type="revolute">
       <parent link="18"/>
       <child  link="19"/>
       <origin rpy="0 0 0" xyz="0 -0.3978597781869675 -0.22283159647175527" />
     <axis xyz="0 1 0"/>
       <limit effort="0.0" lower="-3.14159" upper="3.14159" velocity="0.0"/>
    </joint>
    <link name="20">
        <inertial>
            <origin xyz="0 0 -0.49539707192597243" rpy="0 0 0"/>
            <mass value="1" />
            <inertia ixx="100" ixy="0" ixz="0" iyy="100" iyz="0" izz="100" />
        </inertial>
        <visual>
            <origin xyz="0 0 -0.49539707192597243" rpy="0 0 0"/>
            <geometry>
                <box size="0.8963227912879197 0.6573612030812583 0.9907941438519449" />
            </geometry>
            <material name="Green">
                <color rgba="0 128 0 1"/>
            </material>
        </visual>
        <collision>
            <origin xyz="0 0 -0.49539707192597243" rpy="0 0 0"/>
            <geometry>
                <box size="0.8963227912879197 0.6573612030812583 0.9907941438519449" />
            </geometry>
        </collision>
    </link>
    <joint name="19_20" type="revolute">
       <parent link="19"/>
       <child  link="20"/>
       <origin rpy="0 0 0" xyz="0 0 -1.457137115463904" />
     <axis xyz="1 1 1"/>
       <limit effort="0.0" lower="-3.14159" upper="3.14159" velocity="0.0"/>
    </joint>
    <link name="21">
        <inertial>
            <origin xyz="0 0 -0.07603437034207566" rpy="0 0 0"/>
            <mass value="1" />
            <inertia ixx="100" ixy="0" ixz="0" iyy="100" iyz="0" izz="100" />
        </inertial>
        <visual>
            <origin xyz="0 0 -0.07603437034207566" rpy="0 0 0"/>
            <geometry>
                <box size="0.23329238597258628 0.5903610815943162 0.15206874068415133" />
            </geometry>
            <material name="Green">
                <color rgba="0 128 0 1"/>
            </material>
        </visual>
        <collision>
            <origin xyz="0 0 -0.07603437034207566" rpy="0 0 0"/>
            <geometry>
                <box size="0.23329238597258628 0.5903610815943162 0.15206874068415133" />
            </geometry>
        </collision>
    </link>
    <joint name="20_21" type="revolute">
       <parent link="20"/>
       <child  link="21"/>
       <origin rpy="0 0 0" xyz="0 0 -0.9907941438519449" />
     <axis xyz="1 0 0"/>
       <limit effort="0.0" lower="-3.14159" upper="3.14159" velocity="0.0"/>
    </joint>
    <link name="22">
        <inertial>
            <origin xyz="0 0.44236721801733747 0" rpy="0 0 0"/>
            <mass value="1" />
            <inertia ixx="100" ixy="0" ixz="0" iyy="100" iyz="0" izz="100" />
        </inertial>
        <visual>
            <origin xyz="0 0.44236721801733747 0" rpy="0 0 0"/>
            <geometry>
                <box size="0.40773652814139283 0.8847344360346749 0.9674836854906224" />
            </geometry>
            <material name="Green">
                <color rgba="0 128 0 1"/>
            </material>
        </visual>
        <collision>
            <origin xyz="0 0.44236721801733747 0" rpy="0 0 0"/>
            <geometry>
                <box size="0.40773652814139283 0.8847344360346749 0.9674836854906224" />
            </geometry>
        </collision>
    </link>
    <joint name="0_22" type="revolute">
       <parent link="0"/>
       <child  link="22"/>
       <origin rpy="0 0 0" xyz="0 0.75 3" />
     <axis xyz="1 1 0"/>
       <limit effort="0.0" lower="-3.14159" upper="3.14159" velocity="0.0"/>
    </joint>
    <link name="23">
        <inertial>
            <origin xyz="0 0.019939307744610335 0" rpy="0 0 0"/>
            <mass value="1" />
            <inertia ixx="100" ixy="0" ixz="0" iyy="100" iyz="0" izz="100" />
        </inertial>
        <visual>
            <origin xyz="0 0.019939307744610335 0" rpy="0 0 0"/>
            <geometry>
                <box size="0.04816695369999102 0.03987861548922067 0.3925614552216299" />
            </geometry>
            <material name="Green">
                <color rgba="0 128 0 1"/>
            </material>
        </visual>
        <collision>
            <origin xyz="0 0.019939307744610335 0" rpy="0 0 0"/>
            <geometry>
                <box size="0.04816695369999102 0.03987861548922067 0.3925614552216299" />
            </geometry>
        </collision>
    </link>
    <joint name="22_23" type="revolute">
       <parent link="22"/>
       <child  link="23"/>
       <origin rpy="0 0 0" xyz="0 0.8847344360346749 0" />
     <axis xyz="1 0 1"/>
       <limit effort="0.0" lower="-3.14159" upper="3.14159" velocity="0.0"/>
    </joint>
    <link name="24">
        <inertial>
            <origin xyz="0 0.06898419225651803 0" rpy="0 0 0"/>
            <mass value="1" />
            <inertia ixx="100" ixy="0" ixz="0" iyy="100" iyz="0" izz="100" />
        </inertial>
        <visual>
            <origin xyz="0 0.06898419225651803 0" rpy="0 0 0"/>
            <geometry>
                <box size="0.8885297095038022 0.13796838451303606 0.29159689067192496" />
            </geometry>
            <material name="Green">
                <color rgba="0 128 0 1"/>
            </material>
        </visual>
        <collision>
            <origin xyz="0 0.06898419225651803 0" rpy="0 0 0"/>
            <geometry>
                <box size="0.8885297095038022 0.13796838451303606 0.29159689067192496" />
            </geometry>
        </collision>
    </link>
    <joint name="23_24" type="revolute">
       <parent link="23"/>
       <child  link="24"/>
       <origin rpy="0 0 0" xyz="0 0.03987861548922067 0" />
     <axis xyz="1 1 1"/>
       <limit effort="0.0" lower="-3.14159" upper="3.14159" velocity="0.0"/>
    </joint>
    <link name="25">
        <inertial>
            <origin xyz="0 0.3258029361101491 0" rpy="0 0 0"/>
            <mass value="1" />
            <inertia ixx="100" ixy="0" ixz="0" iyy="100" iyz="0" izz="100" />
        </inertial>
        <visual>
            <origin xyz="0 0.3258029361101491 0" rpy="0 0 0"/>
            <geometry>
                <box size="0.5324866297223977 0.6516058722202982 0.10685930441749414" />
            </geometry>
            <material name="Green">
                <color rgba="0 128 0 1"/>
            </material>
        </visual>
        <collision>
            <origin xyz="0 0.3258029361101491 0" rpy="0 0 0"/>
            <geometry>
                <box size="0.5324866297223977 0.6516058722202982 0.10685930441749414" />
            </geometry>
        </collision>
    </link>
    <joint name="24_25" type="revolute">
       <parent link="24"/>
       <child  link="25"/>
       <origin rpy="0 0 0" xyz="0 0.13796838451303606 0" />
     <axis xyz="0 0 1"/>
       <limit effort="0.0" lower="-3.14159" upper="3.14159" velocity="0.0"/>
    </joint>
    <link name="26">
        <inertial>
            <origin xyz="0 0 -1.27118244602684" rpy="0 0 0"/>
            <mass value="1" />
            <inertia ixx="100" ixy="0" ixz="0" iyy="100" iyz="0" izz="100" />
        </inertial>
        <visual>
            <origin xyz="0 0 -1.27118244602684" rpy="0 0 0"/>
            <geometry>
                <box size="0.6011126069741546 0.1083831841665156 2.54236489205368" />
            </geometry>
            <material name="Green">
                <color rgba="0 128 0 1"/>
            </material>
        </visual>
        <collision>
            <origin xyz="0 0 -1.27118244602684" rpy="0 0 0"/>
            <geometry>
                <box size="0.6011126069741546 0.1083831841665156 2.54236489205368" />
            </geometry>
        </collision>
    </link>
    <joint name="25_26" type="revolute">
       <parent link="25"/>
       <child  link="26"/>
       <origin rpy="0 0 0" xyz="0 0.3258029361101491 -0.05342965220874707" />
     <axis xyz="0 1 0"/>
       <limit effort="0.0" lower="-3.14159" upper="3.14159" velocity="0.0"/>
    </joint>
    <link name="27">
        <inertial>
            <origin xyz="0 0 -0.022195780306030158" rpy="0 0 0"/>
            <mass value="1" />
            <inertia ixx="100" ixy="0" ixz="0" iyy="100" iyz="0" izz="100" />
        </inertial>
        <visual>
            <origin xyz="0 0 -0.022195780306030158" rpy="0 0 0"/>
            <geometry>
                <box size="0.3549089070065661 0.5258988982757752 0.044391560612060316" />
            </geometry>
            <material name="Green">
                <color rgba="0 128 0 1"/>
            </material>
        </visual>
        <collision>
            <origin xyz="0 0 -0.022195780306030158" rpy="0 0 0"/>
            <geometry>
                <box size="0.3549089070065661 0.5258988982757752 0.044391560612060316" />
            </geometry>
        </collision>
    </link>
    <joint name="26_27" type="revolute">
       <parent link="26"/>
       <child  link="27"/>
       <origin rpy="0 0 0" xyz="0 0 -2.54236489205368" />
     <axis xyz="0 0 1"/>
       <limit effort="0.0" lower="-3.14159" upper="3.14159" velocity="0.0"/>
    </joint>
    <link name="28">
        <inertial>
            <origin xyz="0 0 -0.006621773667129946" rpy="0 0 0"/>
            <mass value="1" />
            <inertia ixx="100" ixy="0" ixz="0" iyy="100" iyz="0" izz="100" />
        </inertial>
        <visual>
            <origin xyz="0 0 -0.006621773667129946" rpy="0 0 0"/>
            <geometry>
                <box size="0.011613713864546682 0.3838181393382155 0.013243547334259892" />
            </geometry>
            <material name="Blue">
                <color rgba="0 0 255 1"/>
            </material>
        </visual>
        <collision>
            <origin xyz="0 0 -0.006621773667129946" rpy="0 0 0"/>
            <geometry>
                <box size="0.011613713864546682 0.3838181393382155 0.013243547334259892" />
            </geometry>
        </collision>
    </link>
    <joint name="27_28" type="revolute">
       <parent link="27"/>
       <child  link="28"/>
       <origin rpy="0 0 0" xyz="0 0 -0.044391560612060316" />
     <axis xyz="0 1 0"/>
       <limit effort="0.0" lower="-3.14159" upper="3.14159" velocity="0.0"/>
    </joint>
</robot>