<robot name = "robot">
    <link name="0">
        <inertial>
            <origin xyz="0 0 0.35" rpy="0 0 0"/>
            <mass value="1" />
            <inertia ixx="100" ixy="0" ixz="0" iyy="100" iyz="0" izz="100" />
        </inertial>
        <visual>
            <origin xyz="0 0 0.35" rpy="0 0 0"/>
            <geometry>
                <box size="0.7 0.7 0.7" />
            </geometry>
            <material name="Blue">
                <color rgba="0 0 255 1"/>
            </material>
        </visual>
        <collision>
            <origin xyz="0 0 0.35" rpy="0 0 0"/>
            <geometry>
                <box size="0.7 0.7 0.7" />
            </geometry>
        </collision>
    </link>
    <link name="1">
        <inertial>
            <origin xyz="0.1484362327509116 0 0.16080804891300793" rpy="0 0 0"/>
            <mass value="1" />
            <inertia ixx="100" ixy="0" ixz="0" iyy="100" iyz="0" izz="100" />
        </inertial>
        <visual>
            <origin xyz="0.1484362327509116 0 0.16080804891300793" rpy="0 0 0"/>
            <geometry>
                <box size="0.2968724655018232 0.6899918223268333 0.32161609782601586" />
            </geometry>
            <material name="Blue">
                <color rgba="0 0 255 1"/>
            </material>
        </visual>
        <collision>
            <origin xyz="0.1484362327509116 0 0.16080804891300793" rpy="0 0 0"/>
            <geometry>
                <box size="0.2968724655018232 0.6899918223268333 0.32161609782601586" />
            </geometry>
        </collision>
    </link>
    <joint name="0_1" type="revolute">
       <parent link="0"/>
       <child  link="1"/>
       <origin rpy="0 0 0" xyz="0.35 0 0.7" />
     <axis xyz="0 0 1"/>
       <limit effort="0.0" lower="-3.14159" upper="3.14159" velocity="0.0"/>
    </joint>
    <link name="2">
        <inertial>
            <origin xyz="0.4001860570878021 0 0.08186750165964546" rpy="0 0 0"/>
            <mass value="1" />
            <inertia ixx="100" ixy="0" ixz="0" iyy="100" iyz="0" izz="100" />
        </inertial>
        <visual>
            <origin xyz="0.4001860570878021 0 0.08186750165964546" rpy="0 0 0"/>
            <geometry>
                <box size="0.8003721141756042 0.8135356826819284 0.16373500331929092" />
            </geometry>
            <material name="Green">
                <color rgba="0 128 0 1"/>
            </material>
        </visual>
        <collision>
            <origin xyz="0.4001860570878021 0 0.08186750165964546" rpy="0 0 0"/>
            <geometry>
                <box size="0.8003721141756042 0.8135356826819284 0.16373500331929092" />
            </geometry>
        </collision>
    </link>
    <joint name="1_2" type="revolute">
       <parent link="1"/>
       <child  link="2"/>
       <origin rpy="0 0 0" xyz="0.2968724655018232 0 0.32161609782601586" />
     <axis xyz="0 0 1"/>
       <limit effort="0.0" lower="-3.14159" upper="3.14159" velocity="0.0"/>
    </joint>
    <link name="3">
        <inertial>
            <origin xyz="0 -0.22320494688294518 0.06814848053247341" rpy="0 0 0"/>
            <mass value="1" />
            <inertia ixx="100" ixy="0" ixz="0" iyy="100" iyz="0" izz="100" />
        </inertial>
        <visual>
            <origin xyz="0 -0.22320494688294518 0.06814848053247341" rpy="0 0 0"/>
            <geometry>
                <box size="0.35592374955007045 0.44640989376589035 0.13629696106494682" />
            </geometry>
            <material name="Green">
                <color rgba="0 128 0 1"/>
            </material>
        </visual>
        <collision>
            <origin xyz="0 -0.22320494688294518 0.06814848053247341" rpy="0 0 0"/>
            <geometry>
                <box size="0.35592374955007045 0.44640989376589035 0.13629696106494682" />
            </geometry>
        </collision>
    </link>
    <joint name="0_3" type="revolute">
       <parent link="0"/>
       <child  link="3"/>
       <origin rpy="0 0 0" xyz="0 -0.35 0.7" />
     <axis xyz="1 0 0"/>
       <limit effort="0.0" lower="-3.14159" upper="3.14159" velocity="0.0"/>
    </joint>
    <link name="4">
        <inertial>
            <origin xyz="0 -0.2634943055400772 0.09055075733010365" rpy="0 0 0"/>
            <mass value="1" />
            <inertia ixx="100" ixy="0" ixz="0" iyy="100" iyz="0" izz="100" />
        </inertial>
        <visual>
            <origin xyz="0 -0.2634943055400772 0.09055075733010365" rpy="0 0 0"/>
            <geometry>
                <box size="0.9737482270257036 0.5269886110801544 0.1811015146602073" />
            </geometry>
            <material name="Green">
                <color rgba="0 128 0 1"/>
            </material>
        </visual>
        <collision>
            <origin xyz="0 -0.2634943055400772 0.09055075733010365" rpy="0 0 0"/>
            <geometry>
                <box size="0.9737482270257036 0.5269886110801544 0.1811015146602073" />
            </geometry>
        </collision>
    </link>
    <joint name="3_4" type="revolute">
       <parent link="3"/>
       <child  link="4"/>
       <origin rpy="0 0 0" xyz="0 -0.44640989376589035 0.13629696106494682" />
     <axis xyz="1 1 1"/>
       <limit effort="0.0" lower="-3.14159" upper="3.14159" velocity="0.0"/>
    </joint>
    <link name="5">
        <inertial>
            <origin xyz="0 -0.3304936178880658 0.2951856529565987" rpy="0 0 0"/>
            <mass value="1" />
            <inertia ixx="100" ixy="0" ixz="0" iyy="100" iyz="0" izz="100" />
        </inertial>
        <visual>
            <origin xyz="0 -0.3304936178880658 0.2951856529565987" rpy="0 0 0"/>
            <geometry>
                <box size="0.01958099547508263 0.6609872357761316 0.5903713059131974" />
            </geometry>
            <material name="Green">
                <color rgba="0 128 0 1"/>
            </material>
        </visual>
        <collision>
            <origin xyz="0 -0.3304936178880658 0.2951856529565987" rpy="0 0 0"/>
            <geometry>
                <box size="0.01958099547508263 0.6609872357761316 0.5903713059131974" />
            </geometry>
        </collision>
    </link>
    <joint name="4_5" type="revolute">
       <parent link="4"/>
       <child  link="5"/>
       <origin rpy="0 0 0" xyz="0 -0.5269886110801544 0.1811015146602073" />
     <axis xyz="0 1 1"/>
       <limit effort="0.0" lower="-3.14159" upper="3.14159" velocity="0.0"/>
    </joint>
    <link name="6">
        <inertial>
            <origin xyz="0 -0.09148054795397254 0.14277978328433893" rpy="0 0 0"/>
            <mass value="1" />
            <inertia ixx="100" ixy="0" ixz="0" iyy="100" iyz="0" izz="100" />
        </inertial>
        <visual>
            <origin xyz="0 -0.09148054795397254 0.14277978328433893" rpy="0 0 0"/>
            <geometry>
                <box size="0.0426826189009436 0.18296109590794507 0.28555956656867787" />
            </geometry>
            <material name="Green">
                <color rgba="0 128 0 1"/>
            </material>
        </visual>
        <collision>
            <origin xyz="0 -0.09148054795397254 0.14277978328433893" rpy="0 0 0"/>
            <geometry>
                <box size="0.0426826189009436 0.18296109590794507 0.28555956656867787" />
            </geometry>
        </collision>
    </link>
    <joint name="5_6" type="revolute">
       <parent link="5"/>
       <child  link="6"/>
       <origin rpy="0 0 0" xyz="0 -0.6609872357761316 0.5903713059131974" />
     <axis xyz="1 0 1"/>
       <limit effort="0.0" lower="-3.14159" upper="3.14159" velocity="0.0"/>
    </joint>
    <link name="7">
        <inertial>
            <origin xyz="0 0.17276577624793454 0.3378748328863268" rpy="0 0 0"/>
            <mass value="1" />
            <inertia ixx="100" ixy="0" ixz="0" iyy="100" iyz="0" izz="100" />
        </inertial>
        <visual>
            <origin xyz="0 0.17276577624793454 0.3378748328863268" rpy="0 0 0"/>
            <geometry>
                <box size="0.17009918190504647 0.3455315524958691 0.6757496657726536" />
            </geometry>
            <material name="Green">
                <color rgba="0 128 0 1"/>
            </material>
        </visual>
        <collision>
            <origin xyz="0 0.17276577624793454 0.3378748328863268" rpy="0 0 0"/>
            <geometry>
                <box size="0.17009918190504647 0.3455315524958691 0.6757496657726536" />
            </geometry>
        </collision>
    </link>
    <joint name="0_7" type="revolute">
       <parent link="0"/>
       <child  link="7"/>
       <origin rpy="0 0 0" xyz="0 0.35 0.7" />
     <axis xyz="0 1 0"/>
       <limit effort="0.0" lower="-3.14159" upper="3.14159" velocity="0.0"/>
    </joint>
    <link name="8">
        <inertial>
            <origin xyz="0 0.1675388662707612 0.26881163951803916" rpy="0 0 0"/>
            <mass value="1" />
            <inertia ixx="100" ixy="0" ixz="0" iyy="100" iyz="0" izz="100" />
        </inertial>
        <visual>
            <origin xyz="0 0.1675388662707612 0.26881163951803916" rpy="0 0 0"/>
            <geometry>
                <box size="0.25800614503641783 0.3350777325415224 0.5376232790360783" />
            </geometry>
            <material name="Green">
                <color rgba="0 128 0 1"/>
            </material>
        </visual>
        <collision>
            <origin xyz="0 0.1675388662707612 0.26881163951803916" rpy="0 0 0"/>
            <geometry>
                <box size="0.25800614503641783 0.3350777325415224 0.5376232790360783" />
            </geometry>
        </collision>
    </link>
    <joint name="7_8" type="revolute">
       <parent link="7"/>
       <child  link="8"/>
       <origin rpy="0 0 0" xyz="0 0.3455315524958691 0.6757496657726536" />
     <axis xyz="1 0 0"/>
       <limit effort="0.0" lower="-3.14159" upper="3.14159" velocity="0.0"/>
    </joint>
</robot>