<robot name = "robot">
    <link name="0">
        <inertial>
            <origin xyz="0 0 0.35" rpy="0 0 0"/>
            <mass value="1" />
            <inertia ixx="100" ixy="0" ixz="0" iyy="100" iyz="0" izz="100" />
        </inertial>
        <visual>
            <origin xyz="0 0 0.35" rpy="0 0 0"/>
            <geometry>
                <box size="0.7 0.7 0.7" />
            </geometry>
            <material name="Green">
                <color rgba="0 128 0 1"/>
            </material>
        </visual>
        <collision>
            <origin xyz="0 0 0.35" rpy="0 0 0"/>
            <geometry>
                <box size="0.7 0.7 0.7" />
            </geometry>
        </collision>
    </link>
    <link name="1">
        <inertial>
            <origin xyz="0.38136518675828734 0 0.4882016456686185" rpy="0 0 0"/>
            <mass value="1" />
            <inertia ixx="100" ixy="0" ixz="0" iyy="100" iyz="0" izz="100" />
        </inertial>
        <visual>
            <origin xyz="0.38136518675828734 0 0.4882016456686185" rpy="0 0 0"/>
            <geometry>
                <box size="0.7627303735165747 0.7004239803876297 0.976403291337237" />
            </geometry>
            <material name="Green">
                <color rgba="0 128 0 1"/>
            </material>
        </visual>
        <collision>
            <origin xyz="0.38136518675828734 0 0.4882016456686185" rpy="0 0 0"/>
            <geometry>
                <box size="0.7627303735165747 0.7004239803876297 0.976403291337237" />
            </geometry>
        </collision>
    </link>
    <joint name="0_1" type="revolute">
       <parent link="0"/>
       <child  link="1"/>
       <origin rpy="0 0 0" xyz="0.35 0 0.7" />
     <axis xyz="1 0 1"/>
       <limit effort="0.0" lower="-3.14159" upper="3.14159" velocity="0.0"/>
    </joint>
    <link name="2">
        <inertial>
            <origin xyz="0.47140813306475315 0 0.4700054543582861" rpy="0 0 0"/>
            <mass value="1" />
            <inertia ixx="100" ixy="0" ixz="0" iyy="100" iyz="0" izz="100" />
        </inertial>
        <visual>
            <origin xyz="0.47140813306475315 0 0.4700054543582861" rpy="0 0 0"/>
            <geometry>
                <box size="0.9428162661295063 0.43129396671011977 0.9400109087165722" />
            </geometry>
            <material name="Green">
                <color rgba="0 128 0 1"/>
            </material>
        </visual>
        <collision>
            <origin xyz="0.47140813306475315 0 0.4700054543582861" rpy="0 0 0"/>
            <geometry>
                <box size="0.9428162661295063 0.43129396671011977 0.9400109087165722" />
            </geometry>
        </collision>
    </link>
    <joint name="1_2" type="revolute">
       <parent link="1"/>
       <child  link="2"/>
       <origin rpy="0 0 0" xyz="0.7627303735165747 0 0.976403291337237" />
     <axis xyz="1 0 0"/>
       <limit effort="0.0" lower="-3.14159" upper="3.14159" velocity="0.0"/>
    </joint>
    <link name="3">
        <inertial>
            <origin xyz="0 -0.42634697738439864 0.14259343232740934" rpy="0 0 0"/>
            <mass value="1" />
            <inertia ixx="100" ixy="0" ixz="0" iyy="100" iyz="0" izz="100" />
        </inertial>
        <visual>
            <origin xyz="0 -0.42634697738439864 0.14259343232740934" rpy="0 0 0"/>
            <geometry>
                <box size="0.35971428421535445 0.8526939547687973 0.2851868646548187" />
            </geometry>
            <material name="Blue">
                <color rgba="0 0 255 1"/>
            </material>
        </visual>
        <collision>
            <origin xyz="0 -0.42634697738439864 0.14259343232740934" rpy="0 0 0"/>
            <geometry>
                <box size="0.35971428421535445 0.8526939547687973 0.2851868646548187" />
            </geometry>
        </collision>
    </link>
    <joint name="0_3" type="revolute">
       <parent link="0"/>
       <child  link="3"/>
       <origin rpy="0 0 0" xyz="0 -0.35 0.7" />
     <axis xyz="1 1 1"/>
       <limit effort="0.0" lower="-3.14159" upper="3.14159" velocity="0.0"/>
    </joint>
    <link name="4">
        <inertial>
            <origin xyz="0 -0.27306432485409576 0.02356855263805374" rpy="0 0 0"/>
            <mass value="1" />
            <inertia ixx="100" ixy="0" ixz="0" iyy="100" iyz="0" izz="100" />
        </inertial>
        <visual>
            <origin xyz="0 -0.27306432485409576 0.02356855263805374" rpy="0 0 0"/>
            <geometry>
                <box size="0.26786315656753135 0.5461286497081915 0.04713710527610748" />
            </geometry>
            <material name="Green">
                <color rgba="0 128 0 1"/>
            </material>
        </visual>
        <collision>
            <origin xyz="0 -0.27306432485409576 0.02356855263805374" rpy="0 0 0"/>
            <geometry>
                <box size="0.26786315656753135 0.5461286497081915 0.04713710527610748" />
            </geometry>
        </collision>
    </link>
    <joint name="3_4" type="revolute">
       <parent link="3"/>
       <child  link="4"/>
       <origin rpy="0 0 0" xyz="0 -0.8526939547687973 0.2851868646548187" />
     <axis xyz="0 0 1"/>
       <limit effort="0.0" lower="-3.14159" upper="3.14159" velocity="0.0"/>
    </joint>
    <link name="5">
        <inertial>
            <origin xyz="0 -0.46506509857874423 0.2597839348392862" rpy="0 0 0"/>
            <mass value="1" />
            <inertia ixx="100" ixy="0" ixz="0" iyy="100" iyz="0" izz="100" />
        </inertial>
        <visual>
            <origin xyz="0 -0.46506509857874423 0.2597839348392862" rpy="0 0 0"/>
            <geometry>
                <box size="0.7475110683039072 0.9301301971574885 0.5195678696785724" />
            </geometry>
            <material name="Green">
                <color rgba="0 128 0 1"/>
            </material>
        </visual>
        <collision>
            <origin xyz="0 -0.46506509857874423 0.2597839348392862" rpy="0 0 0"/>
            <geometry>
                <box size="0.7475110683039072 0.9301301971574885 0.5195678696785724" />
            </geometry>
        </collision>
    </link>
    <joint name="4_5" type="revolute">
       <parent link="4"/>
       <child  link="5"/>
       <origin rpy="0 0 0" xyz="0 -0.5461286497081915 0.04713710527610748" />
     <axis xyz="0 0 1"/>
       <limit effort="0.0" lower="-3.14159" upper="3.14159" velocity="0.0"/>
    </joint>
    <link name="6">
        <inertial>
            <origin xyz="0 -0.08286470156204212 0.025129888213932305" rpy="0 0 0"/>
            <mass value="1" />
            <inertia ixx="100" ixy="0" ixz="0" iyy="100" iyz="0" izz="100" />
        </inertial>
        <visual>
            <origin xyz="0 -0.08286470156204212 0.025129888213932305" rpy="0 0 0"/>
            <geometry>
                <box size="0.5358362199429954 0.16572940312408424 0.05025977642786461" />
            </geometry>
            <material name="Blue">
                <color rgba="0 0 255 1"/>
            </material>
        </visual>
        <collision>
            <origin xyz="0 -0.08286470156204212 0.025129888213932305" rpy="0 0 0"/>
            <geometry>
                <box size="0.5358362199429954 0.16572940312408424 0.05025977642786461" />
            </geometry>
        </collision>
    </link>
    <joint name="5_6" type="revolute">
       <parent link="5"/>
       <child  link="6"/>
       <origin rpy="0 0 0" xyz="0 -0.9301301971574885 0.5195678696785724" />
     <axis xyz="1 0 1"/>
       <limit effort="0.0" lower="-3.14159" upper="3.14159" velocity="0.0"/>
    </joint>
</robot>