<robot name = "robot">
    <link name="0">
        <inertial>
            <origin xyz="0 0 0.35" rpy="0 0 0"/>
            <mass value="1" />
            <inertia ixx="100" ixy="0" ixz="0" iyy="100" iyz="0" izz="100" />
        </inertial>
        <visual>
            <origin xyz="0 0 0.35" rpy="0 0 0"/>
            <geometry>
                <box size="0.7 0.7 0.7" />
            </geometry>
            <material name="Green">
                <color rgba="0 128 0 1"/>
            </material>
        </visual>
        <collision>
            <origin xyz="0 0 0.35" rpy="0 0 0"/>
            <geometry>
                <box size="0.7 0.7 0.7" />
            </geometry>
        </collision>
    </link>
    <link name="1">
        <inertial>
            <origin xyz="-0.12494119542739296 0 0.25994483883786906" rpy="0 0 0"/>
            <mass value="1" />
            <inertia ixx="100" ixy="0" ixz="0" iyy="100" iyz="0" izz="100" />
        </inertial>
        <visual>
            <origin xyz="-0.12494119542739296 0 0.25994483883786906" rpy="0 0 0"/>
            <geometry>
                <box size="0.24988239085478592 0.3793739827692869 0.5198896776757381" />
            </geometry>
            <material name="Blue">
                <color rgba="0 0 255 1"/>
            </material>
        </visual>
        <collision>
            <origin xyz="-0.12494119542739296 0 0.25994483883786906" rpy="0 0 0"/>
            <geometry>
                <box size="0.24988239085478592 0.3793739827692869 0.5198896776757381" />
            </geometry>
        </collision>
    </link>
    <joint name="0_1" type="revolute">
       <parent link="0"/>
       <child  link="1"/>
       <origin rpy="0 0 0" xyz="-0.35 0 0.7" />
     <axis xyz="0 1 0"/>
       <limit effort="0.0" lower="-3.14159" upper="3.14159" velocity="0.0"/>
    </joint>
    <link name="2">
        <inertial>
            <origin xyz="-0.2862394341807258 0 0.2217766669698702" rpy="0 0 0"/>
            <mass value="1" />
            <inertia ixx="100" ixy="0" ixz="0" iyy="100" iyz="0" izz="100" />
        </inertial>
        <visual>
            <origin xyz="-0.2862394341807258 0 0.2217766669698702" rpy="0 0 0"/>
            <geometry>
                <box size="0.5724788683614516 0.5832359723334187 0.4435533339397404" />
            </geometry>
            <material name="Green">
                <color rgba="0 128 0 1"/>
            </material>
        </visual>
        <collision>
            <origin xyz="-0.2862394341807258 0 0.2217766669698702" rpy="0 0 0"/>
            <geometry>
                <box size="0.5724788683614516 0.5832359723334187 0.4435533339397404" />
            </geometry>
        </collision>
    </link>
    <joint name="1_2" type="revolute">
       <parent link="1"/>
       <child  link="2"/>
       <origin rpy="0 0 0" xyz="-0.24988239085478592 0 0.5198896776757381" />
     <axis xyz="0 0 1"/>
       <limit effort="0.0" lower="-3.14159" upper="3.14159" velocity="0.0"/>
    </joint>
    <link name="3">
        <inertial>
            <origin xyz="-0.013869078280141334 0 0.49405090589632855" rpy="0 0 0"/>
            <mass value="1" />
            <inertia ixx="100" ixy="0" ixz="0" iyy="100" iyz="0" izz="100" />
        </inertial>
        <visual>
            <origin xyz="-0.013869078280141334 0 0.49405090589632855" rpy="0 0 0"/>
            <geometry>
                <box size="0.027738156560282667 0.12611677788017517 0.9881018117926571" />
            </geometry>
            <material name="Green">
                <color rgba="0 128 0 1"/>
            </material>
        </visual>
        <collision>
            <origin xyz="-0.013869078280141334 0 0.49405090589632855" rpy="0 0 0"/>
            <geometry>
                <box size="0.027738156560282667 0.12611677788017517 0.9881018117926571" />
            </geometry>
        </collision>
    </link>
    <joint name="2_3" type="revolute">
       <parent link="2"/>
       <child  link="3"/>
       <origin rpy="0 0 0" xyz="-0.5724788683614516 0 0.4435533339397404" />
     <axis xyz="1 0 1"/>
       <limit effort="0.0" lower="-3.14159" upper="3.14159" velocity="0.0"/>
    </joint>
    <link name="4">
        <inertial>
            <origin xyz="0.2973408554145341 0 0.23505219799991972" rpy="0 0 0"/>
            <mass value="1" />
            <inertia ixx="100" ixy="0" ixz="0" iyy="100" iyz="0" izz="100" />
        </inertial>
        <visual>
            <origin xyz="0.2973408554145341 0 0.23505219799991972" rpy="0 0 0"/>
            <geometry>
                <box size="0.5946817108290682 0.7850168077648089 0.47010439599983944" />
            </geometry>
            <material name="Green">
                <color rgba="0 128 0 1"/>
            </material>
        </visual>
        <collision>
            <origin xyz="0.2973408554145341 0 0.23505219799991972" rpy="0 0 0"/>
            <geometry>
                <box size="0.5946817108290682 0.7850168077648089 0.47010439599983944" />
            </geometry>
        </collision>
    </link>
    <joint name="0_4" type="revolute">
       <parent link="0"/>
       <child  link="4"/>
       <origin rpy="0 0 0" xyz="0.35 0 0.7" />
     <axis xyz="0 0 1"/>
       <limit effort="0.0" lower="-3.14159" upper="3.14159" velocity="0.0"/>
    </joint>
    <link name="5">
        <inertial>
            <origin xyz="0.3886168750904874 0 0.28189319992990824" rpy="0 0 0"/>
            <mass value="1" />
            <inertia ixx="100" ixy="0" ixz="0" iyy="100" iyz="0" izz="100" />
        </inertial>
        <visual>
            <origin xyz="0.3886168750904874 0 0.28189319992990824" rpy="0 0 0"/>
            <geometry>
                <box size="0.7772337501809748 0.7188187627638007 0.5637863998598165" />
            </geometry>
            <material name="Green">
                <color rgba="0 128 0 1"/>
            </material>
        </visual>
        <collision>
            <origin xyz="0.3886168750904874 0 0.28189319992990824" rpy="0 0 0"/>
            <geometry>
                <box size="0.7772337501809748 0.7188187627638007 0.5637863998598165" />
            </geometry>
        </collision>
    </link>
    <joint name="4_5" type="revolute">
       <parent link="4"/>
       <child  link="5"/>
       <origin rpy="0 0 0" xyz="0.5946817108290682 0 0.47010439599983944" />
     <axis xyz="1 0 0"/>
       <limit effort="0.0" lower="-3.14159" upper="3.14159" velocity="0.0"/>
    </joint>
    <link name="6">
        <inertial>
            <origin xyz="0.10592754914478758 0 0.40754959318537753" rpy="0 0 0"/>
            <mass value="1" />
            <inertia ixx="100" ixy="0" ixz="0" iyy="100" iyz="0" izz="100" />
        </inertial>
        <visual>
            <origin xyz="0.10592754914478758 0 0.40754959318537753" rpy="0 0 0"/>
            <geometry>
                <box size="0.21185509828957516 0.5216546952814282 0.8150991863707551" />
            </geometry>
            <material name="Green">
                <color rgba="0 128 0 1"/>
            </material>
        </visual>
        <collision>
            <origin xyz="0.10592754914478758 0 0.40754959318537753" rpy="0 0 0"/>
            <geometry>
                <box size="0.21185509828957516 0.5216546952814282 0.8150991863707551" />
            </geometry>
        </collision>
    </link>
    <joint name="5_6" type="revolute">
       <parent link="5"/>
       <child  link="6"/>
       <origin rpy="0 0 0" xyz="0.7772337501809748 0 0.5637863998598165" />
     <axis xyz="0 0 1"/>
       <limit effort="0.0" lower="-3.14159" upper="3.14159" velocity="0.0"/>
    </joint>
    <link name="7">
        <inertial>
            <origin xyz="0.3992731540087363 0 0.2810087681929036" rpy="0 0 0"/>
            <mass value="1" />
            <inertia ixx="100" ixy="0" ixz="0" iyy="100" iyz="0" izz="100" />
        </inertial>
        <visual>
            <origin xyz="0.3992731540087363 0 0.2810087681929036" rpy="0 0 0"/>
            <geometry>
                <box size="0.7985463080174726 0.5051975572062043 0.5620175363858072" />
            </geometry>
            <material name="Green">
                <color rgba="0 128 0 1"/>
            </material>
        </visual>
        <collision>
            <origin xyz="0.3992731540087363 0 0.2810087681929036" rpy="0 0 0"/>
            <geometry>
                <box size="0.7985463080174726 0.5051975572062043 0.5620175363858072" />
            </geometry>
        </collision>
    </link>
    <joint name="6_7" type="revolute">
       <parent link="6"/>
       <child  link="7"/>
       <origin rpy="0 0 0" xyz="0.21185509828957516 0 0.8150991863707551" />
     <axis xyz="1 1 1"/>
       <limit effort="0.0" lower="-3.14159" upper="3.14159" velocity="0.0"/>
    </joint>
</robot>