<robot name = "robot">
    <link name="0">
        <inertial>
            <origin xyz="0 0 0.35" rpy="0 0 0"/>
            <mass value="1" />
            <inertia ixx="100" ixy="0" ixz="0" iyy="100" iyz="0" izz="100" />
        </inertial>
        <visual>
            <origin xyz="0 0 0.35" rpy="0 0 0"/>
            <geometry>
                <box size="0.7 0.7 0.7" />
            </geometry>
            <material name="Green">
                <color rgba="0 128 0 1"/>
            </material>
        </visual>
        <collision>
            <origin xyz="0 0 0.35" rpy="0 0 0"/>
            <geometry>
                <box size="0.7 0.7 0.7" />
            </geometry>
        </collision>
    </link>
    <link name="1">
        <inertial>
            <origin xyz="-0.49139273801882655 0 0.45108297521979135" rpy="0 0 0"/>
            <mass value="1" />
            <inertia ixx="100" ixy="0" ixz="0" iyy="100" iyz="0" izz="100" />
        </inertial>
        <visual>
            <origin xyz="-0.49139273801882655 0 0.45108297521979135" rpy="0 0 0"/>
            <geometry>
                <box size="0.9827854760376531 0.8102172359965896 0.9021659504395827" />
            </geometry>
            <material name="Blue">
                <color rgba="0 0 255 1"/>
            </material>
        </visual>
        <collision>
            <origin xyz="-0.49139273801882655 0 0.45108297521979135" rpy="0 0 0"/>
            <geometry>
                <box size="0.9827854760376531 0.8102172359965896 0.9021659504395827" />
            </geometry>
        </collision>
    </link>
    <joint name="0_1" type="revolute">
       <parent link="0"/>
       <child  link="1"/>
       <origin rpy="0 0 0" xyz="-0.35 0 0.7" />
     <axis xyz="0 0 1"/>
       <limit effort="0.0" lower="-3.14159" upper="3.14159" velocity="0.0"/>
    </joint>
    <link name="2">
        <inertial>
            <origin xyz="-0.049381672329573856 0 0.4252369131296274" rpy="0 0 0"/>
            <mass value="1" />
            <inertia ixx="100" ixy="0" ixz="0" iyy="100" iyz="0" izz="100" />
        </inertial>
        <visual>
            <origin xyz="-0.049381672329573856 0 0.4252369131296274" rpy="0 0 0"/>
            <geometry>
                <box size="0.09876334465914771 0.07374243362872512 0.8504738262592548" />
            </geometry>
            <material name="Green">
                <color rgba="0 128 0 1"/>
            </material>
        </visual>
        <collision>
            <origin xyz="-0.049381672329573856 0 0.4252369131296274" rpy="0 0 0"/>
            <geometry>
                <box size="0.09876334465914771 0.07374243362872512 0.8504738262592548" />
            </geometry>
        </collision>
    </link>
    <joint name="1_2" type="revolute">
       <parent link="1"/>
       <child  link="2"/>
       <origin rpy="0 0 0" xyz="-0.9827854760376531 0 0.9021659504395827" />
     <axis xyz="0 0 1"/>
       <limit effort="0.0" lower="-3.14159" upper="3.14159" velocity="0.0"/>
    </joint>
    <link name="3">
        <inertial>
            <origin xyz="0.23607135772635668 0 0.21708591772689184" rpy="0 0 0"/>
            <mass value="1" />
            <inertia ixx="100" ixy="0" ixz="0" iyy="100" iyz="0" izz="100" />
        </inertial>
        <visual>
            <origin xyz="0.23607135772635668 0 0.21708591772689184" rpy="0 0 0"/>
            <geometry>
                <box size="0.47214271545271336 0.1007012080683658 0.4341718354537837" />
            </geometry>
            <material name="Green">
                <color rgba="0 128 0 1"/>
            </material>
        </visual>
        <collision>
            <origin xyz="0.23607135772635668 0 0.21708591772689184" rpy="0 0 0"/>
            <geometry>
                <box size="0.47214271545271336 0.1007012080683658 0.4341718354537837" />
            </geometry>
        </collision>
    </link>
    <joint name="0_3" type="revolute">
       <parent link="0"/>
       <child  link="3"/>
       <origin rpy="0 0 0" xyz="0.35 0 0.7" />
     <axis xyz="1 1 0"/>
       <limit effort="0.0" lower="-3.14159" upper="3.14159" velocity="0.0"/>
    </joint>
    <link name="4">
        <inertial>
            <origin xyz="0.45799724017844234 0 0.42004560827770654" rpy="0 0 0"/>
            <mass value="1" />
            <inertia ixx="100" ixy="0" ixz="0" iyy="100" iyz="0" izz="100" />
        </inertial>
        <visual>
            <origin xyz="0.45799724017844234 0 0.42004560827770654" rpy="0 0 0"/>
            <geometry>
                <box size="0.9159944803568847 0.09327186435241008 0.8400912165554131" />
            </geometry>
            <material name="Green">
                <color rgba="0 128 0 1"/>
            </material>
        </visual>
        <collision>
            <origin xyz="0.45799724017844234 0 0.42004560827770654" rpy="0 0 0"/>
            <geometry>
                <box size="0.9159944803568847 0.09327186435241008 0.8400912165554131" />
            </geometry>
        </collision>
    </link>
    <joint name="3_4" type="revolute">
       <parent link="3"/>
       <child  link="4"/>
       <origin rpy="0 0 0" xyz="0.47214271545271336 0 0.4341718354537837" />
     <axis xyz="1 1 0"/>
       <limit effort="0.0" lower="-3.14159" upper="3.14159" velocity="0.0"/>
    </joint>
    <link name="5">
        <inertial>
            <origin xyz="0.30594854240707253 0 0.1665675686445492" rpy="0 0 0"/>
            <mass value="1" />
            <inertia ixx="100" ixy="0" ixz="0" iyy="100" iyz="0" izz="100" />
        </inertial>
        <visual>
            <origin xyz="0.30594854240707253 0 0.1665675686445492" rpy="0 0 0"/>
            <geometry>
                <box size="0.6118970848141451 0.8280632784038988 0.3331351372890984" />
            </geometry>
            <material name="Blue">
                <color rgba="0 0 255 1"/>
            </material>
        </visual>
        <collision>
            <origin xyz="0.30594854240707253 0 0.1665675686445492" rpy="0 0 0"/>
            <geometry>
                <box size="0.6118970848141451 0.8280632784038988 0.3331351372890984" />
            </geometry>
        </collision>
    </link>
    <joint name="4_5" type="revolute">
       <parent link="4"/>
       <child  link="5"/>
       <origin rpy="0 0 0" xyz="0.9159944803568847 0 0.8400912165554131" />
     <axis xyz="1 1 0"/>
       <limit effort="0.0" lower="-3.14159" upper="3.14159" velocity="0.0"/>
    </joint>
    <link name="6">
        <inertial>
            <origin xyz="0 -0.031492137130599784 0.4585094845574749" rpy="0 0 0"/>
            <mass value="1" />
            <inertia ixx="100" ixy="0" ixz="0" iyy="100" iyz="0" izz="100" />
        </inertial>
        <visual>
            <origin xyz="0 -0.031492137130599784 0.4585094845574749" rpy="0 0 0"/>
            <geometry>
                <box size="0.7036425461655201 0.06298427426119957 0.9170189691149498" />
            </geometry>
            <material name="Green">
                <color rgba="0 128 0 1"/>
            </material>
        </visual>
        <collision>
            <origin xyz="0 -0.031492137130599784 0.4585094845574749" rpy="0 0 0"/>
            <geometry>
                <box size="0.7036425461655201 0.06298427426119957 0.9170189691149498" />
            </geometry>
        </collision>
    </link>
    <joint name="0_6" type="revolute">
       <parent link="0"/>
       <child  link="6"/>
       <origin rpy="0 0 0" xyz="0 -0.35 0.7" />
     <axis xyz="1 0 0"/>
       <limit effort="0.0" lower="-3.14159" upper="3.14159" velocity="0.0"/>
    </joint>
    <link name="7">
        <inertial>
            <origin xyz="0 -0.45964117670080684 0.4811212432552096" rpy="0 0 0"/>
            <mass value="1" />
            <inertia ixx="100" ixy="0" ixz="0" iyy="100" iyz="0" izz="100" />
        </inertial>
        <visual>
            <origin xyz="0 -0.45964117670080684 0.4811212432552096" rpy="0 0 0"/>
            <geometry>
                <box size="0.030134234552269934 0.9192823534016137 0.9622424865104192" />
            </geometry>
            <material name="Blue">
                <color rgba="0 0 255 1"/>
            </material>
        </visual>
        <collision>
            <origin xyz="0 -0.45964117670080684 0.4811212432552096" rpy="0 0 0"/>
            <geometry>
                <box size="0.030134234552269934 0.9192823534016137 0.9622424865104192" />
            </geometry>
        </collision>
    </link>
    <joint name="6_7" type="revolute">
       <parent link="6"/>
       <child  link="7"/>
       <origin rpy="0 0 0" xyz="0 -0.06298427426119957 0.9170189691149498" />
     <axis xyz="1 0 0"/>
       <limit effort="0.0" lower="-3.14159" upper="3.14159" velocity="0.0"/>
    </joint>
    <link name="8">
        <inertial>
            <origin xyz="0 -0.3941443845066752 0.401589734639935" rpy="0 0 0"/>
            <mass value="1" />
            <inertia ixx="100" ixy="0" ixz="0" iyy="100" iyz="0" izz="100" />
        </inertial>
        <visual>
            <origin xyz="0 -0.3941443845066752 0.401589734639935" rpy="0 0 0"/>
            <geometry>
                <box size="0.23861592861522019 0.7882887690133504 0.80317946927987" />
            </geometry>
            <material name="Blue">
                <color rgba="0 0 255 1"/>
            </material>
        </visual>
        <collision>
            <origin xyz="0 -0.3941443845066752 0.401589734639935" rpy="0 0 0"/>
            <geometry>
                <box size="0.23861592861522019 0.7882887690133504 0.80317946927987" />
            </geometry>
        </collision>
    </link>
    <joint name="7_8" type="revolute">
       <parent link="7"/>
       <child  link="8"/>
       <origin rpy="0 0 0" xyz="0 -0.9192823534016137 0.9622424865104192" />
     <axis xyz="1 0 0"/>
       <limit effort="0.0" lower="-3.14159" upper="3.14159" velocity="0.0"/>
    </joint>
    <link name="9">
        <inertial>
            <origin xyz="0 -0.2756336230452756 0.3532807049334448" rpy="0 0 0"/>
            <mass value="1" />
            <inertia ixx="100" ixy="0" ixz="0" iyy="100" iyz="0" izz="100" />
        </inertial>
        <visual>
            <origin xyz="0 -0.2756336230452756 0.3532807049334448" rpy="0 0 0"/>
            <geometry>
                <box size="0.10905784593110368 0.5512672460905512 0.7065614098668896" />
            </geometry>
            <material name="Green">
                <color rgba="0 128 0 1"/>
            </material>
        </visual>
        <collision>
            <origin xyz="0 -0.2756336230452756 0.3532807049334448" rpy="0 0 0"/>
            <geometry>
                <box size="0.10905784593110368 0.5512672460905512 0.7065614098668896" />
            </geometry>
        </collision>
    </link>
    <joint name="8_9" type="revolute">
       <parent link="8"/>
       <child  link="9"/>
       <origin rpy="0 0 0" xyz="0 -0.7882887690133504 0.80317946927987" />
     <axis xyz="0 1 0"/>
       <limit effort="0.0" lower="-3.14159" upper="3.14159" velocity="0.0"/>
    </joint>
    <link name="10">
        <inertial>
            <origin xyz="0 -0.4611248654882744 0.10160092623471667" rpy="0 0 0"/>
            <mass value="1" />
            <inertia ixx="100" ixy="0" ixz="0" iyy="100" iyz="0" izz="100" />
        </inertial>
        <visual>
            <origin xyz="0 -0.4611248654882744 0.10160092623471667" rpy="0 0 0"/>
            <geometry>
                <box size="0.33275051276733614 0.9222497309765488 0.20320185246943334" />
            </geometry>
            <material name="Green">
                <color rgba="0 128 0 1"/>
            </material>
        </visual>
        <collision>
            <origin xyz="0 -0.4611248654882744 0.10160092623471667" rpy="0 0 0"/>
            <geometry>
                <box size="0.33275051276733614 0.9222497309765488 0.20320185246943334" />
            </geometry>
        </collision>
    </link>
    <joint name="9_10" type="revolute">
       <parent link="9"/>
       <child  link="10"/>
       <origin rpy="0 0 0" xyz="0 -0.5512672460905512 0.7065614098668896" />
     <axis xyz="1 0 0"/>
       <limit effort="0.0" lower="-3.14159" upper="3.14159" velocity="0.0"/>
    </joint>
</robot>