<robot name = "robot">
    <link name="0">
        <inertial>
            <origin xyz="0 0 3" rpy="0 0 0"/>
            <mass value="1" />
            <inertia ixx="100" ixy="0" ixz="0" iyy="100" iyz="0" izz="100" />
        </inertial>
        <visual>
            <origin xyz="0 0 3" rpy="0 0 0"/>
            <geometry>
                <box size="1.5 1.5 0.8" />
            </geometry>
            <material name="Green">
                <color rgba="0 128 0 1"/>
            </material>
        </visual>
        <collision>
            <origin xyz="0 0 3" rpy="0 0 0"/>
            <geometry>
                <box size="1.5 1.5 0.8" />
            </geometry>
        </collision>
    </link>
    <link name="1">
        <inertial>
            <origin xyz="-0.3992044734764413 0 0" rpy="0 0 0"/>
            <mass value="1" />
            <inertia ixx="100" ixy="0" ixz="0" iyy="100" iyz="0" izz="100" />
        </inertial>
        <visual>
            <origin xyz="-0.3992044734764413 0 0" rpy="0 0 0"/>
            <geometry>
                <box size="0.7984089469528826 0.3035524058261264 0.600367855784567" />
            </geometry>
            <material name="Green">
                <color rgba="0 128 0 1"/>
            </material>
        </visual>
        <collision>
            <origin xyz="-0.3992044734764413 0 0" rpy="0 0 0"/>
            <geometry>
                <box size="0.7984089469528826 0.3035524058261264 0.600367855784567" />
            </geometry>
        </collision>
    </link>
    <joint name="0_1" type="revolute">
       <parent link="0"/>
       <child  link="1"/>
       <origin rpy="0 0 0" xyz="-0.75 0 3" />
     <axis xyz="0 0 1"/>
       <limit effort="0.0" lower="-3.14159" upper="3.14159" velocity="0.0"/>
    </joint>
    <link name="2">
        <inertial>
            <origin xyz="-0.37900843271178614 0 0" rpy="0 0 0"/>
            <mass value="1" />
            <inertia ixx="100" ixy="0" ixz="0" iyy="100" iyz="0" izz="100" />
        </inertial>
        <visual>
            <origin xyz="-0.37900843271178614 0 0" rpy="0 0 0"/>
            <geometry>
                <box size="0.7580168654235723 0.6411189732805798 0.20781484054425414" />
            </geometry>
            <material name="Green">
                <color rgba="0 128 0 1"/>
            </material>
        </visual>
        <collision>
            <origin xyz="-0.37900843271178614 0 0" rpy="0 0 0"/>
            <geometry>
                <box size="0.7580168654235723 0.6411189732805798 0.20781484054425414" />
            </geometry>
        </collision>
    </link>
    <joint name="1_2" type="revolute">
       <parent link="1"/>
       <child  link="2"/>
       <origin rpy="0 0 0" xyz="-0.7984089469528826 0 0" />
     <axis xyz="0 1 1"/>
       <limit effort="0.0" lower="-3.14159" upper="3.14159" velocity="0.0"/>
    </joint>
    <link name="3">
        <inertial>
            <origin xyz="0 0 -0.6941787401627644" rpy="0 0 0"/>
            <mass value="1" />
            <inertia ixx="100" ixy="0" ixz="0" iyy="100" iyz="0" izz="100" />
        </inertial>
        <visual>
            <origin xyz="0 0 -0.6941787401627644" rpy="0 0 0"/>
            <geometry>
                <box size="0.8745264256202052 0.7866865483738805 1.3883574803255287" />
            </geometry>
            <material name="Blue">
                <color rgba="0 0 255 1"/>
            </material>
        </visual>
        <collision>
            <origin xyz="0 0 -0.6941787401627644" rpy="0 0 0"/>
            <geometry>
                <box size="0.8745264256202052 0.7866865483738805 1.3883574803255287" />
            </geometry>
        </collision>
    </link>
    <joint name="2_3" type="revolute">
       <parent link="2"/>
       <child  link="3"/>
       <origin rpy="0 0 0" xyz="-0.37900843271178614 0 -0.10390742027212707" />
     <axis xyz="0 0 1"/>
       <limit effort="0.0" lower="-3.14159" upper="3.14159" velocity="0.0"/>
    </joint>
    <link name="4">
        <inertial>
            <origin xyz="0 0 -0.47030180925377907" rpy="0 0 0"/>
            <mass value="1" />
            <inertia ixx="100" ixy="0" ixz="0" iyy="100" iyz="0" izz="100" />
        </inertial>
        <visual>
            <origin xyz="0 0 -0.47030180925377907" rpy="0 0 0"/>
            <geometry>
                <box size="0.9028279570025224 0.30129771527337224 0.9406036185075581" />
            </geometry>
            <material name="Blue">
                <color rgba="0 0 255 1"/>
            </material>
        </visual>
        <collision>
            <origin xyz="0 0 -0.47030180925377907" rpy="0 0 0"/>
            <geometry>
                <box size="0.9028279570025224 0.30129771527337224 0.9406036185075581" />
            </geometry>
        </collision>
    </link>
    <joint name="3_4" type="revolute">
       <parent link="3"/>
       <child  link="4"/>
       <origin rpy="0 0 0" xyz="0 0 -1.3883574803255287" />
     <axis xyz="0 1 0"/>
       <limit effort="0.0" lower="-3.14159" upper="3.14159" velocity="0.0"/>
    </joint>
    <link name="5">
        <inertial>
            <origin xyz="0 0 -0.1355194505834566" rpy="0 0 0"/>
            <mass value="1" />
            <inertia ixx="100" ixy="0" ixz="0" iyy="100" iyz="0" izz="100" />
        </inertial>
        <visual>
            <origin xyz="0 0 -0.1355194505834566" rpy="0 0 0"/>
            <geometry>
                <box size="0.6699228619354058 0.7362242373340192 0.2710389011669132" />
            </geometry>
            <material name="Blue">
                <color rgba="0 0 255 1"/>
            </material>
        </visual>
        <collision>
            <origin xyz="0 0 -0.1355194505834566" rpy="0 0 0"/>
            <geometry>
                <box size="0.6699228619354058 0.7362242373340192 0.2710389011669132" />
            </geometry>
        </collision>
    </link>
    <joint name="4_5" type="revolute">
       <parent link="4"/>
       <child  link="5"/>
       <origin rpy="0 0 0" xyz="0 0 -0.9406036185075581" />
     <axis xyz="1 1 0"/>
       <limit effort="0.0" lower="-3.14159" upper="3.14159" velocity="0.0"/>
    </joint>
    <link name="6">
        <inertial>
            <origin xyz="0.4772932828981801 0 0" rpy="0 0 0"/>
            <mass value="1" />
            <inertia ixx="100" ixy="0" ixz="0" iyy="100" iyz="0" izz="100" />
        </inertial>
        <visual>
            <origin xyz="0.4772932828981801 0 0" rpy="0 0 0"/>
            <geometry>
                <box size="0.9545865657963603 0.9817907089022866 0.818426637708899" />
            </geometry>
            <material name="Green">
                <color rgba="0 128 0 1"/>
            </material>
        </visual>
        <collision>
            <origin xyz="0.4772932828981801 0 0" rpy="0 0 0"/>
            <geometry>
                <box size="0.9545865657963603 0.9817907089022866 0.818426637708899" />
            </geometry>
        </collision>
    </link>
    <joint name="0_6" type="revolute">
       <parent link="0"/>
       <child  link="6"/>
       <origin rpy="0 0 0" xyz="0.75 0 3" />
     <axis xyz="1 0 1"/>
       <limit effort="0.0" lower="-3.14159" upper="3.14159" velocity="0.0"/>
    </joint>
    <link name="7">
        <inertial>
            <origin xyz="0.42125633303340826 0 0" rpy="0 0 0"/>
            <mass value="1" />
            <inertia ixx="100" ixy="0" ixz="0" iyy="100" iyz="0" izz="100" />
        </inertial>
        <visual>
            <origin xyz="0.42125633303340826 0 0" rpy="0 0 0"/>
            <geometry>
                <box size="0.8425126660668165 0.5954310591919888 0.3265008345099454" />
            </geometry>
            <material name="Green">
                <color rgba="0 128 0 1"/>
            </material>
        </visual>
        <collision>
            <origin xyz="0.42125633303340826 0 0" rpy="0 0 0"/>
            <geometry>
                <box size="0.8425126660668165 0.5954310591919888 0.3265008345099454" />
            </geometry>
        </collision>
    </link>
    <joint name="6_7" type="revolute">
       <parent link="6"/>
       <child  link="7"/>
       <origin rpy="0 0 0" xyz="0.9545865657963603 0 0" />
     <axis xyz="0 1 1"/>
       <limit effort="0.0" lower="-3.14159" upper="3.14159" velocity="0.0"/>
    </joint>
    <link name="8">
        <inertial>
            <origin xyz="0 0 -0.7044085974592674" rpy="0 0 0"/>
            <mass value="1" />
            <inertia ixx="100" ixy="0" ixz="0" iyy="100" iyz="0" izz="100" />
        </inertial>
        <visual>
            <origin xyz="0 0 -0.7044085974592674" rpy="0 0 0"/>
            <geometry>
                <box size="0.3684942290393044 0.7042829250482996 1.4088171949185349" />
            </geometry>
            <material name="Green">
                <color rgba="0 128 0 1"/>
            </material>
        </visual>
        <collision>
            <origin xyz="0 0 -0.7044085974592674" rpy="0 0 0"/>
            <geometry>
                <box size="0.3684942290393044 0.7042829250482996 1.4088171949185349" />
            </geometry>
        </collision>
    </link>
    <joint name="7_8" type="revolute">
       <parent link="7"/>
       <child  link="8"/>
       <origin rpy="0 0 0" xyz="0.42125633303340826 0 -0.1632504172549727" />
     <axis xyz="1 1 1"/>
       <limit effort="0.0" lower="-3.14159" upper="3.14159" velocity="0.0"/>
    </joint>
    <link name="9">
        <inertial>
            <origin xyz="0 0 -0.06938827693802455" rpy="0 0 0"/>
            <mass value="1" />
            <inertia ixx="100" ixy="0" ixz="0" iyy="100" iyz="0" izz="100" />
        </inertial>
        <visual>
            <origin xyz="0 0 -0.06938827693802455" rpy="0 0 0"/>
            <geometry>
                <box size="0.2584635620013096 0.5748349132211742 0.1387765538760491" />
            </geometry>
            <material name="Blue">
                <color rgba="0 0 255 1"/>
            </material>
        </visual>
        <collision>
            <origin xyz="0 0 -0.06938827693802455" rpy="0 0 0"/>
            <geometry>
                <box size="0.2584635620013096 0.5748349132211742 0.1387765538760491" />
            </geometry>
        </collision>
    </link>
    <joint name="8_9" type="revolute">
       <parent link="8"/>
       <child  link="9"/>
       <origin rpy="0 0 0" xyz="0 0 -1.4088171949185349" />
     <axis xyz="1 0 0"/>
       <limit effort="0.0" lower="-3.14159" upper="3.14159" velocity="0.0"/>
    </joint>
    <link name="10">
        <inertial>
            <origin xyz="0 0 -0.5262031256027081" rpy="0 0 0"/>
            <mass value="1" />
            <inertia ixx="100" ixy="0" ixz="0" iyy="100" iyz="0" izz="100" />
        </inertial>
        <visual>
            <origin xyz="0 0 -0.5262031256027081" rpy="0 0 0"/>
            <geometry>
                <box size="0.8552854451398381 0.9710412940019189 1.0524062512054162" />
            </geometry>
            <material name="Blue">
                <color rgba="0 0 255 1"/>
            </material>
        </visual>
        <collision>
            <origin xyz="0 0 -0.5262031256027081" rpy="0 0 0"/>
            <geometry>
                <box size="0.8552854451398381 0.9710412940019189 1.0524062512054162" />
            </geometry>
        </collision>
    </link>
    <joint name="9_10" type="revolute">
       <parent link="9"/>
       <child  link="10"/>
       <origin rpy="0 0 0" xyz="0 0 -0.1387765538760491" />
     <axis xyz="0 0 1"/>
       <limit effort="0.0" lower="-3.14159" upper="3.14159" velocity="0.0"/>
    </joint>
    <link name="11">
        <inertial>
            <origin xyz="0 -0.36523783339507054 0" rpy="0 0 0"/>
            <mass value="1" />
            <inertia ixx="100" ixy="0" ixz="0" iyy="100" iyz="0" izz="100" />
        </inertial>
        <visual>
            <origin xyz="0 -0.36523783339507054 0" rpy="0 0 0"/>
            <geometry>
                <box size="0.13804721962203792 0.7304756667901411 0.3531143222700748" />
            </geometry>
            <material name="Blue">
                <color rgba="0 0 255 1"/>
            </material>
        </visual>
        <collision>
            <origin xyz="0 -0.36523783339507054 0" rpy="0 0 0"/>
            <geometry>
                <box size="0.13804721962203792 0.7304756667901411 0.3531143222700748" />
            </geometry>
        </collision>
    </link>
    <joint name="0_11" type="revolute">
       <parent link="0"/>
       <child  link="11"/>
       <origin rpy="0 0 0" xyz="0 -0.75 3" />
     <axis xyz="0 1 0"/>
       <limit effort="0.0" lower="-3.14159" upper="3.14159" velocity="0.0"/>
    </joint>
    <link name="12">
        <inertial>
            <origin xyz="0 -0.40663780790057696 0" rpy="0 0 0"/>
            <mass value="1" />
            <inertia ixx="100" ixy="0" ixz="0" iyy="100" iyz="0" izz="100" />
        </inertial>
        <visual>
            <origin xyz="0 -0.40663780790057696 0" rpy="0 0 0"/>
            <geometry>
                <box size="0.6972270911862232 0.8132756158011539 0.29869516967654597" />
            </geometry>
            <material name="Blue">
                <color rgba="0 0 255 1"/>
            </material>
        </visual>
        <collision>
            <origin xyz="0 -0.40663780790057696 0" rpy="0 0 0"/>
            <geometry>
                <box size="0.6972270911862232 0.8132756158011539 0.29869516967654597" />
            </geometry>
        </collision>
    </link>
    <joint name="11_12" type="revolute">
       <parent link="11"/>
       <child  link="12"/>
       <origin rpy="0 0 0" xyz="0 -0.7304756667901411 0" />
     <axis xyz="0 0 1"/>
       <limit effort="0.0" lower="-3.14159" upper="3.14159" velocity="0.0"/>
    </joint>
    <link name="13">
        <inertial>
            <origin xyz="0 0 -0.8148226894019804" rpy="0 0 0"/>
            <mass value="1" />
            <inertia ixx="100" ixy="0" ixz="0" iyy="100" iyz="0" izz="100" />
        </inertial>
        <visual>
            <origin xyz="0 0 -0.8148226894019804" rpy="0 0 0"/>
            <geometry>
                <box size="0.6479112827057227 0.67776260249478 1.6296453788039609" />
            </geometry>
            <material name="Blue">
                <color rgba="0 0 255 1"/>
            </material>
        </visual>
        <collision>
            <origin xyz="0 0 -0.8148226894019804" rpy="0 0 0"/>
            <geometry>
                <box size="0.6479112827057227 0.67776260249478 1.6296453788039609" />
            </geometry>
        </collision>
    </link>
    <joint name="12_13" type="revolute">
       <parent link="12"/>
       <child  link="13"/>
       <origin rpy="0 0 0" xyz="0 -0.40663780790057696 -0.14934758483827298" />
     <axis xyz="1 1 0"/>
       <limit effort="0.0" lower="-3.14159" upper="3.14159" velocity="0.0"/>
    </joint>
    <link name="14">
        <inertial>
            <origin xyz="0 0 -0.4352546780373135" rpy="0 0 0"/>
            <mass value="1" />
            <inertia ixx="100" ixy="0" ixz="0" iyy="100" iyz="0" izz="100" />
        </inertial>
        <visual>
            <origin xyz="0 0 -0.4352546780373135" rpy="0 0 0"/>
            <geometry>
                <box size="0.4483916994658277 0.23448401909197225 0.870509356074627" />
            </geometry>
            <material name="Green">
                <color rgba="0 128 0 1"/>
            </material>
        </visual>
        <collision>
            <origin xyz="0 0 -0.4352546780373135" rpy="0 0 0"/>
            <geometry>
                <box size="0.4483916994658277 0.23448401909197225 0.870509356074627" />
            </geometry>
        </collision>
    </link>
    <joint name="13_14" type="revolute">
       <parent link="13"/>
       <child  link="14"/>
       <origin rpy="0 0 0" xyz="0 0 -1.6296453788039609" />
     <axis xyz="1 0 0"/>
       <limit effort="0.0" lower="-3.14159" upper="3.14159" velocity="0.0"/>
    </joint>
    <link name="15">
        <inertial>
            <origin xyz="0 0 -0.049922632560706115" rpy="0 0 0"/>
            <mass value="1" />
            <inertia ixx="100" ixy="0" ixz="0" iyy="100" iyz="0" izz="100" />
        </inertial>
        <visual>
            <origin xyz="0 0 -0.049922632560706115" rpy="0 0 0"/>
            <geometry>
                <box size="0.3519941127471494 0.7296567321027795 0.09984526512141223" />
            </geometry>
            <material name="Blue">
                <color rgba="0 0 255 1"/>
            </material>
        </visual>
        <collision>
            <origin xyz="0 0 -0.049922632560706115" rpy="0 0 0"/>
            <geometry>
                <box size="0.3519941127471494 0.7296567321027795 0.09984526512141223" />
            </geometry>
        </collision>
    </link>
    <joint name="14_15" type="revolute">
       <parent link="14"/>
       <child  link="15"/>
       <origin rpy="0 0 0" xyz="0 0 -0.870509356074627" />
     <axis xyz="0 0 1"/>
       <limit effort="0.0" lower="-3.14159" upper="3.14159" velocity="0.0"/>
    </joint>
    <link name="16">
        <inertial>
            <origin xyz="0 0.050293331406870645 0" rpy="0 0 0"/>
            <mass value="1" />
            <inertia ixx="100" ixy="0" ixz="0" iyy="100" iyz="0" izz="100" />
        </inertial>
        <visual>
            <origin xyz="0 0.050293331406870645 0" rpy="0 0 0"/>
            <geometry>
                <box size="0.4513499598752472 0.10058666281374129 0.6702779020811929" />
            </geometry>
            <material name="Blue">
                <color rgba="0 0 255 1"/>
            </material>
        </visual>
        <collision>
            <origin xyz="0 0.050293331406870645 0" rpy="0 0 0"/>
            <geometry>
                <box size="0.4513499598752472 0.10058666281374129 0.6702779020811929" />
            </geometry>
        </collision>
    </link>
    <joint name="0_16" type="revolute">
       <parent link="0"/>
       <child  link="16"/>
       <origin rpy="0 0 0" xyz="0 0.75 3" />
     <axis xyz="1 0 0"/>
       <limit effort="0.0" lower="-3.14159" upper="3.14159" velocity="0.0"/>
    </joint>
    <link name="17">
        <inertial>
            <origin xyz="0 0.1326676659093579 0" rpy="0 0 0"/>
            <mass value="1" />
            <inertia ixx="100" ixy="0" ixz="0" iyy="100" iyz="0" izz="100" />
        </inertial>
        <visual>
            <origin xyz="0 0.1326676659093579 0" rpy="0 0 0"/>
            <geometry>
                <box size="0.0368257915174065 0.2653353318187158 0.09550472238059149" />
            </geometry>
            <material name="Green">
                <color rgba="0 128 0 1"/>
            </material>
        </visual>
        <collision>
            <origin xyz="0 0.1326676659093579 0" rpy="0 0 0"/>
            <geometry>
                <box size="0.0368257915174065 0.2653353318187158 0.09550472238059149" />
            </geometry>
        </collision>
    </link>
    <joint name="16_17" type="revolute">
       <parent link="16"/>
       <child  link="17"/>
       <origin rpy="0 0 0" xyz="0 0.10058666281374129 0" />
     <axis xyz="0 1 1"/>
       <limit effort="0.0" lower="-3.14159" upper="3.14159" velocity="0.0"/>
    </joint>
    <link name="18">
        <inertial>
            <origin xyz="0 0 -1.2107064304567856" rpy="0 0 0"/>
            <mass value="1" />
            <inertia ixx="100" ixy="0" ixz="0" iyy="100" iyz="0" izz="100" />
        </inertial>
        <visual>
            <origin xyz="0 0 -1.2107064304567856" rpy="0 0 0"/>
            <geometry>
                <box size="0.7706165868754989 0.05446176366502942 2.421412860913571" />
            </geometry>
            <material name="Green">
                <color rgba="0 128 0 1"/>
            </material>
        </visual>
        <collision>
            <origin xyz="0 0 -1.2107064304567856" rpy="0 0 0"/>
            <geometry>
                <box size="0.7706165868754989 0.05446176366502942 2.421412860913571" />
            </geometry>
        </collision>
    </link>
    <joint name="17_18" type="revolute">
       <parent link="17"/>
       <child  link="18"/>
       <origin rpy="0 0 0" xyz="0 0.1326676659093579 -0.047752361190295745" />
     <axis xyz="1 1 0"/>
       <limit effort="0.0" lower="-3.14159" upper="3.14159" velocity="0.0"/>
    </joint>
    <link name="19">
        <inertial>
            <origin xyz="0 0 -0.04011503186185536" rpy="0 0 0"/>
            <mass value="1" />
            <inertia ixx="100" ixy="0" ixz="0" iyy="100" iyz="0" izz="100" />
        </inertial>
        <visual>
            <origin xyz="0 0 -0.04011503186185536" rpy="0 0 0"/>
            <geometry>
                <box size="0.04091483262039686 0.5747937791978049 0.08023006372371072" />
            </geometry>
            <material name="Blue">
                <color rgba="0 0 255 1"/>
            </material>
        </visual>
        <collision>
            <origin xyz="0 0 -0.04011503186185536" rpy="0 0 0"/>
            <geometry>
                <box size="0.04091483262039686 0.5747937791978049 0.08023006372371072" />
            </geometry>
        </collision>
    </link>
    <joint name="18_19" type="revolute">
       <parent link="18"/>
       <child  link="19"/>
       <origin rpy="0 0 0" xyz="0 0 -2.421412860913571" />
     <axis xyz="1 0 1"/>
       <limit effort="0.0" lower="-3.14159" upper="3.14159" velocity="0.0"/>
    </joint>
    <link name="20">
        <inertial>
            <origin xyz="0 0 -0.049178537681359075" rpy="0 0 0"/>
            <mass value="1" />
            <inertia ixx="100" ixy="0" ixz="0" iyy="100" iyz="0" izz="100" />
        </inertial>
        <visual>
            <origin xyz="0 0 -0.049178537681359075" rpy="0 0 0"/>
            <geometry>
                <box size="0.05146381499993691 0.7090936690831816 0.09835707536271815" />
            </geometry>
            <material name="Green">
                <color rgba="0 128 0 1"/>
            </material>
        </visual>
        <collision>
            <origin xyz="0 0 -0.049178537681359075" rpy="0 0 0"/>
            <geometry>
                <box size="0.05146381499993691 0.7090936690831816 0.09835707536271815" />
            </geometry>
        </collision>
    </link>
    <joint name="19_20" type="revolute">
       <parent link="19"/>
       <child  link="20"/>
       <origin rpy="0 0 0" xyz="0 0 -0.08023006372371072" />
     <axis xyz="1 0 1"/>
       <limit effort="0.0" lower="-3.14159" upper="3.14159" velocity="0.0"/>
    </joint>
</robot>