<robot name = "robot">
    <link name="0">
        <inertial>
            <origin xyz="0 0 1" rpy="0 0 0"/>
            <mass value="1" />
            <inertia ixx="100" ixy="0" ixz="0" iyy="100" iyz="0" izz="100" />
        </inertial>
        <visual>
            <origin xyz="0 0 1" rpy="0 0 0"/>
            <geometry>
                <box size="1.5 1.5 0.8" />
            </geometry>
            <material name="Green">
                <color rgba="0 128 0 1"/>
            </material>
        </visual>
        <collision>
            <origin xyz="0 0 1" rpy="0 0 0"/>
            <geometry>
                <box size="1.5 1.5 0.8" />
            </geometry>
        </collision>
    </link>
    <link name="1">
        <inertial>
            <origin xyz="-0.29399649102525516 0 0" rpy="0 0 0"/>
            <mass value="1" />
            <inertia ixx="100" ixy="0" ixz="0" iyy="100" iyz="0" izz="100" />
        </inertial>
        <visual>
            <origin xyz="-0.29399649102525516 0 0" rpy="0 0 0"/>
            <geometry>
                <box size="0.5879929820505103 0.5939749425263283 0.47139809099183194" />
            </geometry>
            <material name="Green">
                <color rgba="0 128 0 1"/>
            </material>
        </visual>
        <collision>
            <origin xyz="-0.29399649102525516 0 0" rpy="0 0 0"/>
            <geometry>
                <box size="0.5879929820505103 0.5939749425263283 0.47139809099183194" />
            </geometry>
        </collision>
    </link>
    <joint name="0_1" type="revolute">
       <parent link="0"/>
       <child  link="1"/>
       <origin rpy="0 0 0" xyz="-0.75 0 1" />
     <axis xyz="0 1 0"/>
       <limit effort="0.0" lower="-3.14159" upper="3.14159" velocity="0.0"/>
    </joint>
    <link name="2">
        <inertial>
            <origin xyz="-0.09280300512142581 0 0" rpy="0 0 0"/>
            <mass value="1" />
            <inertia ixx="100" ixy="0" ixz="0" iyy="100" iyz="0" izz="100" />
        </inertial>
        <visual>
            <origin xyz="-0.09280300512142581 0 0" rpy="0 0 0"/>
            <geometry>
                <box size="0.18560601024285162 0.6208427969068857 0.18716100261058233" />
            </geometry>
            <material name="Green">
                <color rgba="0 128 0 1"/>
            </material>
        </visual>
        <collision>
            <origin xyz="-0.09280300512142581 0 0" rpy="0 0 0"/>
            <geometry>
                <box size="0.18560601024285162 0.6208427969068857 0.18716100261058233" />
            </geometry>
        </collision>
    </link>
    <joint name="1_2" type="revolute">
       <parent link="1"/>
       <child  link="2"/>
       <origin rpy="0 0 0" xyz="-0.5879929820505103 0 0" />
     <axis xyz="1 0 0"/>
       <limit effort="0.0" lower="-3.14159" upper="3.14159" velocity="0.0"/>
    </joint>
    <link name="3">
        <inertial>
            <origin xyz="-0.39470306322166754 0 0" rpy="0 0 0"/>
            <mass value="1" />
            <inertia ixx="100" ixy="0" ixz="0" iyy="100" iyz="0" izz="100" />
        </inertial>
        <visual>
            <origin xyz="-0.39470306322166754 0 0" rpy="0 0 0"/>
            <geometry>
                <box size="0.7894061264433351 0.5240645666166543 0.2537852306520493" />
            </geometry>
            <material name="Green">
                <color rgba="0 128 0 1"/>
            </material>
        </visual>
        <collision>
            <origin xyz="-0.39470306322166754 0 0" rpy="0 0 0"/>
            <geometry>
                <box size="0.7894061264433351 0.5240645666166543 0.2537852306520493" />
            </geometry>
        </collision>
    </link>
    <joint name="2_3" type="revolute">
       <parent link="2"/>
       <child  link="3"/>
       <origin rpy="0 0 0" xyz="-0.18560601024285162 0 0" />
     <axis xyz="1 0 0"/>
       <limit effort="0.0" lower="-3.14159" upper="3.14159" velocity="0.0"/>
    </joint>
    <link name="4">
        <inertial>
            <origin xyz="-0.4197873632052574 0 0" rpy="0 0 0"/>
            <mass value="1" />
            <inertia ixx="100" ixy="0" ixz="0" iyy="100" iyz="0" izz="100" />
        </inertial>
        <visual>
            <origin xyz="-0.4197873632052574 0 0" rpy="0 0 0"/>
            <geometry>
                <box size="0.8395747264105148 0.6959006588364723 0.9514251884971998" />
            </geometry>
            <material name="Green">
                <color rgba="0 128 0 1"/>
            </material>
        </visual>
        <collision>
            <origin xyz="-0.4197873632052574 0 0" rpy="0 0 0"/>
            <geometry>
                <box size="0.8395747264105148 0.6959006588364723 0.9514251884971998" />
            </geometry>
        </collision>
    </link>
    <joint name="3_4" type="revolute">
       <parent link="3"/>
       <child  link="4"/>
       <origin rpy="0 0 0" xyz="-0.7894061264433351 0 0" />
     <axis xyz="1 0 1"/>
       <limit effort="0.0" lower="-3.14159" upper="3.14159" velocity="0.0"/>
    </joint>
    <link name="5">
        <inertial>
            <origin xyz="-0.11164450540449472 0 0" rpy="0 0 0"/>
            <mass value="1" />
            <inertia ixx="100" ixy="0" ixz="0" iyy="100" iyz="0" izz="100" />
        </inertial>
        <visual>
            <origin xyz="-0.11164450540449472 0 0" rpy="0 0 0"/>
            <geometry>
                <box size="0.22328901080898944 0.17602023365515163 0.9301393218887173" />
            </geometry>
            <material name="Blue">
                <color rgba="0 0 255 1"/>
            </material>
        </visual>
        <collision>
            <origin xyz="-0.11164450540449472 0 0" rpy="0 0 0"/>
            <geometry>
                <box size="0.22328901080898944 0.17602023365515163 0.9301393218887173" />
            </geometry>
        </collision>
    </link>
    <joint name="4_5" type="revolute">
       <parent link="4"/>
       <child  link="5"/>
       <origin rpy="0 0 0" xyz="-0.8395747264105148 0 0" />
     <axis xyz="1 1 0"/>
       <limit effort="0.0" lower="-3.14159" upper="3.14159" velocity="0.0"/>
    </joint>
    <link name="6">
        <inertial>
            <origin xyz="0 0 -0.2858047628041017" rpy="0 0 0"/>
            <mass value="1" />
            <inertia ixx="100" ixy="0" ixz="0" iyy="100" iyz="0" izz="100" />
        </inertial>
        <visual>
            <origin xyz="0 0 -0.2858047628041017" rpy="0 0 0"/>
            <geometry>
                <box size="0.8652229242134771 0.05718771118357879 0.5716095256082034" />
            </geometry>
            <material name="Blue">
                <color rgba="0 0 255 1"/>
            </material>
        </visual>
        <collision>
            <origin xyz="0 0 -0.2858047628041017" rpy="0 0 0"/>
            <geometry>
                <box size="0.8652229242134771 0.05718771118357879 0.5716095256082034" />
            </geometry>
        </collision>
    </link>
    <joint name="5_6" type="revolute">
       <parent link="5"/>
       <child  link="6"/>
       <origin rpy="0 0 0" xyz="-0.11164450540449472 0 -0.46506966094435864" />
     <axis xyz="0 1 0"/>
       <limit effort="0.0" lower="-3.14159" upper="3.14159" velocity="0.0"/>
    </joint>
    <link name="7">
        <inertial>
            <origin xyz="0 0 -0.013647791451591" rpy="0 0 0"/>
            <mass value="1" />
            <inertia ixx="100" ixy="0" ixz="0" iyy="100" iyz="0" izz="100" />
        </inertial>
        <visual>
            <origin xyz="0 0 -0.013647791451591" rpy="0 0 0"/>
            <geometry>
                <box size="0.5077447198679458 0.3608414903408389 0.027295582903182" />
            </geometry>
            <material name="Green">
                <color rgba="0 128 0 1"/>
            </material>
        </visual>
        <collision>
            <origin xyz="0 0 -0.013647791451591" rpy="0 0 0"/>
            <geometry>
                <box size="0.5077447198679458 0.3608414903408389 0.027295582903182" />
            </geometry>
        </collision>
    </link>
    <joint name="6_7" type="revolute">
       <parent link="6"/>
       <child  link="7"/>
       <origin rpy="0 0 0" xyz="0 0 -0.5716095256082034" />
     <axis xyz="0 1 0"/>
       <limit effort="0.0" lower="-3.14159" upper="3.14159" velocity="0.0"/>
    </joint>
    <link name="8">
        <inertial>
            <origin xyz="0 0 -0.0005474457443072692" rpy="0 0 0"/>
            <mass value="1" />
            <inertia ixx="100" ixy="0" ixz="0" iyy="100" iyz="0" izz="100" />
        </inertial>
        <visual>
            <origin xyz="0 0 -0.0005474457443072692" rpy="0 0 0"/>
            <geometry>
                <box size="0.3010026671333823 0.47023292240888714 0.0010948914886145383" />
            </geometry>
            <material name="Blue">
                <color rgba="0 0 255 1"/>
            </material>
        </visual>
        <collision>
            <origin xyz="0 0 -0.0005474457443072692" rpy="0 0 0"/>
            <geometry>
                <box size="0.3010026671333823 0.47023292240888714 0.0010948914886145383" />
            </geometry>
        </collision>
    </link>
    <joint name="7_8" type="revolute">
       <parent link="7"/>
       <child  link="8"/>
       <origin rpy="0 0 0" xyz="0 0 -0.027295582903182" />
     <axis xyz="1 1 1"/>
       <limit effort="0.0" lower="-3.14159" upper="3.14159" velocity="0.0"/>
    </joint>
    <link name="9">
        <inertial>
            <origin xyz="0.22831057686582695 0 0" rpy="0 0 0"/>
            <mass value="1" />
            <inertia ixx="100" ixy="0" ixz="0" iyy="100" iyz="0" izz="100" />
        </inertial>
        <visual>
            <origin xyz="0.22831057686582695 0 0" rpy="0 0 0"/>
            <geometry>
                <box size="0.4566211537316539 0.7449509441184894 0.20898563414585103" />
            </geometry>
            <material name="Green">
                <color rgba="0 128 0 1"/>
            </material>
        </visual>
        <collision>
            <origin xyz="0.22831057686582695 0 0" rpy="0 0 0"/>
            <geometry>
                <box size="0.4566211537316539 0.7449509441184894 0.20898563414585103" />
            </geometry>
        </collision>
    </link>
    <joint name="0_9" type="revolute">
       <parent link="0"/>
       <child  link="9"/>
       <origin rpy="0 0 0" xyz="0.75 0 1" />
     <axis xyz="1 0 1"/>
       <limit effort="0.0" lower="-3.14159" upper="3.14159" velocity="0.0"/>
    </joint>
    <link name="10">
        <inertial>
            <origin xyz="0.0986612829286947 0 0" rpy="0 0 0"/>
            <mass value="1" />
            <inertia ixx="100" ixy="0" ixz="0" iyy="100" iyz="0" izz="100" />
        </inertial>
        <visual>
            <origin xyz="0.0986612829286947 0 0" rpy="0 0 0"/>
            <geometry>
                <box size="0.1973225658573894 0.19299591644160863 0.16524222400473654" />
            </geometry>
            <material name="Green">
                <color rgba="0 128 0 1"/>
            </material>
        </visual>
        <collision>
            <origin xyz="0.0986612829286947 0 0" rpy="0 0 0"/>
            <geometry>
                <box size="0.1973225658573894 0.19299591644160863 0.16524222400473654" />
            </geometry>
        </collision>
    </link>
    <joint name="9_10" type="revolute">
       <parent link="9"/>
       <child  link="10"/>
       <origin rpy="0 0 0" xyz="0.4566211537316539 0 0" />
     <axis xyz="1 1 1"/>
       <limit effort="0.0" lower="-3.14159" upper="3.14159" velocity="0.0"/>
    </joint>
    <link name="11">
        <inertial>
            <origin xyz="0.0036392247922523158 0 0" rpy="0 0 0"/>
            <mass value="1" />
            <inertia ixx="100" ixy="0" ixz="0" iyy="100" iyz="0" izz="100" />
        </inertial>
        <visual>
            <origin xyz="0.0036392247922523158 0 0" rpy="0 0 0"/>
            <geometry>
                <box size="0.0072784495845046315 0.2864735698680727 0.7672980710831306" />
            </geometry>
            <material name="Blue">
                <color rgba="0 0 255 1"/>
            </material>
        </visual>
        <collision>
            <origin xyz="0.0036392247922523158 0 0" rpy="0 0 0"/>
            <geometry>
                <box size="0.0072784495845046315 0.2864735698680727 0.7672980710831306" />
            </geometry>
        </collision>
    </link>
    <joint name="10_11" type="revolute">
       <parent link="10"/>
       <child  link="11"/>
       <origin rpy="0 0 0" xyz="0.1973225658573894 0 0" />
     <axis xyz="1 1 1"/>
       <limit effort="0.0" lower="-3.14159" upper="3.14159" velocity="0.0"/>
    </joint>
    <link name="12">
        <inertial>
            <origin xyz="0.163463074534067 0 0" rpy="0 0 0"/>
            <mass value="1" />
            <inertia ixx="100" ixy="0" ixz="0" iyy="100" iyz="0" izz="100" />
        </inertial>
        <visual>
            <origin xyz="0.163463074534067 0 0" rpy="0 0 0"/>
            <geometry>
                <box size="0.326926149068134 0.7025187619693536 0.10930811285522934" />
            </geometry>
            <material name="Green">
                <color rgba="0 128 0 1"/>
            </material>
        </visual>
        <collision>
            <origin xyz="0.163463074534067 0 0" rpy="0 0 0"/>
            <geometry>
                <box size="0.326926149068134 0.7025187619693536 0.10930811285522934" />
            </geometry>
        </collision>
    </link>
    <joint name="11_12" type="revolute">
       <parent link="11"/>
       <child  link="12"/>
       <origin rpy="0 0 0" xyz="0.0072784495845046315 0 0" />
     <axis xyz="0 1 0"/>
       <limit effort="0.0" lower="-3.14159" upper="3.14159" velocity="0.0"/>
    </joint>
    <link name="13">
        <inertial>
            <origin xyz="0.04255217642265641 0 0" rpy="0 0 0"/>
            <mass value="1" />
            <inertia ixx="100" ixy="0" ixz="0" iyy="100" iyz="0" izz="100" />
        </inertial>
        <visual>
            <origin xyz="0.04255217642265641 0 0" rpy="0 0 0"/>
            <geometry>
                <box size="0.08510435284531281 0.11851442833501447 0.28563456521980646" />
            </geometry>
            <material name="Blue">
                <color rgba="0 0 255 1"/>
            </material>
        </visual>
        <collision>
            <origin xyz="0.04255217642265641 0 0" rpy="0 0 0"/>
            <geometry>
                <box size="0.08510435284531281 0.11851442833501447 0.28563456521980646" />
            </geometry>
        </collision>
    </link>
    <joint name="12_13" type="revolute">
       <parent link="12"/>
       <child  link="13"/>
       <origin rpy="0 0 0" xyz="0.326926149068134 0 0" />
     <axis xyz="1 0 0"/>
       <limit effort="0.0" lower="-3.14159" upper="3.14159" velocity="0.0"/>
    </joint>
    <link name="14">
        <inertial>
            <origin xyz="0 0 -0.2125949563270759" rpy="0 0 0"/>
            <mass value="1" />
            <inertia ixx="100" ixy="0" ixz="0" iyy="100" iyz="0" izz="100" />
        </inertial>
        <visual>
            <origin xyz="0 0 -0.2125949563270759" rpy="0 0 0"/>
            <geometry>
                <box size="0.7321955600621 0.17161704755403084 0.4251899126541518" />
            </geometry>
            <material name="Green">
                <color rgba="0 128 0 1"/>
            </material>
        </visual>
        <collision>
            <origin xyz="0 0 -0.2125949563270759" rpy="0 0 0"/>
            <geometry>
                <box size="0.7321955600621 0.17161704755403084 0.4251899126541518" />
            </geometry>
        </collision>
    </link>
    <joint name="13_14" type="revolute">
       <parent link="13"/>
       <child  link="14"/>
       <origin rpy="0 0 0" xyz="0.04255217642265641 0 -0.14281728260990323" />
     <axis xyz="1 0 1"/>
       <limit effort="0.0" lower="-3.14159" upper="3.14159" velocity="0.0"/>
    </joint>
    <link name="15">
        <inertial>
            <origin xyz="0 0 -0.08319671208164589" rpy="0 0 0"/>
            <mass value="1" />
            <inertia ixx="100" ixy="0" ixz="0" iyy="100" iyz="0" izz="100" />
        </inertial>
        <visual>
            <origin xyz="0 0 -0.08319671208164589" rpy="0 0 0"/>
            <geometry>
                <box size="0.3491160754132543 0.5407869934700272 0.16639342416329178" />
            </geometry>
            <material name="Green">
                <color rgba="0 128 0 1"/>
            </material>
        </visual>
        <collision>
            <origin xyz="0 0 -0.08319671208164589" rpy="0 0 0"/>
            <geometry>
                <box size="0.3491160754132543 0.5407869934700272 0.16639342416329178" />
            </geometry>
        </collision>
    </link>
    <joint name="14_15" type="revolute">
       <parent link="14"/>
       <child  link="15"/>
       <origin rpy="0 0 0" xyz="0 0 -0.4251899126541518" />
     <axis xyz="0 0 1"/>
       <limit effort="0.0" lower="-3.14159" upper="3.14159" velocity="0.0"/>
    </joint>
    <link name="16">
        <inertial>
            <origin xyz="0 0 -0.004208331591278203" rpy="0 0 0"/>
            <mass value="1" />
            <inertia ixx="100" ixy="0" ixz="0" iyy="100" iyz="0" izz="100" />
        </inertial>
        <visual>
            <origin xyz="0 0 -0.004208331591278203" rpy="0 0 0"/>
            <geometry>
                <box size="0.45476263879884826 0.16611238676878115 0.008416663182556405" />
            </geometry>
            <material name="Blue">
                <color rgba="0 0 255 1"/>
            </material>
        </visual>
        <collision>
            <origin xyz="0 0 -0.004208331591278203" rpy="0 0 0"/>
            <geometry>
                <box size="0.45476263879884826 0.16611238676878115 0.008416663182556405" />
            </geometry>
        </collision>
    </link>
    <joint name="15_16" type="revolute">
       <parent link="15"/>
       <child  link="16"/>
       <origin rpy="0 0 0" xyz="0 0 -0.16639342416329178" />
     <axis xyz="0 0 1"/>
       <limit effort="0.0" lower="-3.14159" upper="3.14159" velocity="0.0"/>
    </joint>
    <link name="17">
        <inertial>
            <origin xyz="0 -0.09859657440869496 0" rpy="0 0 0"/>
            <mass value="1" />
            <inertia ixx="100" ixy="0" ixz="0" iyy="100" iyz="0" izz="100" />
        </inertial>
        <visual>
            <origin xyz="0 -0.09859657440869496 0" rpy="0 0 0"/>
            <geometry>
                <box size="0.8884477153319067 0.19719314881738992 0.8953713314667475" />
            </geometry>
            <material name="Green">
                <color rgba="0 128 0 1"/>
            </material>
        </visual>
        <collision>
            <origin xyz="0 -0.09859657440869496 0" rpy="0 0 0"/>
            <geometry>
                <box size="0.8884477153319067 0.19719314881738992 0.8953713314667475" />
            </geometry>
        </collision>
    </link>
    <joint name="0_17" type="revolute">
       <parent link="0"/>
       <child  link="17"/>
       <origin rpy="0 0 0" xyz="0 -0.75 1" />
     <axis xyz="1 0 0"/>
       <limit effort="0.0" lower="-3.14159" upper="3.14159" velocity="0.0"/>
    </joint>
    <link name="18">
        <inertial>
            <origin xyz="0 -0.07283527918861094 0" rpy="0 0 0"/>
            <mass value="1" />
            <inertia ixx="100" ixy="0" ixz="0" iyy="100" iyz="0" izz="100" />
        </inertial>
        <visual>
            <origin xyz="0 -0.07283527918861094 0" rpy="0 0 0"/>
            <geometry>
                <box size="0.4591046149066601 0.14567055837722187 0.639748905510407" />
            </geometry>
            <material name="Green">
                <color rgba="0 128 0 1"/>
            </material>
        </visual>
        <collision>
            <origin xyz="0 -0.07283527918861094 0" rpy="0 0 0"/>
            <geometry>
                <box size="0.4591046149066601 0.14567055837722187 0.639748905510407" />
            </geometry>
        </collision>
    </link>
    <joint name="17_18" type="revolute">
       <parent link="17"/>
       <child  link="18"/>
       <origin rpy="0 0 0" xyz="0 -0.19719314881738992 0" />
     <axis xyz="0 1 1"/>
       <limit effort="0.0" lower="-3.14159" upper="3.14159" velocity="0.0"/>
    </joint>
    <link name="19">
        <inertial>
            <origin xyz="0 -0.2610627098579157 0" rpy="0 0 0"/>
            <mass value="1" />
            <inertia ixx="100" ixy="0" ixz="0" iyy="100" iyz="0" izz="100" />
        </inertial>
        <visual>
            <origin xyz="0 -0.2610627098579157 0" rpy="0 0 0"/>
            <geometry>
                <box size="0.42235456332576693 0.5221254197158314 0.8254932873040691" />
            </geometry>
            <material name="Blue">
                <color rgba="0 0 255 1"/>
            </material>
        </visual>
        <collision>
            <origin xyz="0 -0.2610627098579157 0" rpy="0 0 0"/>
            <geometry>
                <box size="0.42235456332576693 0.5221254197158314 0.8254932873040691" />
            </geometry>
        </collision>
    </link>
    <joint name="18_19" type="revolute">
       <parent link="18"/>
       <child  link="19"/>
       <origin rpy="0 0 0" xyz="0 -0.14567055837722187 0" />
     <axis xyz="0 1 0"/>
       <limit effort="0.0" lower="-3.14159" upper="3.14159" velocity="0.0"/>
    </joint>
    <link name="20">
        <inertial>
            <origin xyz="0 -0.1739773238294775 0" rpy="0 0 0"/>
            <mass value="1" />
            <inertia ixx="100" ixy="0" ixz="0" iyy="100" iyz="0" izz="100" />
        </inertial>
        <visual>
            <origin xyz="0 -0.1739773238294775 0" rpy="0 0 0"/>
            <geometry>
                <box size="0.37131207243319364 0.347954647658955 0.52857561894554" />
            </geometry>
            <material name="Green">
                <color rgba="0 128 0 1"/>
            </material>
        </visual>
        <collision>
            <origin xyz="0 -0.1739773238294775 0" rpy="0 0 0"/>
            <geometry>
                <box size="0.37131207243319364 0.347954647658955 0.52857561894554" />
            </geometry>
        </collision>
    </link>
    <joint name="19_20" type="revolute">
       <parent link="19"/>
       <child  link="20"/>
       <origin rpy="0 0 0" xyz="0 -0.5221254197158314 0" />
     <axis xyz="1 0 0"/>
       <limit effort="0.0" lower="-3.14159" upper="3.14159" velocity="0.0"/>
    </joint>
    <link name="21">
        <inertial>
            <origin xyz="0 -0.46320935086691456 0" rpy="0 0 0"/>
            <mass value="1" />
            <inertia ixx="100" ixy="0" ixz="0" iyy="100" iyz="0" izz="100" />
        </inertial>
        <visual>
            <origin xyz="0 -0.46320935086691456 0" rpy="0 0 0"/>
            <geometry>
                <box size="0.3014570230702581 0.9264187017338291 0.2041911779782729" />
            </geometry>
            <material name="Blue">
                <color rgba="0 0 255 1"/>
            </material>
        </visual>
        <collision>
            <origin xyz="0 -0.46320935086691456 0" rpy="0 0 0"/>
            <geometry>
                <box size="0.3014570230702581 0.9264187017338291 0.2041911779782729" />
            </geometry>
        </collision>
    </link>
    <joint name="20_21" type="revolute">
       <parent link="20"/>
       <child  link="21"/>
       <origin rpy="0 0 0" xyz="0 -0.347954647658955 0" />
     <axis xyz="1 0 0"/>
       <limit effort="0.0" lower="-3.14159" upper="3.14159" velocity="0.0"/>
    </joint>
    <link name="22">
        <inertial>
            <origin xyz="0 0 -0.1446085814090704" rpy="0 0 0"/>
            <mass value="1" />
            <inertia ixx="100" ixy="0" ixz="0" iyy="100" iyz="0" izz="100" />
        </inertial>
        <visual>
            <origin xyz="0 0 -0.1446085814090704" rpy="0 0 0"/>
            <geometry>
                <box size="0.7094501229663261 0.9564659035439959 0.2892171628181408" />
            </geometry>
            <material name="Blue">
                <color rgba="0 0 255 1"/>
            </material>
        </visual>
        <collision>
            <origin xyz="0 0 -0.1446085814090704" rpy="0 0 0"/>
            <geometry>
                <box size="0.7094501229663261 0.9564659035439959 0.2892171628181408" />
            </geometry>
        </collision>
    </link>
    <joint name="21_22" type="revolute">
       <parent link="21"/>
       <child  link="22"/>
       <origin rpy="0 0 0" xyz="0 -0.46320935086691456 -0.10209558898913645" />
     <axis xyz="1 0 0"/>
       <limit effort="0.0" lower="-3.14159" upper="3.14159" velocity="0.0"/>
    </joint>
    <link name="23">
        <inertial>
            <origin xyz="0 0 -0.030532310363991975" rpy="0 0 0"/>
            <mass value="1" />
            <inertia ixx="100" ixy="0" ixz="0" iyy="100" iyz="0" izz="100" />
        </inertial>
        <visual>
            <origin xyz="0 0 -0.030532310363991975" rpy="0 0 0"/>
            <geometry>
                <box size="0.7988696627888571 0.7375828740338709 0.06106462072798395" />
            </geometry>
            <material name="Green">
                <color rgba="0 128 0 1"/>
            </material>
        </visual>
        <collision>
            <origin xyz="0 0 -0.030532310363991975" rpy="0 0 0"/>
            <geometry>
                <box size="0.7988696627888571 0.7375828740338709 0.06106462072798395" />
            </geometry>
        </collision>
    </link>
    <joint name="22_23" type="revolute">
       <parent link="22"/>
       <child  link="23"/>
       <origin rpy="0 0 0" xyz="0 0 -0.2892171628181408" />
     <axis xyz="0 1 0"/>
       <limit effort="0.0" lower="-3.14159" upper="3.14159" velocity="0.0"/>
    </joint>
    <link name="24">
        <inertial>
            <origin xyz="0 0 -0.1248591082269376" rpy="0 0 0"/>
            <mass value="1" />
            <inertia ixx="100" ixy="0" ixz="0" iyy="100" iyz="0" izz="100" />
        </inertial>
        <visual>
            <origin xyz="0 0 -0.1248591082269376" rpy="0 0 0"/>
            <geometry>
                <box size="0.2494916682811662 0.12617228147049842 0.2497182164538752" />
            </geometry>
            <material name="Blue">
                <color rgba="0 0 255 1"/>
            </material>
        </visual>
        <collision>
            <origin xyz="0 0 -0.1248591082269376" rpy="0 0 0"/>
            <geometry>
                <box size="0.2494916682811662 0.12617228147049842 0.2497182164538752" />
            </geometry>
        </collision>
    </link>
    <joint name="23_24" type="revolute">
       <parent link="23"/>
       <child  link="24"/>
       <origin rpy="0 0 0" xyz="0 0 -0.06106462072798395" />
     <axis xyz="0 1 0"/>
       <limit effort="0.0" lower="-3.14159" upper="3.14159" velocity="0.0"/>
    </joint>
    <link name="25">
        <inertial>
            <origin xyz="0 0.4790026574965302 0" rpy="0 0 0"/>
            <mass value="1" />
            <inertia ixx="100" ixy="0" ixz="0" iyy="100" iyz="0" izz="100" />
        </inertial>
        <visual>
            <origin xyz="0 0.4790026574965302 0" rpy="0 0 0"/>
            <geometry>
                <box size="0.9593326015542265 0.9580053149930604 0.7995717159139747" />
            </geometry>
            <material name="Blue">
                <color rgba="0 0 255 1"/>
            </material>
        </visual>
        <collision>
            <origin xyz="0 0.4790026574965302 0" rpy="0 0 0"/>
            <geometry>
                <box size="0.9593326015542265 0.9580053149930604 0.7995717159139747" />
            </geometry>
        </collision>
    </link>
    <joint name="0_25" type="revolute">
       <parent link="0"/>
       <child  link="25"/>
       <origin rpy="0 0 0" xyz="0 0.75 1" />
     <axis xyz="1 1 0"/>
       <limit effort="0.0" lower="-3.14159" upper="3.14159" velocity="0.0"/>
    </joint>
    <link name="26">
        <inertial>
            <origin xyz="0 0.21558447827303062 0" rpy="0 0 0"/>
            <mass value="1" />
            <inertia ixx="100" ixy="0" ixz="0" iyy="100" iyz="0" izz="100" />
        </inertial>
        <visual>
            <origin xyz="0 0.21558447827303062 0" rpy="0 0 0"/>
            <geometry>
                <box size="0.06862966460566244 0.43116895654606124 0.5548738864175967" />
            </geometry>
            <material name="Green">
                <color rgba="0 128 0 1"/>
            </material>
        </visual>
        <collision>
            <origin xyz="0 0.21558447827303062 0" rpy="0 0 0"/>
            <geometry>
                <box size="0.06862966460566244 0.43116895654606124 0.5548738864175967" />
            </geometry>
        </collision>
    </link>
    <joint name="25_26" type="revolute">
       <parent link="25"/>
       <child  link="26"/>
       <origin rpy="0 0 0" xyz="0 0.9580053149930604 0" />
     <axis xyz="0 1 0"/>
       <limit effort="0.0" lower="-3.14159" upper="3.14159" velocity="0.0"/>
    </joint>
    <link name="27">
        <inertial>
            <origin xyz="0 0.4535521283351761 0" rpy="0 0 0"/>
            <mass value="1" />
            <inertia ixx="100" ixy="0" ixz="0" iyy="100" iyz="0" izz="100" />
        </inertial>
        <visual>
            <origin xyz="0 0.4535521283351761 0" rpy="0 0 0"/>
            <geometry>
                <box size="0.43679350922602356 0.9071042566703522 0.5550898425676191" />
            </geometry>
            <material name="Blue">
                <color rgba="0 0 255 1"/>
            </material>
        </visual>
        <collision>
            <origin xyz="0 0.4535521283351761 0" rpy="0 0 0"/>
            <geometry>
                <box size="0.43679350922602356 0.9071042566703522 0.5550898425676191" />
            </geometry>
        </collision>
    </link>
    <joint name="26_27" type="revolute">
       <parent link="26"/>
       <child  link="27"/>
       <origin rpy="0 0 0" xyz="0 0.43116895654606124 0" />
     <axis xyz="1 0 1"/>
       <limit effort="0.0" lower="-3.14159" upper="3.14159" velocity="0.0"/>
    </joint>
    <link name="28">
        <inertial>
            <origin xyz="0 0.16727524011200556 0" rpy="0 0 0"/>
            <mass value="1" />
            <inertia ixx="100" ixy="0" ixz="0" iyy="100" iyz="0" izz="100" />
        </inertial>
        <visual>
            <origin xyz="0 0.16727524011200556 0" rpy="0 0 0"/>
            <geometry>
                <box size="0.2569737384292363 0.3345504802240111 0.3244184759100228" />
            </geometry>
            <material name="Blue">
                <color rgba="0 0 255 1"/>
            </material>
        </visual>
        <collision>
            <origin xyz="0 0.16727524011200556 0" rpy="0 0 0"/>
            <geometry>
                <box size="0.2569737384292363 0.3345504802240111 0.3244184759100228" />
            </geometry>
        </collision>
    </link>
    <joint name="27_28" type="revolute">
       <parent link="27"/>
       <child  link="28"/>
       <origin rpy="0 0 0" xyz="0 0.9071042566703522 0" />
     <axis xyz="0 1 1"/>
       <limit effort="0.0" lower="-3.14159" upper="3.14159" velocity="0.0"/>
    </joint>
    <link name="29">
        <inertial>
            <origin xyz="0 0.21833865720040935 0" rpy="0 0 0"/>
            <mass value="1" />
            <inertia ixx="100" ixy="0" ixz="0" iyy="100" iyz="0" izz="100" />
        </inertial>
        <visual>
            <origin xyz="0 0.21833865720040935 0" rpy="0 0 0"/>
            <geometry>
                <box size="0.12418261731894142 0.4366773144008187 0.736967027933637" />
            </geometry>
            <material name="Green">
                <color rgba="0 128 0 1"/>
            </material>
        </visual>
        <collision>
            <origin xyz="0 0.21833865720040935 0" rpy="0 0 0"/>
            <geometry>
                <box size="0.12418261731894142 0.4366773144008187 0.736967027933637" />
            </geometry>
        </collision>
    </link>
    <joint name="28_29" type="revolute">
       <parent link="28"/>
       <child  link="29"/>
       <origin rpy="0 0 0" xyz="0 0.3345504802240111 0" />
     <axis xyz="0 0 1"/>
       <limit effort="0.0" lower="-3.14159" upper="3.14159" velocity="0.0"/>
    </joint>
    <link name="30">
        <inertial>
            <origin xyz="0 0 -0.0323337176731837" rpy="0 0 0"/>
            <mass value="1" />
            <inertia ixx="100" ixy="0" ixz="0" iyy="100" iyz="0" izz="100" />
        </inertial>
        <visual>
            <origin xyz="0 0 -0.0323337176731837" rpy="0 0 0"/>
            <geometry>
                <box size="0.22924513907594646 0.37866292451179373 0.0646674353463674" />
            </geometry>
            <material name="Green">
                <color rgba="0 128 0 1"/>
            </material>
        </visual>
        <collision>
            <origin xyz="0 0 -0.0323337176731837" rpy="0 0 0"/>
            <geometry>
                <box size="0.22924513907594646 0.37866292451179373 0.0646674353463674" />
            </geometry>
        </collision>
    </link>
    <joint name="29_30" type="revolute">
       <parent link="29"/>
       <child  link="30"/>
       <origin rpy="0 0 0" xyz="0 0.21833865720040935 -0.3684835139668185" />
     <axis xyz="0 1 0"/>
       <limit effort="0.0" lower="-3.14159" upper="3.14159" velocity="0.0"/>
    </joint>
    <link name="31">
        <inertial>
            <origin xyz="0 0 -0.010196755428137583" rpy="0 0 0"/>
            <mass value="1" />
            <inertia ixx="100" ixy="0" ixz="0" iyy="100" iyz="0" izz="100" />
        </inertial>
        <visual>
            <origin xyz="0 0 -0.010196755428137583" rpy="0 0 0"/>
            <geometry>
                <box size="0.5768010531831533 0.0017050081322609323 0.020393510856275165" />
            </geometry>
            <material name="Green">
                <color rgba="0 128 0 1"/>
            </material>
        </visual>
        <collision>
            <origin xyz="0 0 -0.010196755428137583" rpy="0 0 0"/>
            <geometry>
                <box size="0.5768010531831533 0.0017050081322609323 0.020393510856275165" />
            </geometry>
        </collision>
    </link>
    <joint name="30_31" type="revolute">
       <parent link="30"/>
       <child  link="31"/>
       <origin rpy="0 0 0" xyz="0 0 -0.0646674353463674" />
     <axis xyz="1 1 1"/>
       <limit effort="0.0" lower="-3.14159" upper="3.14159" velocity="0.0"/>
    </joint>
    <link name="32">
        <inertial>
            <origin xyz="0 0 -0.2574695268986787" rpy="0 0 0"/>
            <mass value="1" />
            <inertia ixx="100" ixy="0" ixz="0" iyy="100" iyz="0" izz="100" />
        </inertial>
        <visual>
            <origin xyz="0 0 -0.2574695268986787" rpy="0 0 0"/>
            <geometry>
                <box size="0.30597194430784413 0.6883173459676316 0.5149390537973574" />
            </geometry>
            <material name="Blue">
                <color rgba="0 0 255 1"/>
            </material>
        </visual>
        <collision>
            <origin xyz="0 0 -0.2574695268986787" rpy="0 0 0"/>
            <geometry>
                <box size="0.30597194430784413 0.6883173459676316 0.5149390537973574" />
            </geometry>
        </collision>
    </link>
    <joint name="31_32" type="revolute">
       <parent link="31"/>
       <child  link="32"/>
       <origin rpy="0 0 0" xyz="0 0 -0.020393510856275165" />
     <axis xyz="0 1 1"/>
       <limit effort="0.0" lower="-3.14159" upper="3.14159" velocity="0.0"/>
    </joint>
</robot>